Workbook

Sheet Net
A1: A. Sisa Aset PT BPR Legian (DL) - Netto
B3: Jenis Aset | C3: NP Audited | D3: Setoff Kredit | E3: LANAP | F3: Pencairan Aset s.d. Mei 2021 | G3: Nilai Aset Belum Diselesaikan | H3: % Pencairan (NP) | I3: % Pencairan (LANAP)
B4: (a) | C4: (b) | D4: (c) | E4: (d) | F4: (e) | G4: (f) = (b-c-e) | H4: (g) = (e/(b-c)) | I4: (h) = (e/d)
B5: Kas | C5: 41285600 | E5: 41285600 | F5: 41285600 | G5: =C5-D5-F5 -> 0 | H5: =F5/(C5-D5) -> 1 | I5: =F5/E5 -> 1
B6: Antar Bank Aktiva (ABA) | C6: 6.6624055e+09 | E6: =ABA!F19 -> 6.6624055e+09 | F6: =ABA!G19 -> 7.100292e+08 | G6: =ABA!H19 -> 6001320940 | H6: =F6/(C6-D6) -> 0.1065725 | I6: =F6/E6 -> 0.1065725
B7: Kredit | C7: 1.2695395e+11 | D7: =Kredit!N200 -> 4.2415871e+08 | E7: =Kredit!Z200 -> 1.0133058e+11 | F7: =Kredit!O200 -> 3.6047969e+10 | G7: =C7-D7-F7 -> 9.048182e+10 | H7: =F7/(C7-D7) -> 0.28489709 | I7: =F7/E7 -> 0.35574621
B8: PPAP | C8: -19448944940
B9: Kredit Net | C9: =SUM(C7:C8) -> 1.07505e+11
B10: Aktiva Tetap dan Inventaris | C10: 18360695711
B11: Ak. Penyusutan Aktiva Tetap dan Inventaris | C11: -5565273533
B12: Aktiva Tetap - Nilai Buku | C12: =SUM(C10:C11) -> 12795422178 | E12: ='Tanah dan Bangunan'!E4+Kendaraan!E16+Inventaris!E970 -> 1.4491562e+10 | F12: ='Tanah dan Bangunan'!F4+Kendaraan!F16+Inventaris!F970 -> 2674470000 | G12: ='Tanah dan Bangunan'!G4+Kendaraan!G16+Inventaris!G970 -> 13941214229 | H12: =F12/C12 -> 0.20901772 | I12: =F12/E12 -> 0.1845536
B13: Rupa-Rupa Aktiva
B14: - AYDA | C14: 2.0098758e+10 | E14: 1.3319078e+10 | F14: =AYDA!G25 -> 2.0585047e+09 | G14: =Net!C14-Net!F14 -> 1.8040253e+10 | H14: =F14/C14 -> 0.1024195 | I14: =F14/E14 -> 0.15455309
B15: - PYAD | C15: 239139829 | E15: 3910870709 | F15: =Kredit!P200 -> 3.9680295e+09 | G15: 0 | H15: =F15/C15 -> 16.592926 | I15: =F15/E15 -> 1.0146154
B16: - Akural Denda Kredit | C16: 0 | E16: 1998404527 | F16: =Kredit!Q200 -> 5.1152048e+08 | G16: 0
B17: - Penerimaan Lainnya | C17: 0 | E17: 571652278 | F17: 1.4492681e+09 | G17: 0
B18: Total RRA | C18: =SUM(C14:C17) -> 2.0337898e+10 | D18: =SUM(D14:D17) -> 0 | E18: =SUM(E14:E17) -> 1.9800006e+10 | F18: =SUM(F14:F17) -> 7.9873227e+09 | G18: =SUM(G14:G17) -> 1.8040253e+10 | H18: =F18/C18 -> 0.39273099 | I18: =F18/E18 -> 0.40340002
B19: Total Aset | C19: =C5+C6+C9+C12+C18 -> 1.4734201e+11 | D19: 0 | E19: =E5+E6+E7+E12+E18 -> 1.4232584e+11 | F19: =F5+F6+F7+F12+F18 -> 4.7461077e+10 | G19: =G5+G6+G7+G12+G18 -> 1.2846461e+11 | H19: =F19/C19 -> 0.32211503 | I19: =F19/E19 -> 0.33346775
C21: =SUM(C14:C17) -> 2.0337898e+10 | E21: =SUM(E14:E17) -> 1.9800006e+10 | F21: =SUM(F14:F17) -> 7.9873227e+09 | H21: =F21/C21 -> 0.39273099 | I21: =F21/E21 -> 0.40340002
E24: 97243104404
E25: =E7-E24 -> 4.0874746e+09

Sheet Gross
A1: A. Sisa Aset PT BPR Legian (DL) - Gross
B3: Jenis Aset | C3: NP Audited | D3: Setoff Kredit | E3: LANAP | F3: Pencairan Aset s.d. Mei 2021 | G3: Nilai Aset Belum Diselesaikan | H3: % Pencairan (NP) | I3: % Pencairan (LANAP)
B4: (a) | C4: (b) | D4: (c) | E4: (d) | F4: (e) | G4: (f) = (b-c-e) | H4: (g) = (e/(b-c)) | I4: (h) = (e/d)
B5: Kas | C5: 41285600 | E5: 41285600 | F5: 41285600 | G5: =C5-D5-F5 -> 0 | H5: =F5/(C5-D5) -> 1 | I5: =F5/E5 -> 1
B6: Antar Bank Aktiva (ABA) | C6: 6.6624055e+09 | E6: =ABA!F19 -> 6.6624055e+09 | F6: =ABA!G19 -> 7.100292e+08 | G6: =Net!G6 -> 6001320940 | H6: =F6/(C6-D6) -> 0.1065725 | I6: =F6/E6 -> 0.1065725
B7: Kredit | C7: 1.2695395e+11 | D7: =Kredit!N200 -> 4.2415871e+08 | E7: =Kredit!Z200 -> 1.0133058e+11 | F7: =Kredit!O200 -> 3.6047969e+10 | G7: =C7-D7-F7 -> 9.048182e+10 | H7: =F7/(C7-D7) -> 0.28489709 | I7: =F7/E7 -> 0.35574621
B8: Aktiva Tetap dan Inventaris | C8: 18360695711
B9: Ak. Penyusutan Aktiva Tetap dan Inventaris | C9: -5565273533
B10: Aktiva Tetap - Nilai Buku | C10: =SUM(C8:C9) -> 12795422178 | E10: ='Tanah dan Bangunan'!E4+Kendaraan!E16+Inventaris!E970 -> 1.4491562e+10 | F10: ='Tanah dan Bangunan'!F4+Kendaraan!F16+Inventaris!F970 -> 2674470000 | G10: =Net!G12 -> 13941214229 | H10: =F10/C10 -> 0.20901772 | I10: =F10/E10 -> 0.1845536
B11: Rupa-Rupa Aktiva
B12: - AYDA | C12: 2.0098758e+10 | E12: 1.3319078e+10 | F12: =AYDA!G25 -> 2.0585047e+09 | G12: =Net!G14 -> 1.8040253e+10 | H12: =F12/C12 -> 0.1024195 | I12: =F12/E12 -> 0.15455309
B13: - PYAD | C13: 239139829 | E13: 3910870709 | F13: =Kredit!P200 -> 3.9680295e+09 | G13: =Net!G15 -> 0 | H13: =F13/C13 -> 16.592926 | I13: =F13/E13 -> 1.0146154
B14: - Akural Denda Kredit | C14: 0 | E14: 1998404527 | F14: =Kredit!Q200 -> 5.1152048e+08 | G14: 0
B15: - Penerimaan Lainnya | C15: 0 | E15: 571652278 | F15: 1.4492681e+09 | G15: 0
B16: Total Aset | C16: =C5+C6+C7+C10+C12+C13+C14+C15 -> 1.6679096e+11 | D16: =D5+D6+D7+D10+D12+D13+D14+D15 -> 4.2415871e+08 | E16: =E5+E6+E7+E10+E12+E13+E14+E15 -> 1.4232584e+11 | F16: =F5+F6+F7+F10+F12+F13+F14+F15 -> 4.7461077e+10 | G16: =G5+G6+G7+G10+G12+G13+G14+G15 -> 1.2846461e+11 | H16: =F16/C16 -> 0.28455425 | I16: =F16/E16 -> 0.33346775

Sheet ABA
A2: No. | B2: Nomor Rekening | C2: Uraian Penempatan Pada Bank Lain | D2: Jenis Penempatan Dana | E2: Saldo (NP Audited) | F2: Saldo (LANAP) | G2: Realisasi Pencairan s.d. Mei 2021 | H2: Nilai Aset yang Belum Dicairkan | I2: Keterangan (Cair/Belum Dicairkan) | J2: Strategi Pencairan
A3: 1 | C3: Bank Mandiri - Cab Veteran Denpasar | D3: Giro dan Tabungan | E3: 1700828.8 | F3: 1700828.8 | G3: 1700828.8 | I3: Cair
A4: 2 | C4: Bank BNI Cab Renon Denpsr | D4: Giro dan Tabungan | E4: 76168683 | F4: 76168683 | G4: 76168683 | I4: Cair
A5: 3 | C5: Bank BPD Bali Cab Renon Dpsr | D5: Giro dan Tabungan | E5: 1083390.9 | F5: 1083390.9 | G5: 1083390.9 | I5: Cair
A6: 4 | C6: Bank BCA | D6: Giro dan Tabungan | E6: 10874624 | F6: 10874624 | G6: 10874624 | I6: Cair
A7: 5 | C7: Bank CIMB Niaga | D7: Giro dan Tabungan | E7: 376954845 | F7: 376954845 | G7: 3.7798736e+08 | I7: Cair
A8: 6 | C8: Bank Permata - Dewi Sartika | D8: Giro dan Tabungan | E8: 5001320940 | F8: 5001320940 | G8: 0 | H8: =E8 -> 5001320940 | I8: Belum Cair | J8: Setoff dengan Kewajiban BDL
A9: 7 | C9: Bank Danamon | D9: Giro dan Tabungan | E9: 1973136 | F9: 1973136 | G9: 1973136 | I9: Cair
A10: 8 | C10: Bank BCA | D10: Giro dan Tabungan | E10: 1541708.4 | F10: 1541708.4 | G10: 1541708.4 | I10: Cair
A11: 9 | C11: Bank OK Bank Indonesia | D11: Giro dan Tabungan | E11: 47333657 | F11: 47333657 | G11: 52617188 | I11: Cair
A12: 10 | C12: Bank BNI Cab Renon Denpsr | D12: Giro dan Tabungan | E12: 1343862 | F12: 1343862 | G12: 1343862 | I12: Cair
A13: 11 | C13: Bank Andara - Denpasar | D13: Giro dan Tabungan | E13: 819490.43 | F13: 819490.43 | G13: 819490 | I13: Cair
A14: 12 | C14: Bank BPR Lestari - Denpasar | D14: Giro dan Tabungan | E14: 1461133 | F14: 1461133 | G14: 1461133 | I14: Cair
A15: 13 | C15: Bank BPR Supra - Sukabumi | D15: Giro dan Tabungan | E15: 39829158 | F15: 39829158 | G15: 39829158 | I15: Cair
A16: 14 | C16: Bank Andara - Denpasar | D16: Deposito | E16: 100000000 | F16: 100000000 | G16: 100000000 | I16: Cair
A17: 15 | C17: Bank OK Bank Indonesia | D17: Deposito | E17: 500000000 | F17: 500000000 | G17: 35759621 | H17: =E17 -> 500000000 | I17: Belum Cair | J17: Setoff dengan Kewajiban BDL
A18: 16 | C18: Bank BPR Supra - Sukabumi | D18: Deposito | E18: 500000000 | F18: 500000000 | G18: 6869011.6 | H18: =E18 -> 500000000 | I18: Belum Cair | J18: Setoff dengan Kewajiban BDL
E19: =SUM(E3:E18) -> 6.6624055e+09 | F19: =SUM(F3:F18) -> 6.6624055e+09 | G19: =SUM(G3:G18) -> 7.100292e+08 | H19: =SUM(H3:H18) -> 6001320940
B57: Total | D57: =SUM(D3:D56) -> 0

Sheet Kredit
K2: data set off GPKL
A3: No. | B3: Nomor Rekening | C3: Nama Debitur | D3: Kol. | E3: Baki Debet (NP Audited) | F3: Bunga (NP Audited) | G3: Denda (NP Audited) | H3: Total Kewajiban (NP Audited) | I3: Penyesuaian Bunga Berjalan | J3: Penyesuaian Denda Berjalan | K3: Setoff Pokok | L3: Setoff Bunga | M3: Setoff Denda | N3: Total Setoff | O3: Pencairan Pokok s.d Mei 2021 | P3: Pencairan Bunga s.d Mei 2021 | Q3: Pencairan Denda s.d Mei 2021 | R3: Total Pencairan s.d Mei 2021 | S3: Haircut Bunga s.d Mei 2021 | T3: Haircut Denda s.d Mei 2021 | U3: Sisa Kewajiban Pokok Mei 2021 | V3: Sisa Kewajiban Bunga s.d. Mei 2021 | W3: Sisa Kewajiban Denda s.d. Mei 2021 | X3: Total Sisa Kewajiban s.d. Mei 2021 | Y3: Nilai Likuidasi | Z3: LANAP | AA3: Jenis Agunan | AB3: Jenis Pengikatan | AC3: Keterangan | AD3: Strategi Pencairan | AE3: 44348 | AF3: 44378 | AG3: 44409 | AH3: 44440 | AI3: 44470 | AJ3: 44501 | AK3: 44531 | AL3: 44562 | AM3: 44593 | AN3: 44621 | AO3: 44652 | AP3: 44682 | AQ3: 44713 | AR3: Total
A4: 1 | B4: 02.300408 | C4: Bunardi Podjan | D4: 1 | E4: 7.6251493e+08 | F4: 11231783 | G4: 10972502 | H4: =SUM(E4:G4) -> 7.8471922e+08 | I4: 0 | J4: 0 | K4: 0 | N4: =SUM(K4:M4) -> 0 | O4: 396000000 | P4: 0 | Q4: 0 | R4: =SUM(O4:Q4) -> 396000000 | S4: 0 | T4: 0 | U4: =E4-K4-O4 -> 3.6651493e+08 | V4: =F4+I4-P4-S4 -> 11231783 | W4: =G4+J4-M4-Q4-T4 -> 10972502 | X4: =SUM(U4:W4) -> 3.8871922e+08 | Y4: 1131000000 | Z4: 762514931 | AA4: SHM | AB4: SHT | AC4: Belum Lunas | AD4: Take Over | AE4: 17052632 | AF4: 17052632 | AG4: 17052632 | AH4: 17052632 | AI4: 17052632 | AJ4: 17052632 | AK4: 17052632 | AL4: 17052632 | AM4: 17052632 | AN4: 17052632 | AO4: 17052632 | AP4: =U4-(SUM(AE4:AO4)) -> 1.7893598e+08 | AQ4: 0 | AR4: =SUM(AE4:AQ4) -> 3.6651493e+08
A5: 2 | B5: 02.300506 | C5: Wilman Ardan | D5: 1 | E5: 75054324 | F5: 598573 | G5: 2966605.1 | H5: =SUM(E5:G5) -> 78619502 | I5: 28545351 | J5: 0 | K5: 9023 | N5: =SUM(K5:M5) -> 9023 | O5: 75045301 | P5: 29143924 | Q5: 2966605.1 | R5: =SUM(O5:Q5) -> 1.0715583e+08 | S5: 0 | T5: 0 | U5: =E5-K5-O5 -> 0 | V5: =F5+I5-P5-S5 -> 0 | W5: =G5+J5-M5-Q5-T5 -> 0 | X5: =SUM(U5:W5) -> 0 | Y5: 131000000 | Z5: 75045301 | AA5: SHM | AB5: SHT | AC5: Lunas | AD5: Take Over | AQ5: 0 | AR5: =SUM(AE5:AQ5) -> 0
A6: 3 | B6: 02.300100 | C6: Luluk Badria Murni | D6: 1 | E6: 57660605 | F6: 1365896 | G6: 10489875 | H6: =SUM(E6:G6) -> 69516376 | I6: 11705101 | J6: 10215385 | K6: 8051 | N6: =SUM(K6:M6) -> 8051 | O6: =57660605.07-8051 -> 57652554 | P6: 13070997 | Q6: 20705260 | R6: =SUM(O6:Q6) -> 91428811 | S6: 0 | T6: 0 | U6: =E6-K6-O6 -> 0 | V6: =F6+I6-P6-S6 -> 0 | W6: =G6+J6-M6-Q6-T6 -> 0 | X6: =SUM(U6:W6) -> 0 | Y6: 0 | Z6: 57652554 | AA6: SHM | AB6: SHT | AC6: Lunas | AD6: Lelang KPKNL | AQ6: 0 | AR6: =SUM(AE6:AQ6) -> 0
A7: 4 | B7: 02.300353 | C7: Rokhim | D7: 1 | E7: 47930622 | F7: 263618 | G7: 0 | H7: =SUM(E7:G7) -> 48194240 | I7: 95862 | J7: 2412898 | K7: 0 | N7: =SUM(K7:M7) -> 0 | O7: 47930622 | P7: 359480 | Q7: 2412898 | R7: =SUM(O7:Q7) -> 50703000 | S7: 0 | T7: 0 | U7: =E7-K7-O7 -> 0 | V7: =F7+I7-P7-S7 -> 0 | W7: =G7+J7-M7-Q7-T7 -> 0 | X7: =SUM(U7:W7) -> 0 | Y7: 0 | Z7: 47930622 | AA7: SHM | AB7: SHT | AC7: Lunas | AD7: Lelang KPKNL | AQ7: 0 | AR7: =SUM(AE7:AQ7) -> 0
A8: 5 | B8: 02.300531 | C8: Raju Lusmana | D8: 1 | E8: 6.6148787e+08 | F8: 12237526 | G8: 82574662 | H8: =SUM(E8:G8) -> 7.5630006e+08 | I8: 12035228 | J8: 1146508 | K8: 0 | N8: =SUM(K8:M8) -> 0 | O8: 6.6148787e+08 | P8: 24272754 | Q8: 83721170 | R8: =SUM(O8:Q8) -> 7.6948179e+08 | S8: 0 | T8: 0 | U8: =E8-K8-O8 -> 0 | V8: =F8+I8-P8-S8 -> 0 | W8: =G8+J8-M8-Q8-T8 -> 0 | X8: =SUM(U8:W8) -> 0 | Y8: 0 | Z8: 661487869 | AA8: SHM | AB8: SHT | AC8: Lunas | AD8: Lelang KPKNL | AQ8: 0 | AR8: =SUM(AE8:AQ8) -> 0
A9: 6 | B9: 02.300539 | C9: Kadek Ngurah Robi Juniawan | D9: 1 | E9: 1.6471044e+08 | F9: 1422000 | G9: 0 | H9: =SUM(E9:G9) -> 1.6613244e+08 | I9: 6483419 | J9: 6000 | K9: 20738744 | N9: =SUM(K9:M9) -> 20738744 | O9: 1.439717e+08 | P9: 7905419 | Q9: 6000 | R9: =SUM(O9:Q9) -> 1.5188311e+08 | S9: 0 | T9: 0 | U9: =E9-K9-O9 -> 0 | V9: =F9+I9-P9-S9 -> 0 | W9: =G9+J9-M9-Q9-T9 -> 0 | X9: =SUM(U9:W9) -> 0 | Y9: 0 | Z9: 143971695 | AA9: SHM | AB9: SHT | AC9: Lunas | AD9: Lelang KPKNL | AQ9: 0 | AR9: =SUM(AE9:AQ9) -> 0
A10: 7 | B10: 02.300602 | C10: Putu Ayu Junita Sari | D10: 1 | E10: 38800844 | F10: 206937.72 | G10: 0 | H10: =SUM(E10:G10) -> 39007782 | I10: 0 | J10: 0 | K10: 0 | N10: =SUM(K10:M10) -> 0 | O10: 24527180 | P10: 0 | Q10: 0 | R10: =SUM(O10:Q10) -> 24527180 | S10: 0 | T10: 0 | U10: =E10-K10-O10 -> 14273664 | V10: =F10+I10-P10-S10 -> 206937.72 | W10: =G10+J10-M10-Q10-T10 -> 0 | X10: =SUM(U10:W10) -> 14480602 | Y10: 477000000 | Z10: 38800844 | AA10: SHM | AB10: SHT | AC10: Belum Lunas | AD10: Penagihan Langsung | AE10: 1044302 | AF10: 1044302 | AG10: 1044302 | AH10: 1044302 | AI10: 1044302 | AJ10: 1044302 | AK10: 1044302 | AL10: 1044302 | AM10: 1044302 | AN10: 1044302 | AO10: 1044302 | AP10: =U10-(SUM(AE10:AO10)) -> 2786342.5 | AQ10: 0 | AR10: =SUM(AE10:AQ10) -> 14273664
A11: 8 | B11: 02.300625 | C11: Made Ita Yulita | D11: 1 | E11: 35148500 | F11: 171837 | G11: 0 | H11: =SUM(E11:G11) -> 35320337 | I11: 5686809 | J11: 0 | K11: 84346 | N11: =SUM(K11:M11) -> 84346 | O11: =35061583.76+2570 -> 35064154 | P11: 5858646 | Q11: 0 | R11: =SUM(O11:Q11) -> 40922800 | S11: 0 | T11: 0 | U11: =E11-K11-O11 -> 0 | V11: =F11+I11-P11-S11 -> 0 | W11: =G11+J11-M11-Q11-T11 -> 0 | X11: =SUM(U11:W11) -> 0 | Y11: 0 | Z11: 13014860 | AA11: SHM | AB11: Tidak Ada Pengikatan | AC11: Lunas | AD11: Penagihan Langsung | AQ11: 0 | AR11: =SUM(AE11:AQ11) -> 0
A12: 9 | B12: 02.300666 | C12: Putu Ayu Junita Sari | D12: 1 | E12: 25560631 | F12: 11360.28 | G12: 0 | H12: =SUM(E12:G12) -> 25571991 | I12: 0 | J12: 0 | K12: 0.35219068 | N12: =SUM(K12:M12) -> 0.35219068 | O12: 12442231 | P12: 0 | Q12: 0 | R12: =SUM(O12:Q12) -> 12442231 | S12: 0 | T12: 0 | U12: =E12-K12-O12 -> 13118399 | V12: =F12+I12-P12-S12 -> 11360.28 | W12: =G12+J12-M12-Q12-T12 -> 0 | X12: =SUM(U12:W12) -> 13129760 | Y12: 0 | Z12: 6589591.6 | AA12: SHM | AB12: SHT | AC12: Belum Lunas | AD12: Penagihan Langsung | AE12: 517853.21 | AF12: 517853.21 | AG12: 517853.21 | AH12: 517853.21 | AI12: 517853.21 | AJ12: 517853.21 | AK12: 517853.21 | AL12: 517853.21 | AM12: 517853.21 | AN12: 517853.21 | AO12: 517853.21 | AP12: =U12-(SUM(AE12:AO12)) -> 7422014 | AQ12: 0 | AR12: =SUM(AE12:AQ12) -> 13118399
A13: 10 | B13: 02.300681 | C13: I Nyoman Sidia | D13: 1 | E13: 7.4125969e+08 | F13: 6486022.2 | G13: 221818.86 | H13: =SUM(E13:G13) -> 7.4796753e+08 | I13: 0 | J13: 0 | K13: 9023 | N13: =SUM(K13:M13) -> 9023 | O13: 139109592 | P13: 0 | Q13: 0 | R13: =SUM(O13:Q13) -> 139109592 | S13: 0 | T13: 0 | U13: =E13-K13-O13 -> 6.0214107e+08 | V13: =F13+I13-P13-S13 -> 6486022.2 | W13: =G13+J13-M13-Q13-T13 -> 221818.86 | X13: =SUM(U13:W13) -> 6.0884892e+08 | Y13: 1220000000 | Z13: 741250667 | AA13: SHM | AB13: SHT | AC13: Belum Lunas | AD13: Lelang KPKNL | AF13: 6.0884892e+08 | AQ13: 0 | AR13: =SUM(AE13:AQ13) -> 6.0884892e+08
A14: 11 | B14: 02.300695 | C14: Made Wira Sastrawan | D14: 1 | E14: 3970117.9 | F14: 31761 | G14: 0 | H14: =SUM(E14:G14) -> 4001878.9 | I14: 404796 | J14: 0 | K14: 35351 | N14: =SUM(K14:M14) -> 35351 | O14: 3934766.9 | P14: 436557 | Q14: 0 | R14: =SUM(O14:Q14) -> 4371323.9 | S14: 0 | T14: 0 | U14: =E14-K14-O14 -> 0 | V14: =F14+I14-P14-S14 -> 0 | W14: =G14+J14-M14-Q14-T14 -> 0 | X14: =SUM(U14:W14) -> 0 | Y14: 0 | Z14: 1175116 | AA14: BPKB | AB14: Tidak Ada Pengikatan | AC14: Lunas | AD14: Penagihan Langsung | AQ14: 0 | AR14: =SUM(AE14:AQ14) -> 0
A15: 12 | B15: 02.300701 | C15: I Ketut Sariyana | D15: 1 | E15: 8170422.4 | F15: 72626 | G15: 0 | H15: =SUM(E15:G15) -> 8243048.4 | I15: 1439405 | J15: 0 | K15: 30699 | N15: =SUM(K15:M15) -> 30699 | O15: 8139723.4 | P15: 1512031 | Q15: 0 | R15: =SUM(O15:Q15) -> 9651754.4 | S15: 0 | T15: 0 | U15: =E15-K15-O15 -> 0 | V15: =F15+I15-P15-S15 -> 0 | W15: =G15+J15-M15-Q15-T15 -> 0 | X15: =SUM(U15:W15) -> 0 | Y15: 0 | Z15: 5273550 | AA15: BPKB | AB15: Tidak Ada Pengikatan | AC15: Lunas | AD15: Penagihan Langsung | AQ15: 0 | AR15: =SUM(AE15:AQ15) -> 0
A16: 13 | B16: 02.300702 | C16: I Gede Dananjaya Siadja | D16: 1 | E16: 5.6666523e+08 | F16: 8074979 | G16: 0 | H16: =SUM(E16:G16) -> 5.7474021e+08 | I16: 41922585 | J16: 64294 | K16: 34315042 | N16: =SUM(K16:M16) -> 34315042 | O16: 5.3235019e+08 | P16: 49997564 | Q16: 64294 | R16: =SUM(O16:Q16) -> 5.8241204e+08 | S16: 0 | T16: 0 | U16: =E16-K16-O16 -> 0 | V16: =F16+I16-P16-S16 -> 0 | W16: =G16+J16-M16-Q16-T16 -> 0 | X16: =SUM(U16:W16) -> 0 | Y16: 0 | Z16: 532350186 | AA16: SHM | AB16: SHT | AC16: Lunas | AD16: Lelang KPKNL | AQ16: 0 | AR16: =SUM(AE16:AQ16) -> 0
A17: 14 | B17: 02.300703 | C17: Ni Nengah Nuasih | D17: 1 | E17: 16340836 | F17: 137989 | G17: 0 | H17: =SUM(E17:G17) -> 16478825 | I17: 2772161 | J17: 0 | K17: 56496 | N17: =SUM(K17:M17) -> 56496 | O17: 16284340 | P17: 2910150 | Q17: 0 | R17: =SUM(O17:Q17) -> 19194490 | S17: 0 | T17: 0 | U17: =E17-K17-O17 -> 0 | V17: =F17+I17-P17-S17 -> 0 | W17: =G17+J17-M17-Q17-T17 -> 0 | X17: =SUM(U17:W17) -> 0 | Y17: 0 | Z17: 7670128 | AA17: BPKB | AB17: Tidak Ada Pengikatan | AC17: Lunas | AD17: Penagihan Langsung | AQ17: 0 | AR17: =SUM(AE17:AQ17) -> 0
A18: 15 | B18: 02.300707 | C18: I Ketut Subagia | D18: 1 | E18: 72632800 | F18: 355093.64 | G18: 0 | H18: =SUM(E18:G18) -> 72987894 | I18: 17661768 | J18: 0 | K18: 48103 | N18: =SUM(K18:M18) -> 48103 | O18: =72632800-48103 -> 72584697 | P18: 18016862 | Q18: 0 | R18: =SUM(O18:Q18) -> 90601559 | S18: 0 | T18: 0 | U18: 0 | V18: =F18+I18-P18-S18 -> 0 | W18: =G18+J18-M18-Q18-T18 -> 0 | X18: =SUM(U18:W18) -> 0 | Y18: 0 | Z18: 29181685 | AA18: SHM | AB18: Tidak Ada Pengikatan | AC18: Lunas | AD18: Penagihan Langsung | AQ18: 0 | AR18: =SUM(AE18:AQ18) -> 0
A19: 16 | B19: 02.300709 | C19: I Putu Widi Indriyana | D19: 1 | E19: 29434506 | F19: 353214 | G19: 0 | H19: =SUM(E19:G19) -> 29787720 | I19: 4399453 | J19: 0 | K19: 95713 | N19: =SUM(K19:M19) -> 95713 | O19: =29434506-95713 -> 29338793 | P19: 4752667 | Q19: 0 | R19: =SUM(O19:Q19) -> 34091460 | S19: 0 | T19: 0 | U19: 0 | V19: =F19+I19-P19-S19 -> 0 | W19: =G19+J19-M19-Q19-T19 -> 0 | X19: =SUM(U19:W19) -> 0 | Y19: 0 | Z19: 29338793 | AA19: BPKB | AB19: Tidak Ada Pengikatan | AC19: Lunas | AD19: Penagihan Langsung | AQ19: 0 | AR19: =SUM(AE19:AQ19) -> 0
A20: 17 | B20: 02.300714 | C20: I Wayan Widiatmika Kurniawan | D20: 1 | E20: 11105856 | F20: 64167 | G20: 0 | H20: =SUM(E20:G20) -> 11170023 | I20: 767759 | J20: 0 | K20: 127596 | N20: =SUM(K20:M20) -> 127596 | O20: =11105856-127596 -> 10978260 | P20: 831926 | Q20: 0 | R20: =SUM(O20:Q20) -> 11810186 | S20: 0 | T20: 0 | U20: 0 | V20: =F20+I20-P20-S20 -> 0 | W20: =G20+J20-M20-Q20-T20 -> 0 | X20: =SUM(U20:W20) -> 0 | Y20: 0 | Z20: 10978260 | AA20: BPKB | AB20: Tidak Ada Pengikatan | AC20: Lunas | AD20: Penagihan Langsung | AQ20: 0 | AR20: =SUM(AE20:AQ20) -> 0
A21: 18 | B21: 02.300721 | C21: I Putu Gede Wirawan | D21: 1 | E21: 12463477 | F21: 149562 | G21: 0 | H21: =SUM(E21:G21) -> 12613039 | I21: 1637896 | J21: 0 | K21: 63434 | N21: =SUM(K21:M21) -> 63434 | O21: 12400043 | P21: 1787458 | Q21: 0 | R21: =SUM(O21:Q21) -> 14187501 | S21: 0 | T21: 0 | U21: =E21-K21-O21 -> 0 | V21: =F21+I21-P21-S21 -> 0 | W21: =G21+J21-M21-Q21-T21 -> 0 | X21: =SUM(U21:W21) -> 0 | Y21: 0 | Z21: 8917510 | AA21: BPKB | AB21: Tidak Ada Pengikatan | AC21: Lunas | AD21: Penagihan Langsung | AQ21: 0 | AR21: =SUM(AE21:AQ21) -> 0
A22: 19 | B22: 02.300737 | C22: I Putu Wastika | D22: 1 | E22: 45345152 | F22: 80613.6 | G22: 0 | H22: =SUM(E22:G22) -> 45425765 | I22: 0 | J22: 0 | K22: 63773 | N22: =SUM(K22:M22) -> 63773 | O22: 12172098 | P22: 0 | Q22: 0 | R22: =SUM(O22:Q22) -> 12172098 | S22: 0 | T22: 0 | U22: =E22-K22-O22 -> 33109281 | V22: =F22+I22-P22-S22 -> 80613.6 | W22: =G22+J22-M22-Q22-T22 -> 0 | X22: =SUM(U22:W22) -> 33189894 | Y22: 0 | Z22: 2253000 | AA22: BPKB | AB22: Tidak Ada Pengikatan | AC22: Belum Lunas | AD22: Cessie | AQ22: 1655464 | AR22: =SUM(AE22:AQ22) -> 1655464 | AT22: =AR22/U22 -> 0.05
A23: 20 | B23: 02.200010 | C23: Supyan Yusuf | D23: 1 | E23: 25300984 | F23: 215901 | G23: 2417073 | H23: =SUM(E23:G23) -> 27933958 | I23: 312978 | J23: 47064 | K23: 0 | N23: =SUM(K23:M23) -> 0 | O23: 25300984 | P23: 528879 | Q23: 2464137 | R23: =SUM(O23:Q23) -> 28294000 | S23: 0 | T23: 0 | U23: =E23-K23-O23 -> 0 | V23: =F23+I23-P23-S23 -> 0 | W23: =G23+J23-M23-Q23-T23 -> 0 | X23: =SUM(U23:W23) -> 0 | Y23: 0 | Z23: 25300984 | AA23: SHM | AB23: SHT | AC23: Lunas | AD23: Lelang KPKNL | AQ23: 0 | AR23: =SUM(AE23:AQ23) -> 0
A24: 21 | B24: 02.200125 | C24: Darmika Dewa Gede | D24: 1 | E24: 50005033 | F24: 373371 | G24: 305152 | H24: =SUM(E24:G24) -> 50683556 | I24: 709327 | J24: 6000 | K24: 0 | N24: =SUM(K24:M24) -> 0 | O24: 50005033 | P24: 1082698 | Q24: 311152 | R24: =SUM(O24:Q24) -> 51398883 | S24: 0 | T24: 0 | U24: =E24-K24-O24 -> 0 | V24: =F24+I24-P24-S24 -> 0 | W24: =G24+J24-M24-Q24-T24 -> 0 | X24: =SUM(U24:W24) -> 0 | Y24: 0 | Z24: 50005033 | AA24: SHM | AB24: SHT | AC24: Lunas | AD24: Lelang KPKNL | AQ24: 0 | AR24: =SUM(AE24:AQ24) -> 0
A25: 22 | B25: 02.200335 | C25: Aloisius Rendi Holo | D25: 1 | E25: 23599551 | F25: 73421 | G25: 0 | H25: =SUM(E25:G25) -> 23672972 | I25: 1691586 | J25: 0 | K25: 0 | N25: =SUM(K25:M25) -> 0 | O25: 23599551 | P25: 1765007 | Q25: 0 | R25: =SUM(O25:Q25) -> 25364558 | S25: 0 | T25: 0 | U25: =E25-K25-O25 -> 0 | V25: =F25+I25-P25-S25 -> 0 | W25: =G25+J25-M25-Q25-T25 -> 0 | X25: =SUM(U25:W25) -> 0 | Y25: 0 | Z25: 23599551 | AA25: BPKB | AB25: Tidak Ada Pengikatan | AC25: Lunas | AD25: Penagihan Langsung | AQ25: 0 | AR25: =SUM(AE25:AQ25) -> 0
A26: 23 | B26: 02.200337 | C26: Anak Agung Istri Vera Raditya | D26: 1 | E26: 65803638 | F26: 175476 | G26: 0 | H26: =SUM(E26:G26) -> 65979114 | I26: 2292415 | J26: 0 | K26: 0 | N26: =SUM(K26:M26) -> 0 | O26: 65803638 | P26: 2467891 | Q26: 0 | R26: =SUM(O26:Q26) -> 68271529 | S26: 0 | T26: 0 | U26: =E26-K26-O26 -> 0 | V26: =F26+I26-P26-S26 -> 0 | W26: =G26+J26-M26-Q26-T26 -> 0 | X26: =SUM(U26:W26) -> 0 | Y26: 0 | Z26: 65803638 | AA26: BPKB | AB26: Tidak Ada Pengikatan | AC26: Lunas | AD26: Penagihan Langsung | AQ26: 0 | AR26: =SUM(AE26:AQ26) -> 0
A27: 24 | B27: 02.200342 | C27: Aloisius Rendi Holo | D27: 1 | E27: 483191.4 | F27: 0 | G27: 0 | H27: =SUM(E27:G27) -> 483191.4 | I27: 6440 | J27: 0 | K27: 0 | N27: =SUM(K27:M27) -> 0 | O27: 483191.4 | P27: 6440 | Q27: 0 | R27: =SUM(O27:Q27) -> 489631.4 | S27: 0 | T27: 0 | U27: =E27-K27-O27 -> 0 | V27: =F27+I27-P27-S27 -> 0 | W27: =G27+J27-M27-Q27-T27 -> 0 | X27: =SUM(U27:W27) -> 0 | Y27: 0 | Z27: 483191 | AA27: BPKB | AB27: Tidak Ada Pengikatan | AC27: Lunas | AD27: Penagihan Langsung | AQ27: 0 | AR27: =SUM(AE27:AQ27) -> 0
A28: 25 | B28: 02.200357 | C28: Dewa Nyoman Widnyana | D28: 1 | E28: 3.9573665e+08 | F28: 1846771 | G28: 0 | H28: =SUM(E28:G28) -> 3.9758342e+08 | I28: 0 | J28: 0 | K28: 120862 | N28: =SUM(K28:M28) -> 120862 | O28: 147500000 | P28: 0 | Q28: 0 | R28: =SUM(O28:Q28) -> 147500000 | S28: 0 | T28: 0 | U28: =E28-K28-O28 -> 2.4811579e+08 | V28: =F28+I28-P28-S28 -> 1846771 | W28: =G28+J28-M28-Q28-T28 -> 0 | X28: =SUM(U28:W28) -> 2.4996256e+08 | Y28: 351000000 | Z28: 358000000 | AA28: SHM | AB28: SHT | AC28: Belum Lunas | AD28: Lelang KPKNL | AG28: 2.4996256e+08 | AQ28: 0 | AR28: =SUM(AE28:AQ28) -> 2.4996256e+08
A29: 26 | B29: 02.100361 | C29: I Wayan Mertawa SH | D29: 1 | E29: 12553932 | F29: 224506 | G29: 1259140 | H29: =SUM(E29:G29) -> 14037578 | I29: 257995 | J29: 98627 | K29: 0 | N29: =SUM(K29:M29) -> 0 | O29: 12553932 | P29: 482501 | Q29: 1357767 | R29: =SUM(O29:Q29) -> 14394200 | S29: 0 | T29: 0 | U29: =E29-K29-O29 -> 0 | V29: =F29+I29-P29-S29 -> 0 | W29: =G29+J29-M29-Q29-T29 -> 0 | X29: =SUM(U29:W29) -> 0 | Y29: 0 | Z29: 12553932 | AA29: SHM | AB29: SKMHT | AC29: Lunas | AD29: Penagihan Langsung | AQ29: 0 | AR29: =SUM(AE29:AQ29) -> 0
A30: 27 | B30: 02.100377 | C30: Ni Pande Putu Andri Liani | D30: 1 | E30: 10505589 | F30: 297003 | G30: 166802 | H30: =SUM(E30:G30) -> 10969394 | I30: 19553 | J30: 349053 | K30: 0 | N30: =SUM(K30:M30) -> 0 | O30: 10505589 | P30: 316556 | Q30: 515855 | R30: =SUM(O30:Q30) -> 11338000 | S30: 0 | T30: 0 | U30: =E30-K30-O30 -> 0 | V30: =F30+I30-P30-S30 -> 0 | W30: =G30+J30-M30-Q30-T30 -> 0 | X30: =SUM(U30:W30) -> 0 | Y30: 0 | Z30: 10505589 | AA30: SHM | AB30: SHT | AC30: Lunas | AD30: Lelang KPKNL | AQ30: 0 | AR30: =SUM(AE30:AQ30) -> 0
A31: 28 | B31: 02.100382 | C31: Made Ayu Ima Pradasari | D31: 1 | E31: 13716015 | F31: 276507 | G31: 21808954 | H31: =SUM(E31:G31) -> 35801476 | I31: 234085 | J31: 0 | K31: 0 | N31: =SUM(K31:M31) -> 0 | O31: 13716015 | P31: 510592 | Q31: 53392 | R31: =SUM(O31:Q31) -> 14279999 | S31: 0 | T31: 21755562 | U31: =E31-K31-O31 -> 0 | V31: =F31+I31-P31-S31 -> 0 | W31: =G31+J31-M31-Q31-T31 -> 0 | X31: =SUM(U31:W31) -> 0 | Y31: 0 | Z31: 13716015 | AA31: SHM | AB31: SHT | AC31: Lunas | AD31: Lelang KPKNL | AQ31: 0 | AR31: =SUM(AE31:AQ31) -> 0
A32: 29 | B32: 02.100437 | C32: Ni Made Ayu Sita Setyawati | D32: 1 | E32: 92500000 | F32: 388500 | G32: 0 | H32: =SUM(E32:G32) -> 92888500 | I32: 777000 | J32: 2791000 | K32: 0 | N32: =SUM(K32:M32) -> 0 | O32: 92500000 | P32: 1165500 | Q32: 2791000 | R32: =SUM(O32:Q32) -> 96456500 | S32: 0 | T32: 0 | U32: =E32-K32-O32 -> 0 | V32: =F32+I32-P32-S32 -> 0 | W32: =G32+J32-M32-Q32-T32 -> 0 | X32: =SUM(U32:W32) -> 0 | Y32: 0 | Z32: 92500000 | AA32: SHM | AB32: SHT | AC32: Lunas | AD32: Lelang KPKNL | AQ32: 0 | AR32: =SUM(AE32:AQ32) -> 0
A33: 30 | B33: 02.100449 | C33: Ni Wayan Astini | D33: 1 | E33: 47516925 | F33: 211186 | G33: 0 | H33: =SUM(E33:G33) -> 47728111 | I33: 546971 | J33: 0 | K33: 0 | N33: =SUM(K33:M33) -> 0 | O33: 47516925 | P33: 758157 | Q33: 0 | R33: =SUM(O33:Q33) -> 48275082 | S33: 0 | T33: 0 | U33: =E33-K33-O33 -> 0 | V33: =F33+I33-P33-S33 -> 0 | W33: =G33+J33-M33-Q33-T33 -> 0 | X33: =SUM(U33:W33) -> 0 | Y33: 0 | Z33: 47516925 | AA33: BPKB | AB33: Tidak Ada Pengikatan | AC33: Lunas | AD33: Penagihan Langsung | AQ33: 0 | AR33: =SUM(AE33:AQ33) -> 0
A34: 31 | B34: 02.100404 | C34: I Gede Ketut Dinamika | D34: 1 | E34: 24875216 | F34: 1767712 | G34: 6690777 | H34: =SUM(E34:G34) -> 33333705 | I34: 340902 | J34: 277480 | K34: 0 | N34: =SUM(K34:M34) -> 0 | O34: 24875216 | P34: 2108614 | Q34: 6968257 | R34: =SUM(O34:Q34) -> 33952087 | S34: 0 | T34: 0 | U34: 0 | V34: =F34+I34-P34-S34 -> 0 | W34: =G34+J34-M34-Q34-T34 -> 0 | X34: =SUM(U34:W34) -> 0 | Y34: 0 | Z34: 24875217 | AA34: SHM | AB34: SKMHT | AC34: Lunas | AD34: Penagihan Langsung | AQ34: 0 | AR34: =SUM(AE34:AQ34) -> 0
A35: 32 | B35: 02.300667 | C35: I Ketut Minsana | D35: 1 | E35: 109374995 | F35: 2233593 | G35: 0 | H35: =SUM(E35:G35) -> 111608588 | I35: 5414062 | J35: 167000 | K35: 0 | N35: =SUM(K35:M35) -> 0 | O35: 109374995 | P35: 7647655 | Q35: 167000 | R35: =SUM(O35:Q35) -> 117189650 | S35: 0 | T35: 0 | U35: =E35-K35-O35 -> 0 | V35: =F35+I35-P35-S35 -> 0 | W35: =G35+J35-M35-Q35-T35 -> 0 | X35: =SUM(U35:W35) -> 0 | Y35: 0 | Z35: 1.0946986e+08 | AA35: SHM | AB35: SHT | AC35: Lunas | AD35: Lelang KPKNL | AQ35: 0 | AR35: =SUM(AE35:AQ35) -> 0
A36: 33 | B36: 02.300561 | C36: Pt.Bali Selancar Laut Biru | D36: 1 | E36: 3.967943e+08 | F36: 3915037 | G36: 434633 | H36: =SUM(E36:G36) -> 4.0114397e+08 | I36: 24476895 | J36: 6000 | K36: 9023 | N36: =SUM(K36:M36) -> 9023 | O36: =396794304-9023 -> 396785281 | P36: 28391932 | Q36: 440633 | R36: =SUM(O36:Q36) -> 425617846 | S36: 0 | T36: 0 | U36: 0 | V36: =F36+I36-P36-S36 -> 0 | W36: =G36+J36-M36-Q36-T36 -> 0 | X36: =SUM(U36:W36) -> 0 | Y36: 0 | Z36: 396785281 | AA36: SHM | AB36: SHT | AC36: Lunas | AD36: Lelang KPKNL | AQ36: 0 | AR36: =SUM(AE36:AQ36) -> 0
A37: 34 | B37: 02.300620 | C37: Ni Putu Novi Wulandari | D37: 1 | E37: 9.8497513e+08 | F37: 16416252 | G37: 1713215.3 | H37: =SUM(E37:G37) -> 1.0031046e+09 | I37: 0 | J37: 0 | K37: 41566056 | N37: =SUM(K37:M37) -> 41566056 | O37: 51000000 | P37: 0 | Q37: 0 | R37: =SUM(O37:Q37) -> 51000000 | S37: 0 | T37: 0 | U37: =E37-K37-O37 -> 8.9240908e+08 | V37: =F37+I37-P37-S37 -> 16416252 | W37: =G37+J37-M37-Q37-T37 -> 1713215.3 | X37: =SUM(U37:W37) -> 9.1053854e+08 | Y37: 1034000000 | Z37: 943409077 | AA37: SHM | AB37: SHT | AC37: Belum Lunas | AD37: Cessie | AQ37: 1.7848182e+08 | AR37: =SUM(AE37:AQ37) -> 1.7848182e+08 | AT37: =AR37/U37 -> 0.2
A38: 35 | B38: 02.300186 | C38: I Ketut Minsana | D38: 1 | E38: 52500000 | F38: 844375 | G38: 0 | H38: =SUM(E38:G38) -> 53344375 | I38: 2266572 | J38: 366240 | K38: 245322 | N38: =SUM(K38:M38) -> 245322 | O38: =52500000-245322 -> 52254678 | P38: 3110947 | Q38: 366240 | R38: =SUM(O38:Q38) -> 55731865 | S38: 0 | T38: 0 | U38: =E38-K38-O38 -> 0 | V38: =F38+I38-P38-S38 -> 0 | W38: =G38+J38-M38-Q38-T38 -> 0 | X38: =SUM(U38:W38) -> 0 | Y38: 0 | Z38: 52329906 | AA38: SHM | AB38: SHT | AC38: Lunas | AD38: Lelang KPKNL | AQ38: 0 | AR38: =SUM(AE38:AQ38) -> 0
A39: 36 | B39: 02.200245 | C39: Sebe Adi Putra I Made | D39: 1 | E39: 146066688 | F39: 832580 | G39: 0 | H39: =SUM(E39:G39) -> 146899268 | I39: 4810463 | J39: 4697955 | K39: 587161 | N39: =SUM(K39:M39) -> 587161 | O39: 145479527 | P39: 5643043 | Q39: 4697955 | R39: =SUM(O39:Q39) -> 155820525 | S39: 0 | T39: 0 | U39: =E39-K39-O39 -> 0 | V39: =F39+I39-P39-S39 -> 0 | W39: =G39+J39-M39-Q39-T39 -> 0 | X39: =SUM(U39:W39) -> 0 | Y39: 0 | Z39: 145479527 | AA39: SHM | AB39: SHT | AC39: Lunas | AD39: Lelang KPKNL | AQ39: 0 | AR39: =SUM(AE39:AQ39) -> 0
A40: 37 | B40: 02.200345 | C40: Dwinata Yudistira Putra | D40: 1 | E40: 3.2569071e+08 | F40: 5824435 | G40: 0 | H40: =SUM(E40:G40) -> 3.3151515e+08 | I40: 7623875 | J40: 450610 | K40: 0 | N40: =SUM(K40:M40) -> 0 | O40: 3.2569071e+08 | P40: 13448310 | Q40: 450610 | R40: =SUM(O40:Q40) -> 3.3958963e+08 | S40: 0 | T40: 0 | U40: =E40-K40-O40 -> 0 | V40: =F40+I40-P40-S40 -> 0 | W40: =G40+J40-M40-Q40-T40 -> 0 | X40: =SUM(U40:W40) -> 0 | Y40: 0 | Z40: 325690712 | AA40: SHM | AB40: SHT | AC40: Lunas | AD40: Lelang KPKNL | AQ40: 0 | AR40: =SUM(AE40:AQ40) -> 0
A41: 38 | B41: 02.200321 | C41: I Gede Andriawan Dusak | D41: 1 | E41: 1.2614077e+09 | F41: 8549478 | G41: 1.5994968e+08 | H41: =SUM(E41:G41) -> 1.4299068e+09 | I41: 0 | J41: 0 | K41: 0 | N41: =SUM(K41:M41) -> 0 | O41: 62410000 | P41: 0 | Q41: 0 | R41: =SUM(O41:Q41) -> 62410000 | S41: 0 | T41: 0 | U41: =E41-K41-O41 -> 1.1989977e+09 | V41: =F41+I41-P41-S41 -> 8549478 | W41: =G41+J41-M41-Q41-T41 -> 1.5994968e+08 | X41: =SUM(U41:W41) -> 1.3674968e+09 | Y41: 766000000 | Z41: 766000000 | AA41: SHM | AB41: SHT | AC41: Belum Lunas | AD41: Lelang KPKNL | AG41: 766000000 | AQ41: 0 | AR41: =SUM(AE41:AQ41) -> 766000000
...

Sheet Resume Kredit
A3: Row Labels | B3: Count of Nama Debitur | C3: Sum of Baki Debet (NP Audited) | D3: Sum of Setoff Pokok | E3: Sum of Pencairan Pokok s.d Mei 2021 | F3: Sum of Sisa Kewajiban Pokok Mei 2021 | G3: Sum of LANAP
A4: Belum Lunas | B4: 120 | C4: 1.0550826e+11 | D4: 3.4377527e+08 | E4: 1.4682665e+10 | F4: 9.048182e+10 | G4: 8.1143591e+10
A5: 1 | B5: 13 | C5: 8.1738587e+09 | D5: 1.8143095e+08 | E5: 2.4599068e+09 | F5: 5.5325209e+09 | G5: 6.7057287e+09
A6: 2 | B6: 19 | C6: 1.8389923e+10 | D6: 52993628 | E6: 4.1090957e+09 | F6: 1.4227834e+10 | G6: 1.2995258e+10
A7: 3 | B7: 13 | C7: 1.4180757e+10 | D7: 39299 | E7: 1.3528918e+09 | F7: 1.2827826e+10 | G7: 1.2024772e+10
A8: 4 | B8: 75 | C8: 6.4763721e+10 | D8: 109311391 | E8: 6.7607707e+09 | F8: 5.7893639e+10 | G8: 49417832431
A9: Lunas | B9: 76 | C9: 2.1445688e+10 | D9: 80383442 | E9: 2.1365304e+10 | F9: 0 | G9: 2.0186988e+10
A10: 1 | B10: 43 | C10: 6.561002e+09 | D10: 64476662 | E10: 6.4965254e+09 | F10: 0 | G10: 6.2849566e+09
A11: 2 | B11: 6 | C11: 2283424883 | D11: 56181 | E11: 2283368702 | F11: 0 | G11: 2283368702
A12: 3 | B12: 8 | C12: 4.2574023e+09 | D12: 63779 | E12: 4.2573385e+09 | F12: 0 | G12: 3.4054137e+09
A13: 4 | B13: 19 | C13: 8.3438584e+09 | D13: 15786820 | E13: 8.3280716e+09 | F13: 0 | G13: 8213248885
A14: Grand Total | B14: 196 | C14: 1.2695395e+11 | D14: 4.2415871e+08 | E14: 3.6047969e+10 | F14: 9.048182e+10 | G14: 1.0133058e+11
A16: Keterangan | B16: Kol. | C16: Jumlah Debitur | D16: Baki Debet (NP Audited) | E16: Setoff Pokok | F16: Pencairan s.d. Mei 2021 | G16: Sisa Kewajiban Pokok s.d. Mei 2021
A17: (1) | B17: (2) | C17: (3) | D17: (4) | E17: (5) | F17: (6) | G17: (7) = (4) - (5) - (6)
A18: Belum Lunas | B18: 1 | C18: 13 | D18: 8.1738587e+09 | E18: 1.8143095e+08 | F18: 2.4599068e+09 | G18: =D18-E18-F18 -> 5.5325209e+09
B19: 2 | C19: 19 | D19: 1.8389923e+10 | E19: 52993628 | F19: 4.1090957e+09 | G19: =D19-E19-F19 -> 1.4227834e+10
B20: 3 | C20: 13 | D20: 1.4180757e+10 | E20: 39299 | F20: 1.3528918e+09 | G20: =D20-E20-F20 -> 1.2827826e+10
B21: 4 | C21: 75 | D21: 6.4763721e+10 | E21: 109311391 | F21: 6.7607707e+09 | G21: =D21-E21-F21 -> 5.7893639e+10
A22: Subtotal | C22: =SUM(C18:C21) -> 120 | D22: =SUM(D18:D21) -> 1.0550826e+11 | E22: =SUM(E18:E21) -> 3.4377527e+08 | F22: =SUM(F18:F21) -> 1.4682665e+10 | G22: =SUM(G18:G21) -> 9.048182e+10
A23: Lunas | B23: 1 | C23: 43 | D23: 6.561002e+09 | E23: 64476662 | F23: 6.4965254e+09 | G23: 0
B24: 2 | C24: 6 | D24: 2283424883 | E24: 56181 | F24: 2283368702 | G24: =D24-E24-F24 -> 0
B25: 3 | C25: 8 | D25: 4.2574023e+09 | E25: 63779 | F25: 4.2573385e+09 | G25: =D25-E25-F25 -> 0
B26: 4 | C26: 19 | D26: 8.3438584e+09 | E26: 15786820 | F26: 8.3280716e+09 | G26: =D26-E26-F26 -> 0
A27: Subtotal | C27: =SUM(C23:C26) -> 76 | D27: =SUM(D23:D26) -> 2.1445688e+10 | E27: =SUM(E23:E26) -> 80383442 | F27: =SUM(F23:F26) -> 2.1365304e+10 | G27: =SUM(G23:G26) -> 0
A28: Grand Total | C28: =C22+C27 -> 196 | D28: =D22+D27 -> 1.2695395e+11 | E28: =E22+E27 -> 4.2415871e+08 | F28: =F22+F27 -> 3.6047969e+10 | G28: =G22+G27 -> 9.048182e+10
A31: Row Labels | B31: Count of Nama Debitur | C31: Sum of Baki Debet (NP Audited) | D31: Sum of Setoff Pokok | E31: Sum of Pencairan Pokok s.d Mei 2021 | F31: Sum of Sisa Kewajiban Pokok Mei 2021 | I31: Kol. | J31: Jenis Agunan | K31: Jenis Pengikatan | L31: Jumlah Debitur | M31: Baki Debet (NP Audited) | N31: Setoff Pokok | O31: Pencairan s.d. Mei 2021 | P31: Sisa Kewajiban Pokok s.d. Mei 2021
A32: Belum Lunas | B32: 120 | C32: 1.0550826e+11 | D32: 3.4377527e+08 | E32: 1.4682665e+10 | F32: 9.048182e+10 | I32: (1) | J32: (2) | K32: (3) | L32: (4) | M32: (5) | N32: (6) | O32: (7) | P32: (8) = (5) - (6) - (7)
A33: 1 | B33: 13 | C33: 8.1738587e+09 | D33: 1.8143095e+08 | E33: 2.4599068e+09 | F33: 5.5325209e+09 | I33: 1 | J33: BPKB | K33: Tidak Ada Pengikatan | L33: 1 | M33: 45345152 | N33: 63773 | O33: 12172098 | P33: 33109281
A34: BPKB | B34: 1 | C34: 45345152 | D34: 63773 | E34: 12172098 | F34: 33109281 | J34: SHM | K34: SHT | L34: 12 | M34: 8.1285136e+09 | N34: 1.8136718e+08 | O34: 2447734749 | P34: 5.4994116e+09
A35: Tidak Ada Pengikatan | B35: 1 | C35: 45345152 | D35: 63773 | E35: 12172098 | F35: 33109281 | L35: =SUM(L33:L34) -> 13 | M35: =SUM(M33:M34) -> 8.1738587e+09 | N35: =SUM(N33:N34) -> 1.8143095e+08 | O35: =SUM(O33:O34) -> 2.4599068e+09 | P35: =SUM(P33:P34) -> 5.5325209e+09
A36: SHM | B36: 12 | C36: 8.1285136e+09 | D36: 1.8136718e+08 | E36: 2447734749 | F36: 5.4994116e+09 | I36: 2 | J36: BPKB | K36: Tidak Ada Pengikatan | L36: 2 | M36: 25673024 | N36: 161902 | O36: 12110445 | P36: 13400677
A37: SHT | B37: 12 | C37: 8.1285136e+09 | D37: 1.8136718e+08 | E37: 2447734749 | F37: 5.4994116e+09 | J37: SHGB | K37: SHT | L37: 2 | M37: 3.218318e+09 | N37: 4904983 | O37: 2476212759 | P37: 7.3720031e+08
A38: 2 | B38: 19 | C38: 1.8389923e+10 | D38: 52993628 | E38: 4.1090957e+09 | F38: 1.4227834e+10 | J38: SHM | K38: SHT | L38: 10 | M38: 1.326507e+10 | N38: 47926743 | O38: 1.6207725e+09 | P38: 1.1596371e+10
A39: BPKB | B39: 2 | C39: 25673024 | D39: 161902 | E39: 12110445 | F39: 13400677 | K39: Tidak Ada Pengikatan | L39: 5 | M39: 1.8808616e+09 | N39: 0 | O39: 0 | P39: 1.8808616e+09
A40: Tidak Ada Pengikatan | B40: 2 | C40: 25673024 | D40: 161902 | E40: 12110445 | F40: 13400677 | L40: =SUM(L36:L39) -> 19 | M40: =SUM(M36:M39) -> 1.8389923e+10 | N40: =SUM(N36:N39) -> 52993628 | O40: =SUM(O36:O39) -> 4.1090957e+09 | P40: =SUM(P36:P39) -> 1.4227834e+10
A41: SHGB | B41: 2 | C41: 3.218318e+09 | D41: 4904983 | E41: 2476212759 | F41: 7.3720031e+08 | I41: 3 | J41: SHM | K41: SHT | L41: 10 | M41: 1.3667048e+10 | N41: 39299 | O41: 1.3528918e+09 | P41: 1.2314117e+10
A42: SHT | B42: 2 | C42: 3.218318e+09 | D42: 4904983 | E42: 2476212759 | F42: 7.3720031e+08 | J42: SHM | K42: Tidak Ada Pengikatan | L42: 3 | M42: 5.1370907e+08 | N42: 0 | O42: 0 | P42: 5.1370907e+08
A43: SHM | B43: 15 | C43: 1.5145932e+10 | D43: 47926743 | E43: 1.6207725e+09 | F43: 1.3477233e+10 | L43: =SUM(L41:L42) -> 13 | M43: =SUM(M41:M42) -> 1.4180757e+10 | N43: =SUM(N41:N42) -> 39299 | O43: =SUM(O41:O42) -> 1.3528918e+09 | P43: =SUM(P41:P42) -> 1.2827826e+10
A44: SHT | B44: 10 | C44: 1.326507e+10 | D44: 47926743 | E44: 1.6207725e+09 | F44: 1.1596371e+10 | I44: 4 | J44: KTA | K44: Tidak Ada Pengikatan | L44: 1 | M44: 5.9892996e+08 | N44: 104230918 | O44: 0 | P44: 4.9469904e+08
A45: Tidak Ada Pengikatan | B45: 5 | C45: 1.8808616e+09 | D45: 0 | E45: 0 | F45: 1.8808616e+09 | J45: SHGB | K45: SHT | L45: 2 | M45: 2.2893714e+09 | N45: 0 | O45: 526679600 | P45: 1.7626918e+09
...

Sheet Tanah dan Bangunan
A1: No. | B1: Kode Aset | C1: Uraian | D1: Saldo (NP Audited) | E1: Saldo (LANAP) | F1: Realisasi Pencairan | G1: Nilai Aset yang Belum Dicairkan | H1: Keterangan (Cair/Belum Dicairkan) | I1: Strategi Pencairan | J1: Kendala Pencairan | K1: 44348 | L1: 44378 | M1: 44409 | N1: 44440 | O1: 44470 | P1: 44501 | Q1: 44531 | R1: 44562 | S1: 44593 | T1: 44621 | U1: 44652 | V1: 44682 | W1: 44713 | X1: Total
A2: 1 | C2: Gedung Kantor Pusat Denpasar Jl. Gajah Mada No. 125 sd 127 | D2: 10000000000 | E2: 11318100000 | F2: 0 | G2: =D2 -> 10000000000 | H2: Belum Cair | I2: Penjualan Langsung | J2: Kondisi Perekomian Bali pasca Pandemi | Q2: 5763901874 | X2: =SUM(K2:W2) -> 5763901874
A3: 2 | C3: Gedung Kantor Cabang Tabanan Jl Ngurah Rai No. 97 | D3: 1210718850 | E3: 1089000000 | F3: 1177270000 | G3: 0 | H3: Cair | I3: - | X3: =SUM(K3:W3) -> 0
D4: =SUM(D2:D3) -> 11210718850 | E4: =SUM(E2:E3) -> 12407100000 | F4: =SUM(F2:F3) -> 1177270000 | G4: =SUM(G2:G3) -> 10000000000 | K4: =SUM(K2:K3) -> 0 | L4: =SUM(L2:L3) -> 0 | M4: =SUM(M2:M3) -> 0 | N4: =SUM(N2:N3) -> 0 | O4: =SUM(O2:O3) -> 0 | P4: =SUM(P2:P3) -> 0 | Q4: =SUM(Q2:Q3) -> 5763901874 | R4: =SUM(R2:R3) -> 0 | ... W4: =SUM(W2:W3) -> 0 | X4: =SUM(K4:W4) -> 5763901874

Sheet Kendaraan
A1: No. | B1: Kode Aset | C1: Uraian | D1: Saldo (NP Audited) | E1: Saldo (LANAP) | F1: Realisasi Pencairan s.d. Mei 2021 | G1: Nilai Aset yang Belum Dicairkan | H1: Keterangan (Cair/Belum Dicairkan) | I1: Strategi Pencairan | J1: Kendala Pencairan | K1: 44348 | L1: 44378 | M1: 44409 | N1: 44440 | O1: 44470 | P1: 44501 | Q1: 44531 | R1: 44562 | S1: 44593 | T1: 44621 | U1: 44652 | V1: 44682 | W1: 44713 | X1: Total
A2: 1 | C2: Mobil Alpard DK1092JE | D2: 490539000 | E2: 300000000 | F2: 300000000 | H2: Cair | X2: =SUM(K2:W2) -> 0
A3: 2 | C3: Mobil Alpard DK1473XG | D3: 361736601 | E3: 200000000 | F3: 200000000 | H3: Cair | X3: =SUM(K3:W3) -> 0
A4: 3 | C4: Mobil Inova(DK 1349 GJ) | D4: 220250016 | E4: 117200000 | F4: 117200000 | H4: Cair | X4: =SUM(K4:W4) -> 0
A5: 4 | C5: Mobil Inova | D5: 271950000 | E5: 156000000 | F5: 156000000 | H5: Cair | X5: =SUM(K5:W5) -> 0
A6: 5 | C6: Mobil Inova | D6: 271950000 | E6: 156000000 | F6: 156000000 | H6: Cair | X6: =SUM(K6:W6) -> 0
A7: 6 | C7: Mobil Avanza | D7: 174200000 | E7: 124000000 | F7: 124000000 | H7: Cair | X7: =SUM(K7:W7) -> 0
A8: 7 | C8: Mobil Avanza | D8: 174200000 | E8: 124000000 | F8: 124000000 | H8: Cair | X8: =SUM(K8:W8) -> 0
A9: 8 | C9: Mobil Avanza | D9: 174200000 | E9: 124000000 | F9: 124000000 | H9: Cair | X9: =SUM(K9:W9) -> 0
A10: 9 | C10: Mobil Avanza | D10: 174200000 | E10: 85000000 | F10: 0 | G10: =D10 -> 174200000 | H10: Belum Cair | I10: Penjualan Langsung | T10: 85000000 | X10: =SUM(K10:W10) -> 85000000
A11: 10 | C11: Sepeda Motor Revo | D11: 12190000 | E11: 4150000 | F11: 4150000 | H11: Cair | X11: =SUM(K11:W11) -> 0
A12: 11 | C12: Sepeda Motor Honda Revo | D12: 11940000 | E12: 4000000 | F12: 4000000 | H12: Cair | X12: =SUM(K12:W12) -> 0
A13: 12 | C13: Sepeda Motor Supra X | D13: 14420000 | E13: 3750000 | F13: 3750000 | H13: Cair | X13: =SUM(K13:W13) -> 0
A14: 13 | C14: Sepeda Motor Yamaha Mio | D14: 0 | E14: 5100000 | F14: 5100000 | H14: Cair | X14: =SUM(K14:W14) -> 0
A15: 14 | C15: Sepeda Motor Honda Vario | D15: 0 | E15: 9166666.7 | F15: 0 | G15: 0 | H15: Belum Cair | I15: Penjualan Langsung | T15: 9200000 | X15: =SUM(K15:W15) -> 9200000
D16: =SUM(D2:D15) -> 2351775617 | E16: =SUM(E2:E15) -> 1.4123667e+09 | F16: =SUM(F2:F15) -> 1318200000 | G16: =SUM(G2:G15) -> 174200000 | K16: =SUM(K2:K15) -> 0 | L16: =SUM(L2:L15) -> 0 | M16: =SUM(M2:M15) -> 0 | N16: =SUM(N2:N15) -> 0 | O16: =SUM(O2:O15) -> 0 | P16: =SUM(P2:P15) -> 0 | Q16: =SUM(Q2:Q15) -> 0 | R16: =SUM(R2:R15) -> 0 | ... X16: =SUM(X2:X15) -> 94200000

Sheet Inventaris
A1: No. | B1: Kode Aset | C1: Uraian | D1: Saldo (NP Audited) | E1: Saldo (LANAP) | F1: Realisasi Pencairan s.d. Mei 2021 | G1: Nilai Aset yang Belum Dicairkan | H1: Keterangan (Cair/Belum Dicairkan) | I1: Strategi Pencairan | J1: 44348 | K1: 44378 | L1: 44409 | M1: 44440 | N1: 44470 | O1: 44501 | P1: 44531 | Q1: 44562 | R1: 44593 | S1: 44621 | T1: 44652 | U1: 44682 | V1: 44713 | W1: Total
A2: 1 | C2: Lukisan Gatsu | D2: 50000000 | E2: 3600000 | F2: 0 | G2: =D2 -> 50000000 | H2: Belum Cair | I2: Penjualan Langsung/Lelang | O2: 3600000 | W2: =SUM(J2:V2) -> 3600000
A3: 2 | C3: Lukisan Gatsu | D3: 50000000 | E3: 1575000 | F3: 0 | G3: =D3 -> 50000000 | H3: Belum Cair | I3: Penjualan Langsung/Lelang | O3: 1575000 | W3: =SUM(J3:V3) -> 1575000
A4: 3 | C4: Lukisan Gatsu | D4: 25000000 | E4: 1125000 | F4: 0 | G4: =D4 -> 25000000 | H4: Belum Cair | I4: Penjualan Langsung/Lelang | O4: 1125000 | W4: =SUM(J4:V4) -> 1125000
A5: 4 | C5: Lukisan Gatsu | D5: 10000000 | E5: 450000 | F5: 0 | G5: =D5 -> 10000000 | H5: Belum Cair | I5: Penjualan Langsung/Lelang | O5: 450000 | W5: =SUM(J5:V5) -> 450000
A6: 5 | C6: Lukisan Gatsu | D6: 15000000 | E6: 1125000 | F6: 0 | G6: =D6 -> 15000000 | H6: Belum Cair | I6: Penjualan Langsung/Lelang | O6: 1125000 | W6: =SUM(J6:V6) -> 1125000
A7: 6 | C7: Lukisan Lantai 3 Kpo | D7: 7000000 | E7: 900000 | F7: 0 | G7: =D7 -> 7000000 | H7: Belum Cair | I7: Penjualan Langsung/Lelang | O7: 900000 | W7: =SUM(J7:V7) -> 900000
A8: 7 | C8: Lukisan R.Komisaris | D8: 10000000 | E8: 450000 | F8: 0 | G8: =D8 -> 10000000 | H8: Belum Cair | I8: Penjualan Langsung/Lelang | O8: 450000 | W8: =SUM(J8:V8) -> 450000
A9: 8 | C9: Kursi Sapi Gatsu | D9: 5000000 | E9: 280000 | F9: 300000 | H9: Cair
A10: 9 | C10: Karpet Zebra Kulit Sapi Kk Gatsu | D10: 5000000 | E10: 772000 | F10: 800000 | H10: Cair
A11: 10 | C11: Lukisan R. Komisaris | D11: 10000000 | E11: 495000 | F11: 0 | G11: =D11 -> 10000000 | H11: Belum Cair | I11: Penjualan Langsung/Lelang | O11: 495000 | W11: =SUM(J11:V11) -> 495000
A12: 11 | C12: Sofa Besar R. Komisaris | D12: 4000000 | E12: 616000 | F12: 0 | G12: =D12 -> 4000000 | H12: Belum Cair | I12: Penjualan Langsung/Lelang | O12: 616000 | W12: =SUM(J12:V12) -> 616000
A13: 12 | C13: Jam R. Komisaris | D13: 3500000 | E13: 540000 | F13: 0 | G13: =D13 -> 3500000 | H13: Belum Cair | I13: Penjualan Langsung/Lelang | O13: 540000 | W13: =SUM(J13:V13) -> 540000
A14: 13 | C14: Kursi Kotak Sapi | D14: 5000000 | E14: 432000 | F14: 450000 | H14: Cair
A15: 14 | C15: Cermin Teller Kpo | D15: 5000000 | E15: 772000 | F15: 0 | G15: =D15 -> 5000000 | H15: Belum Cair | I15: Penjualan Langsung/Lelang | O15: 772000 | W15: =SUM(J15:V15) -> 772000
A16: 15 | C16: Lukisan Accounting Kpo | D16: 1500000 | E16: 450000 | F16: 0 | G16: =D16 -> 1500000 | H16: Belum Cair | I16: Penjualan Langsung/Lelang | O16: 450000 | W16: =SUM(J16:V16) -> 450000
A17: 16 | C17: Kursi Komisaris | D17: 3000000 | E17: 464000 | F17: 0 | G17: =D17 -> 3000000 | H17: Belum Cair | I17: Penjualan Langsung/Lelang | O17: 464000 | W17: =SUM(J17:V17) -> 464000
A18: 17 | C18: Lukisan Kom Kpo | D18: 2500000 | E18: 675000 | F18: 0 | G18: =D18 -> 2500000 | H18: Belum Cair | I18: Penjualan Langsung/Lelang | O18: 675000 | W18: =SUM(J18:V18) -> 675000
A19: 18 | C19: Lukisan R. Dirut Kpo | D19: 5000000 | E19: 675000 | F19: 0 | G19: =D19 -> 5000000 | H19: Belum Cair | I19: Penjualan Langsung/Lelang | O19: 675000 | W19: =SUM(J19:V19) -> 675000
A20: 19 | C20: Lukisan R. Hrd | D20: 1500000 | E20: 225000 | F20: 0 | G20: =D20 -> 1500000 | H20: Belum Cair | I20: Penjualan Langsung/Lelang | O20: 225000 | W20: =SUM(J20:V20) -> 225000
A21: 20 | C21: Lukisan R. Bm Kpo | D21: 1500000 | E21: 450000 | F21: 0 | G21: =D21 -> 1500000 | H21: Belum Cair | I21: Penjualan Langsung/Lelang | O21: 450000 | W21: =SUM(J21:V21) -> 450000
A22: 21 | C22: Lukisan R. Hrd | D22: 3500000 | E22: 900000 | F22: 0 | G22: =D22 -> 3500000 | H22: Belum Cair | I22: Penjualan Langsung/Lelang | O22: 900000 | W22: =SUM(J22:V22) -> 900000
A23: 22 | C23: Lukisan Kupu2 | D23: 55000000 | E23: 4950000 | F23: 0 | G23: =D23 -> 55000000 | H23: Belum Cair | I23: Penjualan Langsung/Lelang | O23: 4950000 | W23: =SUM(J23:V23) -> 4950000
A24: 23 | C24: Lukisan 3 Wanita | D24: 12000000 | E24: 2250000 | F24: 0 | G24: =D24 -> 12000000 | H24: Belum Cair | I24: Penjualan Langsung/Lelang | O24: 2250000 | W24: =SUM(J24:V24) -> 2250000
A25: 24 | C25: Lukisan Wanita Penari | D25: 25000000 | E25: 1350000 | F25: 0 | G25: =D25 -> 25000000 | H25: Belum Cair | I25: Penjualan Langsung/Lelang | O25: 1350000 | W25: =SUM(J25:V25) -> 1350000
A26: 25 | C26: Lukisan Wanita Sawah | D26: 28000000 | E26: 900000 | F26: 0 | G26: =D26 -> 28000000 | H26: Belum Cair | I26: Penjualan Langsung/Lelang | O26: 900000 | W26: =SUM(J26:V26) -> 900000
... A49: 48 | C49: Gajah Berantai | D49: 3000000 | E49: 464000 | F49: 0 | G49: =D49 -> 3000000 | H49: Belum Cair | I49: Penjualan Langsung/Lelang | O49: 464000 | W49: =SUM(J49:V49) -> 464000
A50: 49 | C50: Patung Kuda Loncat | D50: 3000000 | E50: 464000 | F50: 470000 | H50: Cair
A51: 50 | C51: Patung Kuda | D51: 2500000 | E51: 388000 | F51: 0 | G51: =D51 -> 2500000 | H51: Belum Cair | I51: Penjualan Langsung/Lelang | O51: 388000 | W51: =SUM(J51:V51) -> 388000
A52: 51 | C52: Lampu Zebra | D52: 5000000 | E52: 772000 | F52: 0 | G52: =D52 -> 5000000 | H52: Belum Cair | I52: Penjualan Langsung/Lelang | O52: 772000 | W52: =SUM(J52:V52) -> 772000
A53: 52 | C53: Lampu Tingkat | D53: 3000000 | E53: 464000 | F53: 475000 | H53: Cair
A54: 53 | C54: Pembelian Kamera Nikon | D54: 25000000 | E54: 3860000 | F54: 0 | G54: =D54 -> 25000000 | H54: Belum Cair | I54: Penjualan Langsung/Lelang | O54: 3860000 | W54: =SUM(J54:V54) -> 3860000
A55: 54 | C55: Pembelian Kaca Hias | D55: 8000000 | E55: 1236000 | F55: 0 | G55: =D55 -> 8000000 | H55: Belum Cair | I55: Penjualan Langsung/Lelang | O55: 1236000 | W55: =SUM(J55:V55) -> 1236000
A56: 55 | C56: GENSET GATSU | D56: 100000000 | E56: 15448000 | F56: 16000000 | H56: Cair
A57: 56 | C57: Lukisan Model Perempuan Besar | D57: 35000000 | E57: 3600000 | F57: 0 | G57: =D57 -> 35000000 | H57: Belum Cair | I57: Penjualan Langsung/Lelang | O57: 3600000 | W57: =SUM(J57:V57) -> 3600000
A58: 57 | C58: 2 Buah Sofa Kerobokan A | D58: 10000000 | E58: 1544000 | F58: 0 | G58: =D58 -> 10000000 | H58: Belum Cair | I58: Penjualan Langsung/Lelang | O58: 1544000 | W58: =SUM(J58:V58) -> 1544000
A59: 58 | C59: 3 Buah Sofa Kerobokan B | D59: 9000000 | E59: 1392000 | F59: 0 | G59: =D59 -> 9000000 | H59: Belum Cair | I59: Penjualan Langsung/Lelang | O59: 1392000 | W59: =SUM(J59:V59) -> 1392000
A60: 59 | C60: 3 Buah Sofa Kerobokan C | D60: 9000000 | E60: 1392000 | F60: 0 | G60: =D60 -> 9000000 | H60: Belum Cair | I60: Penjualan Langsung/Lelang | O60: 1392000 | W60: =SUM(J60:V60) -> 1392000
A61: 60 | C61: 2 Buah Sofa Kerobokan D | D61: 12000000 | E61: 1852000 | F61: 0 | G61: =D61 -> 12000000 | H61: Belum Cair | I61: Penjualan Langsung/Lelang | O61: 1852000 | W61: =SUM(J61:V61) -> 1852000
A62: 61 | C62: 2 Buah Sofa Kerobokan E | D62: 10000000 | E62: 1544000 | F62: 0 | G62: =D62 -> 10000000 | H62: Belum Cair | I62: Penjualan Langsung/Lelang | O62: 1544000 | W62: =SUM(J62:V62) -> 1544000
...

Sheet AYDA
A1: No. | B1: Nomor Rekening | C1: Nama Debitur | D1: Saldo (NP Audited) | E1: Saldo (LANAP) | F1: Nilai Likuidasi Agunan | G1: Realisasi Pencairan s.d. Mei 2021 | H1: Keterangan (Cair/Belum Dicairkan) | I1: Realisasi Upaya | J1: Strategi Pencairan | K1: 44348 | L1: 44378 | M1: 44409 | N1: 44440 | O1: 44470 | P1: 44501 | Q1: 44531 | R1: 44562 | S1: 44593 | T1: 44621 | U1: 44652 | V1: 44682 | W1: 44713 | X1: Total
A2: 1 | C2: I MADE IRWAN WIDIANA | D2: 2.4525567e+08 | E2: 2.7802208e+08 | F2: 0 | G2: 2.7802208e+08 | H2: Lunas | X2: =SUM(K2:W2) -> 0
A3: 2 | C3: I WAYAN JULI ADNYANA | D3: 3.7561415e+08 | E3: 3.7561415e+08 | F3: 751000000 | G3: 0 | H3: Belum Lunas | I3: Lelang I TAP | J3: Lelang 2 | P3: 159000000 | V3: 592000000 | X3: =SUM(K3:W3) -> 751000000
A4: 3 | C4: I MADE ASTRAGINA | D4: 8.029615e+08 | E4: 593000000 | F4: 593000000 | G4: 0 | H4: Belum Lunas | I4: Lelang I TAP | J4: Lelang 2 | Q4: 593000000 | X4: =SUM(K4:W4) -> 593000000
A5: 4 | C5: I GUSTI AGUNG PUTU DHARMA DHARWITA | D5: 3.0782287e+08 | E5: 132000000 | F5: 132000000 | G5: 0 | H5: Belum Lunas | I5: Lelang I TAP | J5: Lelang 2 | R5: 132000000 | X5: =SUM(K5:W5) -> 132000000
A6: 5 | C6: MONEY BHASKARA PUTRA | D6: 4.658356e+08 | E6: 233000000 | F6: 233000000 | G6: 0 | H6: Belum Lunas | I6: Lelang I TAP | J6: Lelang 2 | K6: 233000000 | X6: =SUM(K6:W6) -> 233000000
A7: 6 | C7: I GEDE DERESTI | D7: 1098038253 | E7: 779000000 | F7: 779000000 | G7: 0 | H7: Belum Lunas | I7: Lelang I TAP | J7: Lelang 2 | K7: 779000000 | X7: =SUM(K7:W7) -> 779000000
A8: 7 | C8: BAGUS KURNIAWAN | D8: 2.2881877e+09 | E8: 1070000000 | F8: 1070000000 | G8: 1309670503 | H8: Belum Lunas | I8: Lelang I LAKU | X8: =SUM(K8:W8) -> 0
A9: 8 | C9: GUSTI AYU MERTININGSIH | D9: 9.6826611e+08 | E9: 440000000 | F9: 440000000 | G9: 0 | H9: Belum Lunas | I9: Lelang I TAP | J9: Lelang 2 | S9: 440000000 | X9: =SUM(K9:W9) -> 440000000
A10: 9 | C10: I MADE YASA | D10: 335000000 | E10: 335000000 | F10: 624000000 | G10: 0 | H10: Belum Lunas | I10: Lelang I TAP | J10: Lelang 2 | T10: 4.6453333e+08 | X10: =SUM(K10:W10) -> 4.6453333e+08
A11: 10 | C11: I MADE YASA | D11: 115000000 | E11: 115000000 | F11: 0 | G11: 0 | H11: Belum Lunas | I11: Lelang I TAP | J11: Lelang 2 | T11: 1.5946667e+08 | X11: =SUM(K11:W11) -> 1.5946667e+08
A12: 11 | C12: I PUTU DANA | D12: 46506319 | E12: 46506319 | F12: 967000000 | G12: 0 | H12: Belum Lunas | I12: Lelang I TAP | J12: Lelang 2 | R12: 46053694 | X12: =SUM(K12:W12) -> 46053694
A13: 12 | C13: I PUTU DANA | D13: 1.6333087e+08 | E13: 163330868 | F13: 0 | G13: 0 | H13: Belum Lunas | I13: Lelang I TAP | J13: Lelang 2 | R13: 1.6174125e+08 | X13: =SUM(K13:W13) -> 1.6174125e+08
A14: 13 | C14: I PUTU DANA | D14: 766666665 | E14: 766666665 | F14: 0 | G14: 0 | H14: Belum Lunas | I14: Lelang I TAP | J14: Lelang 2 | R14: 7.5920506e+08 | X14: =SUM(K14:W14) -> 7.5920506e+08
A15: 14 | C15: I WAYAN BUDIANA | D15: 2.4575003e+09 | E15: 2183000000 | F15: 2183000000 | G15: 0 | H15: Belum Lunas | I15: Lelang I TAP | J15: Lelang 2 / Penjualan Sukarela | S15: 1.8795323e+09 | X15: =SUM(K15:W15) -> 1.8795323e+09
A16: 15 | C16: I WAYAN BUDIANA | D16: 396785869 | E16: 0 | F16: 0 | G16: 0 | H16: Belum Lunas | I16: Lelang I TAP | J16: Lelang 2 / Penjualan Sukarela | S16: 3.0346767e+08 | X16: =SUM(K16:W16) -> 3.0346767e+08
A17: 16 | C17: KOMANG ASTIKA YASA | D17: 2.4909596e+09 | E17: 2012000000 | F17: 2012000000 | G17: 0 | H17: Belum Lunas | I17: Lelang I TAP | J17: Lelang 2 | P17: 1.7548605e+09 | X17: =SUM(K17:W17) -> 1.7548605e+09
A18: 17 | C18: KOMANG ASTIKA YASA | D18: 365000000 | E18: 0 | F18: 0 | G18: 0 | H18: Belum Lunas | I18: Lelang I TAP | J18: Lelang 2 | P18: 2.5713949e+08 | X18: =SUM(K18:W18) -> 2.5713949e+08
A19: 18 | C19: HENNY | D19: 9.6157205e+08 | E19: 600000000 | F19: 600000000 | G19: 0 | H19: Belum Lunas | I19: Non HT | J19: Cessie | W19: 1 | X19: =SUM(K19:W19) -> 1
A20: 19 | C20: JUNANTO TJANDRAWINATA | D20: 2.1601976e+09 | E20: 315920000 | F20: 0 | G20: 0 | H20: Belum Lunas | I20: Proses Balik Nama Sertifikat | J20: Penjualan Sukarela | U20: 2.1601976e+09 | X20: =SUM(K20:W20) -> 2.1601976e+09
A21: 20 | C21: DANIEL KURNIAWAN | D21: 1.4130907e+09 | E21: 1413090694 | F21: 1658000000 | G21: 0 | H21: Belum Lunas | I21: Non HT | J21: Cessie | W21: 1 | X21: =SUM(K21:W21) -> 1
A22: 21 | C22: PUTU AGUS HERLLY DIANTARA | D22: 7.4728787e+08 | E22: 440000000 | F22: 404000000 | G22: 470812100 | H22: Belum Lunas | I22: Lelang I LAKU | X22: =SUM(K22:W22) -> 0
A23: 22 | C23: PUTU AGUS HERLLY DIANTARA | D23: 99951047 | E23: 0 | F23: 0 | G23: 0 | H23: Belum Lunas | I23: Lelang I LAKU | X23: =SUM(K23:W23) -> 0
A24: 23 | C24: CHRISTIAN SUGIANTO | D24: 1.0279274e+09 | E24: 1027927367 | F24: 1058000000 | G24: 0 | H24: Belum Lunas | I24: Non HT | J24: Cessie | W24: 1 | X24: =SUM(K24:W24) -> 1
D25: =SUM(D2:D24) -> 2.0098758e+10 | E25: =SUM(E2:E24) -> 1.3319078e+10 | G25: =SUM(G2:G24) -> 2.0585047e+09 | K25: =SUM(K2:K24) -> 1012000000 | L25: =SUM(L2:L24) -> 0 | M25: =SUM(M2:M24) -> 0 | N25: =SUM(N2:N24) -> 0 | O25: =SUM(O2:O24) -> 0 | P25: =SUM(P2:P24) -> 2171000000 | Q25: =SUM(Q2:Q24) -> 593000000 | R25: =SUM(R2:R24) -> 1099000000 | ... X25: =SUM(X2:X24) -> 1.0874198e+10

Sheet Prognosa Biaya
A2: No | B2: Jenis Aset/ Biaya | C2: Realisasi Pencairan/Biaya per 31 Mei 2021 | D2: Prognosa June 2021 | E2: 44378 | F2: 44409 | G2: 44440 | H2: 44470 | I2: 44501 | J2: 44531 | K2: 44562 | L2: 44593 | M2: 44621 | N2: 44652 | O2: 44682 | P2: 44713 | Q2: Dana Cadangan Pengakhiran | R2: Grand Total
B4: 1. Biaya Pendukung Likuidasi
A5: 1 | B5: Honor Tim Likuidasi | C5: =818416260+61823656 -> 880239916 | D5: 51544670 | E5: 51544670 | F5: 51544670 | G5: 51544670 | H5: 63573170 | I5: 63573170 | J5: 63573170 | K5: 63573170 | L5: 63573170 | M5: 63573170 | N5: 63573170 | O5: 63573170 | P5: 63573170 | R5: =SUM(C5:Q5) -> 1.6585771e+09
A6: 2 | B6: Honor Tenaga Pendukung | C6: =652084996+16459132 -> 668544128 | D6: 22750780 | E6: 22750780 | F6: 22750780 | G6: 22750780 | H6: 22750780 | I6: 22750780 | J6: 22750780 | K6: 22750780 | L6: 22750780 | M6: 22750780 | N6: 22750780 | O6: 22750780 | P6: 22750780 | R6: =SUM(C6:Q6) -> 964304268
A7: 3 | B7: Pembayaran THR Tim Likuidasi dan Tenaga Pendukung | C7: 104600949 | D7: 0 | E7: 0 | F7: 0 | G7: 0 | H7: 0 | I7: 0 | J7: 0 | K7: 0 | L7: 0 | M7: 0 | N7: 79176200 | O7: 0 | P7: 0 | R7: =SUM(C7:Q7) -> 183777149
A8: 4 | B8: Biaya kantor dan operasional lainya | C8: 362185568 | D8: 20146113 | E8: 20146113 | F8: 20146113 | G8: 20146113 | H8: 20146113 | I8: 20146113 | J8: 20146113 | K8: 20146113 | L8: 20146113 | M8: 20146113 | N8: 20146113 | O8: 20146113 | P8: 20146113 | R8: =SUM(C8:Q8) -> 6.2408503e+08
A9: 5 | B9: Insentif pencairan aset dan penagihan piutang | C9: 0 | P9: 1159271544 | R9: =SUM(C9:Q9) -> 1159271544
B10: Subtotal Biaya Pendukung | C10: =SUM(C5:C9) -> 2015570561 | D10: =SUM(D5:D9) -> 94441562 | E10: =SUM(E5:E9) -> 94441562 | F10: =SUM(F5:F9) -> 94441562 | G10: =SUM(G5:G9) -> 94441562 | H10: =SUM(H5:H9) -> 1.0647006e+08 | I10: =SUM(I5:I9) -> 1.0647006e+08 | J10: =SUM(J5:J9) -> 1.0647006e+08 | ... R10: =SUM(R5:R9) -> 4.5900151e+09
B11: 2. Biaya Kegiatan Likuidasi
A12: 1 | B12: Menyampaikan Rencana Kerja dan Anggaran TL. | C12: 318000 | D12: 95000 | E12: 95000 | F12: 95000 | G12: 95000 | H12: 95000 | I12: 95000 | J12: 95000 | K12: 95000 | L12: 95000 | M12: 95000 | N12: 95000 | O12: 95000 | P12: 95000 | R12: =SUM(C12:Q12) -> 1553000
A13: 2 | B13: Menindaklanjuti aspek legal pembubaran badan hukum bank. | C13: 7507500 | R13: =SUM(C13:Q13) -> 7507500
A14: 3 | B14: Menyelesaikan kewajiban kepada pegawai. | C14: 1079629772 | P14: 241103000 | R14: =SUM(C14:Q14) -> 1320732772
A15: 4 | B15: Menyampaikan Neraca Penutupan yang telah diaudit KAP/Inst. Pemerintah Bid. Audit kpd LPS. | C15: 115052750 | R15: =SUM(C15:Q15) -> 115052750
A16: 5 | B16: Melakukan inventarisasi aset dan kewajiban. | C16: 59216000 | E16: 3600000 | R16: =SUM(C16:Q16) -> 62816000
A17: 6 | B17: Melakukan penyelesaian kewajiban pihak yg menyebabkan bank gagal. | C17: 105155000 | E17: 27000000 | R17: =SUM(C17:Q17) -> 132155000
A18: 7 | B18: Menyampaikan Laporan Perubahan Aset Neto periode 2021 untuk mendapat persetujuan LPS. | C18: 98122000 | L18: 47400000 | R18: =SUM(C18:Q18) -> 145522000
A19: 8 | B19: Melakukan pencairan aset/inventarisasi aset | C19: 236132444 | J19: 396128000 | R19: =SUM(C19:Q19) -> 632260444
A20: 9 | B20: Melakukan penagihan kredit. | C20: 974639438 | D20: 1.2508512e+08 | E20: 1.2508512e+08 | F20: 1.2508512e+08 | G20: 1.2508512e+08 | H20: 1.2508512e+08 | I20: 1.2508512e+08 | J20: 1.2508512e+08 | K20: 1.2508512e+08 | L20: 1.2508512e+08 | M20: 1.2508512e+08 | N20: 1.2508512e+08 | O20: 1.2508512e+08 | P20: 1.2508512e+08 | R20: =SUM(C20:Q20) -> 2.600746e+09
A21: 10 | B21: Melakukan pembayaran kewajiban sesuai ketentuan | C21: 0 | P21: 4150000 | R21: =SUM(C21:Q21) -> 4150000
A22: 11 | B22: Menyampaikan Neraca Akhir Likuidasi kepada LPS. | C22: 0 | P22: 250000 | R22: =SUM(C22:Q22) -> 250000
A23: 12 | B23: Menindaklanjuti pengakhiran proses likuidasi. | C23: 0 | Q23: 328465650 | R23: =SUM(C23:Q23) -> 328465650
B24: Subtotal Biaya Kegiatan | C24: =SUM(C12:C23) -> 2675772904 | D24: =SUM(D12:D23) -> 1.2518012e+08 | E24: =SUM(E12:E23) -> 1.5578012e+08 | F24: =SUM(F12:F23) -> 1.2518012e+08 | G24: =SUM(G12:G23) -> 1.2518012e+08 | H24: =SUM(H12:H23) -> 1.2518012e+08 | I24: =SUM(I12:I23) -> 1.2518012e+08 | J24: =SUM(J12:J23) -> 5.2130812e+08 | ... R24: =SUM(R12:R23) -> 5.3512111e+09
B25: Total Biaya | C25: =C10+C24 -> 4691343465 | D25: =D10+D24 -> 2.1962168e+08 | E25: =E10+E24 -> 2.5022168e+08 | F25: =F10+F24 -> 2.1962168e+08 | G25: =G10+G24 -> 2.1962168e+08 | H25: =H10+H24 -> 2.3165018e+08 | I25: =I10+I24 -> 2.3165018e+08 | J25: =J10+J24 -> 6.2777818e+08 | ... R25: =R10+R24 -> 9.9412262e+09

Sheet Prognosa Penerimaan vs Biaya
A1: A. Tidak Dilakukan Perpanjangan
A3: Keterangan | B3: Realisasi sd 31 Mei 2021 | C3: Prognosa Juni 2021 | D3: Total Penerimaan/Biaya
A5: (1) | B5: (2) | C5: (3) | D5: (4) = (2) + (3)
A6: Kas | B6: =Net!F5 -> 41285600 | C6: 0 | D6: =SUM(B6:C6) -> 41285600
A7: Antar Bank Aktiva (ABA) | B7: =ABA!G19 -> 7.100292e+08 | C7: 0 | D7: =SUM(B7:C7) -> 7.100292e+08
A8: Kredit | B8: =Kredit!O200 -> 3.6047969e+10 | C8: =Kredit!AE200 -> 1.2967727e+09 | D8: =SUM(B8:C8) -> 3.7344742e+10
A9: Aktiva Tetap dan Inventaris
A10: - Tanah dan Bangunan | B10: ='Tanah dan Bangunan'!F4 -> 1177270000 | C10: ='Tanah dan Bangunan'!K4 -> 0 | D10: =SUM(B10:C10) -> 1177270000
A11: - Kendaraan | B11: =Kendaraan!F16 -> 1318200000 | C11: =Kendaraan!K16 -> 0 | D11: =SUM(B11:C11) -> 1318200000
A12: - Inventaris | B12: =Inventaris!F970 -> 179000000 | C12: =Inventaris!J970 -> 0 | D12: =SUM(B12:C12) -> 179000000
A13: Rupa-Rupa Aktiva
A14: - AYDA | B14: =AYDA!G25 -> 2.0585047e+09 | C14: =AYDA!K25 -> 1012000000 | D14: =SUM(B14:C14) -> 3.0705047e+09
A15: - PYAD | B15: =Kredit!P200 -> 3.9680295e+09 | C15: 0 | D15: =SUM(B15:C15) -> 3.9680295e+09
A16: - Akural Denda Kredit | B16: =Kredit!Q200 -> 5.1152048e+08 | C16: 0 | D16: =SUM(B16:C16) -> 5.1152048e+08
A17: - Penerimaan Lainnya | B17: 1.4492681e+09 | C17: 0 | D17: =SUM(B17:C17) -> 1.4492681e+09
A18: Total Penerimaan | B18: =SUM(B6:B17) -> 4.7461077e+10 | C18: =SUM(C6:C13) -> 1.2967727e+09 | D18: =SUM(B18:C18) -> 4.8757849e+10
A19: Biaya Pendukung Likuidasi | B19: ='Prognosa Biaya'!C10 -> 2015570561 | C19: ='Prognosa Biaya'!D10 -> 94441562 | D19: =B19+C19 -> 2.1100121e+09
A20: Biaya Kegiatan Likuidasi | B20: ='Prognosa Biaya'!C24 -> 2675772904 | C20: ='Prognosa Biaya'!D24 -> 1.2518012e+08 | D20: =B20+C20 -> 2.800953e+09
A21: Biaya Cadangan Pengakhiran | B21: 0 | C21: ='Prognosa Biaya'!Q23 -> 328465650 | D21: =B21+C21 -> 328465650
A22: Total Biaya Likuidasi | B22: =SUM(B19:B21) -> 4691343465 | C22: =SUM(C19:C21) -> 5.4808733e+08 | D22: =SUM(D19:D21) -> 5.2394308e+09
A23: Surplus/Defisit Likuidasi | B23: =B18-B22 -> 4.2769733e+10 | C23: =C18-C22 -> 7.4868535e+08 | D23: =D18-D22 -> 4.3518419e+10
A25: B. Opsi Perpanjangan 3 Bulan
A27: Keterangan | B27: Realisasi sd 31 Mei 2021 | C27: Prognosa Juni 2021 | D27: 44378 | E27: 44409 | F27: 44440 | G27: Total Penerimaan/Biaya
N28: =#REF!-#REF! -> #REF!
A29: (1) | B29: (2) | C29: (3) | D29: (4) | E29: (5) | F29: (6) | G29: (7) = (2) + (3) + (4) + (5) + (6)
A30: Kas | B30: =Net!F5 -> 41285600 | C30: 0 | G30: =SUM(B30:F30) -> 41285600
