Workbook

Sheet Draft
A1: KERTAS KERJA PENILAIAN PENUNJUKKAN KAP DALAM RANGKA AUDIT ATAS NERACA PENUTUPAN PT BPR TEBAS LOKARIZKI (DL) - SAMBAS
A2: I. Administrasi
A3: No. | B3: KAP | C3: Proposal diterima tepat waktu | D3: Surat Pengantar | G3: Izin Menkeu | H3: Terdaftar di BI/OJK | I3: Pengalaman Audit Industri Perbankan | J3: Pegawai Tetap | L3: Lulus | M3: Tidak Lulus
D4: Tepat Waktu | E4: di TTD Pimpinan/ Rekan | F4: Memuat pernyataan yg disyaratkan | J4: Minimal 6 orang | K4: Min 50% dari pegawai yg ditugaskan
A5: 1 | B5: KAP Luthfi Muhammad & Rekan | C5: V | D5: V | E5: V | F5: V | G5: V | H5: V | I5: V | J5: V | K5: V | L5: V
A6: 2 | B6: KAP Yaniswar & Rekan | C6: V | D6: V | E6: V | F6: V | G6: V | H6: V | I6: V | J6: V | K6: V | L6: V | M6: -
A7: 3 | B7: KAP Drs. Abror, Ak | C7: V | D7: V | E7: V | F7: V | G7: V | H7: V | I7: V | J7: V | K7: V | L7: V | M7: -
A9: II. Penilaian
A10: A. | B10: Penilaian Teknis - Pengalaman KAP
A11: No. | B11: KAP | C11: Pengalaman KAP | D11: Nilai | F11: Jumlah | H11: Keterangan
D12: TL | E12: Analisis | F12: TL | G12: Analisis
A13: 1 | B13: KAP Luthfi Muhammad & Rekan | C13: 0.3 | D13: 85 | E13: 80 | F13: =D13*C13 -> 25.5 | G13: =E13*C13 -> 24 | H13: Hasil penilaian TL telah sesuai dengan pedoman penunjukkan KAP, berdasarkan verifikasi atas proposal, KAP telah memiliki pengalaman audit NAL & NP pada 3 BDL dalam 5 tahun terakhir.
A14: 2 | B14: KAP Yaniswar & Rekan | C14: 0.3 | D14: 85 | E14: 90 | F14: =D14*C14 -> 25.5 | G14: =E14*C14 -> 27 | H14: Hasil penilaian TL telah sesuai dengan pedoman penunjukkan KAP, berdasarkan verifikasi atas proposal, KAP telah memiliki pengalaman audit NAL & NP pada 4 BDL dalam 5 tahun terakhir.
A15: 3 | B15: KAP Drs. Abror, Ak | C15: 0.3 | D15: 100 | E15: =D15 -> 100 | F15: =D15*C15 -> 30 | G15: =E15*C15 -> 30 | H15: Hasil penilaian TL telah sesuai dengan pedoman penunjukkan KAP, berdasarkan verifikasi atas proposal, KAP/Personil telah memiliki pengalaman audit NAL & NP pada 4 BDL & audit umum pada 5 BPR dalam 5 th terakhir.
A17: B. | B17: Penilaian Teknis - AP/Personil
A18: No. | B18: KAP | C18: Pengalaman KAP | D18: Nilai | F18: Jumlah | H18: Keterangan
D19: TL | E19: Analisis | F19: TL | G19: Analisis
A20: 1 | B20: KAP Luthfi Muhammad & Rekan | C20: 0.3 | D20: 85 | E20: 80 | F20: =D20*C20 -> 25.5 | G20: =E20*C20 -> 24 | H20: Hasil penilaian TL telah sesuai dengan pedoman penunjukkan KAP, berdasarkan verifikasi atas proposal, KAP telah memiliki pengalaman audit NAL & NP pada 3 BDL dalam 5 tahun terakhir.
A21: 2 | B21: KAP Yaniswar & Rekan | C21: 0.3 | D21: 85 | E21: 90 | F21: =D21*C21 -> 25.5 | G21: =E21*C21 -> 27 | H21: Hasil penilaian TL telah sesuai dengan pedoman penunjukkan KAP, berdasarkan verifikasi atas proposal, KAP telah memiliki pengalaman audit NAL & NP pada 4 BDL dalam 5 tahun terakhir.
A22: 3 | B22: KAP Drs. Abror, Ak | C22: 0.3 | D22: 100 | E22: =D22 -> 100 | F22: =D22*C22 -> 30 | G22: =E22*C22 -> 30 | H22: Hasil penilaian TL telah sesuai dengan pedoman penunjukkan KAP, berdasarkan verifikasi atas proposal, KAP/Personil telah memiliki pengalaman audit NAL & NP pada 6 BDL & audit umum pada 14 BPR serta 1 BPD dalam 5 th terakhir.
A24: C. | B24: Penilaian Teknis - Metodologi & Usulan Prosedur yang Disepakati
A25: No. | B25: KAP | C25: Pengalaman KAP | D25: Nilai | F25: Jumlah | H25: Keterangan
D26: TL | E26: Analisis | F26: TL | G26: Analisis
A27: 1 | B27: KAP Luthfi Muhammad & Rekan | C27: 0.3 | D27: 81 | E27: 50 | F27: =D27*C27 -> 24.3 | G27: =E27*C27 -> 15 | H27: Hasil penilaian TL telah sesuai dengan pedoman penunjukkan KAP, berdasarkan verifikasi atas proposal cakupan dan relevansi atas metodologi dan usulan prosedur yang disepakati telah sesuai.
A28: 2 | B28: KAP Yaniswar & Rekan | C28: 0.3 | D28: 81 | E28: 50 | F28: =D28*C28 -> 24.3 | G28: =E28*C28 -> 15 | H28: Hasil penilaian TL telah sesuai dengan pedoman penunjukkan KAP, berdasarkan verifikasi atas proposal cakupan dan relevansi atas metodologi dan usulan prosedur yang disepakati telah sesuai.
A29: 3 | B29: KAP Drs. Abror, Ak | C29: 0.3 | D29: 85 | E29: 100 | F29: =D29*C29 -> 25.5 | G29: =E29*C29 -> 30 | H29: Hasil penilaian TL telah sesuai dengan pedoman penunjukkan KAP, berdasarkan verifikasi atas proposal cakupan dan relevansi atas metodologi dan usulan prosedur yang disepakati telah sesuai.
A32: D. | B32: Penilaian Biaya
A33: No. | B33: KAP | C33: Biaya Remunerasi | E33: Biaya Operasional | G33: PPN | I33: Total | K33: Keterangan
C34: Penawaran | D34: HPS | E34: Penawaran | F34: HPS | G34: Penawaran | H34: HPS | I34: Penawaran | J34: HPS (Pembulatan) | K34: Dibawah HPS | L34: Diatas HPS | M34: Penjelasan
A35: 1 | B35: KAP Luthfi Muhammad & Rekan | C35: 83000000 | D35: 55775000 | E35: 17000000 | F35: 13943750 | G35: 10000000 | H35: 7808500 | I35: =SUM(C35,E35,G35) -> 110000000 | J35: =D35+F35+H35 -> 77527250 | K35: - | L35: Ya
A36: 2 | B36: KAP Yaniswar & Rekan | C36: 49450000 | D36: =D35 -> 55775000 | E36: 13960000 | F36: =F35 -> 13943750 | G36: 6341000 | H36: =H35 -> 7808500 | I36: =SUM(C36,E36,G36) -> 69751000 | J36: =D36+F36+H36 -> 77527250 | K36: Ya | L36: -
A37: 3 | B37: KAP Drs. Abror, Ak | C37: 47000000 | D37: =D36 -> 55775000 | E37: 18000000 | F37: =F36 -> 13943750 | G37: 0 | H37: =H36 -> 7808500 | I37: =SUM(C37,E37,G37) -> 65000000 | J37: =D37+F37+H37 -> 77527250 | K37: Ya | L37: - | M37: Menawarkan biaya terendah
A39: III. Kesimpulan :
A40: No. | B40: KAP | C40: Administrasi | D40: Teknis | E40: Biaya | F40: Keterangan 1) TL telah mengundang 8 (delapan) KAP untuk mengajukan proposal penawaran 2) Berdasarkan hasil verifikasi atas penilaian TL terhadap proposal penawaran, diketahui bahwa hasil penilaian tersebut telah sesuai dengan Pedoman Penunjukkan KAP dalam rangka Audit Atas Neraca Penutupan Bank Yang dicabut Izin Usahanya (Lampiran KKE No.Kep-064/KE/VII/2008 Tgl 10 Juli 2008) 2) KAP Drs. Abror, Ak yang diusulkan TL telah memenuhi syarat untuk ditunjuk sebagai pelaksana Audit atas Neraca Penutupan PT. BPR Tebas Lokarizki.(DL) dari aspek administrasi, teknis dan biaya.
A42: 1 | B42: KAP Luthfi Muhammad & Rekan | C42: Lulus | D42: =F13+F20+F27 -> 75.3 | E42: =I35 -> 110000000
A43: 2 | B43: KAP Yaniswar & Rekan | C43: Lulus | D43: =F14+F21+F28 -> 75.3 | E43: =I36 -> 69751000
A44: 3 | B44: KAP Drs. Abror, Ak | C44: Lulus | D44: =F15+F22+F29 -> 85.5 | E44: =I37 -> 65000000
D46: 0.7 | E46: =D44*D46 -> 59.85 | F46: KAP Luthfi Muhammad & Rekan
C47: 100 | D47: 0.3 | E47: =C47*D47 -> 30 | F47: KAP Yaniswar & Rekan
F48: KAP Drs. Abror, Ak

Sheet Revised
A1: KERTAS KERJA PENILAIAN PENUNJUKKAN KAP DALAM RANGKA AUDIT ATAS NERACA PENUTUPAN PT BPR TEBAS LOKARIZKI (DL) - SAMBAS
A2: I. Administrasi
A3: No. | B3: KAP | C3: Proposal diterima tepat waktu | D3: Surat Pengantar | G3: Izin Menkeu | H3: Terdaftar di BI/OJK | I3: Pengalaman Audit Industri Perbankan | J3: Pegawai Tetap | L3: Lulus | M3: Tidak Lulus
D4: Tepat Waktu | E4: di TTD Pimpinan/ Rekan | F4: Memuat pernyataan yg disyaratkan | J4: Minimal 6 orang | K4: Min 50% dari pegawai yg ditugaskan
A5: 1 | B5: KAP Luthfi Muhammad & Rekan | C5: V | D5: V | E5: V | F5: V | G5: V | H5: V | I5: V | J5: - | K5: - | L5: - | M5: V
A6: 2 | B6: KAP Yaniswar & Rekan | C6: V | D6: V | E6: V | F6: V | G6: V | H6: V | I6: V | J6: V | K6: V | L6: V
A7: 3 | B7: KAP Drs. Abror, Ak | C7: V | D7: V | E7: V | F7: V | G7: V | H7: V | I7: V | J7: V | K7: V | L7: V | M7: -
A9: II. Penilaian
A10: A. | B10: Penilaian Teknis - Pengalaman KAP
A11: No. | B11: KAP | C11: Pengalaman KAP | D11: Nilai | F11: Jumlah | H11: Keterangan
D12: TL | E12: Analisis | F12: TL | G12: Analisis
A13: 1 | B13: KAP Luthfi Muhammad & Rekan | C13: 0.3 | D13: 85 | E13: N/A | F13: =C13*D13 -> 25.5 | G13: N/A | H13: N/A
A14: 2 | B14: KAP Yaniswar & Rekan | C14: 0.3 | D14: 85 | E14: N/A | F14: =C14*D14 -> 25.5 | G14: N/A | H14: N/A
A15: 3 | B15: KAP Drs. Abror, Ak | C15: 0.3 | D15: 100 | E15: =D15 -> 100 | F15: =C15*D15 -> 30 | G15: =E15*C15 -> 30 | H15: Hasil penilaian TL telah sesuai dengan pedoman penunjukkan KAP, berdasarkan verifikasi atas proposal, KAP/Personil telah memiliki pengalaman audit NAL & NP pada 4 BDL & audit umum pada 5 BPR dalam 5 th terakhir.
A17: B. | B17: Penilaian Teknis - AP/Personil
A18: No. | B18: KAP | C18: Pengalaman KAP | D18: Nilai | F18: Jumlah | H18: Keterangan
D19: TL | E19: Analisis | F19: TL | G19: Analisis
A20: 1 | B20: KAP Luthfi Muhammad & Rekan | C20: 0.3 | D20: 85 | E20: N/A | F20: =C20*D20 -> 25.5 | G20: N/A | H20: N/A
A21: 2 | B21: KAP Yaniswar & Rekan | C21: 0.3 | D21: 85 | E21: N/A | F21: =C21*D21 -> 25.5 | G21: N/A | H21: N/A
A22: 3 | B22: KAP Drs. Abror, Ak | C22: 0.3 | D22: 100 | E22: =D22 -> 100 | F22: =C22*D22 -> 30 | G22: =E22*C22 -> 30 | H22: Hasil penilaian TL telah sesuai dengan pedoman penunjukkan KAP, berdasarkan verifikasi atas proposal, KAP/Personil telah memiliki pengalaman audit NAL & NP pada 6 BDL & audit umum pada 14 BPR serta 1 BPD dalam 5 th terakhir.
A24: C. | B24: Penilaian Teknis - Metodologi & Usulan Prosedur yang Disepakati
A25: No. | B25: KAP | C25: Pengalaman KAP | D25: Nilai | F25: Jumlah | H25: Keterangan
D26: TL | E26: Analisis | F26: TL | G26: Analisis
A27: 1 | B27: KAP Luthfi Muhammad & Rekan | C27: 0.4 | D27: 81 | E27: N/A | F27: =C27*D27 -> 32.4 | G27: N/A | H27: N/A
A28: 2 | B28: KAP Yaniswar & Rekan | C28: 0.4 | D28: 81 | E28: N/A | F28: =C28*D28 -> 32.4 | G28: N/A | H28: N/A
A29: 3 | B29: KAP Drs. Abror, Ak | C29: 0.4 | D29: 85 | E29: 100 | F29: =C29*D29 -> 34 | G29: =E29*C29 -> 40 | H29: Hasil penilaian TL telah sesuai dengan pedoman penunjukkan KAP, berdasarkan verifikasi atas proposal cakupan dan relevansi atas metodologi dan usulan prosedur yang disepakati telah sesuai.
A32: D. | B32: Penilaian Biaya
A33: No. | B33: KAP | C33: Biaya Remunerasi | E33: Biaya Operasional | G33: PPN | I33: Total | K33: Keterangan
C34: Penawaran | D34: HPS | E34: Penawaran | F34: HPS | G34: Penawaran | H34: HPS | I34: Penawaran | J34: HPS (Pembulatan) | K34: Dibawah HPS | L34: Diatas HPS | M34: Penjelasan
A35: 1 | B35: KAP Luthfi Muhammad & Rekan | C35: N/A | D35: 55775000 | E35: N/A | F35: 13943750 | G35: N/A | H35: 6971875 | I35: =SUM(C35,E35,G35) -> 0 | J35: =ROUNDUP(D35+F35+H35,-3) -> 76691000 | K35: - | L35: - | M35: N/A
A36: 2 | B36: KAP Yaniswar & Rekan | C36: N/A | D36: =D35 -> 55775000 | E36: N/A | F36: =F35 -> 13943750 | G36: N/A | H36: =H35 -> 6971875 | I36: =SUM(C36,E36,G36) -> 0 | J36: =ROUNDUP(D36+F36+H36,-3) -> 76691000 | K36: - | L36: - | M36: N/A
A37: 3 | B37: KAP Drs. Abror, Ak | C37: 47000000 | D37: =D36 -> 55775000 | E37: 18000000 | F37: =F36 -> 13943750 | G37: 0 | H37: =H36 -> 6971875 | I37: =SUM(C37,E37,G37) -> 65000000 | J37: =ROUNDUP(D37+F37+H37,-3) -> 76691000 | K37: Ya | L37: - | M37: Menawarkan biaya terendah
A39: III. Kesimpulan :
A40: No. | B40: KAP | C40: Administrasi | D40: Teknis | E40: Biaya | F40: Total | G40: Keterangan 1) TL telah mengundang 8 (delapan) KAP untuk mengajukan proposal penawaran 2) Berdasarkan hasil verifikasi atas penilaian TL terhadap proposal penawaran, diketahui bahwa hasil penilaian tersebut telah sesuai dengan Pedoman Penunjukkan KAP dalam rangka Audit Atas Neraca Penutupan Bank Yang dicabut Izin Usahanya (Lampiran KKE No.Kep-064/KE/VII/2008 Tgl 10 Juli 2008) 2) KAP Drs. Abror, Ak yang diusulkan TL telah memenuhi syarat untuk ditunjuk sebagai pelaksana Audit atas Neraca Penutupan PT. BPR Tebas Lokarizki.(DL) dari aspek administrasi, teknis dan biaya.
A42: 1 | B42: KAP Luthfi Muhammad & Rekan | C42: Tidak Lulus | D42: N/A | E42: N/A | F42: N/A
A43: 2 | B43: KAP Yaniswar & Rekan | C43: Tidak Lulus | D43: N/A | E43: N/A | F43: N/A
A44: 3 | B44: KAP Drs. Abror, Ak | C44: Lulus | D44: =(F15+F22+F29) -> 94 | E44: =100 -> 100 | F44: =D44*0.7+E44*0.3 -> 95.8
A46: KECAKUPAN DAN RELEVANSI USULAN PROSEDUR YANG DISEPAKATI*)
A47: No. | B47: AKUN | D47: KECAKUPAN | E47: KECAKUPAN | F47: RELEVANSI
D48: (Ya/Tidak) | E48: (0 atau 4.2) | F48: (0,1.4,2.8,4.2)
...

Sheet Rekap Penilaian KAP
A1: KERTAS KERJA
A2: PENILAIAN PENUNJUKKAN KAP DALAM RANGKA AUDIT ATAS NERACA PENUTUPAN
A3: KOPERASI BPR ABANG PASAR (DL)
A5: I. Administrasi
A6: No. | B6: KAP | C6: A1. Kelengkapan Dokumen | E6: A2. Penilaian Aspek Administratif | G6: A3. Harga Perkiraan Sendiri (HPS) | I6: A4. Umum | K6: Jumlah | M6: Keterangan
C8: TL | D8: Analisis | E8: TL | F8: Analisis | G8: TL | H8: Analisis | I8: TL | J8: Analisis | K8: TL | L8: Analisis
A9: 1 | B9: =IF('Aspek Penilaian KAP Yaniswar'!$C$2=0,"",('Aspek Penilaian KAP Yaniswar'!$A$2&" "&'Aspek Penilaian KAP Yaniswar'!$C$2)) -> KAP KAP Yaniswar dan Rekan | C9: ='Aspek Penilaian KAP Yaniswar'!F28 -> 94.444444 | D9: ='Aspek Penilaian KAP Yaniswar'!O28 -> 100 | E9: ='Aspek Penilaian KAP Yaniswar'!F40 -> 100 | F9: ='Aspek Penilaian KAP Yaniswar'!O40 -> 87.5 | G9: ='Aspek Penilaian KAP Yaniswar'!F47 -> 66.666667 | H9: ='Aspek Penilaian KAP Yaniswar'!O47 -> 66.666667 | I9: ='Aspek Penilaian KAP Yaniswar'!F58 -> 100 | J9: ='Aspek Penilaian KAP Yaniswar'!O58 -> 100 | K9: ='Aspek Penilaian KAP Yaniswar'!F59 -> 94.444444 | L9: ='Aspek Penilaian KAP Yaniswar'!O59 -> 94.444444 | M9: Tanda daftar KAP terlampir pada https://kapyaniswar.com/aspek-legal/
A10: 2 | B10: =IF('Aspek Penilaian KAP DEF'!$C$2=0,"",('Aspek Penilaian KAP DEF'!$A$2&" "&'Aspek Penilaian KAP DEF'!$C$2)) | C10: ='Aspek Penilaian KAP DEF'!F28 -> 0 | D10: ='Aspek Penilaian KAP DEF'!O28 -> 0 | E10: ='Aspek Penilaian KAP DEF'!F40 -> 0 | F10: ='Aspek Penilaian KAP DEF'!O40 -> 0 | G10: ='Aspek Penilaian KAP DEF'!F47 -> 0 | H10: ='Aspek Penilaian KAP DEF'!O47 -> 0 | I10: ='Aspek Penilaian KAP DEF'!F58 -> 0 | J10: ='Aspek Penilaian KAP DEF'!O58 -> 0 | K10: ='Aspek Penilaian KAP DEF'!F59 -> 0 | L10: ='Aspek Penilaian KAP DEF'!O59 -> 0
A11: 3 | B11: =IF('Aspek Penilaian KAP GHI'!$C$2=0,"",('Aspek Penilaian KAP GHI'!$A$2&" "&'Aspek Penilaian KAP GHI'!$C$2)) | C11: ='Aspek Penilaian KAP GHI'!F28 -> 0 | D11: ='Aspek Penilaian KAP GHI'!O28 -> 0 | E11: ='Aspek Penilaian KAP GHI'!F40 -> 0 | F11: ='Aspek Penilaian KAP GHI'!O40 -> 0 | G11: ='Aspek Penilaian KAP GHI'!F47 -> 0 | H11: ='Aspek Penilaian KAP GHI'!O47 -> 0 | I11: ='Aspek Penilaian KAP GHI'!F58 -> 0 | J11: ='Aspek Penilaian KAP GHI'!O58 -> 0 | K11: ='Aspek Penilaian KAP GHI'!F59 -> 0 | L11: ='Aspek Penilaian KAP GHI'!O59 -> 0
A12: 4 | B12: =IF('Aspek Penilaian KAP JKL'!$C$2=0,"",('Aspek Penilaian KAP JKL'!$A$2&" "&'Aspek Penilaian KAP JKL'!$C$2)) | C12: ='Aspek Penilaian KAP JKL'!F28 -> 0 | D12: ='Aspek Penilaian KAP JKL'!O28 -> 0 | E12: ='Aspek Penilaian KAP JKL'!F40 -> 0 | F12: ='Aspek Penilaian KAP JKL'!O40 -> 0 | G12: ='Aspek Penilaian KAP JKL'!F47 -> 0 | H12: ='Aspek Penilaian KAP JKL'!O47 -> 0 | I12: ='Aspek Penilaian KAP JKL'!F58 -> 0 | J12: ='Aspek Penilaian KAP JKL'!O58 -> 0 | K12: ='Aspek Penilaian KAP JKL'!F59 -> 0 | L12: ='Aspek Penilaian KAP JKL'!O59 -> 0
A13: 5 | B13: =IF('Aspek Penilaian KAP MNO'!$C$2=0,"",('Aspek Penilaian KAP MNO'!$A$2&" "&'Aspek Penilaian KAP MNO'!$C$2)) | C13: ='Aspek Penilaian KAP MNO'!F28 -> 0 | D13: ='Aspek Penilaian KAP MNO'!O28 -> 0 | E13: ='Aspek Penilaian KAP MNO'!F40 -> 0 | F13: ='Aspek Penilaian KAP MNO'!O40 -> 0 | G13: ='Aspek Penilaian KAP MNO'!F47 -> 0 | H13: ='Aspek Penilaian KAP MNO'!O47 -> 0 | I13: ='Aspek Penilaian KAP MNO'!F58 -> 0 | J13: ='Aspek Penilaian KAP MNO'!O58 -> 0 | K13: ='Aspek Penilaian KAP MNO'!F59 -> 0 | L13: ='Aspek Penilaian KAP MNO'!O59 -> 0
A15: II. Penilaian
A16: A. | B16: Penilaian Teknis - Pengalaman KAP
A17: No. | B17: KAP | C17: Pengalaman KAP | D17: Nilai | F17: Jumlah | H17: Keterangan
D18: TL | E18: Analisis | F18: TL | G18: Analisis
A19: 1 | B19: =IF('Aspek Penilaian KAP Yaniswar'!$C$2=0,"",('Aspek Penilaian KAP Yaniswar'!$A$2&" "&'Aspek Penilaian KAP Yaniswar'!$C$2)) -> KAP KAP Yaniswar dan Rekan | C19: 0.3 | D19: ='Aspek Penilaian KAP Yaniswar'!E63 -> 0 | E19: ='Aspek Penilaian KAP Yaniswar'!N63 -> 24 | F19: =C19*D19 -> 0 | G19: =E19*C19 -> 7.2
A20: 2 | B20: =IF('Aspek Penilaian KAP DEF'!$C$2=0,"",('Aspek Penilaian KAP DEF'!$A$2&" "&'Aspek Penilaian KAP DEF'!$C$2)) | C20: 0.3 | D20: ='Aspek Penilaian KAP DEF'!E63 -> 0 | E20: ='Aspek Penilaian KAP DEF'!N63 -> 0 | F20: =C20*D20 -> 0 | G20: =E20*C20 -> 0
A21: 3 | B21: =IF('Aspek Penilaian KAP GHI'!$C$2=0,"",('Aspek Penilaian KAP GHI'!$A$2&" "&'Aspek Penilaian KAP GHI'!$C$2)) | C21: 0.3 | D21: ='Aspek Penilaian KAP GHI'!E63 -> 0 | E21: ='Aspek Penilaian KAP GHI'!N63 -> 0 | F21: =C21*D21 -> 0 | G21: =E21*C21 -> 0
A22: 4 | B22: =IF('Aspek Penilaian KAP JKL'!$C$2=0,"",('Aspek Penilaian KAP JKL'!$A$2&" "&'Aspek Penilaian KAP JKL'!$C$2)) | C22: 0.3 | D22: ='Aspek Penilaian KAP JKL'!E63 -> 0 | E22: ='Aspek Penilaian KAP JKL'!N63 -> 0 | F22: =C22*D22 -> 0 | G22: =E22*C22 -> 0
A23: 5 | B23: =IF('Aspek Penilaian KAP MNO'!$C$2=0,"",('Aspek Penilaian KAP MNO'!$A$2&" "&'Aspek Penilaian KAP MNO'!$C$2)) | C23: 0.3 | D23: ='Aspek Penilaian KAP MNO'!E63 -> 0 | E23: ='Aspek Penilaian KAP MNO'!N63 -> 0 | F23: =C23*D23 -> 0 | G23: =E23*C23 -> 0
A25: B. | B25: Penilaian Teknis - AP/Personil
A26: No. | B26: KAP | C26: Pengalaman KAP | D26: Nilai | F26: Jumlah | H26: Keterangan
D27: TL | E27: Analisis | F27: TL | G27: Analisis
A28: 1 | B28: =IF('Aspek Penilaian KAP Yaniswar'!$C$2=0,"",('Aspek Penilaian KAP Yaniswar'!$A$2&" "&'Aspek Penilaian KAP Yaniswar'!$C$2)) -> KAP KAP Yaniswar dan Rekan | C28: 0.3 | D28: ='Aspek Penilaian KAP Yaniswar'!E64 -> 100 | E28: ='Aspek Penilaian KAP Yaniswar'!N64 -> 16 | F28: =C28*D28 -> 30 | G28: =E28*C28 -> 4.8
A29: 2 | B29: =IF('Aspek Penilaian KAP DEF'!$C$2=0,"",('Aspek Penilaian KAP DEF'!$A$2&" "&'Aspek Penilaian KAP DEF'!$C$2)) | C29: 0.3 | D29: ='Aspek Penilaian KAP DEF'!E64 -> 0 | E29: ='Aspek Penilaian KAP DEF'!N64 -> 0 | F29: =C29*D29 -> 0 | G29: =E29*C29 -> 0
A30: 3 | B30: =IF('Aspek Penilaian KAP GHI'!$C$2=0,"",('Aspek Penilaian KAP GHI'!$A$2&" "&'Aspek Penilaian KAP GHI'!$C$2)) | C30: 0.3 | D30: ='Aspek Penilaian KAP GHI'!E64 -> 0 | E30: ='Aspek Penilaian KAP GHI'!N64 -> 0 | F30: =C30*D30 -> 0 | G30: =E30*C30 -> 0
A31: 4 | B31: =IF('Aspek Penilaian KAP JKL'!$C$2=0,"",('Aspek Penilaian KAP JKL'!$A$2&" "&'Aspek Penilaian KAP JKL'!$C$2)) | C31: 0.3 | D31: ='Aspek Penilaian KAP JKL'!E64 -> 0 | E31: ='Aspek Penilaian KAP JKL'!N64 -> 0 | F31: =C31*D31 -> 0 | G31: =E31*C31 -> 0
A32: 5 | B32: =IF('Aspek Penilaian KAP MNO'!$C$2=0,"",('Aspek Penilaian KAP MNO'!$A$2&" "&'Aspek Penilaian KAP MNO'!$C$2)) | C32: 0.3 | D32: ='Aspek Penilaian KAP MNO'!E64 -> 0 | E32: ='Aspek Penilaian KAP MNO'!N64 -> 0 | F32: =C32*D32 -> 0 | G32: =E32*C32 -> 0
A34: C. | B34: Penilaian Teknis - Metodologi & Usulan Prosedur yang Disepakati
A35: No. | B35: KAP | C35: Pengalaman KAP | D35: Nilai | F35: Jumlah | H35: Keterangan
D36: TL | E36: Analisis | F36: TL | G36: Analisis
A37: 1 | B37: =IF('Aspek Penilaian KAP Yaniswar'!$C$2=0,"",('Aspek Penilaian KAP Yaniswar'!$A$2&" "&'Aspek Penilaian KAP Yaniswar'!$C$2)) -> KAP KAP Yaniswar dan Rekan | C37: 0.4 | D37: ='Aspek Penilaian KAP Yaniswar'!E65 -> 40 | E37: ='Aspek Penilaian KAP Yaniswar'!N65 -> 48.4 | F37: =C37*D37 -> 16 | G37: =E37*C37 -> 19.36 | H37: Prosedur yang diusulkan berdasarkan KAK yang ditetapkan TL sesuai pedoman LPS
A38: 2 | B38: =IF('Aspek Penilaian KAP DEF'!$C$2=0,"",('Aspek Penilaian KAP DEF'!$A$2&" "&'Aspek Penilaian KAP DEF'!$C$2)) | C38: 0.4 | D38: ='Aspek Penilaian KAP DEF'!E65 -> 0 | E38: ='Aspek Penilaian KAP DEF'!N65 -> 0 | F38: =C38*D38 -> 0 | G38: =E38*C38 -> 0
A39: 3 | B39: =IF('Aspek Penilaian KAP GHI'!$C$2=0,"",('Aspek Penilaian KAP GHI'!$A$2&" "&'Aspek Penilaian KAP GHI'!$C$2)) | C39: 0.4 | D39: ='Aspek Penilaian KAP GHI'!E65 -> 0 | E39: ='Aspek Penilaian KAP GHI'!N65 -> 0 | F39: =C39*D39 -> 0 | G39: =E39*C39 -> 0
A40: 4 | B40: =IF('Aspek Penilaian KAP JKL'!$C$2=0,"",('Aspek Penilaian KAP JKL'!$A$2&" "&'Aspek Penilaian KAP JKL'!$C$2)) | C40: 0.4 | D40: ='Aspek Penilaian KAP JKL'!E65 -> 0 | E40: ='Aspek Penilaian KAP JKL'!N65 -> 0 | F40: =C40*D40 -> 0 | G40: =E40*C40 -> 0
A41: 5 | B41: =IF('Aspek Penilaian KAP MNO'!$C$2=0,"",('Aspek Penilaian KAP MNO'!$A$2&" "&'Aspek Penilaian KAP MNO'!$C$2)) | C41: 0.4 | D41: ='Aspek Penilaian KAP MNO'!E65 -> 0 | E41: ='Aspek Penilaian KAP MNO'!N65 -> 0 | F41: =C41*D41 -> 0 | G41: =E41*C41 -> 0
A43: D. | B43: Penilaian Biaya
A44: No. | B44: KAP | C44: Biaya Remunerasi | F44: Biaya Operasional | I44: PPN | L44: Total | O44: Keterangan
C45: Penawaran | E45: HPS | F45: Penawaran | H45: HPS | I45: Penawaran | K45: HPS | L45: Penawaran | N45: HPS (Pembulatan) | O45: Di bawah HPS | Q45: Penjelasan
C46: TL | D46: Analisis | F46: TL | G46: Analisis | I46: TL | J46: Analisis | L46: TL | M46: Analisis | O46: TL | P46: Analisis
...

Sheet Aspek Penilaian KAP Yaniswar
A1: PENILAIAN
A2: KAP | B2: : | C2: KAP Yaniswar dan Rekan
A3: Peserta Penugasan Audit Neraca Penutupan Koperasi BPR Abang Pasar (DL)
A5: PENILAIAN TL | J5: PENILAIAN PIC
A7: A. | B7: 1. | C7: ASPEK ADMINISTRATIF - KELENGKAPAN DOKUMEN | J7: A. | K7: 1. | L7: ASPEK ADMINISTRATIF - KELENGKAPAN DOKUMEN
A8: No. | B8: Item Yang Dinilai | D8: Keterangan | E8: Pemenuhan | F8: Nilai | J8: No. | K8: Item Yang Dinilai | M8: Keterangan | N8: Pemenuhan | O8: Nilai
A9: 1. | B9: Proposal diterima tepat waktu | E9: Ya | F9: =IF(E9="Ya",100,0) -> 100 | J9: 1. | K9: Proposal diterima tepat waktu | N9: Ya | O9: =IF(N9="Ya",100,0) -> 100
A10: 2. | B10: Surat Pengantar | E10: Ya | F10: =IF(E10="Ya",100,0) -> 100 | J10: 2. | K10: Surat Pengantar | N10: Ya | O10: =IF(N10="Ya",100,0) -> 100
A11: 3. | B11: Surat Pengantar ditanda-tangani oleh Pimpinan KAP/Rekan dengan materai | E11: Ya | F11: =IF(E11="Ya",100,0) -> 100 | J11: 3. | K11: Surat Pengantar ditanda-tangani oleh Pimpinan KAP/Rekan dengan materai | N11: Ya | O11: =IF(N11="Ya",100,0) -> 100
A12: 4. | B12: Surat Pengantar memuat pernyataan : | J12: 4. | K12: Surat Pengantar memuat pernyataan :
B13: a. | C13: Tidak memiliki dan tidak pernah memiliki kepentingan dengan Koperasi BPR Abang Pasar dalam 3 tahun terakhir. | E13: Ya | F13: =IF(E13="Ya",100,0) -> 100 | K13: a. | L13: Tidak memiliki dan tidak pernah memiliki kepentingan dengan Koperasi BPR Abang Pasar dalam 3 tahun terakhir. | N13: Ya | O13: =IF(N13="Ya",100,0) -> 100
B14: b. | C14: Bersedia untuk tidak ikut proses seleksi lebih lanjut apabila menurut Tim Likuidasi ternyata KAP pernah memiliki kepentingan dalam 3 tahun terakhir. | E14: Ya | F14: =IF(E14="Ya",100,0) -> 100 | K14: b. | L14: Bersedia untuk tidak ikut proses seleksi lebih lanjut apabila menurut Tim Likuidasi ternyata KAP pernah memiliki kepentingan dalam 3 tahun terakhir. | N14: Ya | O14: =IF(N14="Ya",100,0) -> 100
B15: c. | C15: KAP dan personil sanggup menjaga kerahasiaan penugasan | E15: Ya | F15: =IF(E15="Ya",100,0) -> 100 | K15: c. | L15: KAP dan personil sanggup menjaga kerahasiaan penugasan | N15: Ya | O15: =IF(N15="Ya",100,0) -> 100
B16: d. | C16: Bahwa data dan informasi yang disajikan dalam proposal adalah benar/sah dan KAP sanggup menunjukan dokumen asli ketika diminta. | E16: Ya | F16: =IF(E16="Ya",100,0) -> 100 | K16: d. | L16: Bahwa data dan informasi yang disajikan dalam proposal adalah benar/sah dan KAP sanggup menunjukan dokumen asli ketika diminta. | N16: Ya | O16: =IF(N16="Ya",100,0) -> 100
B17: e. | C17: AP dan/atau KAP tidak sedang menjalani sanksi pembekuan izin oleh Departemen Keuangan, IAI atau IAPI | E17: Ya | F17: =IF(E17="Ya",100,0) -> 100 | K17: e. | L17: AP dan/atau KAP tidak sedang menjalani sanksi pembekuan izin oleh Departemen Keuangan, IAI atau IAPI | N17: Ya | O17: =IF(N17="Ya",100,0) -> 100
B18: f. | C18: AP dan/atau KAP tidak sedang menjalani proses pemeriksaan oleh Departemen Keuangan, IAI atau IAPI terkait dengan indikasi pelanggaran azas SPAP dan/atau peraturan perundang-undangan yang berlaku. | E18: Ya | F18: =IF(E18="Ya",100,0) -> 100 | K18: f. | L18: AP dan/atau KAP tidak sedang menjalani proses pemeriksaan oleh Departemen Keuangan, IAI atau IAPI terkait dengan indikasi pelanggaran azas SPAP dan/atau peraturan perundang-undangan yang berlaku. | N18: Ya | O18: =IF(N18="Ya",100,0) -> 100
B19: g. | C19: Kesanggupan untuk mengikuti seleksi dengan biaya sendiri | E19: Ya | F19: =IF(E19="Ya",100,0) -> 100 | K19: g. | L19: Kesanggupan untuk mengikuti seleksi dengan biaya sendiri | N19: Ya | O19: =IF(N19="Ya",100,0) -> 100
A20: 5. | B20: AP memiliki izin AP dari Menteri Keuangan | E20: Ya | F20: =IF(E20="Ya",100,0) -> 100 | J20: 5. | K20: AP memiliki izin AP dari Menteri Keuangan | M20: Izin Usaha Kantor Akuntan Publik (KAP) SK Menkeu Nomor : 44/KM.1/2018 | N20: Ya | O20: =IF(N20="Ya",100,0) -> 100
A21: 6. | B21: AP memiliki atau menjadi rekan pada KAP yang memiliki izin dari Menteri Keuangan. | E21: Ya | F21: =IF(E21="Ya",100,0) -> 100 | J21: 6. | K21: AP memiliki atau menjadi rekan pada KAP yang memiliki izin dari Menteri Keuangan. | N21: Ya | O21: =IF(N21="Ya",100,0) -> 100
A22: 7. | B22: Merupakan AP yang terdaftar di BI / OJK | E22: Ya | F22: =IF(E22="Ya",100,0) -> 100 | J22: 7. | K22: Merupakan AP yang terdaftar di BI / OJK | M22: No. STTD.AP-359/NB.122/2018 | N22: Ya | O22: =IF(N22="Ya",100,0) -> 100
A23: 8. | B23: Memiliki pengalaman audit di industri perbankan | E23: Ya | F23: =IF(E23="Ya",100,0) -> 100 | J23: 8. | K23: Memiliki pengalaman audit di industri perbankan | N23: Ya | O23: =IF(N23="Ya",100,0) -> 100
A24: 9. | B24: Memiliki auditor yang pegawai tetap sekurang-kurangya 6 orang | E24: Ya | F24: =IF(E24="Ya",100,0) -> 100 | J24: 9. | K24: Memiliki auditor yang pegawai tetap sekurang-kurangya 6 orang | N24: Ya | O24: =IF(N24="Ya",100,0) -> 100
A25: 10. | B25: Auditor yang ditugaskan sekurang-kurangnya 50 % telah menjadi pegawai tetap sejak 1 tahun terakhir. | E25: Ya | F25: =IF(E25="Ya",100,0) -> 100 | J25: 10. | K25: Auditor yang ditugaskan sekurang-kurangnya 50 % telah menjadi pegawai tetap sejak 1 tahun terakhir. | N25: Ya | O25: =IF(N25="Ya",100,0) -> 100
A26: 11. | B26: Bukan AP/KAP yang melakukan audit atas laporan keuangan KBPR Abang Pasar | E26: Ya | F26: =IF(E26="Ya",100,0) -> 100 | J26: 11. | K26: Bukan AP/KAP yang melakukan audit atas laporan keuangan KBPR Abang Pasar | N26: Ya | O26: =IF(N26="Ya",100,0) -> 100
A27: 12. | B27: KAK telah ditandatnagani oleh TL | F27: =IF(E27="Ya",100,0) -> 0 | J27: 12. | K27: KAK telah ditandatangani oleh TL | N27: Ya | O27: =IF(N27="Ya",100,0) -> 100
A28: Kesimpulan : Lulus persyaratan administratif | E28: Total A1 | F28: =AVERAGE(F9:F27) -> 94.444444 | J28: Kesimpulan A1-A4 : Lulus persyaratan administratif | N28: Total A1 | O28: =AVERAGE(O9:O27) -> 100
A30: A. | B30: 2. | C30: PENILAIAN ASPEK ADMINISTRATIF | J30: A. | K30: 2. | L30: PENILAIAN ASPEK ADMINISTRATIF
A31: No. | B31: Item Yang Dinilai | D31: Keterangan | E31: Pemenuhan | F31: Nilai | J31: No. | K31: Item Yang Dinilai | M31: Keterangan | N31: Pemenuhan | O31: Nilai
A32: 1. | B32: Form A ditandatangani oleh Pimpinan atau penanggungjawab dari KAP/Cabang KAP | E32: Ya | F32: =IF(E32="Ya",100,0) -> 100 | J32: 1. | K32: Form A ditandatangani oleh Pimpinan atau penanggungjawab dari KAP/Cabang KAP | N32: Ya | O32: =IF(N32="Ya",100,0) -> 100
A33: 2. | B33: Form B dibuat lengkap | E33: Ya | F33: =IF(E33="Ya",100,0) -> 100 | J33: 2. | K33: Form B dibuat lengkap | N33: Ya | O33: =IF(N33="Ya",100,0) -> 100
A34: 3. | B34: Form C (biodata personil) ditandatangani oleh personil yang bersangkutan dan oleh KAP | E34: Ya | F34: =IF(E34="Ya",100,0) -> 100 | J34: 3. | K34: Form C (biodata personil) ditandatangani oleh personil yang bersangkutan dan oleh KAP | N34: Tidak | O34: =IF(N34="Ya",100,0) -> 0
A35: 4. | B35: Form D (usulan prosedur yang disepakati) diisi dengan lengkap | E35: Ya | F35: =IF(E35="Ya",100,0) -> 100 | J35: 4. | K35: Form D (usulan prosedur yang disepakati) diisi dengan lengkap | N35: Ya | O35: =IF(N35="Ya",100,0) -> 100
A36: 5. | B36: Form E (rincian biaya) diisi lengkap | E36: Ya | F36: =IF(E36="Ya",100,0) -> 100 | J36: 5. | K36: Form E (rincian biaya) diisi lengkap | N36: Ya | O36: =IF(N36="Ya",100,0) -> 100
A37: 6. | B37: Form F (Daftar Pegawai Tetap) diisi dengan lengkap | E37: Ya | F37: =IF(E37="Ya",100,0) -> 100 | J37: 6. | K37: Form F (Daftar Pegawai Tetap) diisi dengan lengkap | N37: Ya | O37: =IF(N37="Ya",100,0) -> 100
A38: 7. | B38: KAP/AP independen terhadap objek audit | E38: Ya | F38: =IF(E38="Ya",100,0) -> 100 | J38: 7. | K38: KAP/AP independen terhadap objek audit | N38: Ya | O38: =IF(N38="Ya",100,0) -> 100
A39: 8. | B39: KAP dan/atau AP memiliki pengalaman yang dinilai | E39: Ya | F39: =IF(E39="Ya",100,0) -> 100 | J39: 8. | K39: KAP dan/atau AP memiliki pengalaman yang dinilai | N39: Ya | O39: =IF(N39="Ya",100,0) -> 100
E40: Total A2 | F40: =AVERAGE(F32:F39) -> 100 | N40: Total A2 | O40: =AVERAGE(O32:O39) -> 87.5
A42: A. | B42: 3. | C42: HARGA PERKIRAAN SENDIRI (HPS) | J42: A. | K42: 3. | L42: HARGA PERKIRAAN SENDIRI (HPS)
A43: No. | B43: Item Yang Dinilai | D43: Keterangan | E43: Pemenuhan | F43: Nilai | J43: No. | K43: Item Yang Dinilai | M43: Keterangan | N43: Pemenuhan | O43: Nilai
A44: 1. | B44: Billing rate HPS TL mengacu berdasarkan tarif jasa konsultan | D44: Billing rate Inkindo Tahun 2021 | E44: Ya | F44: =IF(E44="Ya",100,0) -> 100 | J44: 1. | K44: Billing rate HPS TL mengacu berdasarkan tarif jasa konsultan | M44: Billing rate Inkindo Tahun 2021 | N44: Ya | O44: =IF(N44="Ya",100,0) -> 100
...

Sheet Aspek Penilaian KAP DEF
A1: PENILAIAN
A2: KAP | B2: :
A3: Peserta Penugasan Audit Neraca Penutupan PT BPR XXX (DL)
A5: PENILAIAN TL | J5: PENILAIAN PIC
A7: A. | B7: 1. | C7: ASPEK ADMINISTRATIF - KELENGKAPAN DOKUMEN | J7: A. | K7: 1. | L7: ASPEK ADMINISTRATIF - KELENGKAPAN DOKUMEN
A8: No. | B8: Item Yang Dinilai | D8: Keterangan | E8: Pemenuhan | F8: Nilai | J8: No. | K8: Item Yang Dinilai | M8: Keterangan | N8: Pemenuhan | O8: Nilai
A9: 1. | B9: Proposal diterima tepat waktu | E9: Tidak | F9: =IF(E9="Ya",100,0) -> 0 | J9: 1. | K9: Proposal diterima tepat waktu | N9: Tidak | O9: =IF(N9="Ya",100,0) -> 0
A10: 2. | B10: Surat Pengantar | E10: Tidak | F10: =IF(E10="Ya",100,0) -> 0 | J10: 2. | K10: Surat Pengantar | N10: Tidak | O10: =IF(N10="Ya",100,0) -> 0
A11: 3. | B11: Surat Pengantar ditanda-tangani oleh Pimpinan KAP/Rekan dengan materai | E11: Tidak | F11: =IF(E11="Ya",100,0) -> 0 | J11: 3. | K11: Surat Pengantar ditanda-tangani oleh Pimpinan KAP/Rekan dengan materai | N11: Tidak | O11: =IF(N11="Ya",100,0) -> 0
A12: 4. | B12: Surat Pengantar memuat pernyataan : | J12: 4. | K12: Surat Pengantar memuat pernyataan :
B13: a. | C13: Tidak memiliki dan tidak pernah memiliki kepentingan dengan PT BPR XXX dalam 3 tahun terakhir. | E13: Tidak | F13: =IF(E13="Ya",100,0) -> 0 | K13: a. | L13: Tidak memiliki dan tidak pernah memiliki kepentingan dengan PT BPR XXX dalam 3 tahun terakhir. | N13: Tidak | O13: =IF(N13="Ya",100,0) -> 0
B14: b. | C14: Bersedia untuk tidak ikut proses seleksi lebih lanjut apabila menurut Tim Likuidasi ternyata KAP pernah memiliki kepentingan dalam 3 tahun terakhir. | E14: Tidak | F14: =IF(E14="Ya",100,0) -> 0 | K14: b. | L14: Bersedia untuk tidak ikut proses seleksi lebih lanjut apabila menurut Tim Likuidasi ternyata KAP pernah memiliki kepentingan dalam 3 tahun terakhir. | N14: Tidak | O14: =IF(N14="Ya",100,0) -> 0
B15: c. | C15: KAP dan personil sanggup menjaga kerahasiaan penugasan | E15: Tidak | F15: =IF(E15="Ya",100,0) -> 0 | K15: c. | L15: KAP dan personil sanggup menjaga kerahasiaan penugasan | N15: Tidak | O15: =IF(N15="Ya",100,0) -> 0
B16: d. | C16: Bahwa data dan informasi yang disajikan dalam proposal adalah benar/sah dan KAP sanggup menunjukan dokumen asli ketika diminta. | E16: Tidak | F16: =IF(E16="Ya",100,0) -> 0 | K16: d. | L16: Bahwa data dan informasi yang disajikan dalam proposal adalah benar/sah dan KAP sanggup menunjukan dokumen asli ketika diminta. | N16: Tidak | O16: =IF(N16="Ya",100,0) -> 0
B17: e. | C17: AP dan/atau KAP tidak sedang menjalani sanksi pembekuan izin oleh Departemen Keuangan, IAI atau IAPI | E17: Tidak | F17: =IF(E17="Ya",100,0) -> 0 | K17: e. | L17: AP dan/atau KAP tidak sedang menjalani sanksi pembekuan izin oleh Departemen Keuangan, IAI atau IAPI | N17: Tidak | O17: =IF(N17="Ya",100,0) -> 0
B18: f. | C18: AP dan/atau KAP tidak sedang menjalani proses pemeriksaan oleh Departemen Keuangan, IAI atau IAPI terkait dengan indikasi pelanggaran azas SPAP dan/atau peraturan perundang-undangan yang berlaku. | E18: Tidak | F18: =IF(E18="Ya",100,0) -> 0 | K18: f. | L18: AP dan/atau KAP tidak sedang menjalani proses pemeriksaan oleh Departemen Keuangan, IAI atau IAPI terkait dengan indikasi pelanggaran azas SPAP dan/atau peraturan perundang-undangan yang berlaku. | N18: Tidak | O18: =IF(N18="Ya",100,0) -> 0
B19: g. | C19: Kesanggupan untuk mengikuti seleksi dengan biaya sendiri | E19: Tidak | F19: =IF(E19="Ya",100,0) -> 0 | K19: g. | L19: Kesanggupan untuk mengikuti seleksi dengan biaya sendiri | N19: Tidak | O19: =IF(N19="Ya",100,0) -> 0
A20: 5. | B20: AP memiliki izin AP dari Menteri Keuangan | E20: Tidak | F20: =IF(E20="Ya",100,0) -> 0 | J20: 5. | K20: AP memiliki izin AP dari Menteri Keuangan | N20: Tidak | O20: =IF(N20="Ya",100,0) -> 0
A21: 6. | B21: AP memiliki atau menjadi rekan pada KAP yang memiliki izin dari Menteri Keuangan. | E21: Tidak | F21: =IF(E21="Ya",100,0) -> 0 | J21: 6. | K21: AP memiliki atau menjadi rekan pada KAP yang memiliki izin dari Menteri Keuangan. | N21: Tidak | O21: =IF(N21="Ya",100,0) -> 0
A22: 7. | B22: Merupakan AP yang terdaftar di BI / OJK | E22: Tidak | F22: =IF(E22="Ya",100,0) -> 0 | J22: 7. | K22: Merupakan AP yang terdaftar di BI / OJK | N22: Tidak | O22: =IF(N22="Ya",100,0) -> 0
A23: 8. | B23: Memiliki pengalaman audit di industri perbankan | E23: Tidak | F23: =IF(E23="Ya",100,0) -> 0 | J23: 8. | K23: Memiliki pengalaman audit di industri perbankan | N23: Tidak | O23: =IF(N23="Ya",100,0) -> 0
A24: 9. | B24: Memiliki auditor yang pegawai tetap sekurang-kurangya 6 orang | E24: Tidak | F24: =IF(E24="Ya",100,0) -> 0 | J24: 9. | K24: Memiliki auditor yang pegawai tetap sekurang-kurangya 6 orang | N24: Tidak | O24: =IF(N24="Ya",100,0) -> 0
A25: 10. | B25: Auditor yang ditugaskan sekurang-kurangnya 50 % telah menjadi pegawai tetap sejak 1 tahun terakhir. | E25: Tidak | F25: =IF(E25="Ya",100,0) -> 0 | J25: 10. | K25: Auditor yang ditugaskan sekurang-kurangnya 50 % telah menjadi pegawai tetap sejak 1 tahun terakhir. | N25: Tidak | O25: =IF(N25="Ya",100,0) -> 0
A26: 11. | B26: Bukan AP/KAP yang melakukan audit atas laporan keuangan PT BPR XXX | E26: Tidak | F26: =IF(E26="Ya",100,0) -> 0 | J26: 11. | K26: Bukan AP/KAP yang melakukan audit atas laporan keuangan PT BPR XXX | N26: Tidak | O26: =IF(N26="Ya",100,0) -> 0
A27: 12. | B27: KAK telah ditandatnagani oleh TL | E27: Tidak | F27: =IF(E27="Ya",100,0) -> 0 | J27: 12. | K27: KAK telah ditandatangani oleh TL | N27: Tidak | O27: =IF(N27="Ya",100,0) -> 0
A28: Kesimpulan : Lulus persyaratan administratif | E28: Total A1 | F28: =AVERAGE(F9:F27) -> 0 | J28: Kesimpulan A1-A4 : Lulus persyaratan administratif | N28: Total A1 | O28: =AVERAGE(O9:O27) -> 0
A30: A. | B30: 2. | C30: PENILAIAN ASPEK ADMINISTRATIF | J30: A. | K30: 2. | L30: PENILAIAN ASPEK ADMINISTRATIF
A31: No. | B31: Item Yang Dinilai | D31: Keterangan | E31: Pemenuhan | F31: Nilai | J31: No. | K31: Item Yang Dinilai | M31: Keterangan | N31: Pemenuhan | O31: Nilai
A32: 1. | B32: Form A ditandatangani oleh Pimpinan atau penanggungjawab dari KAP/Cabang KAP | E32: Tidak | F32: =IF(E32="Ya",100,0) -> 0 | J32: 1. | K32: Form A ditandatangani oleh Pimpinan atau penanggungjawab dari KAP/Cabang KAP | N32: Tidak | O32: =IF(N32="Ya",100,0) -> 0
A33: 2. | B33: Form B dibuat lengkap | E33: Tidak | F33: =IF(E33="Ya",100,0) -> 0 | J33: 2. | K33: Form B dibuat lengkap | N33: Tidak | O33: =IF(N33="Ya",100,0) -> 0
A34: 3. | B34: Form C (biodata personil) ditandatangani oleh personil yang bersangkutan dan oleh KAP | E34: Tidak | F34: =IF(E34="Ya",100,0) -> 0 | J34: 3. | K34: Form C (biodata personil) ditandatangani oleh personil yang bersangkutan dan oleh KAP | N34: Tidak | O34: =IF(N34="Ya",100,0) -> 0
A35: 4. | B35: Form D (usulan prosedur yang disepakati) diisi dengan lengkap | E35: Tidak | F35: =IF(E35="Ya",100,0) -> 0 | J35: 4. | K35: Form D (usulan prosedur yang disepakati) diisi dengan lengkap | N35: Tidak | O35: =IF(N35="Ya",100,0) -> 0
A36: 5. | B36: Form E (rincian biaya) diisi lengkap | E36: Tidak | F36: =IF(E36="Ya",100,0) -> 0 | J36: 5. | K36: Form E (rincian biaya) diisi lengkap | N36: Tidak | O36: =IF(N36="Ya",100,0) -> 0
A37: 6. | B37: Form F (Daftar Pegawai Tetap) diisi dengan lengkap | E37: Tidak | F37: =IF(E37="Ya",100,0) -> 0 | J37: 6. | K37: Form F (Daftar Pegawai Tetap) diisi dengan lengkap | N37: Tidak | O37: =IF(N37="Ya",100,0) -> 0
A38: 7. | B38: KAP/AP independen terhadap objek audit | E38: Tidak | F38: =IF(E38="Ya",100,0) -> 0 | J38: 7. | K38: KAP/AP independen terhadap objek audit | N38: Tidak | O38: =IF(N38="Ya",100,0) -> 0
A39: 8. | B39: KAP dan/atau AP memiliki pengalaman yang dinilai | E39: Tidak | F39: =IF(E39="Ya",100,0) -> 0 | J39: 8. | K39: KAP dan/atau AP memiliki pengalaman yang dinilai | N39: Tidak | O39: =IF(N39="Ya",100,0) -> 0
E40: Total A2 | F40: =AVERAGE(F32:F39) -> 0 | N40: Total A2 | O40: =AVERAGE(O32:O39) -> 0
A42: A. | B42: 3. | C42: HARGA PERKIRAAN SENDIRI (HPS) | J42: A. | K42: 3. | L42: HARGA PERKIRAAN SENDIRI (HPS)
A43: No. | B43: Item Yang Dinilai | D43: Keterangan | E43: Pemenuhan | F43: Nilai | J43: No. | K43: Item Yang Dinilai | M43: Keterangan | N43: Pemenuhan | O43: Nilai
A44: 1. | B44: Billing rate HPS TL mengacu berdasarkan tarif jasa konsultan | D44: Billing rate Inkindo Tahun 2021 | E44: Tidak | F44: =IF(E44="Ya",100,0) -> 0 | J44: 1. | K44: Billing rate HPS TL mengacu berdasarkan tarif jasa konsultan | M44: Billing rate Inkindo Tahun 2021 | N44: Tidak | O44: =IF(N44="Ya",100,0) -> 0
...

Sheet Aspek Penilaian KAP GHI
A1: PENILAIAN
A2: KAP | B2: :
A3: Peserta Penugasan Audit Neraca Penutupan PT BPR XXX (DL)
A5: PENILAIAN TL | J5: PENILAIAN PIC
A7: A. | B7: 1. | C7: ASPEK ADMINISTRATIF - KELENGKAPAN DOKUMEN | J7: A. | K7: 1. | L7: ASPEK ADMINISTRATIF - KELENGKAPAN DOKUMEN
A8: No. | B8: Item Yang Dinilai | D8: Keterangan | E8: Pemenuhan | F8: Nilai | J8: No. | K8: Item Yang Dinilai | M8: Keterangan | N8: Pemenuhan | O8: Nilai
A9: 1. | B9: Proposal diterima tepat waktu | E9: Tidak | F9: =IF(E9="Ya",100,0) -> 0 | J9: 1. | K9: Proposal diterima tepat waktu | N9: Tidak | O9: =IF(N9="Ya",100,0) -> 0
A10: 2. | B10: Surat Pengantar | E10: Tidak | F10: =IF(E10="Ya",100,0) -> 0 | J10: 2. | K10: Surat Pengantar | N10: Tidak | O10: =IF(N10="Ya",100,0) -> 0
A11: 3. | B11: Surat Pengantar ditanda-tangani oleh Pimpinan KAP/Rekan dengan materai | E11: Tidak | F11: =IF(E11="Ya",100,0) -> 0 | J11: 3. | K11: Surat Pengantar ditanda-tangani oleh Pimpinan KAP/Rekan dengan materai | N11: Tidak | O11: =IF(N11="Ya",100,0) -> 0
A12: 4. | B12: Surat Pengantar memuat pernyataan : | J12: 4. | K12: Surat Pengantar memuat pernyataan :
B13: a. | C13: Tidak memiliki dan tidak pernah memiliki kepentingan dengan PT BPR XXX (DL) dalam 3 tahun terakhir. | E13: Tidak | F13: =IF(E13="Ya",100,0) -> 0 | K13: a. | L13: Tidak memiliki dan tidak pernah memiliki kepentingan dengan PT BPR XXX (DL) dalam 3 tahun terakhir. | N13: Tidak | O13: =IF(N13="Ya",100,0) -> 0
B14: b. | C14: Bersedia untuk tidak ikut proses seleksi lebih lanjut apabila menurut Tim Likuidasi ternyata KAP pernah memiliki kepentingan dalam 3 tahun terakhir. | E14: Tidak | F14: =IF(E14="Ya",100,0) -> 0 | K14: b. | L14: Bersedia untuk tidak ikut proses seleksi lebih lanjut apabila menurut Tim Likuidasi ternyata KAP pernah memiliki kepentingan dalam 3 tahun terakhir. | N14: Tidak | O14: =IF(N14="Ya",100,0) -> 0
B15: c. | C15: KAP dan personil sanggup menjaga kerahasiaan penugasan | E15: Tidak | F15: =IF(E15="Ya",100,0) -> 0 | K15: c. | L15: KAP dan personil sanggup menjaga kerahasiaan penugasan | N15: Tidak | O15: =IF(N15="Ya",100,0) -> 0
B16: d. | C16: Bahwa data dan informasi yang disajikan dalam proposal adalah benar/sah dan KAP sanggup menunjukan dokumen asli ketika diminta. | E16: Tidak | F16: =IF(E16="Ya",100,0) -> 0 | K16: d. | L16: Bahwa data dan informasi yang disajikan dalam proposal adalah benar/sah dan KAP sanggup menunjukan dokumen asli ketika diminta. | N16: Tidak | O16: =IF(N16="Ya",100,0) -> 0
B17: e. | C17: AP dan/atau KAP tidak sedang menjalani sanksi pembekuan izin oleh Departemen Keuangan, IAI atau IAPI | E17: Tidak | F17: =IF(E17="Ya",100,0) -> 0 | K17: e. | L17: AP dan/atau KAP tidak sedang menjalani sanksi pembekuan izin oleh Departemen Keuangan, IAI atau IAPI | N17: Tidak | O17: =IF(N17="Ya",100,0) -> 0
B18: f. | C18: AP dan/atau KAP tidak sedang menjalani proses pemeriksaan oleh Departemen Keuangan, IAI atau IAPI terkait dengan indikasi pelanggaran azas SPAP dan/atau peraturan perundang-undangan yang berlaku. | E18: Tidak | F18: =IF(E18="Ya",100,0) -> 0 | K18: f. | L18: AP dan/atau KAP tidak sedang menjalani proses pemeriksaan oleh Departemen Keuangan, IAI atau IAPI terkait dengan indikasi pelanggaran azas SPAP dan/atau peraturan perundang-undangan yang berlaku. | N18: Tidak | O18: =IF(N18="Ya",100,0) -> 0
B19: g. | C19: Kesanggupan untuk mengikuti seleksi dengan biaya sendiri | E19: Tidak | F19: =IF(E19="Ya",100,0) -> 0 | K19: g. | L19: Kesanggupan untuk mengikuti seleksi dengan biaya sendiri | N19: Tidak | O19: =IF(N19="Ya",100,0) -> 0
A20: 5. | B20: AP memiliki izin AP dari Menteri Keuangan | E20: Tidak | F20: =IF(E20="Ya",100,0) -> 0 | J20: 5. | K20: AP memiliki izin AP dari Menteri Keuangan | N20: Tidak | O20: =IF(N20="Ya",100,0) -> 0
A21: 6. | B21: AP memiliki atau menjadi rekan pada KAP yang memiliki izin dari Menteri Keuangan. | E21: Tidak | F21: =IF(E21="Ya",100,0) -> 0 | J21: 6. | K21: AP memiliki atau menjadi rekan pada KAP yang memiliki izin dari Menteri Keuangan. | N21: Tidak | O21: =IF(N21="Ya",100,0) -> 0
A22: 7. | B22: Merupakan AP yang terdaftar di BI / OJK | E22: Tidak | F22: =IF(E22="Ya",100,0) -> 0 | J22: 7. | K22: Merupakan AP yang terdaftar di BI / OJK | N22: Tidak | O22: =IF(N22="Ya",100,0) -> 0
A23: 8. | B23: Memiliki pengalaman audit di industri perbankan | E23: Tidak | F23: =IF(E23="Ya",100,0) -> 0 | J23: 8. | K23: Memiliki pengalaman audit di industri perbankan | N23: Tidak | O23: =IF(N23="Ya",100,0) -> 0
A24: 9. | B24: Memiliki auditor yang pegawai tetap sekurang-kurangya 6 orang | E24: Tidak | F24: =IF(E24="Ya",100,0) -> 0 | J24: 9. | K24: Memiliki auditor yang pegawai tetap sekurang-kurangya 6 orang | N24: Tidak | O24: =IF(N24="Ya",100,0) -> 0
A25: 10. | B25: Auditor yang ditugaskan sekurang-kurangnya 50 % telah menjadi pegawai tetap sejak 1 tahun terakhir. | E25: Tidak | F25: =IF(E25="Ya",100,0) -> 0 | J25: 10. | K25: Auditor yang ditugaskan sekurang-kurangnya 50 % telah menjadi pegawai tetap sejak 1 tahun terakhir. | N25: Tidak | O25: =IF(N25="Ya",100,0) -> 0
A26: 11. | B26: Bukan AP/KAP yang melakukan audit atas laporan keuangan PT BPR XXX (DL) | E26: Tidak | F26: =IF(E26="Ya",100,0) -> 0 | J26: 11. | K26: Bukan AP/KAP yang melakukan audit atas laporan keuangan PT BPR XXX (DL) | N26: Tidak | O26: =IF(N26="Ya",100,0) -> 0
A27: 12. | B27: KAK telah ditandatnagani oleh TL | E27: Tidak | F27: =IF(E27="Ya",100,0) -> 0 | J27: 12. | K27: KAK telah ditandatangani oleh TL | N27: Tidak | O27: =IF(N27="Ya",100,0) -> 0
A28: Kesimpulan : Lulus persyaratan administratif | E28: Total A1 | F28: =AVERAGE(F9:F27) -> 0 | J28: Kesimpulan A1-A4 : Lulus persyaratan administratif | N28: Total A1 | O28: =AVERAGE(O9:O27) -> 0
A30: A. | B30: 2. | C30: PENILAIAN ASPEK ADMINISTRATIF | J30: A. | K30: 2. | L30: PENILAIAN ASPEK ADMINISTRATIF
A31: No. | B31: Item Yang Dinilai | D31: Keterangan | E31: Pemenuhan | F31: Nilai | J31: No. | K31: Item Yang Dinilai | M31: Keterangan | N31: Pemenuhan | O31: Nilai
A32: 1. | B32: Form A ditandatangani oleh Pimpinan atau penanggungjawab dari KAP/Cabang KAP | E32: Tidak | F32: =IF(E32="Ya",100,0) -> 0 | J32: 1. | K32: Form A ditandatangani oleh Pimpinan atau penanggungjawab dari KAP/Cabang KAP | N32: Tidak | O32: =IF(N32="Ya",100,0) -> 0
A33: 2. | B33: Form B dibuat lengkap | E33: Tidak | F33: =IF(E33="Ya",100,0) -> 0 | J33: 2. | K33: Form B dibuat lengkap | N33: Tidak | O33: =IF(N33="Ya",100,0) -> 0
A34: 3. | B34: Form C (biodata personil) ditandatangani oleh personil yang bersangkutan dan oleh KAP | E34: Tidak | F34: =IF(E34="Ya",100,0) -> 0 | J34: 3. | K34: Form C (biodata personil) ditandatangani oleh personil yang bersangkutan dan oleh KAP | N34: Tidak | O34: =IF(N34="Ya",100,0) -> 0
A35: 4. | B35: Form D (usulan prosedur yang disepakati) diisi dengan lengkap | E35: Tidak | F35: =IF(E35="Ya",100,0) -> 0 | J35: 4. | K35: Form D (usulan prosedur yang disepakati) diisi dengan lengkap | N35: Tidak | O35: =IF(N35="Ya",100,0) -> 0
A36: 5. | B36: Form E (rincian biaya) diisi lengkap | E36: Tidak | F36: =IF(E36="Ya",100,0) -> 0 | J36: 5. | K36: Form E (rincian biaya) diisi lengkap | N36: Tidak | O36: =IF(N36="Ya",100,0) -> 0
A37: 6. | B37: Form F (Daftar Pegawai Tetap) diisi dengan lengkap | E37: Tidak | F37: =IF(E37="Ya",100,0) -> 0 | J37: 6. | K37: Form F (Daftar Pegawai Tetap) diisi dengan lengkap | N37: Tidak | O37: =IF(N37="Ya",100,0) -> 0
A38: 7. | B38: KAP/AP independen terhadap objek audit | E38: Tidak | F38: =IF(E38="Ya",100,0) -> 0 | J38: 7. | K38: KAP/AP independen terhadap objek audit | N38: Tidak | O38: =IF(N38="Ya",100,0) -> 0
A39: 8. | B39: KAP dan/atau AP memiliki pengalaman yang dinilai | E39: Tidak | F39: =IF(E39="Ya",100,0) -> 0 | J39: 8. | K39: KAP dan/atau AP memiliki pengalaman yang dinilai | N39: Tidak | O39: =IF(N39="Ya",100,0) -> 0
E40: Total A2 | F40: =AVERAGE(F32:F39) -> 0 | N40: Total A2 | O40: =AVERAGE(O32:O39) -> 0
A42: A. | B42: 3. | C42: HARGA PERKIRAAN SENDIRI (HPS) | J42: A. | K42: 3. | L42: HARGA PERKIRAAN SENDIRI (HPS)
A43: No. | B43: Item Yang Dinilai | D43: Keterangan | E43: Pemenuhan | F43: Nilai | J43: No. | K43: Item Yang Dinilai | M43: Keterangan | N43: Pemenuhan | O43: Nilai
A44: 1. | B44: Billing rate HPS TL mengacu berdasarkan tarif jasa konsultan | D44: Billing rate Inkindo Tahun 2021 | E44: Tidak | F44: =IF(E44="Ya",100,0) -> 0 | J44: 1. | K44: Billing rate HPS TL mengacu berdasarkan tarif jasa konsultan | M44: Billing rate Inkindo Tahun 2021 | N44: Tidak | O44: =IF(N44="Ya",100,0) -> 0
...

Sheet Aspek Penilaian KAP JKL
A1: PENILAIAN
A2: KAP | B2: :
A3: Peserta Penugasan Audit Neraca Penutupan PT BPR XXX (DL)
A5: PENILAIAN TL | J5: PENILAIAN PIC
A7: A. | B7: 1. | C7: ASPEK ADMINISTRATIF - KELENGKAPAN DOKUMEN | J7: A. | K7: 1. | L7: ASPEK ADMINISTRATIF - KELENGKAPAN DOKUMEN
A8: No. | B8: Item Yang Dinilai | D8: Keterangan | E8: Pemenuhan | F8: Nilai | J8: No. | K8: Item Yang Dinilai | M8: Keterangan | N8: Pemenuhan | O8: Nilai
A9: 1. | B9: Proposal diterima tepat waktu | E9: Tidak | F9: =IF(E9="Ya",100,0) -> 0 | J9: 1. | K9: Proposal diterima tepat waktu | N9: Tidak | O9: =IF(N9="Ya",100,0) -> 0
A10: 2. | B10: Surat Pengantar | E10: Tidak | F10: =IF(E10="Ya",100,0) -> 0 | J10: 2. | K10: Surat Pengantar | N10: Tidak | O10: =IF(N10="Ya",100,0) -> 0
A11: 3. | B11: Surat Pengantar ditanda-tangani oleh Pimpinan KAP/Rekan dengan materai | E11: Tidak | F11: =IF(E11="Ya",100,0) -> 0 | J11: 3. | K11: Surat Pengantar ditanda-tangani oleh Pimpinan KAP/Rekan dengan materai | N11: Tidak | O11: =IF(N11="Ya",100,0) -> 0
A12: 4. | B12: Surat Pengantar memuat pernyataan : | J12: 4. | K12: Surat Pengantar memuat pernyataan :
B13: a. | C13: Tidak memiliki dan tidak pernah memiliki kepentingan dengan PT BPR XXX (DL) dalam 3 tahun terakhir. | E13: Tidak | F13: =IF(E13="Ya",100,0) -> 0 | K13: a. | L13: Tidak memiliki dan tidak pernah memiliki kepentingan dengan PT BPR XXX (DL) dalam 3 tahun terakhir. | N13: Tidak | O13: =IF(N13="Ya",100,0) -> 0
B14: b. | C14: Bersedia untuk tidak ikut proses seleksi lebih lanjut apabila menurut Tim Likuidasi ternyata KAP pernah memiliki kepentingan dalam 3 tahun terakhir. | E14: Tidak | F14: =IF(E14="Ya",100,0) -> 0 | K14: b. | L14: Bersedia untuk tidak ikut proses seleksi lebih lanjut apabila menurut Tim Likuidasi ternyata KAP pernah memiliki kepentingan dalam 3 tahun terakhir. | N14: Tidak | O14: =IF(N14="Ya",100,0) -> 0
B15: c. | C15: KAP dan personil sanggup menjaga kerahasiaan penugasan | E15: Tidak | F15: =IF(E15="Ya",100,0) -> 0 | K15: c. | L15: KAP dan personil sanggup menjaga kerahasiaan penugasan | N15: Tidak | O15: =IF(N15="Ya",100,0) -> 0
B16: d. | C16: Bahwa data dan informasi yang disajikan dalam proposal adalah benar/sah dan KAP sanggup menunjukan dokumen asli ketika diminta. | E16: Tidak | F16: =IF(E16="Ya",100,0) -> 0 | K16: d. | L16: Bahwa data dan informasi yang disajikan dalam proposal adalah benar/sah dan KAP sanggup menunjukan dokumen asli ketika diminta. | N16: Tidak | O16: =IF(N16="Ya",100,0) -> 0
B17: e. | C17: AP dan/atau KAP tidak sedang menjalani sanksi pembekuan izin oleh Departemen Keuangan, IAI atau IAPI | E17: Tidak | F17: =IF(E17="Ya",100,0) -> 0 | K17: e. | L17: AP dan/atau KAP tidak sedang menjalani sanksi pembekuan izin oleh Departemen Keuangan, IAI atau IAPI | N17: Tidak | O17: =IF(N17="Ya",100,0) -> 0
B18: f. | C18: AP dan/atau KAP tidak sedang menjalani proses pemeriksaan oleh Departemen Keuangan, IAI atau IAPI terkait dengan indikasi pelanggaran azas SPAP dan/atau peraturan perundang-undangan yang berlaku. | E18: Tidak | F18: =IF(E18="Ya",100,0) -> 0 | K18: f. | L18: AP dan/atau KAP tidak sedang menjalani proses pemeriksaan oleh Departemen Keuangan, IAI atau IAPI terkait dengan indikasi pelanggaran azas SPAP dan/atau peraturan perundang-undangan yang berlaku. | N18: Tidak | O18: =IF(N18="Ya",100,0) -> 0
B19: g. | C19: Kesanggupan untuk mengikuti seleksi dengan biaya sendiri | E19: Tidak | F19: =IF(E19="Ya",100,0) -> 0 | K19: g. | L19: Kesanggupan untuk mengikuti seleksi dengan biaya sendiri | N19: Tidak | O19: =IF(N19="Ya",100,0) -> 0
A20: 5. | B20: AP memiliki izin AP dari Menteri Keuangan | E20: Tidak | F20: =IF(E20="Ya",100,0) -> 0 | J20: 5. | K20: AP memiliki izin AP dari Menteri Keuangan | N20: Tidak | O20: =IF(N20="Ya",100,0) -> 0
A21: 6. | B21: AP memiliki atau menjadi rekan pada KAP yang memiliki izin dari Menteri Keuangan. | E21: Tidak | F21: =IF(E21="Ya",100,0) -> 0 | J21: 6. | K21: AP memiliki atau menjadi rekan pada KAP yang memiliki izin dari Menteri Keuangan. | N21: Tidak | O21: =IF(N21="Ya",100,0) -> 0
A22: 7. | B22: Merupakan AP yang terdaftar di BI / OJK | E22: Tidak | F22: =IF(E22="Ya",100,0) -> 0 | J22: 7. | K22: Merupakan AP yang terdaftar di BI / OJK | N22: Tidak | O22: =IF(N22="Ya",100,0) -> 0
A23: 8. | B23: Memiliki pengalaman audit di industri perbankan | E23: Tidak | F23: =IF(E23="Ya",100,0) -> 0 | J23: 8. | K23: Memiliki pengalaman audit di industri perbankan | N23: Tidak | O23: =IF(N23="Ya",100,0) -> 0
A24: 9. | B24: Memiliki auditor yang pegawai tetap sekurang-kurangya 6 orang | E24: Tidak | F24: =IF(E24="Ya",100,0) -> 0 | J24: 9. | K24: Memiliki auditor yang pegawai tetap sekurang-kurangya 6 orang | N24: Tidak | O24: =IF(N24="Ya",100,0) -> 0
A25: 10. | B25: Auditor yang ditugaskan sekurang-kurangnya 50 % telah menjadi pegawai tetap sejak 1 tahun terakhir. | E25: Tidak | F25: =IF(E25="Ya",100,0) -> 0 | J25: 10. | K25: Auditor yang ditugaskan sekurang-kurangnya 50 % telah menjadi pegawai tetap sejak 1 tahun terakhir. | N25: Tidak | O25: =IF(N25="Ya",100,0) -> 0
A26: 11. | B26: Bukan AP/KAP yang melakukan audit atas laporan keuangan PT BPR XXX (DL) | E26: Tidak | F26: =IF(E26="Ya",100,0) -> 0 | J26: 11. | K26: Bukan AP/KAP yang melakukan audit atas laporan keuangan PT BPR XXX (DL) | N26: Tidak | O26: =IF(N26="Ya",100,0) -> 0
A27: 12. | B27: KAK telah ditandatnagani oleh TL | E27: Tidak | F27: =IF(E27="Ya",100,0) -> 0 | J27: 12. | K27: KAK telah ditandatangani oleh TL | N27: Tidak | O27: =IF(N27="Ya",100,0) -> 0
A28: Kesimpulan : Lulus persyaratan administratif | E28: Total A1 | F28: =AVERAGE(F9:F27) -> 0 | J28: Kesimpulan A1-A4 : Lulus persyaratan administratif | N28: Total A1 | O28: =AVERAGE(O9:O27) -> 0
A30: A. | B30: 2. | C30: PENILAIAN ASPEK ADMINISTRATIF | J30: A. | K30: 2. | L30: PENILAIAN ASPEK ADMINISTRATIF
A31: No. | B31: Item Yang Dinilai | D31: Keterangan | E31: Pemenuhan | F31: Nilai | J31: No. | K31: Item Yang Dinilai | M31: Keterangan | N31: Pemenuhan | O31: Nilai
A32: 1. | B32: Form A ditandatangani oleh Pimpinan atau penanggungjawab dari KAP/Cabang KAP | E32: Tidak | F32: =IF(E32="Ya",100,0) -> 0 | J32: 1. | K32: Form A ditandatangani oleh Pimpinan atau penanggungjawab dari KAP/Cabang KAP | N32: Tidak | O32: =IF(N32="Ya",100,0) -> 0
A33: 2. | B33: Form B dibuat lengkap | E33: Tidak | F33: =IF(E33="Ya",100,0) -> 0 | J33: 2. | K33: Form B dibuat lengkap | N33: Tidak | O33: =IF(N33="Ya",100,0) -> 0
A34: 3. | B34: Form C (biodata personil) ditandatangani oleh personil yang bersangkutan dan oleh KAP | E34: Tidak | F34: =IF(E34="Ya",100,0) -> 0 | J34: 3. | K34: Form C (biodata personil) ditandatangani oleh personil yang bersangkutan dan oleh KAP | N34: Tidak | O34: =IF(N34="Ya",100,0) -> 0
A35: 4. | B35: Form D (usulan prosedur yang disepakati) diisi dengan lengkap | E35: Tidak | F35: =IF(E35="Ya",100,0) -> 0 | J35: 4. | K35: Form D (usulan prosedur yang disepakati) diisi dengan lengkap | N35: Tidak | O35: =IF(N35="Ya",100,0) -> 0
A36: 5. | B36: Form E (rincian biaya) diisi lengkap | E36: Tidak | F36: =IF(E36="Ya",100,0) -> 0 | J36: 5. | K36: Form E (rincian biaya) diisi lengkap | N36: Tidak | O36: =IF(N36="Ya",100,0) -> 0
A37: 6. | B37: Form F (Daftar Pegawai Tetap) diisi dengan lengkap | E37: Tidak | F37: =IF(E37="Ya",100,0) -> 0 | J37: 6. | K37: Form F (Daftar Pegawai Tetap) diisi dengan lengkap | N37: Tidak | O37: =IF(N37="Ya",100,0) -> 0
A38: 7. | B38: KAP/AP independen terhadap objek audit | E38: Tidak | F38: =IF(E38="Ya",100,0) -> 0 | J38: 7. | K38: KAP/AP independen terhadap objek audit | N38: Tidak | O38: =IF(N38="Ya",100,0) -> 0
A39: 8. | B39: KAP dan/atau AP memiliki pengalaman yang dinilai | E39: Tidak | F39: =IF(E39="Ya",100,0) -> 0 | J39: 8. | K39: KAP dan/atau AP memiliki pengalaman yang dinilai | N39: Tidak | O39: =IF(N39="Ya",100,0) -> 0
E40: Total A2 | F40: =AVERAGE(F32:F39) -> 0 | N40: Total A2 | O40: =AVERAGE(O32:O39) -> 0
A42: A. | B42: 3. | C42: HARGA PERKIRAAN SENDIRI (HPS) | J42: A. | K42: 3. | L42: HARGA PERKIRAAN SENDIRI (HPS)
A43: No. | B43: Item Yang Dinilai | D43: Keterangan | E43: Pemenuhan | F43: Nilai | J43: No. | K43: Item Yang Dinilai | M43: Keterangan | N43: Pemenuhan | O43: Nilai
A44: 1. | B44: Billing rate HPS TL mengacu berdasarkan tarif jasa konsultan | D44: Billing rate Inkindo Tahun 2021 | E44: Tidak | F44: =IF(E44="Ya",100,0) -> 0 | J44: 1. | K44: Billing rate HPS TL mengacu berdasarkan tarif jasa konsultan | M44: Billing rate Inkindo Tahun 2021 | N44: Tidak | O44: =IF(N44="Ya",100,0) -> 0
...

Sheet Aspek Penilaian KAP MNO
A1: PENILAIAN
A2: KAP | B2: :
A3: Peserta Penugasan Audit Neraca Penutupan PT BPR XXX (DL)
A5: PENILAIAN TL | J5: PENILAIAN PIC
A7: A. | B7: 1. | C7: ASPEK ADMINISTRATIF - KELENGKAPAN DOKUMEN | J7: A. | K7: 1. | L7: ASPEK ADMINISTRATIF - KELENGKAPAN DOKUMEN
A8: No. | B8: Item Yang Dinilai | D8: Keterangan | E8: Pemenuhan | F8: Nilai | J8: No. | K8: Item Yang Dinilai | M8: Keterangan | N8: Pemenuhan | O8: Nilai
A9: 1. | B9: Proposal diterima tepat waktu | E9: Tidak | F9: =IF(E9="Ya",100,0) -> 0 | J9: 1. | K9: Proposal diterima tepat waktu | N9: Tidak | O9: =IF(N9="Ya",100,0) -> 0
A10: 2. | B10: Surat Pengantar | E10: Tidak | F10: =IF(E10="Ya",100,0) -> 0 | J10: 2. | K10: Surat Pengantar | N10: Tidak | O10: =IF(N10="Ya",100,0) -> 0
A11: 3. | B11: Surat Pengantar ditanda-tangani oleh Pimpinan KAP/Rekan dengan materai | E11: Tidak | F11: =IF(E11="Ya",100,0) -> 0 | J11: 3. | K11: Surat Pengantar ditanda-tangani oleh Pimpinan KAP/Rekan dengan materai | N11: Tidak | O11: =IF(N11="Ya",100,0) -> 0
A12: 4. | B12: Surat Pengantar memuat pernyataan : | J12: 4. | K12: Surat Pengantar memuat pernyataan :
B13: a. | C13: Tidak memiliki dan tidak pernah memiliki kepentingan dengan PT BPR XXX (DL) dalam 3 tahun terakhir. | E13: Tidak | F13: =IF(E13="Ya",100,0) -> 0 | K13: a. | L13: Tidak memiliki dan tidak pernah memiliki kepentingan dengan PT BPR XXX (DL) dalam 3 tahun terakhir. | N13: Tidak | O13: =IF(N13="Ya",100,0) -> 0
B14: b. | C14: Bersedia untuk tidak ikut proses seleksi lebih lanjut apabila menurut Tim Likuidasi ternyata KAP pernah memiliki kepentingan dalam 3 tahun terakhir. | E14: Tidak | F14: =IF(E14="Ya",100,0) -> 0 | K14: b. | L14: Bersedia untuk tidak ikut proses seleksi lebih lanjut apabila menurut Tim Likuidasi ternyata KAP pernah memiliki kepentingan dalam 3 tahun terakhir. | N14: Tidak | O14: =IF(N14="Ya",100,0) -> 0
B15: c. | C15: KAP dan personil sanggup menjaga kerahasiaan penugasan | E15: Tidak | F15: =IF(E15="Ya",100,0) -> 0 | K15: c. | L15: KAP dan personil sanggup menjaga kerahasiaan penugasan | N15: Tidak | O15: =IF(N15="Ya",100,0) -> 0
B16: d. | C16: Bahwa data dan informasi yang disajikan dalam proposal adalah benar/sah dan KAP sanggup menunjukan dokumen asli ketika diminta. | E16: Tidak | F16: =IF(E16="Ya",100,0) -> 0 | K16: d. | L16: Bahwa data dan informasi yang disajikan dalam proposal adalah benar/sah dan KAP sanggup menunjukan dokumen asli ketika diminta. | N16: Tidak | O16: =IF(N16="Ya",100,0) -> 0
B17: e. | C17: AP dan/atau KAP tidak sedang menjalani sanksi pembekuan izin oleh Departemen Keuangan, IAI atau IAPI | E17: Tidak | F17: =IF(E17="Ya",100,0) -> 0 | K17: e. | L17: AP dan/atau KAP tidak sedang menjalani sanksi pembekuan izin oleh Departemen Keuangan, IAI atau IAPI | N17: Tidak | O17: =IF(N17="Ya",100,0) -> 0
B18: f. | C18: AP dan/atau KAP tidak sedang menjalani proses pemeriksaan oleh Departemen Keuangan, IAI atau IAPI terkait dengan indikasi pelanggaran azas SPAP dan/atau peraturan perundang-undangan yang berlaku. | E18: Tidak | F18: =IF(E18="Ya",100,0) -> 0 | K18: f. | L18: AP dan/atau KAP tidak sedang menjalani proses pemeriksaan oleh Departemen Keuangan, IAI atau IAPI terkait dengan indikasi pelanggaran azas SPAP dan/atau peraturan perundang-undangan yang berlaku. | N18: Tidak | O18: =IF(N18="Ya",100,0) -> 0
B19: g. | C19: Kesanggupan untuk mengikuti seleksi dengan biaya sendiri | E19: Tidak | F19: =IF(E19="Ya",100,0) -> 0 | K19: g. | L19: Kesanggupan untuk mengikuti seleksi dengan biaya sendiri | N19: Tidak | O19: =IF(N19="Ya",100,0) -> 0
A20: 5. | B20: AP memiliki izin AP dari Menteri Keuangan | E20: Tidak | F20: =IF(E20="Ya",100,0) -> 0 | J20: 5. | K20: AP memiliki izin AP dari Menteri Keuangan | N20: Tidak | O20: =IF(N20="Ya",100,0) -> 0
A21: 6. | B21: AP memiliki atau menjadi rekan pada KAP yang memiliki izin dari Menteri Keuangan. | E21: Tidak | F21: =IF(E21="Ya",100,0) -> 0 | J21: 6. | K21: AP memiliki atau menjadi rekan pada KAP yang memiliki izin dari Menteri Keuangan. | N21: Tidak | O21: =IF(N21="Ya",100,0) -> 0
A22: 7. | B22: Merupakan AP yang terdaftar di BI / OJK | E22: Tidak | F22: =IF(E22="Ya",100,0) -> 0 | J22: 7. | K22: Merupakan AP yang terdaftar di BI / OJK | N22: Tidak | O22: =IF(N22="Ya",100,0) -> 0
A23: 8. | B23: Memiliki pengalaman audit di industri perbankan | E23: Tidak | F23: =IF(E23="Ya",100,0) -> 0 | J23: 8. | K23: Memiliki pengalaman audit di industri perbankan | N23: Tidak | O23: =IF(N23="Ya",100,0) -> 0
A24: 9. | B24: Memiliki auditor yang pegawai tetap sekurang-kurangya 6 orang | E24: Tidak | F24: =IF(E24="Ya",100,0) -> 0 | J24: 9. | K24: Memiliki auditor yang pegawai tetap sekurang-kurangya 6 orang | N24: Tidak | O24: =IF(N24="Ya",100,0) -> 0
A25: 10. | B25: Auditor yang ditugaskan sekurang-kurangnya 50 % telah menjadi pegawai tetap sejak 1 tahun terakhir. | E25: Tidak | F25: =IF(E25="Ya",100,0) -> 0 | J25: 10. | K25: Auditor yang ditugaskan sekurang-kurangnya 50 % telah menjadi pegawai tetap sejak 1 tahun terakhir. | N25: Tidak | O25: =IF(N25="Ya",100,0) -> 0
