Workbook

Sheet 1. Perhitungan Pesangon
A2: KERTAS KERJA
A3: ANALISA PEMBERIAN PESANGON PEGAWAI
A4: =UPPER($C$7) -> PT BPRS HAREUKAT (DL)
A5: Perhitungan Pesangon
A7: Nama BDL | C7: PT BPRS Hareukat (DL)
A8: Tanggal Cabut Izin Usaha | C8: 43749
H10: Rincian Take Home Pay | N10: Perhitungan Pesangon
A11: No. | B11: Nama | C11: Jabatan | D11: Status Pegawai | E11: Tanggal Mulai Kerja | F11: Tanggal PHK | G11: Masa Kerja (tahun) | H11: Gaji Pokok | I11: Tunj. 1 | J11: Tunj. 2 | K11: Tunj. 3 | L11: Tunj. 4 | M11: THP | N11: Multiplier Pesangon | O11: Multiplier Jenis PHK* | P11: Gross Pesangon | Q11: Kewajiban Pegawai | R11: Nett Pesangon | S11: Sisa Kewajiban
A12: 1 | B12: Pegawai 1 | C12: Kabag Operasional | D12: Pegawai Tetap (PKWTT) | E12: 38863 | F12: 43822 | G12: =DATEDIF(E12,F12,"Y") -> 13 | H12: =IF(ISNUMBER(INDEX(Historis_Gaji[Angka yang Digunakan],MATCH(Data_Pegawai[[#This Row],[Nama]],Historis_Gaji[Nama],0))),INDEX(Historis_Gaji[Angka yang Digunakan],MATCH(Data_Pegawai[[#This Row],[Nama]],Historis_Gaji[Nama],0)),0) -> 2500000 | I12: =IF(ISNUMBER(INDEX(Historis_Tunj1[Angka yang Digunakan],MATCH(Data_Pegawai[[#This Row],[Nama]],Historis_Tunj1[Nama],0))),INDEX(Historis_Tunj1[Angka yang Digunakan],MATCH(Data_Pegawai[[#This Row],[Nama]],Historis_Tunj1[Nama],0)),0) -> 500000 | J12: =IF(ISNUMBER(INDEX(Historis_Tunj2[Angka yang Digunakan],MATCH(Data_Pegawai[[#This Row],[Nama]],Historis_Tunj2[Nama],0))),INDEX(Historis_Tunj2[Angka yang Digunakan],MATCH(Data_Pegawai[[#This Row],[Nama]],Historis_Tunj2[Nama],0)),0) -> 0 | K12: =IF(ISNUMBER(INDEX(Historis_Tunj3[Angka yang Digunakan],MATCH(Data_Pegawai[[#This Row],[Nama]],Historis_Tunj3[Nama],0))),INDEX(Historis_Tunj3[Angka yang Digunakan],MATCH(Data_Pegawai[[#This Row],[Nama]],Historis_Tunj3[Nama],0)),0) -> 0 | L12: =IF(ISNUMBER(INDEX(Historis_Tunj4[Angka yang Digunakan],MATCH(Data_Pegawai[[#This Row],[Nama]],Historis_Tunj4[Nama],0))),INDEX(Historis_Tunj4[Angka yang Digunakan],MATCH(Data_Pegawai[[#This Row],[Nama]],Historis_Tunj4[Nama],0)),0) -> 50000 | M12: =SUM(H12:L12) -> 3050000 | N12: =MIN(Data_Pegawai[[#This Row],[Masa Kerja (tahun)]]+1,9) -> 9 | O12: 0.5 | P12: =IF(Data_Pegawai[[#This Row],[Status Pegawai]]="Pegawai Tetap (PKWTT)",Data_Pegawai[[#This Row],[Multiplier Pesangon]]*Data_Pegawai[[#This Row],[THP]]*Data_Pegawai[[#This Row],[Multiplier Jenis PHK*]],0) -> 13725000 | Q12: =IF(ISNUMBER(INDEX(Data_Kewajiban[Sisa Kewajiban sebelum Pesangon],MATCH(Data_Pegawai[[#This Row],[Nama]],Data_Kewajiban[Nama],0))),INDEX(Data_Kewajiban[Sisa Kewajiban sebelum Pesangon],MATCH(Data_Pegawai[[#This Row],[Nama]],Data_Kewajiban[Nama],0)),0) -> 0 | R12: =IF(Data_Pegawai[[#This Row],[Gross Pesangon]]>Data_Pegawai[[#This Row],[Kewajiban Pegawai]],Data_Pegawai[[#This Row],[Gross Pesangon]]-Data_Pegawai[[#This Row],[Kewajiban Pegawai]],0) -> 13725000 | S12: =IF(Data_Pegawai[[#This Row],[Kewajiban Pegawai]]>Data_Pegawai[[#This Row],[Gross Pesangon]],Data_Pegawai[[#This Row],[Kewajiban Pegawai]]-Data_Pegawai[[#This Row],[Gross Pesangon]],0) -> 0
A13: 2 | B13: Pegawai 2 | C13: Kabag Pembiayaan | D13: Pegawai Tetap (PKWTT) | E13: 38863 | F13: 43822 | G13: =DATEDIF(E13,F13,"Y") -> 13 | H13: =IF(ISNUMBER(INDEX(Historis_Gaji[Angka yang Digunakan],MATCH(Data_Pegawai[[#This Row],[Nama]],Historis_Gaji[Nama],0))),INDEX(Historis_Gaji[Angka yang Digunakan],MATCH(Data_Pegawai[[#This Row],[Nama]],Historis_Gaji[Nama],0)),0) -> 2500000 | I13: =IF(ISNUMBER(INDEX(Historis_Tunj1[Angka yang Digunakan],MATCH(Data_Pegawai[[#This Row],[Nama]],Historis_Tunj1[Nama],0))),INDEX(Historis_Tunj1[Angka yang Digunakan],MATCH(Data_Pegawai[[#This Row],[Nama]],Historis_Tunj1[Nama],0)),0) -> 500000 | J13: =IF(ISNUMBER(INDEX(Historis_Tunj2[Angka yang Digunakan],MATCH(Data_Pegawai[[#This Row],[Nama]],Historis_Tunj2[Nama],0))),INDEX(Historis_Tunj2[Angka yang Digunakan],MATCH(Data_Pegawai[[#This Row],[Nama]],Historis_Tunj2[Nama],0)),0) -> 300000 | K13: =IF(ISNUMBER(INDEX(Historis_Tunj3[Angka yang Digunakan],MATCH(Data_Pegawai[[#This Row],[Nama]],Historis_Tunj3[Nama],0))),INDEX(Historis_Tunj3[Angka yang Digunakan],MATCH(Data_Pegawai[[#This Row],[Nama]],Historis_Tunj3[Nama],0)),0) -> 0 | L13: =IF(ISNUMBER(INDEX(Historis_Tunj4[Angka yang Digunakan],MATCH(Data_Pegawai[[#This Row],[Nama]],Historis_Tunj4[Nama],0))),INDEX(Historis_Tunj4[Angka yang Digunakan],MATCH(Data_Pegawai[[#This Row],[Nama]],Historis_Tunj4[Nama],0)),0) -> 50000 | M13: =SUM(H13:L13) -> 3350000 | N13: =MIN(Data_Pegawai[[#This Row],[Masa Kerja (tahun)]]+1,9) -> 9 | O13: 0.5 | P13: =IF(Data_Pegawai[[#This Row],[Status Pegawai]]="Pegawai Tetap (PKWTT)",Data_Pegawai[[#This Row],[Multiplier Pesangon]]*Data_Pegawai[[#This Row],[THP]]*Data_Pegawai[[#This Row],[Multiplier Jenis PHK*]],0) -> 15075000 | Q13: =IF(ISNUMBER(INDEX(Data_Kewajiban[Sisa Kewajiban sebelum Pesangon],MATCH(Data_Pegawai[[#This Row],[Nama]],Data_Kewajiban[Nama],0))),INDEX(Data_Kewajiban[Sisa Kewajiban sebelum Pesangon],MATCH(Data_Pegawai[[#This Row],[Nama]],Data_Kewajiban[Nama],0)),0) -> 83034225 | R13: =IF(Data_Pegawai[[#This Row],[Gross Pesangon]]>Data_Pegawai[[#This Row],[Kewajiban Pegawai]],Data_Pegawai[[#This Row],[Gross Pesangon]]-Data_Pegawai[[#This Row],[Kewajiban Pegawai]],0) -> 0 | S13: =IF(Data_Pegawai[[#This Row],[Kewajiban Pegawai]]>Data_Pegawai[[#This Row],[Gross Pesangon]],Data_Pegawai[[#This Row],[Kewajiban Pegawai]]-Data_Pegawai[[#This Row],[Gross Pesangon]],0) -> 67959225
A14: 3 | B14: Pegawai 3 | C14: A/O Loan | D14: Pegawai Tetap (PKWTT) | E14: 38863 | F14: 43794 | G14: =DATEDIF(E14,F14,"Y") -> 13 | H14: =IF(ISNUMBER(INDEX(Historis_Gaji[Angka yang Digunakan],MATCH(Data_Pegawai[[#This Row],[Nama]],Historis_Gaji[Nama],0))),INDEX(Historis_Gaji[Angka yang Digunakan],MATCH(Data_Pegawai[[#This Row],[Nama]],Historis_Gaji[Nama],0)),0) -> 2500000 | I14: =IF(ISNUMBER(INDEX(Historis_Tunj1[Angka yang Digunakan],MATCH(Data_Pegawai[[#This Row],[Nama]],Historis_Tunj1[Nama],0))),INDEX(Historis_Tunj1[Angka yang Digunakan],MATCH(Data_Pegawai[[#This Row],[Nama]],Historis_Tunj1[Nama],0)),0) -> 0 | J14: =IF(ISNUMBER(INDEX(Historis_Tunj2[Angka yang Digunakan],MATCH(Data_Pegawai[[#This Row],[Nama]],Historis_Tunj2[Nama],0))),INDEX(Historis_Tunj2[Angka yang Digunakan],MATCH(Data_Pegawai[[#This Row],[Nama]],Historis_Tunj2[Nama],0)),0) -> 600000 | K14: =IF(ISNUMBER(INDEX(Historis_Tunj3[Angka yang Digunakan],MATCH(Data_Pegawai[[#This Row],[Nama]],Historis_Tunj3[Nama],0))),INDEX(Historis_Tunj3[Angka yang Digunakan],MATCH(Data_Pegawai[[#This Row],[Nama]],Historis_Tunj3[Nama],0)),0) -> 0 | L14: =IF(ISNUMBER(INDEX(Historis_Tunj4[Angka yang Digunakan],MATCH(Data_Pegawai[[#This Row],[Nama]],Historis_Tunj4[Nama],0))),INDEX(Historis_Tunj4[Angka yang Digunakan],MATCH(Data_Pegawai[[#This Row],[Nama]],Historis_Tunj4[Nama],0)),0) -> 0 | M14: =SUM(H14:L14) -> 3100000 | N14: =MIN(Data_Pegawai[[#This Row],[Masa Kerja (tahun)]]+1,9) -> 9 | O14: 0.5 | P14: =IF(Data_Pegawai[[#This Row],[Status Pegawai]]="Pegawai Tetap (PKWTT)",Data_Pegawai[[#This Row],[Multiplier Pesangon]]*Data_Pegawai[[#This Row],[THP]]*Data_Pegawai[[#This Row],[Multiplier Jenis PHK*]],0) -> 13950000 | Q14: =IF(ISNUMBER(INDEX(Data_Kewajiban[Sisa Kewajiban sebelum Pesangon],MATCH(Data_Pegawai[[#This Row],[Nama]],Data_Kewajiban[Nama],0))),INDEX(Data_Kewajiban[Sisa Kewajiban sebelum Pesangon],MATCH(Data_Pegawai[[#This Row],[Nama]],Data_Kewajiban[Nama],0)),0) -> 126768140 | R14: =IF(Data_Pegawai[[#This Row],[Gross Pesangon]]>Data_Pegawai[[#This Row],[Kewajiban Pegawai]],Data_Pegawai[[#This Row],[Gross Pesangon]]-Data_Pegawai[[#This Row],[Kewajiban Pegawai]],0) -> 0 | S14: =IF(Data_Pegawai[[#This Row],[Kewajiban Pegawai]]>Data_Pegawai[[#This Row],[Gross Pesangon]],Data_Pegawai[[#This Row],[Kewajiban Pegawai]]-Data_Pegawai[[#This Row],[Gross Pesangon]],0) -> 112818140
A15: 4 | B15: Pegawai 4 | C15: Funding | D15: Pegawai Tetap (PKWTT) | E15: 38863 | F15: 43794 | G15: =DATEDIF(E15,F15,"Y") -> 13 | H15: =IF(ISNUMBER(INDEX(Historis_Gaji[Angka yang Digunakan],MATCH(Data_Pegawai[[#This Row],[Nama]],Historis_Gaji[Nama],0))),INDEX(Historis_Gaji[Angka yang Digunakan],MATCH(Data_Pegawai[[#This Row],[Nama]],Historis_Gaji[Nama],0)),0) -> 2000000 | I15: =IF(ISNUMBER(INDEX(Historis_Tunj1[Angka yang Digunakan],MATCH(Data_Pegawai[[#This Row],[Nama]],Historis_Tunj1[Nama],0))),INDEX(Historis_Tunj1[Angka yang Digunakan],MATCH(Data_Pegawai[[#This Row],[Nama]],Historis_Tunj1[Nama],0)),0) -> 0 | J15: =IF(ISNUMBER(INDEX(Historis_Tunj2[Angka yang Digunakan],MATCH(Data_Pegawai[[#This Row],[Nama]],Historis_Tunj2[Nama],0))),INDEX(Historis_Tunj2[Angka yang Digunakan],MATCH(Data_Pegawai[[#This Row],[Nama]],Historis_Tunj2[Nama],0)),0) -> 300000 | K15: =IF(ISNUMBER(INDEX(Historis_Tunj3[Angka yang Digunakan],MATCH(Data_Pegawai[[#This Row],[Nama]],Historis_Tunj3[Nama],0))),INDEX(Historis_Tunj3[Angka yang Digunakan],MATCH(Data_Pegawai[[#This Row],[Nama]],Historis_Tunj3[Nama],0)),0) -> 0 | L15: =IF(ISNUMBER(INDEX(Historis_Tunj4[Angka yang Digunakan],MATCH(Data_Pegawai[[#This Row],[Nama]],Historis_Tunj4[Nama],0))),INDEX(Historis_Tunj4[Angka yang Digunakan],MATCH(Data_Pegawai[[#This Row],[Nama]],Historis_Tunj4[Nama],0)),0) -> 50000 | M15: =SUM(H15:L15) -> 2350000 | N15: =MIN(Data_Pegawai[[#This Row],[Masa Kerja (tahun)]]+1,9) -> 9 | O15: 0.5 | P15: =IF(Data_Pegawai[[#This Row],[Status Pegawai]]="Pegawai Tetap (PKWTT)",Data_Pegawai[[#This Row],[Multiplier Pesangon]]*Data_Pegawai[[#This Row],[THP]]*Data_Pegawai[[#This Row],[Multiplier Jenis PHK*]],0) -> 10575000 | Q15: =IF(ISNUMBER(INDEX(Data_Kewajiban[Sisa Kewajiban sebelum Pesangon],MATCH(Data_Pegawai[[#This Row],[Nama]],Data_Kewajiban[Nama],0))),INDEX(Data_Kewajiban[Sisa Kewajiban sebelum Pesangon],MATCH(Data_Pegawai[[#This Row],[Nama]],Data_Kewajiban[Nama],0)),0) -> 104214476 | R15: =IF(Data_Pegawai[[#This Row],[Gross Pesangon]]>Data_Pegawai[[#This Row],[Kewajiban Pegawai]],Data_Pegawai[[#This Row],[Gross Pesangon]]-Data_Pegawai[[#This Row],[Kewajiban Pegawai]],0) -> 0 | S15: =IF(Data_Pegawai[[#This Row],[Kewajiban Pegawai]]>Data_Pegawai[[#This Row],[Gross Pesangon]],Data_Pegawai[[#This Row],[Kewajiban Pegawai]]-Data_Pegawai[[#This Row],[Gross Pesangon]],0) -> 93639476
A16: 5 | B16: Pegawai 5 | C16: A/O Loan | D16: Pegawai Tetap (PKWTT) | E16: 39265 | F16: 43822 | G16: =DATEDIF(E16,F16,"Y") -> 12 | H16: =IF(ISNUMBER(INDEX(Historis_Gaji[Angka yang Digunakan],MATCH(Data_Pegawai[[#This Row],[Nama]],Historis_Gaji[Nama],0))),INDEX(Historis_Gaji[Angka yang Digunakan],MATCH(Data_Pegawai[[#This Row],[Nama]],Historis_Gaji[Nama],0)),0) -> 1900000 | I16: =IF(ISNUMBER(INDEX(Historis_Tunj1[Angka yang Digunakan],MATCH(Data_Pegawai[[#This Row],[Nama]],Historis_Tunj1[Nama],0))),INDEX(Historis_Tunj1[Angka yang Digunakan],MATCH(Data_Pegawai[[#This Row],[Nama]],Historis_Tunj1[Nama],0)),0) -> 0 | J16: =IF(ISNUMBER(INDEX(Historis_Tunj2[Angka yang Digunakan],MATCH(Data_Pegawai[[#This Row],[Nama]],Historis_Tunj2[Nama],0))),INDEX(Historis_Tunj2[Angka yang Digunakan],MATCH(Data_Pegawai[[#This Row],[Nama]],Historis_Tunj2[Nama],0)),0) -> 600000 | K16: =IF(ISNUMBER(INDEX(Historis_Tunj3[Angka yang Digunakan],MATCH(Data_Pegawai[[#This Row],[Nama]],Historis_Tunj3[Nama],0))),INDEX(Historis_Tunj3[Angka yang Digunakan],MATCH(Data_Pegawai[[#This Row],[Nama]],Historis_Tunj3[Nama],0)),0) -> 0 | L16: =IF(ISNUMBER(INDEX(Historis_Tunj4[Angka yang Digunakan],MATCH(Data_Pegawai[[#This Row],[Nama]],Historis_Tunj4[Nama],0))),INDEX(Historis_Tunj4[Angka yang Digunakan],MATCH(Data_Pegawai[[#This Row],[Nama]],Historis_Tunj4[Nama],0)),0) -> 0 | M16: =SUM(H16:L16) -> 2500000 | N16: =MIN(Data_Pegawai[[#This Row],[Masa Kerja (tahun)]]+1,9) -> 9 | O16: 0.5 | P16: =IF(Data_Pegawai[[#This Row],[Status Pegawai]]="Pegawai Tetap (PKWTT)",Data_Pegawai[[#This Row],[Multiplier Pesangon]]*Data_Pegawai[[#This Row],[THP]]*Data_Pegawai[[#This Row],[Multiplier Jenis PHK*]],0) -> 11250000 | Q16: =IF(ISNUMBER(INDEX(Data_Kewajiban[Sisa Kewajiban sebelum Pesangon],MATCH(Data_Pegawai[[#This Row],[Nama]],Data_Kewajiban[Nama],0))),INDEX(Data_Kewajiban[Sisa Kewajiban sebelum Pesangon],MATCH(Data_Pegawai[[#This Row],[Nama]],Data_Kewajiban[Nama],0)),0) -> 75737508 | R16: =IF(Data_Pegawai[[#This Row],[Gross Pesangon]]>Data_Pegawai[[#This Row],[Kewajiban Pegawai]],Data_Pegawai[[#This Row],[Gross Pesangon]]-Data_Pegawai[[#This Row],[Kewajiban Pegawai]],0) -> 0 | S16: =IF(Data_Pegawai[[#This Row],[Kewajiban Pegawai]]>Data_Pegawai[[#This Row],[Gross Pesangon]],Data_Pegawai[[#This Row],[Kewajiban Pegawai]]-Data_Pegawai[[#This Row],[Gross Pesangon]],0) -> 64487508
A17: 6 | B17: Pegawai 6 | C17: ADM Pelaporan | D17: Pegawai Tetap (PKWTT) | E17: 40063 | F17: 43794 | G17: =DATEDIF(E17,F17,"Y") -> 10 | H17: =IF(ISNUMBER(INDEX(Historis_Gaji[Angka yang Digunakan],MATCH(Data_Pegawai[[#This Row],[Nama]],Historis_Gaji[Nama],0))),INDEX(Historis_Gaji[Angka yang Digunakan],MATCH(Data_Pegawai[[#This Row],[Nama]],Historis_Gaji[Nama],0)),0) -> 1900000 | I17: =IF(ISNUMBER(INDEX(Historis_Tunj1[Angka yang Digunakan],MATCH(Data_Pegawai[[#This Row],[Nama]],Historis_Tunj1[Nama],0))),INDEX(Historis_Tunj1[Angka yang Digunakan],MATCH(Data_Pegawai[[#This Row],[Nama]],Historis_Tunj1[Nama],0)),0) -> 0 | J17: =IF(ISNUMBER(INDEX(Historis_Tunj2[Angka yang Digunakan],MATCH(Data_Pegawai[[#This Row],[Nama]],Historis_Tunj2[Nama],0))),INDEX(Historis_Tunj2[Angka yang Digunakan],MATCH(Data_Pegawai[[#This Row],[Nama]],Historis_Tunj2[Nama],0)),0) -> 400000 | K17: =IF(ISNUMBER(INDEX(Historis_Tunj3[Angka yang Digunakan],MATCH(Data_Pegawai[[#This Row],[Nama]],Historis_Tunj3[Nama],0))),INDEX(Historis_Tunj3[Angka yang Digunakan],MATCH(Data_Pegawai[[#This Row],[Nama]],Historis_Tunj3[Nama],0)),0) -> 0 | L17: =IF(ISNUMBER(INDEX(Historis_Tunj4[Angka yang Digunakan],MATCH(Data_Pegawai[[#This Row],[Nama]],Historis_Tunj4[Nama],0))),INDEX(Historis_Tunj4[Angka yang Digunakan],MATCH(Data_Pegawai[[#This Row],[Nama]],Historis_Tunj4[Nama],0)),0) -> 0 | M17: =SUM(H17:L17) -> 2300000 | N17: =MIN(Data_Pegawai[[#This Row],[Masa Kerja (tahun)]]+1,9) -> 9 | O17: 0.5 | P17: =IF(Data_Pegawai[[#This Row],[Status Pegawai]]="Pegawai Tetap (PKWTT)",Data_Pegawai[[#This Row],[Multiplier Pesangon]]*Data_Pegawai[[#This Row],[THP]]*Data_Pegawai[[#This Row],[Multiplier Jenis PHK*]],0) -> 10350000 | Q17: =IF(ISNUMBER(INDEX(Data_Kewajiban[Sisa Kewajiban sebelum Pesangon],MATCH(Data_Pegawai[[#This Row],[Nama]],Data_Kewajiban[Nama],0))),INDEX(Data_Kewajiban[Sisa Kewajiban sebelum Pesangon],MATCH(Data_Pegawai[[#This Row],[Nama]],Data_Kewajiban[Nama],0)),0) -> 92863954 | R17: =IF(Data_Pegawai[[#This Row],[Gross Pesangon]]>Data_Pegawai[[#This Row],[Kewajiban Pegawai]],Data_Pegawai[[#This Row],[Gross Pesangon]]-Data_Pegawai[[#This Row],[Kewajiban Pegawai]],0) -> 0 | S17: =IF(Data_Pegawai[[#This Row],[Kewajiban Pegawai]]>Data_Pegawai[[#This Row],[Gross Pesangon]],Data_Pegawai[[#This Row],[Kewajiban Pegawai]]-Data_Pegawai[[#This Row],[Gross Pesangon]],0) -> 82513954
A18: 7 | B18: Pegawai 7 | C18: Funding | D18: Pegawai Tetap (PKWTT) | E18: 40063 | F18: 43794 | G18: =DATEDIF(E18,F18,"Y") -> 10 | H18: =IF(ISNUMBER(INDEX(Historis_Gaji[Angka yang Digunakan],MATCH(Data_Pegawai[[#This Row],[Nama]],Historis_Gaji[Nama],0))),INDEX(Historis_Gaji[Angka yang Digunakan],MATCH(Data_Pegawai[[#This Row],[Nama]],Historis_Gaji[Nama],0)),0) -> 1900000 | I18: =IF(ISNUMBER(INDEX(Historis_Tunj1[Angka yang Digunakan],MATCH(Data_Pegawai[[#This Row],[Nama]],Historis_Tunj1[Nama],0))),INDEX(Historis_Tunj1[Angka yang Digunakan],MATCH(Data_Pegawai[[#This Row],[Nama]],Historis_Tunj1[Nama],0)),0) -> 0 | J18: =IF(ISNUMBER(INDEX(Historis_Tunj2[Angka yang Digunakan],MATCH(Data_Pegawai[[#This Row],[Nama]],Historis_Tunj2[Nama],0))),INDEX(Historis_Tunj2[Angka yang Digunakan],MATCH(Data_Pegawai[[#This Row],[Nama]],Historis_Tunj2[Nama],0)),0) -> 300000 | K18: =IF(ISNUMBER(INDEX(Historis_Tunj3[Angka yang Digunakan],MATCH(Data_Pegawai[[#This Row],[Nama]],Historis_Tunj3[Nama],0))),INDEX(Historis_Tunj3[Angka yang Digunakan],MATCH(Data_Pegawai[[#This Row],[Nama]],Historis_Tunj3[Nama],0)),0) -> 0 | L18: =IF(ISNUMBER(INDEX(Historis_Tunj4[Angka yang Digunakan],MATCH(Data_Pegawai[[#This Row],[Nama]],Historis_Tunj4[Nama],0))),INDEX(Historis_Tunj4[Angka yang Digunakan],MATCH(Data_Pegawai[[#This Row],[Nama]],Historis_Tunj4[Nama],0)),0) -> 50000 | M18: =SUM(H18:L18) -> 2250000 | N18: =MIN(Data_Pegawai[[#This Row],[Masa Kerja (tahun)]]+1,9) -> 9 | O18: 0.5 | P18: =IF(Data_Pegawai[[#This Row],[Status Pegawai]]="Pegawai Tetap (PKWTT)",Data_Pegawai[[#This Row],[Multiplier Pesangon]]*Data_Pegawai[[#This Row],[THP]]*Data_Pegawai[[#This Row],[Multiplier Jenis PHK*]],0) -> 10125000 | Q18: =IF(ISNUMBER(INDEX(Data_Kewajiban[Sisa Kewajiban sebelum Pesangon],MATCH(Data_Pegawai[[#This Row],[Nama]],Data_Kewajiban[Nama],0))),INDEX(Data_Kewajiban[Sisa Kewajiban sebelum Pesangon],MATCH(Data_Pegawai[[#This Row],[Nama]],Data_Kewajiban[Nama],0)),0) -> 119953232 | R18: =IF(Data_Pegawai[[#This Row],[Gross Pesangon]]>Data_Pegawai[[#This Row],[Kewajiban Pegawai]],Data_Pegawai[[#This Row],[Gross Pesangon]]-Data_Pegawai[[#This Row],[Kewajiban Pegawai]],0) -> 0 | S18: =IF(Data_Pegawai[[#This Row],[Kewajiban Pegawai]]>Data_Pegawai[[#This Row],[Gross Pesangon]],Data_Pegawai[[#This Row],[Kewajiban Pegawai]]-Data_Pegawai[[#This Row],[Gross Pesangon]],0) -> 109828232
A19: 8 | B19: Pegawai 8 | C19: ADM Pembiayaan | D19: Pegawai Tetap (PKWTT) | E19: 40266 | F19: 43822 | G19: =DATEDIF(E19,F19,"Y") -> 9 | H19: =IF(ISNUMBER(INDEX(Historis_Gaji[Angka yang Digunakan],MATCH(Data_Pegawai[[#This Row],[Nama]],Historis_Gaji[Nama],0))),INDEX(Historis_Gaji[Angka yang Digunakan],MATCH(Data_Pegawai[[#This Row],[Nama]],Historis_Gaji[Nama],0)),0) -> 1750000 | I19: =IF(ISNUMBER(INDEX(Historis_Tunj1[Angka yang Digunakan],MATCH(Data_Pegawai[[#This Row],[Nama]],Historis_Tunj1[Nama],0))),INDEX(Historis_Tunj1[Angka yang Digunakan],MATCH(Data_Pegawai[[#This Row],[Nama]],Historis_Tunj1[Nama],0)),0) -> 0 | J19: =IF(ISNUMBER(INDEX(Historis_Tunj2[Angka yang Digunakan],MATCH(Data_Pegawai[[#This Row],[Nama]],Historis_Tunj2[Nama],0))),INDEX(Historis_Tunj2[Angka yang Digunakan],MATCH(Data_Pegawai[[#This Row],[Nama]],Historis_Tunj2[Nama],0)),0) -> 400000 | K19: =IF(ISNUMBER(INDEX(Historis_Tunj3[Angka yang Digunakan],MATCH(Data_Pegawai[[#This Row],[Nama]],Historis_Tunj3[Nama],0))),INDEX(Historis_Tunj3[Angka yang Digunakan],MATCH(Data_Pegawai[[#This Row],[Nama]],Historis_Tunj3[Nama],0)),0) -> 0 | L19: =IF(ISNUMBER(INDEX(Historis_Tunj4[Angka yang Digunakan],MATCH(Data_Pegawai[[#This Row],[Nama]],Historis_Tunj4[Nama],0))),INDEX(Historis_Tunj4[Angka yang Digunakan],MATCH(Data_Pegawai[[#This Row],[Nama]],Historis_Tunj4[Nama],0)),0) -> 0 | M19: =SUM(H19:L19) -> 2150000 | N19: =MIN(Data_Pegawai[[#This Row],[Masa Kerja (tahun)]]+1,9) -> 9 | O19: 0.5 | P19: =IF(Data_Pegawai[[#This Row],[Status Pegawai]]="Pegawai Tetap (PKWTT)",Data_Pegawai[[#This Row],[Multiplier Pesangon]]*Data_Pegawai[[#This Row],[THP]]*Data_Pegawai[[#This Row],[Multiplier Jenis PHK*]],0) -> 9675000 | Q19: =IF(ISNUMBER(INDEX(Data_Kewajiban[Sisa Kewajiban sebelum Pesangon],MATCH(Data_Pegawai[[#This Row],[Nama]],Data_Kewajiban[Nama],0))),INDEX(Data_Kewajiban[Sisa Kewajiban sebelum Pesangon],MATCH(Data_Pegawai[[#This Row],[Nama]],Data_Kewajiban[Nama],0)),0) -> 40672634 | R19: =IF(Data_Pegawai[[#This Row],[Gross Pesangon]]>Data_Pegawai[[#This Row],[Kewajiban Pegawai]],Data_Pegawai[[#This Row],[Gross Pesangon]]-Data_Pegawai[[#This Row],[Kewajiban Pegawai]],0) -> 0 | S19: =IF(Data_Pegawai[[#This Row],[Kewajiban Pegawai]]>Data_Pegawai[[#This Row],[Gross Pesangon]],Data_Pegawai[[#This Row],[Kewajiban Pegawai]]-Data_Pegawai[[#This Row],[Gross Pesangon]],0) -> 30997634
A20: 9 | B20: Pegawai 9 | C20: Teller | D20: Pegawai Tetap (PKWTT) | E20: 41456 | F20: 43794 | G20: =DATEDIF(E20,F20,"Y") -> 6 | H20: =IF(ISNUMBER(INDEX(Historis_Gaji[Angka yang Digunakan],MATCH(Data_Pegawai[[#This Row],[Nama]],Historis_Gaji[Nama],0))),INDEX(Historis_Gaji[Angka yang Digunakan],MATCH(Data_Pegawai[[#This Row],[Nama]],Historis_Gaji[Nama],0)),0) -> 1200000 | I20: =IF(ISNUMBER(INDEX(Historis_Tunj1[Angka yang Digunakan],MATCH(Data_Pegawai[[#This Row],[Nama]],Historis_Tunj1[Nama],0))),INDEX(Historis_Tunj1[Angka yang Digunakan],MATCH(Data_Pegawai[[#This Row],[Nama]],Historis_Tunj1[Nama],0)),0) -> 250000 | J20: =IF(ISNUMBER(INDEX(Historis_Tunj2[Angka yang Digunakan],MATCH(Data_Pegawai[[#This Row],[Nama]],Historis_Tunj2[Nama],0))),INDEX(Historis_Tunj2[Angka yang Digunakan],MATCH(Data_Pegawai[[#This Row],[Nama]],Historis_Tunj2[Nama],0)),0) -> 100000 | K20: =IF(ISNUMBER(INDEX(Historis_Tunj3[Angka yang Digunakan],MATCH(Data_Pegawai[[#This Row],[Nama]],Historis_Tunj3[Nama],0))),INDEX(Historis_Tunj3[Angka yang Digunakan],MATCH(Data_Pegawai[[#This Row],[Nama]],Historis_Tunj3[Nama],0)),0) -> 0 | L20: =IF(ISNUMBER(INDEX(Historis_Tunj4[Angka yang Digunakan],MATCH(Data_Pegawai[[#This Row],[Nama]],Historis_Tunj4[Nama],0))),INDEX(Historis_Tunj4[Angka yang Digunakan],MATCH(Data_Pegawai[[#This Row],[Nama]],Historis_Tunj4[Nama],0)),0) -> 50000 | M20: =SUM(H20:L20) -> 1600000 | N20: =MIN(Data_Pegawai[[#This Row],[Masa Kerja (tahun)]]+1,9) -> 7 | O20: 0.5 | P20: =IF(Data_Pegawai[[#This Row],[Status Pegawai]]="Pegawai Tetap (PKWTT)",Data_Pegawai[[#This Row],[Multiplier Pesangon]]*Data_Pegawai[[#This Row],[THP]]*Data_Pegawai[[#This Row],[Multiplier Jenis PHK*]],0) -> 5600000 | Q20: =IF(ISNUMBER(INDEX(Data_Kewajiban[Sisa Kewajiban sebelum Pesangon],MATCH(Data_Pegawai[[#This Row],[Nama]],Data_Kewajiban[Nama],0))),INDEX(Data_Kewajiban[Sisa Kewajiban sebelum Pesangon],MATCH(Data_Pegawai[[#This Row],[Nama]],Data_Kewajiban[Nama],0)),0) -> 53092960 | R20: =IF(Data_Pegawai[[#This Row],[Gross Pesangon]]>Data_Pegawai[[#This Row],[Kewajiban Pegawai]],Data_Pegawai[[#This Row],[Gross Pesangon]]-Data_Pegawai[[#This Row],[Kewajiban Pegawai]],0) -> 0 | S20: =IF(Data_Pegawai[[#This Row],[Kewajiban Pegawai]]>Data_Pegawai[[#This Row],[Gross Pesangon]],Data_Pegawai[[#This Row],[Kewajiban Pegawai]]-Data_Pegawai[[#This Row],[Gross Pesangon]],0) -> 47492960
A21: 10 | B21: Pegawai 10 | C21: A/O Loan | D21: Pegawai Tetap (PKWTT) | E21: 41988 | F21: 43794 | G21: =DATEDIF(E21,F21,"Y") -> 4 | H21: =IF(ISNUMBER(INDEX(Historis_Gaji[Angka yang Digunakan],MATCH(Data_Pegawai[[#This Row],[Nama]],Historis_Gaji[Nama],0))),INDEX(Historis_Gaji[Angka yang Digunakan],MATCH(Data_Pegawai[[#This Row],[Nama]],Historis_Gaji[Nama],0)),0) -> 1200000 | I21: =IF(ISNUMBER(INDEX(Historis_Tunj1[Angka yang Digunakan],MATCH(Data_Pegawai[[#This Row],[Nama]],Historis_Tunj1[Nama],0))),INDEX(Historis_Tunj1[Angka yang Digunakan],MATCH(Data_Pegawai[[#This Row],[Nama]],Historis_Tunj1[Nama],0)),0) -> 0 | J21: =IF(ISNUMBER(INDEX(Historis_Tunj2[Angka yang Digunakan],MATCH(Data_Pegawai[[#This Row],[Nama]],Historis_Tunj2[Nama],0))),INDEX(Historis_Tunj2[Angka yang Digunakan],MATCH(Data_Pegawai[[#This Row],[Nama]],Historis_Tunj2[Nama],0)),0) -> 0 | K21: =IF(ISNUMBER(INDEX(Historis_Tunj3[Angka yang Digunakan],MATCH(Data_Pegawai[[#This Row],[Nama]],Historis_Tunj3[Nama],0))),INDEX(Historis_Tunj3[Angka yang Digunakan],MATCH(Data_Pegawai[[#This Row],[Nama]],Historis_Tunj3[Nama],0)),0) -> 0 | L21: =IF(ISNUMBER(INDEX(Historis_Tunj4[Angka yang Digunakan],MATCH(Data_Pegawai[[#This Row],[Nama]],Historis_Tunj4[Nama],0))),INDEX(Historis_Tunj4[Angka yang Digunakan],MATCH(Data_Pegawai[[#This Row],[Nama]],Historis_Tunj4[Nama],0)),0) -> 0 | M21: =SUM(H21:L21) -> 1200000 | N21: =MIN(Data_Pegawai[[#This Row],[Masa Kerja (tahun)]]+1,9) -> 5 | O21: 0.5 | P21: =IF(Data_Pegawai[[#This Row],[Status Pegawai]]="Pegawai Tetap (PKWTT)",Data_Pegawai[[#This Row],[Multiplier Pesangon]]*Data_Pegawai[[#This Row],[THP]]*Data_Pegawai[[#This Row],[Multiplier Jenis PHK*]],0) -> 3000000 | Q21: =IF(ISNUMBER(INDEX(Data_Kewajiban[Sisa Kewajiban sebelum Pesangon],MATCH(Data_Pegawai[[#This Row],[Nama]],Data_Kewajiban[Nama],0))),INDEX(Data_Kewajiban[Sisa Kewajiban sebelum Pesangon],MATCH(Data_Pegawai[[#This Row],[Nama]],Data_Kewajiban[Nama],0)),0) -> 33330051 | R21: =IF(Data_Pegawai[[#This Row],[Gross Pesangon]]>Data_Pegawai[[#This Row],[Kewajiban Pegawai]],Data_Pegawai[[#This Row],[Gross Pesangon]]-Data_Pegawai[[#This Row],[Kewajiban Pegawai]],0) -> 0 | S21: =IF(Data_Pegawai[[#This Row],[Kewajiban Pegawai]]>Data_Pegawai[[#This Row],[Gross Pesangon]],Data_Pegawai[[#This Row],[Kewajiban Pegawai]]-Data_Pegawai[[#This Row],[Gross Pesangon]],0) -> 30330051
A22: 11 | B22: Pegawai 11 | C22: ADM Pembiayaan | D22: Pegawai Tetap (PKWTT) | E22: 42828 | F22: 43794 | G22: =DATEDIF(E22,F22,"Y") -> 2 | H22: =IF(ISNUMBER(INDEX(Historis_Gaji[Angka yang Digunakan],MATCH(Data_Pegawai[[#This Row],[Nama]],Historis_Gaji[Nama],0))),INDEX(Historis_Gaji[Angka yang Digunakan],MATCH(Data_Pegawai[[#This Row],[Nama]],Historis_Gaji[Nama],0)),0) -> 1200000 | I22: =IF(ISNUMBER(INDEX(Historis_Tunj1[Angka yang Digunakan],MATCH(Data_Pegawai[[#This Row],[Nama]],Historis_Tunj1[Nama],0))),INDEX(Historis_Tunj1[Angka yang Digunakan],MATCH(Data_Pegawai[[#This Row],[Nama]],Historis_Tunj1[Nama],0)),0) -> 0 | J22: =IF(ISNUMBER(INDEX(Historis_Tunj2[Angka yang Digunakan],MATCH(Data_Pegawai[[#This Row],[Nama]],Historis_Tunj2[Nama],0))),INDEX(Historis_Tunj2[Angka yang Digunakan],MATCH(Data_Pegawai[[#This Row],[Nama]],Historis_Tunj2[Nama],0)),0) -> 0 | K22: =IF(ISNUMBER(INDEX(Historis_Tunj3[Angka yang Digunakan],MATCH(Data_Pegawai[[#This Row],[Nama]],Historis_Tunj3[Nama],0))),INDEX(Historis_Tunj3[Angka yang Digunakan],MATCH(Data_Pegawai[[#This Row],[Nama]],Historis_Tunj3[Nama],0)),0) -> 0 | L22: =IF(ISNUMBER(INDEX(Historis_Tunj4[Angka yang Digunakan],MATCH(Data_Pegawai[[#This Row],[Nama]],Historis_Tunj4[Nama],0))),INDEX(Historis_Tunj4[Angka yang Digunakan],MATCH(Data_Pegawai[[#This Row],[Nama]],Historis_Tunj4[Nama],0)),0) -> 50000 | M22: =SUM(H22:L22) -> 1250000 | N22: =MIN(Data_Pegawai[[#This Row],[Masa Kerja (tahun)]]+1,9) -> 3 | O22: 0.5 | P22: =IF(Data_Pegawai[[#This Row],[Status Pegawai]]="Pegawai Tetap (PKWTT)",Data_Pegawai[[#This Row],[Multiplier Pesangon]]*Data_Pegawai[[#This Row],[THP]]*Data_Pegawai[[#This Row],[Multiplier Jenis PHK*]],0) -> 1875000 | Q22: =IF(ISNUMBER(INDEX(Data_Kewajiban[Sisa Kewajiban sebelum Pesangon],MATCH(Data_Pegawai[[#This Row],[Nama]],Data_Kewajiban[Nama],0))),INDEX(Data_Kewajiban[Sisa Kewajiban sebelum Pesangon],MATCH(Data_Pegawai[[#This Row],[Nama]],Data_Kewajiban[Nama],0)),0) -> 0 | R22: =IF(Data_Pegawai[[#This Row],[Gross Pesangon]]>Data_Pegawai[[#This Row],[Kewajiban Pegawai]],Data_Pegawai[[#This Row],[Gross Pesangon]]-Data_Pegawai[[#This Row],[Kewajiban Pegawai]],0) -> 1875000 | S22: =IF(Data_Pegawai[[#This Row],[Kewajiban Pegawai]]>Data_Pegawai[[#This Row],[Gross Pesangon]],Data_Pegawai[[#This Row],[Kewajiban Pegawai]]-Data_Pegawai[[#This Row],[Gross Pesangon]],0) -> 0
A23: 12 | B23: Pegawai 12 | C23: Bag.Umum | D23: Pegawai Tetap (PKWTT) | E23: 43542 | F23: 43822 | G23: =DATEDIF(E23,F23,"Y") -> 0 | H23: =IF(ISNUMBER(INDEX(Historis_Gaji[Angka yang Digunakan],MATCH(Data_Pegawai[[#This Row],[Nama]],Historis_Gaji[Nama],0))),INDEX(Historis_Gaji[Angka yang Digunakan],MATCH(Data_Pegawai[[#This Row],[Nama]],Historis_Gaji[Nama],0)),0) -> 1000000 | I23: =IF(ISNUMBER(INDEX(Historis_Tunj1[Angka yang Digunakan],MATCH(Data_Pegawai[[#This Row],[Nama]],Historis_Tunj1[Nama],0))),INDEX(Historis_Tunj1[Angka yang Digunakan],MATCH(Data_Pegawai[[#This Row],[Nama]],Historis_Tunj1[Nama],0)),0) -> 0 | J23: =IF(ISNUMBER(INDEX(Historis_Tunj2[Angka yang Digunakan],MATCH(Data_Pegawai[[#This Row],[Nama]],Historis_Tunj2[Nama],0))),INDEX(Historis_Tunj2[Angka yang Digunakan],MATCH(Data_Pegawai[[#This Row],[Nama]],Historis_Tunj2[Nama],0)),0) -> 320000 | K23: =IF(ISNUMBER(INDEX(Historis_Tunj3[Angka yang Digunakan],MATCH(Data_Pegawai[[#This Row],[Nama]],Historis_Tunj3[Nama],0))),INDEX(Historis_Tunj3[Angka yang Digunakan],MATCH(Data_Pegawai[[#This Row],[Nama]],Historis_Tunj3[Nama],0)),0) -> 0 | L23: =IF(ISNUMBER(INDEX(Historis_Tunj4[Angka yang Digunakan],MATCH(Data_Pegawai[[#This Row],[Nama]],Historis_Tunj4[Nama],0))),INDEX(Historis_Tunj4[Angka yang Digunakan],MATCH(Data_Pegawai[[#This Row],[Nama]],Historis_Tunj4[Nama],0)),0) -> 0 | M23: =SUM(H23:L23) -> 1320000 | N23: =MIN(Data_Pegawai[[#This Row],[Masa Kerja (tahun)]]+1,9) -> 1 | O23: 0.5 | P23: =IF(Data_Pegawai[[#This Row],[Status Pegawai]]="Pegawai Tetap (PKWTT)",Data_Pegawai[[#This Row],[Multiplier Pesangon]]*Data_Pegawai[[#This Row],[THP]]*Data_Pegawai[[#This Row],[Multiplier Jenis PHK*]],0) -> 660000 | Q23: =IF(ISNUMBER(INDEX(Data_Kewajiban[Sisa Kewajiban sebelum Pesangon],MATCH(Data_Pegawai[[#This Row],[Nama]],Data_Kewajiban[Nama],0))),INDEX(Data_Kewajiban[Sisa Kewajiban sebelum Pesangon],MATCH(Data_Pegawai[[#This Row],[Nama]],Data_Kewajiban[Nama],0)),0) -> 0 | R23: =IF(Data_Pegawai[[#This Row],[Gross Pesangon]]>Data_Pegawai[[#This Row],[Kewajiban Pegawai]],Data_Pegawai[[#This Row],[Gross Pesangon]]-Data_Pegawai[[#This Row],[Kewajiban Pegawai]],0) -> 660000 | S23: =IF(Data_Pegawai[[#This Row],[Kewajiban Pegawai]]>Data_Pegawai[[#This Row],[Gross Pesangon]],Data_Pegawai[[#This Row],[Kewajiban Pegawai]]-Data_Pegawai[[#This Row],[Gross Pesangon]],0) -> 0
A24: 13 | B24: Pegawai 13 | C24: Satpam | D24: Pegawai Tetap (PKWTT) | E24: 43542 | F24: 43822 | G24: =DATEDIF(E24,F24,"Y") -> 0 | H24: =IF(ISNUMBER(INDEX(Historis_Gaji[Angka yang Digunakan],MATCH(Data_Pegawai[[#This Row],[Nama]],Historis_Gaji[Nama],0))),INDEX(Historis_Gaji[Angka yang Digunakan],MATCH(Data_Pegawai[[#This Row],[Nama]],Historis_Gaji[Nama],0)),0) -> 1000000 | I24: =IF(ISNUMBER(INDEX(Historis_Tunj1[Angka yang Digunakan],MATCH(Data_Pegawai[[#This Row],[Nama]],Historis_Tunj1[Nama],0))),INDEX(Historis_Tunj1[Angka yang Digunakan],MATCH(Data_Pegawai[[#This Row],[Nama]],Historis_Tunj1[Nama],0)),0) -> 0 | J24: =IF(ISNUMBER(INDEX(Historis_Tunj2[Angka yang Digunakan],MATCH(Data_Pegawai[[#This Row],[Nama]],Historis_Tunj2[Nama],0))),INDEX(Historis_Tunj2[Angka yang Digunakan],MATCH(Data_Pegawai[[#This Row],[Nama]],Historis_Tunj2[Nama],0)),0) -> 240000 | K24: =IF(ISNUMBER(INDEX(Historis_Tunj3[Angka yang Digunakan],MATCH(Data_Pegawai[[#This Row],[Nama]],Historis_Tunj3[Nama],0))),INDEX(Historis_Tunj3[Angka yang Digunakan],MATCH(Data_Pegawai[[#This Row],[Nama]],Historis_Tunj3[Nama],0)),0) -> 0 | L24: =IF(ISNUMBER(INDEX(Historis_Tunj4[Angka yang Digunakan],MATCH(Data_Pegawai[[#This Row],[Nama]],Historis_Tunj4[Nama],0))),INDEX(Historis_Tunj4[Angka yang Digunakan],MATCH(Data_Pegawai[[#This Row],[Nama]],Historis_Tunj4[Nama],0)),0) -> 0 | M24: =SUM(H24:L24) -> 1240000 | N24: =MIN(Data_Pegawai[[#This Row],[Masa Kerja (tahun)]]+1,9) -> 1 | O24: 0.5 | P24: =IF(Data_Pegawai[[#This Row],[Status Pegawai]]="Pegawai Tetap (PKWTT)",Data_Pegawai[[#This Row],[Multiplier Pesangon]]*Data_Pegawai[[#This Row],[THP]]*Data_Pegawai[[#This Row],[Multiplier Jenis PHK*]],0) -> 620000 | Q24: =IF(ISNUMBER(INDEX(Data_Kewajiban[Sisa Kewajiban sebelum Pesangon],MATCH(Data_Pegawai[[#This Row],[Nama]],Data_Kewajiban[Nama],0))),INDEX(Data_Kewajiban[Sisa Kewajiban sebelum Pesangon],MATCH(Data_Pegawai[[#This Row],[Nama]],Data_Kewajiban[Nama],0)),0) -> 0 | R24: =IF(Data_Pegawai[[#This Row],[Gross Pesangon]]>Data_Pegawai[[#This Row],[Kewajiban Pegawai]],Data_Pegawai[[#This Row],[Gross Pesangon]]-Data_Pegawai[[#This Row],[Kewajiban Pegawai]],0) -> 620000 | S24: =IF(Data_Pegawai[[#This Row],[Kewajiban Pegawai]]>Data_Pegawai[[#This Row],[Gross Pesangon]],Data_Pegawai[[#This Row],[Kewajiban Pegawai]]-Data_Pegawai[[#This Row],[Gross Pesangon]],0) -> 0
A25: 14 | G25: =DATEDIF(E25,F25,"Y") -> 0 | H25: =IF(ISNUMBER(INDEX(Historis_Gaji[Angka yang Digunakan],MATCH(Data_Pegawai[[#This Row],[Nama]],Historis_Gaji[Nama],0))),INDEX(Historis_Gaji[Angka yang Digunakan],MATCH(Data_Pegawai[[#This Row],[Nama]],Historis_Gaji[Nama],0)),0) -> 0 | I25: =IF(ISNUMBER(INDEX(Historis_Tunj1[Angka yang Digunakan],MATCH(Data_Pegawai[[#This Row],[Nama]],Historis_Tunj1[Nama],0))),INDEX(Historis_Tunj1[Angka yang Digunakan],MATCH(Data_Pegawai[[#This Row],[Nama]],Historis_Tunj1[Nama],0)),0) -> 0 | J25: =IF(ISNUMBER(INDEX(Historis_Tunj2[Angka yang Digunakan],MATCH(Data_Pegawai[[#This Row],[Nama]],Historis_Tunj2[Nama],0))),INDEX(Historis_Tunj2[Angka yang Digunakan],MATCH(Data_Pegawai[[#This Row],[Nama]],Historis_Tunj2[Nama],0)),0) -> 0 | K25: =IF(ISNUMBER(INDEX(Historis_Tunj3[Angka yang Digunakan],MATCH(Data_Pegawai[[#This Row],[Nama]],Historis_Tunj3[Nama],0))),INDEX(Historis_Tunj3[Angka yang Digunakan],MATCH(Data_Pegawai[[#This Row],[Nama]],Historis_Tunj3[Nama],0)),0) -> 0 | L25: =IF(ISNUMBER(INDEX(Historis_Tunj4[Angka yang Digunakan],MATCH(Data_Pegawai[[#This Row],[Nama]],Historis_Tunj4[Nama],0))),INDEX(Historis_Tunj4[Angka yang Digunakan],MATCH(Data_Pegawai[[#This Row],[Nama]],Historis_Tunj4[Nama],0)),0) -> 0 | M25: =SUM(H25:L25) -> 0 | N25: =MIN(Data_Pegawai[[#This Row],[Masa Kerja (tahun)]]+1,9) -> 1 | O25: 0.5 | P25: =IF(Data_Pegawai[[#This Row],[Status Pegawai]]="Pegawai Tetap (PKWTT)",Data_Pegawai[[#This Row],[Multiplier Pesangon]]*Data_Pegawai[[#This Row],[THP]]*Data_Pegawai[[#This Row],[Multiplier Jenis PHK*]],0) -> 0 | Q25: =IF(ISNUMBER(INDEX(Data_Kewajiban[Sisa Kewajiban sebelum Pesangon],MATCH(Data_Pegawai[[#This Row],[Nama]],Data_Kewajiban[Nama],0))),INDEX(Data_Kewajiban[Sisa Kewajiban sebelum Pesangon],MATCH(Data_Pegawai[[#This Row],[Nama]],Data_Kewajiban[Nama],0)),0) -> 0 | R25: =IF(Data_Pegawai[[#This Row],[Gross Pesangon]]>Data_Pegawai[[#This Row],[Kewajiban Pegawai]],Data_Pegawai[[#This Row],[Gross Pesangon]]-Data_Pegawai[[#This Row],[Kewajiban Pegawai]],0) -> 0 | S25: =IF(Data_Pegawai[[#This Row],[Kewajiban Pegawai]]>Data_Pegawai[[#This Row],[Gross Pesangon]],Data_Pegawai[[#This Row],[Kewajiban Pegawai]]-Data_Pegawai[[#This Row],[Gross Pesangon]],0) -> 0
A26: 15 | G26: =DATEDIF(E26,F26,"Y") -> 0 | H26: =IF(ISNUMBER(INDEX(Historis_Gaji[Angka yang Digunakan],MATCH(Data_Pegawai[[#This Row],[Nama]],Historis_Gaji[Nama],0))),INDEX(Historis_Gaji[Angka yang Digunakan],MATCH(Data_Pegawai[[#This Row],[Nama]],Historis_Gaji[Nama],0)),0) -> 0 | I26: =IF(ISNUMBER(INDEX(Historis_Tunj1[Angka yang Digunakan],MATCH(Data_Pegawai[[#This Row],[Nama]],Historis_Tunj1[Nama],0))),INDEX(Historis_Tunj1[Angka yang Digunakan],MATCH(Data_Pegawai[[#This Row],[Nama]],Historis_Tunj1[Nama],0)),0) -> 0 | J26: =IF(ISNUMBER(INDEX(Historis_Tunj2[Angka yang Digunakan],MATCH(Data_Pegawai[[#This Row],[Nama]],Historis_Tunj2[Nama],0))),INDEX(Historis_Tunj2[Angka yang Digunakan],MATCH(Data_Pegawai[[#This Row],[Nama]],Historis_Tunj2[Nama],0)),0) -> 0 | K26: =IF(ISNUMBER(INDEX(Historis_Tunj3[Angka yang Digunakan],MATCH(Data_Pegawai[[#This Row],[Nama]],Historis_Tunj3[Nama],0))),INDEX(Historis_Tunj3[Angka yang Digunakan],MATCH(Data_Pegawai[[#This Row],[Nama]],Historis_Tunj3[Nama],0)),0) -> 0 | L26: =IF(ISNUMBER(INDEX(Historis_Tunj4[Angka yang Digunakan],MATCH(Data_Pegawai[[#This Row],[Nama]],Historis_Tunj4[Nama],0))),INDEX(Historis_Tunj4[Angka yang Digunakan],MATCH(Data_Pegawai[[#This Row],[Nama]],Historis_Tunj4[Nama],0)),0) -> 0 | M26: =SUM(H26:L26) -> 0 | N26: =MIN(Data_Pegawai[[#This Row],[Masa Kerja (tahun)]]+1,9) -> 1 | O26: 0.5 | P26: =IF(Data_Pegawai[[#This Row],[Status Pegawai]]="Pegawai Tetap (PKWTT)",Data_Pegawai[[#This Row],[Multiplier Pesangon]]*Data_Pegawai[[#This Row],[THP]]*Data_Pegawai[[#This Row],[Multiplier Jenis PHK*]],0) -> 0 | Q26: =IF(ISNUMBER(INDEX(Data_Kewajiban[Sisa Kewajiban sebelum Pesangon],MATCH(Data_Pegawai[[#This Row],[Nama]],Data_Kewajiban[Nama],0))),INDEX(Data_Kewajiban[Sisa Kewajiban sebelum Pesangon],MATCH(Data_Pegawai[[#This Row],[Nama]],Data_Kewajiban[Nama],0)),0) -> 0 | R26: =IF(Data_Pegawai[[#This Row],[Gross Pesangon]]>Data_Pegawai[[#This Row],[Kewajiban Pegawai]],Data_Pegawai[[#This Row],[Gross Pesangon]]-Data_Pegawai[[#This Row],[Kewajiban Pegawai]],0) -> 0 | S26: =IF(Data_Pegawai[[#This Row],[Kewajiban Pegawai]]>Data_Pegawai[[#This Row],[Gross Pesangon]],Data_Pegawai[[#This Row],[Kewajiban Pegawai]]-Data_Pegawai[[#This Row],[Gross Pesangon]],0) -> 0
A27: 16 | G27: =DATEDIF(E27,F27,"Y") -> 0 | H27: =IF(ISNUMBER(INDEX(Historis_Gaji[Angka yang Digunakan],MATCH(Data_Pegawai[[#This Row],[Nama]],Historis_Gaji[Nama],0))),INDEX(Historis_Gaji[Angka yang Digunakan],MATCH(Data_Pegawai[[#This Row],[Nama]],Historis_Gaji[Nama],0)),0) -> 0 | I27: =IF(ISNUMBER(INDEX(Historis_Tunj1[Angka yang Digunakan],MATCH(Data_Pegawai[[#This Row],[Nama]],Historis_Tunj1[Nama],0))),INDEX(Historis_Tunj1[Angka yang Digunakan],MATCH(Data_Pegawai[[#This Row],[Nama]],Historis_Tunj1[Nama],0)),0) -> 0 | J27: =IF(ISNUMBER(INDEX(Historis_Tunj2[Angka yang Digunakan],MATCH(Data_Pegawai[[#This Row],[Nama]],Historis_Tunj2[Nama],0))),INDEX(Historis_Tunj2[Angka yang Digunakan],MATCH(Data_Pegawai[[#This Row],[Nama]],Historis_Tunj2[Nama],0)),0) -> 0 | K27: =IF(ISNUMBER(INDEX(Historis_Tunj3[Angka yang Digunakan],MATCH(Data_Pegawai[[#This Row],[Nama]],Historis_Tunj3[Nama],0))),INDEX(Historis_Tunj3[Angka yang Digunakan],MATCH(Data_Pegawai[[#This Row],[Nama]],Historis_Tunj3[Nama],0)),0) -> 0 | L27: =IF(ISNUMBER(INDEX(Historis_Tunj4[Angka yang Digunakan],MATCH(Data_Pegawai[[#This Row],[Nama]],Historis_Tunj4[Nama],0))),INDEX(Historis_Tunj4[Angka yang Digunakan],MATCH(Data_Pegawai[[#This Row],[Nama]],Historis_Tunj4[Nama],0)),0) -> 0 | M27: =SUM(H27:L27) -> 0 | N27: =MIN(Data_Pegawai[[#This Row],[Masa Kerja (tahun)]]+1,9) -> 1 | O27: 0.5 | P27: =IF(Data_Pegawai[[#This Row],[Status Pegawai]]="Pegawai Tetap (PKWTT)",Data_Pegawai[[#This Row],[Multiplier Pesangon]]*Data_Pegawai[[#This Row],[THP]]*Data_Pegawai[[#This Row],[Multiplier Jenis PHK*]],0) -> 0 | Q27: =IF(ISNUMBER(INDEX(Data_Kewajiban[Sisa Kewajiban sebelum Pesangon],MATCH(Data_Pegawai[[#This Row],[Nama]],Data_Kewajiban[Nama],0))),INDEX(Data_Kewajiban[Sisa Kewajiban sebelum Pesangon],MATCH(Data_Pegawai[[#This Row],[Nama]],Data_Kewajiban[Nama],0)),0) -> 0 | R27: =IF(Data_Pegawai[[#This Row],[Gross Pesangon]]>Data_Pegawai[[#This Row],[Kewajiban Pegawai]],Data_Pegawai[[#This Row],[Gross Pesangon]]-Data_Pegawai[[#This Row],[Kewajiban Pegawai]],0) -> 0 | S27: =IF(Data_Pegawai[[#This Row],[Kewajiban Pegawai]]>Data_Pegawai[[#This Row],[Gross Pesangon]],Data_Pegawai[[#This Row],[Kewajiban Pegawai]]-Data_Pegawai[[#This Row],[Gross Pesangon]],0) -> 0
A28: 17 | G28: =DATEDIF(E28,F28,"Y") -> 0 | H28: =IF(ISNUMBER(INDEX(Historis_Gaji[Angka yang Digunakan],MATCH(Data_Pegawai[[#This Row],[Nama]],Historis_Gaji[Nama],0))),INDEX(Historis_Gaji[Angka yang Digunakan],MATCH(Data_Pegawai[[#This Row],[Nama]],Historis_Gaji[Nama],0)),0) -> 0 | I28: =IF(ISNUMBER(INDEX(Historis_Tunj1[Angka yang Digunakan],MATCH(Data_Pegawai[[#This Row],[Nama]],Historis_Tunj1[Nama],0))),INDEX(Historis_Tunj1[Angka yang Digunakan],MATCH(Data_Pegawai[[#This Row],[Nama]],Historis_Tunj1[Nama],0)),0) -> 0 | J28: =IF(ISNUMBER(INDEX(Historis_Tunj2[Angka yang Digunakan],MATCH(Data_Pegawai[[#This Row],[Nama]],Historis_Tunj2[Nama],0))),INDEX(Historis_Tunj2[Angka yang Digunakan],MATCH(Data_Pegawai[[#This Row],[Nama]],Historis_Tunj2[Nama],0)),0) -> 0 | K28: =IF(ISNUMBER(INDEX(Historis_Tunj3[Angka yang Digunakan],MATCH(Data_Pegawai[[#This Row],[Nama]],Historis_Tunj3[Nama],0))),INDEX(Historis_Tunj3[Angka yang Digunakan],MATCH(Data_Pegawai[[#This Row],[Nama]],Historis_Tunj3[Nama],0)),0) -> 0 | L28: =IF(ISNUMBER(INDEX(Historis_Tunj4[Angka yang Digunakan],MATCH(Data_Pegawai[[#This Row],[Nama]],Historis_Tunj4[Nama],0))),INDEX(Historis_Tunj4[Angka yang Digunakan],MATCH(Data_Pegawai[[#This Row],[Nama]],Historis_Tunj4[Nama],0)),0) -> 0 | M28: =SUM(H28:L28) -> 0 | N28: =MIN(Data_Pegawai[[#This Row],[Masa Kerja (tahun)]]+1,9) -> 1 | O28: 0.5 | P28: =IF(Data_Pegawai[[#This Row],[Status Pegawai]]="Pegawai Tetap (PKWTT)",Data_Pegawai[[#This Row],[Multiplier Pesangon]]*Data_Pegawai[[#This Row],[THP]]*Data_Pegawai[[#This Row],[Multiplier Jenis PHK*]],0) -> 0 | Q28: =IF(ISNUMBER(INDEX(Data_Kewajiban[Sisa Kewajiban sebelum Pesangon],MATCH(Data_Pegawai[[#This Row],[Nama]],Data_Kewajiban[Nama],0))),INDEX(Data_Kewajiban[Sisa Kewajiban sebelum Pesangon],MATCH(Data_Pegawai[[#This Row],[Nama]],Data_Kewajiban[Nama],0)),0) -> 0 | R28: =IF(Data_Pegawai[[#This Row],[Gross Pesangon]]>Data_Pegawai[[#This Row],[Kewajiban Pegawai]],Data_Pegawai[[#This Row],[Gross Pesangon]]-Data_Pegawai[[#This Row],[Kewajiban Pegawai]],0) -> 0 | S28: =IF(Data_Pegawai[[#This Row],[Kewajiban Pegawai]]>Data_Pegawai[[#This Row],[Gross Pesangon]],Data_Pegawai[[#This Row],[Kewajiban Pegawai]]-Data_Pegawai[[#This Row],[Gross Pesangon]],0) -> 0
A29: 18 | G29: =DATEDIF(E29,F29,"Y") -> 0 | H29: =IF(ISNUMBER(INDEX(Historis_Gaji[Angka yang Digunakan],MATCH(Data_Pegawai[[#This Row],[Nama]],Historis_Gaji[Nama],0))),INDEX(Historis_Gaji[Angka yang Digunakan],MATCH(Data_Pegawai[[#This Row],[Nama]],Historis_Gaji[Nama],0)),0) -> 0 | I29: =IF(ISNUMBER(INDEX(Historis_Tunj1[Angka yang Digunakan],MATCH(Data_Pegawai[[#This Row],[Nama]],Historis_Tunj1[Nama],0))),INDEX(Historis_Tunj1[Angka yang Digunakan],MATCH(Data_Pegawai[[#This Row],[Nama]],Historis_Tunj1[Nama],0)),0) -> 0 | J29: =IF(ISNUMBER(INDEX(Historis_Tunj2[Angka yang Digunakan],MATCH(Data_Pegawai[[#This Row],[Nama]],Historis_Tunj2[Nama],0))),INDEX(Historis_Tunj2[Angka yang Digunakan],MATCH(Data_Pegawai[[#This Row],[Nama]],Historis_Tunj2[Nama],0)),0) -> 0 | K29: =IF(ISNUMBER(INDEX(Historis_Tunj3[Angka yang Digunakan],MATCH(Data_Pegawai[[#This Row],[Nama]],Historis_Tunj3[Nama],0))),INDEX(Historis_Tunj3[Angka yang Digunakan],MATCH(Data_Pegawai[[#This Row],[Nama]],Historis_Tunj3[Nama],0)),0) -> 0 | L29: =IF(ISNUMBER(INDEX(Historis_Tunj4[Angka yang Digunakan],MATCH(Data_Pegawai[[#This Row],[Nama]],Historis_Tunj4[Nama],0))),INDEX(Historis_Tunj4[Angka yang Digunakan],MATCH(Data_Pegawai[[#This Row],[Nama]],Historis_Tunj4[Nama],0)),0) -> 0 | M29: =SUM(H29:L29) -> 0 | N29: =MIN(Data_Pegawai[[#This Row],[Masa Kerja (tahun)]]+1,9) -> 1 | O29: 0.5 | P29: =IF(Data_Pegawai[[#This Row],[Status Pegawai]]="Pegawai Tetap (PKWTT)",Data_Pegawai[[#This Row],[Multiplier Pesangon]]*Data_Pegawai[[#This Row],[THP]]*Data_Pegawai[[#This Row],[Multiplier Jenis PHK*]],0) -> 0 | Q29: =IF(ISNUMBER(INDEX(Data_Kewajiban[Sisa Kewajiban sebelum Pesangon],MATCH(Data_Pegawai[[#This Row],[Nama]],Data_Kewajiban[Nama],0))),INDEX(Data_Kewajiban[Sisa Kewajiban sebelum Pesangon],MATCH(Data_Pegawai[[#This Row],[Nama]],Data_Kewajiban[Nama],0)),0) -> 0 | R29: =IF(Data_Pegawai[[#This Row],[Gross Pesangon]]>Data_Pegawai[[#This Row],[Kewajiban Pegawai]],Data_Pegawai[[#This Row],[Gross Pesangon]]-Data_Pegawai[[#This Row],[Kewajiban Pegawai]],0) -> 0 | S29: =IF(Data_Pegawai[[#This Row],[Kewajiban Pegawai]]>Data_Pegawai[[#This Row],[Gross Pesangon]],Data_Pegawai[[#This Row],[Kewajiban Pegawai]]-Data_Pegawai[[#This Row],[Gross Pesangon]],0) -> 0
A30: 19 | G30: =DATEDIF(E30,F30,"Y") -> 0 | H30: =IF(ISNUMBER(INDEX(Historis_Gaji[Angka yang Digunakan],MATCH(Data_Pegawai[[#This Row],[Nama]],Historis_Gaji[Nama],0))),INDEX(Historis_Gaji[Angka yang Digunakan],MATCH(Data_Pegawai[[#This Row],[Nama]],Historis_Gaji[Nama],0)),0) -> 0 | I30: =IF(ISNUMBER(INDEX(Historis_Tunj1[Angka yang Digunakan],MATCH(Data_Pegawai[[#This Row],[Nama]],Historis_Tunj1[Nama],0))),INDEX(Historis_Tunj1[Angka yang Digunakan],MATCH(Data_Pegawai[[#This Row],[Nama]],Historis_Tunj1[Nama],0)),0) -> 0 | J30: =IF(ISNUMBER(INDEX(Historis_Tunj2[Angka yang Digunakan],MATCH(Data_Pegawai[[#This Row],[Nama]],Historis_Tunj2[Nama],0))),INDEX(Historis_Tunj2[Angka yang Digunakan],MATCH(Data_Pegawai[[#This Row],[Nama]],Historis_Tunj2[Nama],0)),0) -> 0 | K30: =IF(ISNUMBER(INDEX(Historis_Tunj3[Angka yang Digunakan],MATCH(Data_Pegawai[[#This Row],[Nama]],Historis_Tunj3[Nama],0))),INDEX(Historis_Tunj3[Angka yang Digunakan],MATCH(Data_Pegawai[[#This Row],[Nama]],Historis_Tunj3[Nama],0)),0) -> 0 | L30: =IF(ISNUMBER(INDEX(Historis_Tunj4[Angka yang Digunakan],MATCH(Data_Pegawai[[#This Row],[Nama]],Historis_Tunj4[Nama],0))),INDEX(Historis_Tunj4[Angka yang Digunakan],MATCH(Data_Pegawai[[#This Row],[Nama]],Historis_Tunj4[Nama],0)),0) -> 0 | M30: =SUM(H30:L30) -> 0 | N30: =MIN(Data_Pegawai[[#This Row],[Masa Kerja (tahun)]]+1,9) -> 1 | O30: 0.5 | P30: =IF(Data_Pegawai[[#This Row],[Status Pegawai]]="Pegawai Tetap (PKWTT)",Data_Pegawai[[#This Row],[Multiplier Pesangon]]*Data_Pegawai[[#This Row],[THP]]*Data_Pegawai[[#This Row],[Multiplier Jenis PHK*]],0) -> 0 | Q30: =IF(ISNUMBER(INDEX(Data_Kewajiban[Sisa Kewajiban sebelum Pesangon],MATCH(Data_Pegawai[[#This Row],[Nama]],Data_Kewajiban[Nama],0))),INDEX(Data_Kewajiban[Sisa Kewajiban sebelum Pesangon],MATCH(Data_Pegawai[[#This Row],[Nama]],Data_Kewajiban[Nama],0)),0) -> 0 | R30: =IF(Data_Pegawai[[#This Row],[Gross Pesangon]]>Data_Pegawai[[#This Row],[Kewajiban Pegawai]],Data_Pegawai[[#This Row],[Gross Pesangon]]-Data_Pegawai[[#This Row],[Kewajiban Pegawai]],0) -> 0 | S30: =IF(Data_Pegawai[[#This Row],[Kewajiban Pegawai]]>Data_Pegawai[[#This Row],[Gross Pesangon]],Data_Pegawai[[#This Row],[Kewajiban Pegawai]]-Data_Pegawai[[#This Row],[Gross Pesangon]],0) -> 0
A31: 20 | G31: =DATEDIF(E31,F31,"Y") -> 0 | H31: =IF(ISNUMBER(INDEX(Historis_Gaji[Angka yang Digunakan],MATCH(Data_Pegawai[[#This Row],[Nama]],Historis_Gaji[Nama],0))),INDEX(Historis_Gaji[Angka yang Digunakan],MATCH(Data_Pegawai[[#This Row],[Nama]],Historis_Gaji[Nama],0)),0) -> 0 | I31: =IF(ISNUMBER(INDEX(Historis_Tunj1[Angka yang Digunakan],MATCH(Data_Pegawai[[#This Row],[Nama]],Historis_Tunj1[Nama],0))),INDEX(Historis_Tunj1[Angka yang Digunakan],MATCH(Data_Pegawai[[#This Row],[Nama]],Historis_Tunj1[Nama],0)),0) -> 0 | J31: =IF(ISNUMBER(INDEX(Historis_Tunj2[Angka yang Digunakan],MATCH(Data_Pegawai[[#This Row],[Nama]],Historis_Tunj2[Nama],0))),INDEX(Historis_Tunj2[Angka yang Digunakan],MATCH(Data_Pegawai[[#This Row],[Nama]],Historis_Tunj2[Nama],0)),0) -> 0 | K31: =IF(ISNUMBER(INDEX(Historis_Tunj3[Angka yang Digunakan],MATCH(Data_Pegawai[[#This Row],[Nama]],Historis_Tunj3[Nama],0))),INDEX(Historis_Tunj3[Angka yang Digunakan],MATCH(Data_Pegawai[[#This Row],[Nama]],Historis_Tunj3[Nama],0)),0) -> 0 | L31: =IF(ISNUMBER(INDEX(Historis_Tunj4[Angka yang Digunakan],MATCH(Data_Pegawai[[#This Row],[Nama]],Historis_Tunj4[Nama],0))),INDEX(Historis_Tunj4[Angka yang Digunakan],MATCH(Data_Pegawai[[#This Row],[Nama]],Historis_Tunj4[Nama],0)),0) -> 0 | M31: =SUM(H31:L31) -> 0 | N31: =MIN(Data_Pegawai[[#This Row],[Masa Kerja (tahun)]]+1,9) -> 1 | O31: 0.5 | P31: =IF(Data_Pegawai[[#This Row],[Status Pegawai]]="Pegawai Tetap (PKWTT)",Data_Pegawai[[#This Row],[Multiplier Pesangon]]*Data_Pegawai[[#This Row],[THP]]*Data_Pegawai[[#This Row],[Multiplier Jenis PHK*]],0) -> 0 | Q31: =IF(ISNUMBER(INDEX(Data_Kewajiban[Sisa Kewajiban sebelum Pesangon],MATCH(Data_Pegawai[[#This Row],[Nama]],Data_Kewajiban[Nama],0))),INDEX(Data_Kewajiban[Sisa Kewajiban sebelum Pesangon],MATCH(Data_Pegawai[[#This Row],[Nama]],Data_Kewajiban[Nama],0)),0) -> 0 | R31: =IF(Data_Pegawai[[#This Row],[Gross Pesangon]]>Data_Pegawai[[#This Row],[Kewajiban Pegawai]],Data_Pegawai[[#This Row],[Gross Pesangon]]-Data_Pegawai[[#This Row],[Kewajiban Pegawai]],0) -> 0 | S31: =IF(Data_Pegawai[[#This Row],[Kewajiban Pegawai]]>Data_Pegawai[[#This Row],[Gross Pesangon]],Data_Pegawai[[#This Row],[Kewajiban Pegawai]]-Data_Pegawai[[#This Row],[Gross Pesangon]],0) -> 0
A32: Total | B32: =SUBTOTAL(103,Data_Pegawai[Nama]) -> 13 | H32: =SUBTOTAL(109,Data_Pegawai[Gaji Pokok]) -> 22550000 | I32: =SUBTOTAL(109,Data_Pegawai[Tunj. 1]) -> 1250000 | J32: =SUBTOTAL(109,Data_Pegawai[Tunj. 2]) -> 3560000 | K32: =SUBTOTAL(109,Data_Pegawai[Tunj. 3]) -> 0 | L32: =SUBTOTAL(109,Data_Pegawai[Tunj. 4]) -> 300000 | M32: =SUBTOTAL(109,Data_Pegawai[THP]) -> 27660000 | P32: =SUBTOTAL(109,Data_Pegawai[Gross Pesangon]) -> 106480000 | Q32: =SUBTOTAL(109,Data_Pegawai[Kewajiban Pegawai]) -> 729667180 | R32: =SUBTOTAL(109,Data_Pegawai[Nett Pesangon]) -> 16880000 | S32: =SUBTOTAL(109,Data_Pegawai[Sisa Kewajiban]) -> 640067180
A35: Catatan:
A36: Faktor pengali berdasarkan Pasal 44 PP No. 35 Tahun 2021
A37: "Perusahaan tutup yang disebabkan Perusahaan mengalami kerugian secara terus menerus selama 2 (dua) tahun atau mengalami kerugian tidak secara terus menerus selama 2 (dua) tahun"

Sheet 2. Historis Gaji Pokok
A2: KERTAS KERJA
A3: ANALISA PEMBERIAN PESANGON PEGAWAI
A4: =UPPER('1. Perhitungan Pesangon'!$C$7) -> PT BPRS HAREUKAT (DL)
A5: Historis Gaji Pokok
D7: Historis Gaji Pokok
D8: =DATE(YEAR('1. Perhitungan Pesangon'!$C$8),MONTH('1. Perhitungan Pesangon'!$C$8)-12,1) -> 43374 | E8: =DATE(YEAR('1. Perhitungan Pesangon'!$C$8),MONTH('1. Perhitungan Pesangon'!$C$8)-11,1) -> 43405 | F8: =DATE(YEAR('1. Perhitungan Pesangon'!$C$8),MONTH('1. Perhitungan Pesangon'!$C$8)-10,1) -> 43435 | G8: =DATE(YEAR('1. Perhitungan Pesangon'!$C$8),MONTH('1. Perhitungan Pesangon'!$C$8)-9,1) -> 43466 | H8: =DATE(YEAR('1. Perhitungan Pesangon'!$C$8),MONTH('1. Perhitungan Pesangon'!$C$8)-8,1) -> 43497 | I8: =DATE(YEAR('1. Perhitungan Pesangon'!$C$8),MONTH('1. Perhitungan Pesangon'!$C$8)-7,1) -> 43525 | J8: =DATE(YEAR('1. Perhitungan Pesangon'!$C$8),MONTH('1. Perhitungan Pesangon'!$C$8)-6,1) -> 43556 | K8: =DATE(YEAR('1. Perhitungan Pesangon'!$C$8),MONTH('1. Perhitungan Pesangon'!$C$8)-5,1) -> 43586 | L8: =DATE(YEAR('1. Perhitungan Pesangon'!$C$8),MONTH('1. Perhitungan Pesangon'!$C$8)-4,1) -> 43617 | M8: =DATE(YEAR('1. Perhitungan Pesangon'!$C$8),MONTH('1. Perhitungan Pesangon'!$C$8)-3,1) -> 43647 | N8: =DATE(YEAR('1. Perhitungan Pesangon'!$C$8),MONTH('1. Perhitungan Pesangon'!$C$8)-2,1) -> 43678 | O8: =DATE(YEAR('1. Perhitungan Pesangon'!$C$8),MONTH('1. Perhitungan Pesangon'!$C$8)-1,1) -> 43709
A9: No. | B9: Nama | C9: Jabatan | D9: 1 | E9: 2 | F9: 3 | G9: 4 | H9: 5 | I9: 6 | J9: 7 | K9: 8 | L9: 9 | M9: 10 | N9: 11 | O9: 12 | P9: Avg. | Q9: Angka Terakhir | R9: Angka yang Digunakan | S9: Keterangan
A10: 1 | B10: Pegawai 1 | C10: =INDEX(Data_Pegawai[Jabatan],MATCH(Historis_Gaji[[#This Row],[Nama]],Data_Pegawai[Nama],0)) -> Kabag Operasional | D10: 2500000 | E10: 2500000 | F10: 2500000 | G10: 2500000 | H10: 2500000 | I10: 2500000 | J10: 2500000 | K10: 2500000 | L10: 2500000 | M10: 2500000 | N10: 2500000 | O10: 2500000 | P10: =IF(ISNUMBER(AVERAGEIF(Historis_Gaji[[#This Row],[1]:[12]],">0")),AVERAGEIF(Historis_Gaji[[#This Row],[1]:[12]],">0"),0) -> 2500000 | Q10: =Historis_Gaji[[#This Row],[12]] -> 2500000 | R10: 2500000
A11: 2 | B11: Pegawai 2 | C11: =INDEX(Data_Pegawai[Jabatan],MATCH(Historis_Gaji[[#This Row],[Nama]],Data_Pegawai[Nama],0)) -> Kabag Pembiayaan | D11: 2500000 | E11: 2500000 | F11: 2500000 | G11: 2500000 | H11: 2500000 | I11: 2500000 | J11: 2500000 | K11: 2500000 | L11: 2500000 | M11: 2500000 | N11: 2500000 | O11: 2500000 | P11: =IF(ISNUMBER(AVERAGEIF(Historis_Gaji[[#This Row],[1]:[12]],">0")),AVERAGEIF(Historis_Gaji[[#This Row],[1]:[12]],">0"),0) -> 2500000 | Q11: =Historis_Gaji[[#This Row],[12]] -> 2500000 | R11: 2500000
A12: 3 | B12: Pegawai 3 | C12: =INDEX(Data_Pegawai[Jabatan],MATCH(Historis_Gaji[[#This Row],[Nama]],Data_Pegawai[Nama],0)) -> A/O Loan | D12: 0 | E12: 0 | F12: 0 | G12: 0 | H12: 0 | I12: 738100 | J12: 2500000 | K12: 2500000 | L12: 2500000 | M12: 2500000 | N12: 2500000 | O12: 2500000 | P12: =IF(ISNUMBER(AVERAGEIF(Historis_Gaji[[#This Row],[1]:[12]],">0")),AVERAGEIF(Historis_Gaji[[#This Row],[1]:[12]],">0"),0) -> 2248300 | Q12: =Historis_Gaji[[#This Row],[12]] -> 2500000 | R12: 2500000
A13: 4 | B13: Pegawai 4 | C13: =INDEX(Data_Pegawai[Jabatan],MATCH(Historis_Gaji[[#This Row],[Nama]],Data_Pegawai[Nama],0)) -> Funding | D13: 0 | E13: 0 | F13: 0 | G13: 0 | H13: 0 | I13: 0 | J13: 0 | K13: 0 | L13: 0 | M13: 0 | N13: 0 | O13: 0 | P13: =IF(ISNUMBER(AVERAGEIF(Historis_Gaji[[#This Row],[1]:[12]],">0")),AVERAGEIF(Historis_Gaji[[#This Row],[1]:[12]],">0"),0) -> 0 | Q13: =Historis_Gaji[[#This Row],[12]] -> 0 | R13: 2000000
A14: 5 | B14: Pegawai 5 | C14: =INDEX(Data_Pegawai[Jabatan],MATCH(Historis_Gaji[[#This Row],[Nama]],Data_Pegawai[Nama],0)) -> A/O Loan | D14: 1900000 | E14: 1900000 | F14: 1900000 | G14: 1900000 | H14: 1900000 | I14: 1900000 | J14: 1900000 | K14: 1900000 | L14: 1900000 | M14: 1900000 | N14: 1900000 | O14: 1900000 | P14: =IF(ISNUMBER(AVERAGEIF(Historis_Gaji[[#This Row],[1]:[12]],">0")),AVERAGEIF(Historis_Gaji[[#This Row],[1]:[12]],">0"),0) -> 1900000 | Q14: =Historis_Gaji[[#This Row],[12]] -> 1900000 | R14: 1900000
A15: 6 | B15: Pegawai 6 | C15: =INDEX(Data_Pegawai[Jabatan],MATCH(Historis_Gaji[[#This Row],[Nama]],Data_Pegawai[Nama],0)) -> ADM Pelaporan | D15: 1900000 | E15: 1900000 | F15: 1900000 | G15: 1900000 | H15: 1900000 | I15: 1900000 | J15: 1900000 | K15: 1900000 | L15: 1900000 | M15: 1900000 | N15: 1900000 | O15: 1900000 | P15: =IF(ISNUMBER(AVERAGEIF(Historis_Gaji[[#This Row],[1]:[12]],">0")),AVERAGEIF(Historis_Gaji[[#This Row],[1]:[12]],">0"),0) -> 1900000 | Q15: =Historis_Gaji[[#This Row],[12]] -> 1900000 | R15: 1900000
A16: 7 | B16: Pegawai 7 | C16: =INDEX(Data_Pegawai[Jabatan],MATCH(Historis_Gaji[[#This Row],[Nama]],Data_Pegawai[Nama],0)) -> Funding | D16: 0 | E16: 0 | F16: 0 | G16: 0 | H16: 0 | I16: 0 | J16: 0 | K16: 0 | L16: 0 | M16: 0 | N16: 0 | O16: 0 | P16: =IF(ISNUMBER(AVERAGEIF(Historis_Gaji[[#This Row],[1]:[12]],">0")),AVERAGEIF(Historis_Gaji[[#This Row],[1]:[12]],">0"),0) -> 0 | Q16: =Historis_Gaji[[#This Row],[12]] -> 0 | R16: 1900000
A17: 8 | B17: Pegawai 8 | C17: =INDEX(Data_Pegawai[Jabatan],MATCH(Historis_Gaji[[#This Row],[Nama]],Data_Pegawai[Nama],0)) -> ADM Pembiayaan | D17: 1750000 | E17: 1750000 | F17: 1750000 | G17: 1750000 | H17: 1750000 | I17: 1750000 | J17: 1750000 | K17: 1750000 | L17: 1750000 | M17: 1750000 | N17: 1750000 | O17: 1750000 | P17: =IF(ISNUMBER(AVERAGEIF(Historis_Gaji[[#This Row],[1]:[12]],">0")),AVERAGEIF(Historis_Gaji[[#This Row],[1]:[12]],">0"),0) -> 1750000 | Q17: =Historis_Gaji[[#This Row],[12]] -> 1750000 | R17: 1750000
A18: 9 | B18: Pegawai 9 | C18: =INDEX(Data_Pegawai[Jabatan],MATCH(Historis_Gaji[[#This Row],[Nama]],Data_Pegawai[Nama],0)) -> Teller | D18: 1200000 | E18: 1200000 | F18: 1200000 | G18: 1200000 | H18: 1200000 | I18: 1200000 | J18: 1200000 | K18: 1200000 | L18: 1200000 | M18: 1200000 | N18: 1200000 | O18: 1200000 | P18: =IF(ISNUMBER(AVERAGEIF(Historis_Gaji[[#This Row],[1]:[12]],">0")),AVERAGEIF(Historis_Gaji[[#This Row],[1]:[12]],">0"),0) -> 1200000 | Q18: =Historis_Gaji[[#This Row],[12]] -> 1200000 | R18: 1200000
A19: 10 | B19: Pegawai 10 | C19: =INDEX(Data_Pegawai[Jabatan],MATCH(Historis_Gaji[[#This Row],[Nama]],Data_Pegawai[Nama],0)) -> A/O Loan | D19: 0 | E19: 0 | F19: 0 | G19: 0 | H19: 0 | I19: 0 | J19: 0 | K19: 0 | L19: 0 | M19: 0 | N19: 0 | O19: 0 | P19: =IF(ISNUMBER(AVERAGEIF(Historis_Gaji[[#This Row],[1]:[12]],">0")),AVERAGEIF(Historis_Gaji[[#This Row],[1]:[12]],">0"),0) -> 0 | Q19: =Historis_Gaji[[#This Row],[12]] -> 0 | R19: 1200000
A20: 11 | B20: Pegawai 11 | C20: =INDEX(Data_Pegawai[Jabatan],MATCH(Historis_Gaji[[#This Row],[Nama]],Data_Pegawai[Nama],0)) -> ADM Pembiayaan | D20: 1200000 | E20: 1200000 | F20: 1200000 | G20: 0 | H20: 0 | I20: 0 | J20: 0 | K20: 0 | L20: 0 | M20: 0 | N20: 0 | O20: 0 | P20: =IF(ISNUMBER(AVERAGEIF(Historis_Gaji[[#This Row],[1]:[12]],">0")),AVERAGEIF(Historis_Gaji[[#This Row],[1]:[12]],">0"),0) -> 1200000 | Q20: =Historis_Gaji[[#This Row],[12]] -> 0 | R20: 1200000
A21: 12 | B21: Pegawai 12 | C21: =INDEX(Data_Pegawai[Jabatan],MATCH(Historis_Gaji[[#This Row],[Nama]],Data_Pegawai[Nama],0)) -> Bag.Umum | D21: 1000000 | E21: 1000000 | F21: 1000000 | G21: 1000000 | H21: 1000000 | I21: 1000000 | J21: 1000000 | K21: 1000000 | L21: 1000000 | M21: 1000000 | N21: 1200000 | O21: 1200000 | P21: =IF(ISNUMBER(AVERAGEIF(Historis_Gaji[[#This Row],[1]:[12]],">0")),AVERAGEIF(Historis_Gaji[[#This Row],[1]:[12]],">0"),0) -> 1033333.3 | Q21: =Historis_Gaji[[#This Row],[12]] -> 1200000 | R21: 1000000
A22: 13 | B22: Pegawai 13 | C22: =INDEX(Data_Pegawai[Jabatan],MATCH(Historis_Gaji[[#This Row],[Nama]],Data_Pegawai[Nama],0)) -> Satpam | D22: 1000000 | E22: 1000000 | F22: 1000000 | G22: 1000000 | H22: 1000000 | I22: 1000000 | J22: 1000000 | K22: 1000000 | L22: 1000000 | M22: 1000000 | N22: 1200000 | O22: 1200000 | P22: =IF(ISNUMBER(AVERAGEIF(Historis_Gaji[[#This Row],[1]:[12]],">0")),AVERAGEIF(Historis_Gaji[[#This Row],[1]:[12]],">0"),0) -> 1033333.3 | Q22: =Historis_Gaji[[#This Row],[12]] -> 1200000 | R22: 1000000
A23: 14 | C23: =INDEX(Data_Pegawai[Jabatan],MATCH(Historis_Gaji[[#This Row],[Nama]],Data_Pegawai[Nama],0)) -> #N/A | P23: =IF(ISNUMBER(AVERAGEIF(Historis_Gaji[[#This Row],[1]:[12]],">0")),AVERAGEIF(Historis_Gaji[[#This Row],[1]:[12]],">0"),0) -> 0 | Q23: =Historis_Gaji[[#This Row],[12]] -> 0
A24: 15 | C24: =INDEX(Data_Pegawai[Jabatan],MATCH(Historis_Gaji[[#This Row],[Nama]],Data_Pegawai[Nama],0)) -> #N/A | P24: =IF(ISNUMBER(AVERAGEIF(Historis_Gaji[[#This Row],[1]:[12]],">0")),AVERAGEIF(Historis_Gaji[[#This Row],[1]:[12]],">0"),0) -> 0 | Q24: =Historis_Gaji[[#This Row],[12]] -> 0
A25: 16 | C25: =INDEX(Data_Pegawai[Jabatan],MATCH(Historis_Gaji[[#This Row],[Nama]],Data_Pegawai[Nama],0)) -> #N/A | P25: =IF(ISNUMBER(AVERAGEIF(Historis_Gaji[[#This Row],[1]:[12]],">0")),AVERAGEIF(Historis_Gaji[[#This Row],[1]:[12]],">0"),0) -> 0 | Q25: =Historis_Gaji[[#This Row],[12]] -> 0
A26: 17 | C26: =INDEX(Data_Pegawai[Jabatan],MATCH(Historis_Gaji[[#This Row],[Nama]],Data_Pegawai[Nama],0)) -> #N/A | P26: =IF(ISNUMBER(AVERAGEIF(Historis_Gaji[[#This Row],[1]:[12]],">0")),AVERAGEIF(Historis_Gaji[[#This Row],[1]:[12]],">0"),0) -> 0 | Q26: =Historis_Gaji[[#This Row],[12]] -> 0
A27: 18 | C27: =INDEX(Data_Pegawai[Jabatan],MATCH(Historis_Gaji[[#This Row],[Nama]],Data_Pegawai[Nama],0)) -> #N/A | P27: =IF(ISNUMBER(AVERAGEIF(Historis_Gaji[[#This Row],[1]:[12]],">0")),AVERAGEIF(Historis_Gaji[[#This Row],[1]:[12]],">0"),0) -> 0 | Q27: =Historis_Gaji[[#This Row],[12]] -> 0
A28: 19 | C28: =INDEX(Data_Pegawai[Jabatan],MATCH(Historis_Gaji[[#This Row],[Nama]],Data_Pegawai[Nama],0)) -> #N/A | P28: =IF(ISNUMBER(AVERAGEIF(Historis_Gaji[[#This Row],[1]:[12]],">0")),AVERAGEIF(Historis_Gaji[[#This Row],[1]:[12]],">0"),0) -> 0 | Q28: =Historis_Gaji[[#This Row],[12]] -> 0
A29: 20 | C29: =INDEX(Data_Pegawai[Jabatan],MATCH(Historis_Gaji[[#This Row],[Nama]],Data_Pegawai[Nama],0)) -> #N/A | P29: =IF(ISNUMBER(AVERAGEIF(Historis_Gaji[[#This Row],[1]:[12]],">0")),AVERAGEIF(Historis_Gaji[[#This Row],[1]:[12]],">0"),0) -> 0 | Q29: =Historis_Gaji[[#This Row],[12]] -> 0
A30: Total | B30: =SUBTOTAL(103,Historis_Gaji[Nama]) -> 13 | D30: =SUBTOTAL(109,Historis_Gaji[1]) -> 14950000 | E30: =SUBTOTAL(109,Historis_Gaji[2]) -> 14950000 | F30: =SUBTOTAL(109,Historis_Gaji[3]) -> 14950000 | G30: =SUBTOTAL(109,Historis_Gaji[4]) -> 13750000 | H30: =SUBTOTAL(109,Historis_Gaji[5]) -> 13750000 | I30: =SUBTOTAL(109,Historis_Gaji[6]) -> 14488100 | J30: =SUBTOTAL(109,Historis_Gaji[7]) -> 16250000 | K30: =SUBTOTAL(109,Historis_Gaji[8]) -> 16250000 | L30: =SUBTOTAL(109,Historis_Gaji[9]) -> 16250000 | M30: =SUBTOTAL(109,Historis_Gaji[10]) -> 16250000 | N30: =SUBTOTAL(109,Historis_Gaji[11]) -> 16650000 | O30: =SUBTOTAL(109,Historis_Gaji[12]) -> 16650000 | R30: =SUBTOTAL(109,Historis_Gaji[Angka yang Digunakan]) -> 22550000
A32: Keterangan:
B33: Terdapat perubahan historis gaji dari bulan sebelumnya

Sheet 3. Historis Tunjangan 1
A2: KERTAS KERJA
A3: ANALISA PEMBERIAN PESANGON PEGAWAI
A4: =UPPER('1. Perhitungan Pesangon'!$C$7) -> PT BPRS HAREUKAT (DL)
A5: ="Historis "&C7 -> Historis Tunjangan Jabatan
A7: Jenis Tunjangan | C7: Tunjangan Jabatan
D9: Historis Tunjangan
