Workbook

Sheet 1.2 Usulan Anggaran Biaya
M1: Lampiran 1.2
M2: Nota Dinas No. ND- /GLIK
M3: tanggal Maret 2021
A4: Rincian Usulan Anggaran Biaya
A5: Koperasi BPR Abang Pasar (DL)
A7: No. | B7: Kegiatan | C7: 44228 | D7: 44256 | E7: 44228 | F7: 44256 | G7: 44287 | H7: 44317 | I7: 44348 | J7: 44378 | K7: 44409 | L7: 44440 | M7: 44470 | N7: 44501 | O7: Jumlah
A8: A. | B8: BIAYA PENDUKUNG LIKUIDASI | C8: =SUM(C9:C13) -> 26541067 | D8: =SUM(D9:D13) -> 26541067 | E8: =SUM(E9:E13) -> 0 | F8: =SUM(F9:F13) -> 53082133 | G8: =SUM(G9:G13) -> 26541067 | H8: =SUM(H9:H13) -> 26541067 | I8: =SUM(I9:I13) -> 26541067 | J8: =SUM(J9:J13) -> 26541067 | ... O8: =SUM(O9:O13) -> 1.8578747e+08
A9: 1 | B9: Pembayaran honor Tim Likuidasi. | C9: =$O9/7 -> 17254135 | D9: =$O9/7 -> 17254135 | E9: 0 | F9: =C9+D9 -> 34508270 | G9: =$O9/7 -> 17254135 | H9: =$O9/7 -> 17254135 | I9: =$O9/7 -> 17254135 | J9: =$O9/7 -> 17254135 | K9: =$O9/7 -> 17254135 | L9: 0 | M9: 0 | N9: 0 | O9: 120778944
A10: 2 | B10: Pembayaran honor tenaga pendukung TL. | C10: =$O10/7 -> 3056797.7 | D10: =$O10/7 -> 3056797.7 | E10: 0 | F10: =C10+D10 -> 6113595.4 | G10: =$O10/7 -> 3056797.7 | H10: =$O10/7 -> 3056797.7 | I10: =$O10/7 -> 3056797.7 | J10: =$O10/7 -> 3056797.7 | K10: =$O10/7 -> 3056797.7 | L10: 0 | M10: 0 | N10: 0 | O10: 21397584
A11: 3 | B11: Pembayaran THR - Tim Likuidasi. - Tenaga Pendukung. | C11: =$O11/7 -> 806190.48 | D11: =$O11/7 -> 806190.48 | E11: 0 | F11: =C11+D11 -> 1612381 | G11: =$O11/7 -> 806190.48 | H11: =$O11/7 -> 806190.48 | I11: =$O11/7 -> 806190.48 | J11: =$O11/7 -> 806190.48 | K11: =$O11/7 -> 806190.48 | L11: 0 | M11: 0 | N11: 0 | O11: 5643333.3
A12: 4 | B12: Biaya kantor dan operasional lainnya - Biaya utilitas (listrik, air, telepon). - Biaya ATK. - Biaya lainnya. | C12: =$O12/7 -> 3704200 | D12: =$O12/7 -> 3704200 | E12: 0 | F12: =C12+D12 -> 7408400 | G12: =$O12/7 -> 3704200 | H12: =$O12/7 -> 3704200 | I12: =$O12/7 -> 3704200 | J12: =$O12/7 -> 3704200 | K12: =$O12/7 -> 3704200 | L12: 0 | M12: 0 | N12: 0 | O12: 25929400
A13: 5 | B13: Insentif pencairan aset dan penagihan piutang. | C13: =$O13/7 -> 1719743.5 | D13: =$O13/7 -> 1719743.5 | E13: 0 | F13: =C13+D13 -> 3439486.9 | G13: =$O13/7 -> 1719743.5 | H13: =$O13/7 -> 1719743.5 | I13: =$O13/7 -> 1719743.5 | J13: =$O13/7 -> 1719743.5 | K13: =$O13/7 -> 1719743.5 | L13: 0 | M13: 0 | N13: 0 | O13: 12038204
A14: B. | B14: BIAYA KEGIATAN LIKUIDASI | C14: =SUM(C15:C27) -> 33681532 | D14: =SUM(D15:D27) -> 80837532 | E14: =SUM(E15:E27) -> 0 | F14: =SUM(F15:F27) -> 1.1451906e+08 | G14: =SUM(G15:G27) -> 78474032 | H14: =SUM(H15:H27) -> 1.2255759e+08 | I14: =SUM(I15:I27) -> 36388679 | J14: =SUM(J15:J27) -> 9723428.6 | ... O14: =SUM(O15:O27) -> 4.5024476e+08
A15: 1 | B15: Menyampaikan RKAB dan Laporan Bulanan. | C15: =O15 -> 1242000 | D15: 0 | E15: 0 | F15: =C15+D15 -> 1242000 | G15: 0 | H15: 0 | I15: 0 | J15: 0 | K15: 0 | L15: 0 | M15: 0 | N15: 0 | O15: 1242000
A16: 2 | B16: Menindaklanjuti aspek legal pembubaran badan hukum bank. | C16: =$O16/2 -> 3363500 | D16: =$O16/2 -> 3363500 | E16: 0 | F16: =C16+D16 -> 6727000 | G16: 0 | H16: 0 | I16: 0 | J16: 0 | K16: 0 | L16: 0 | M16: 0 | N16: 0 | O16: 6727000
A17: 3 | B17: Menyelesaikan kewajiban kepada pegawai dan mengangkat tenaga pendukung. | C17: 19352603 | D17: 19352603 | E17: 0 | F17: =C17+D17 -> 38705206 | G17: 19352603 | H17: 86168909 | I17: 0 | J17: 0 | K17: 0 | L17: 0 | M17: 0 | N17: 0 | O17: 144226718
A18: 4 | B18: Menyampaikan Neraca Penutupan yang telah diaudit KAP kepada LPS. | C18: 0 | D18: =$O18/2 -> 48398000 | E18: 0 | F18: =C18+D18 -> 48398000 | G18: =$O18/2 -> 48398000 | H18: 0 | I18: 0 | J18: 0 | K18: 0 | L18: 0 | M18: 0 | N18: 0 | O18: 96796000
A19: 5 | B19: Melakukan inventarisasi aset dan kewajiban. | C19: =$O19/7 -> 100000 | D19: =$O19/7 -> 100000 | E19: 0 | F19: =C19+D19 -> 200000 | G19: =$O19/7 -> 100000 | H19: =$O19/7 -> 100000 | I19: =$O19/7 -> 100000 | J19: =$O19/7 -> 100000 | K19: =$O19/7 -> 100000 | L19: 0 | M19: 0 | N19: 0 | O19: 700000
A20: 6 | B20: Melakukan penyelesaian kewajiban pihak-pihak yang melakukan kelalaian dan atau perbuatan melanggar hukum yang mengakibatkan kerugian atau membahayakan kelangsungan usaha bank. | C20: 0 | D20: 0 | E20: 0 | F20: =C20+D20 -> 0 | G20: 0 | H20: 0 | I20: 0 | J20: 0 | K20: 0 | L20: 0 | M20: 0 | N20: 0 | O20: 0
A21: 7 | B21: Menyampaikan Laporan Perubahan Aset Neto Awal Periode (LANAP) untuk mendapat persetujuan LPS. | C21: 0 | D21: 0 | E21: 0 | F21: =C21+D21 -> 0 | G21: 0 | H21: =$O21/2 -> 25665250 | I21: =$O21/2 -> 25665250 | J21: 0 | K21: 0 | L21: 0 | M21: 0 | N21: 0 | O21: 51330500
A22: 8 | B22: Melakukan pencairan aset. | C22: 0 | D22: 0 | E22: 0 | F22: =C22+D22 -> 0 | G22: =$O22/3 -> 1000000 | H22: =$O22/3 -> 1000000 | I22: =$O22/3 -> 1000000 | J22: 0 | K22: 0 | L22: 0 | M22: 0 | N22: 0 | O22: 3000000
A23: 9 | B23: Melakukan penagihan piutang. | C23: =$O23/7 -> 8752428.6 | D23: =$O23/7 -> 8752428.6 | E23: 0 | F23: =C23+D23 -> 17504857 | G23: =$O23/7 -> 8752428.6 | H23: =$O23/7 -> 8752428.6 | I23: =$O23/7 -> 8752428.6 | J23: =$O23/7 -> 8752428.6 | K23: =$O23/7 -> 8752428.6 | L23: 0 | M23: 0 | N23: 0 | O23: 61267000
A24: 10 | B24: Menyampaikan Laporan Perubahan Aset Neto Selama Periode untuk mendapat persetujuan LPS. | C24: 0 | D24: 0 | E24: 0 | F24: =C24+D24 -> 0 | G24: 0 | H24: 0 | I24: 0 | J24: 0 | K24: 0 | L24: 0 | M24: 0 | N24: 0 | O24: 0
A25: 11 | B25: Melakukan pembayaran kewajiban sesuai ketentuan. | C25: =$O25/7 -> 871000 | D25: =$O25/7 -> 871000 | E25: 0 | F25: =C25+D25 -> 1742000 | G25: =$O25/7 -> 871000 | H25: =$O25/7 -> 871000 | I25: =$O25/7 -> 871000 | J25: =$O25/7 -> 871000 | K25: =$O25/7 -> 871000 | L25: 0 | M25: 0 | N25: 0 | O25: 6097000
A26: 12 | B26: Mempertanggungjawabkan pelaksanaan likuidasi. | C26: 0 | D26: 0 | E26: 0 | F26: =C26+D26 -> 0 | G26: 0 | H26: 0 | I26: 0 | J26: 0 | K26: =O26 -> 117000 | L26: 0 | M26: 0 | N26: 0 | O26: 117000
A27: 13 | B27: Menindaklanjuti pengakhiran proses likuidasi. | E27: 0 | F27: =C27+D27 -> 0 | K27: 8630500 | L27: =70111039/3 -> 23370346 | M27: =70111039/3 -> 23370346 | N27: =70111039/3 -> 23370346 | O27: 78741539
A28: Jumlah (A+B) | C28: =C8+C14 -> 60222598 | D28: =D8+D14 -> 1.073786e+08 | E28: =E8+E14 -> 0 | F28: =F8+F14 -> 1.676012e+08 | G28: =G8+G14 -> 1.050151e+08 | H28: =H8+H14 -> 1.4909865e+08 | I28: =I8+I14 -> 62929745 | J28: =J8+J14 -> 36264495 | ... O28: =O8+O14 -> 6.3603222e+08
A30: *Anggaran biaya untuk bulan Februari 2021 direklas ke dalam anggaran biaya bulan Maret 2021 karena pencatatan pengeluaran oleh TL belum dilakukan

Sheet 1.3 Rincian ATI
N1: Lampiran 1.3
N2: Nota Dinas No. ND- /GLIK
N3: tanggal Maret 2021
A4: Rincian Potensi Pencairan Aset KBPR Abang Pasar (DL)
A5: Aset Tetap dan Inventaris
A7: No. | B7: Aset | C7: Kondisi | D7: Survey 1 | E7: Survey 2 | F7: Rata-Rata | G7: 44228 | H7: 44256 | I7: 44287 | J7: 44317 | K7: 44348 | L7: 44378 | M7: 44409 | N7: 44440 | O7: 44470 | P7: 44501
A8: 1 | B8: Kursi Putar Ergosit Putar | C8: Baik | D8: 50000 | E8: 50000 | F8: =AVERAGE(D8:E8) -> 50000 | M8: =F8 -> 50000
A9: 2 | B9: Kursi Putar Ergosit Putar | C9: Baik | D9: 50000 | E9: 50000 | F9: =AVERAGE(D9:E9) -> 50000 | M9: =F9 -> 50000
A10: 3 | B10: Kursi Putar Ergosit Putar | C10: Baik | D10: 50000 | E10: 50000 | F10: =AVERAGE(D10:E10) -> 50000 | M10: =F10 -> 50000
A11: 4 | B11: Kursi Putar Ergosit Putar | C11: Baik | D11: 50000 | E11: 50000 | F11: =AVERAGE(D11:E11) -> 50000 | M11: =F11 -> 50000
A12: 5 | B12: Kursi Putar Ergosit Putar | C12: Baik | D12: 50000 | E12: 50000 | F12: =AVERAGE(D12:E12) -> 50000 | M12: =F12 -> 50000
A13: 6 | B13: Kursi Putar Ergosit Putar | C13: Rusak | D13: 10000 | E13: 10000 | F13: =AVERAGE(D13:E13) -> 10000 | M13: =F13 -> 10000
A14: 7 | B14: Kursi Putar Ergosit Putar | C14: - | D14: 0 | E14: 0 | F14: =AVERAGE(D14:E14) -> 0 | M14: =F14 -> 0
A15: 8 | B15: Kursi Putar Ergosit Putar | C15: - | D15: 0 | E15: 0 | F15: =AVERAGE(D15:E15) -> 0 | M15: =F15 -> 0
A16: 9 | B16: Kursi Rapat | C16: - | D16: 0 | E16: 0 | F16: =AVERAGE(D16:E16) -> 0 | M16: =F16 -> 0
A17: 10 | B17: Kursi Rapat | C17: - | D17: 0 | E17: 0 | F17: =AVERAGE(D17:E17) -> 0 | M17: =F17 -> 0
A18: 11 | B18: Kursi Rapat | C18: - | D18: 0 | E18: 0 | F18: =AVERAGE(D18:E18) -> 0 | M18: =F18 -> 0
A19: 12 | B19: Kursi ruang tunggu | C19: Baik | D19: 100000 | E19: 100000 | F19: =AVERAGE(D19:E19) -> 100000 | M19: =F19 -> 100000
... A78: 71 | B78: Printer EPSON L210 | C78: Baik | D78: 150000 | E78: 0 | F78: =AVERAGE(D78:E78) -> 75000 | M78: =F78 -> 75000
B79: Total | D79: =SUM(D8:D78) -> 6200000 | E79: =SUM(E8:E78) -> 5605000 | F79: =SUM(F8:F78) -> 5902500 | G79: =SUM(G8:G78) -> 0 | H79: =SUM(H8:H78) -> 0 | I79: =SUM(I8:I78) -> 0 | J79: =SUM(J8:J78) -> 0 | K79: =SUM(K8:K78) -> 0 | ... P79: =SUM(P8:P78) -> 0

Sheet 1.4 Rincian HB
L1: Lampiran 1.4
L2: Nota Dinas No. ND- /GLIK
L3: tanggal Maret 2021
A4: Rincian Potensi Pencairan Aset KBPR Abang Pasar (DL)
A5: Kredit Hapus Buku
A7: No. | B7: Rek | C7: Nama | D7: Baki Debet | E7: Agunan | F7: Pengikatan | G7: 44228 | H7: 44256 | I7: 44287 | J7: 44317 | K7: 44348 | L7: 44378 | M7: 44409 | N7: Total
A8: 1 | B8: 0011010000009 | C8: Hapus Buku BPR | D8: 65941000 | E8: - | F8: - | N8: =SUM(G8:M8) -> 0
A9: 2 | B9: 0011010000010 | C9: Abd. Rasyid .Y | D9: 1400000 | E9: BPKB | F9: Tanpa Pengikatan | N9: =SUM(G9:M9) -> 0
A10: 3 | B10: 0011010000011 | C10: Suwarni Bambang | D10: 2500000 | E10: BPKB | F10: Tanpa Pengikatan | N10: =SUM(G10:M10) -> 0
A11: 4 | B11: 0011010000012 | C11: Andi Raisal Nur,SE | D11: 981328 | E11: - | F11: - | N11: =SUM(G11:M11) -> 0
A12: 5 | B12: 0011010000013 | C12: Nia Dg Puji | D12: 610800 | E12: - | F12: - | N12: =SUM(G12:M12) -> 0
A13: 6 | B13: 0011010000014 | C13: Murniati | D13: 143760 | E13: - | F13: - | N13: =SUM(G13:M13) -> 0
A14: 7 | B14: 0011010000015 | C14: Dewi Ratna Sari Pajar | D14: 900000 | E14: - | F14: - | N14: =SUM(G14:M14) -> 0
A15: 8 | B15: 0011010000016 | C15: Amiruddin Bilu | D15: 2717002 | E15: BPKB | F15: Tanpa Pengikatan | N15: =SUM(G15:M15) -> 0
A16: 9 | B16: 0011010000017 | C16: Hj. Martia Dg Sannang | D16: 2540166 | E16: - | F16: - | N16: =SUM(G16:M16) -> 0
A17: 10 | B17: 0011010000018 | C17: Arwin Roby | D17: 3750000 | E17: BPKB | F17: Tanpa Pengikatan | N17: =SUM(G17:M17) -> 0
A18: 11 | B18: 0011010000019 | C18: Bachtiar | D18: 8888880 | E18: SHM | F18: Tanpa Pengikatan | N18: =SUM(G18:M18) -> 0
A19: 12 | B19: 0011010000020 | C19: Herawati | D19: 3500000 | E19: BPKB | F19: Tanpa Pengikatan | N19: =SUM(G19:M19) -> 0
... A83: 76 | B83: 0011030000004 | C83: Zulkarnain, S.Sos | D83: 7333333 | E83: - | F83: - | N83: =SUM(G83:M83) -> 0
A84: 77 | B84: 0011030000012 | C84: Fitriani Farid | D84: 4883113 | E84: Non Aset | F84: Tanpa Pengikatan | G84: 1000000 | N84: =SUM(G84:M84) -> 1000000
A85: 78 | B85: 0011010000002 | C85: Hj. Nurbaya Dg. Pajja | D85: 12158143 | E85: Non Aset | F85: Tanpa Pengikatan | N85: =SUM(G85:M85) -> 0
A86: 79 | B86: 0011030000007 | C86: Irsan Syahrir | D86: 5081562 | E86: Tanpa Agunan | F86: Tanpa Agunan | N86: =SUM(G86:M86) -> 0
A87: 80 | B87: 0011030000013 | C87: M. Dirham. R | D87: 5809594 | E87: Non Aset | F87: Tanpa Pengikatan | N87: =SUM(G87:M87) -> 0
A88: 81 | B88: 0011030000021 | C88: Andi Wasop Hasir. HS | D88: 3811863 | E88: Non Aset | F88: Tanpa Pengikatan | N88: =SUM(G88:M88) -> 0
A89: 82 | B89: 0011030000024 | C89: Novi Yuliarti | D89: 3296082 | E89: Tanpa Agunan | F89: Tanpa Agunan | N89: =SUM(G89:M89) -> 0
A90: 83 | B90: 0011030000076 | C90: Hasniaty Kasim | D90: 1999993 | E90: Tanpa Agunan | F90: Tanpa Agunan | N90: =SUM(G90:M90) -> 0
A91: 84 | B91: 0011030000104 | C91: Pangerang S | D91: 8603076 | E91: BPKB | F91: Surat Kuasa Menjual | N91: =SUM(G91:M91) -> 0
A92: 85 | B92: 0011030000130 | C92: Rudiansyah ST | D92: 4014353 | E92: BPKB | F92: Surat Kuasa Menjual | N92: =SUM(G92:M92) -> 0
A93: 86 | B93: 0011030000136 | C93: A Ardiansyah | D93: 10689069 | E93: BPKB | F93: Surat Kuasa Menjual | N93: =SUM(G93:M93) -> 0
A94: 87 | B94: 0011030000169 | C94: Andi Besse Hafira | D94: 35261405 | E94: BPKB | F94: Surat Kuasa Menjual | N94: =SUM(G94:M94) -> 0
A95: 88 | B95: 0011030000188 | C95: AL Ma Ruf | D95: 10330484 | E95: BPKB | F95: Surat Kuasa Menjual | N95: =SUM(G95:M95) -> 0
A96: 89 | B96: 0011030000192 | C96: Lucky Bong | D96: 27903972 | E96: BPKB | F96: Surat Kuasa Menjual | N96: =SUM(G96:M96) -> 0
... A98: 91 | B98: 0011030000226 | C98: Mansur | D98: 11246189 | E98: BPKB | F98: Surat Kuasa Menjual | N98: =SUM(G98:M98) -> 0
A99: 92 | B99: 0011030000057 | C99: Baruli Purba | D99: 7917962 | E99: BPKB | F99: Sertifikat Jaminan Fidusia | M99: 7917962 | N99: =SUM(G99:M99) -> 7917962
A100: 93 | B100: 0011030000125 | C100: Musliadi | D100: 3644201 | E100: BPKB | F100: Surat Kuasa Menjual | N100: =SUM(G100:M100) -> 0
A101: 94 | B101: 0011030000133 | C101: Musrifah | D101: 37389590 | E101: BPKB | F101: Surat Kuasa Menjual | N101: =SUM(G101:M101) -> 0
A102: 95 | B102: 0011030000142 | C102: La Mpaga | D102: 10402117 | E102: BPKB | F102: Surat Kuasa Menjual | N102: =SUM(G102:M102) -> 0
A103: 96 | B103: 0011030000155 | C103: Ambo Enre | D103: 17327999 | E103: BPKB | F103: Surat Kuasa Menjual | N103: =SUM(G103:M103) -> 0
A104: 97 | B104: 0011030000222 | C104: Andi M Akbar Jamalauddin | D104: 36440448 | E104: SHM | F104: Tanpa Pengikatan | N104: =SUM(G104:M104) -> 0
A105: 98 | B105: 0011010000006 | C105: Aldonna (2) | D105: 39112813 | E105: BPKB | F105: Akta Fidusia | N105: =SUM(G105:M105) -> 0
...

Sheet 1.5 Kebutuhan Biaya
K1: Lampiran 1.5
K2: Nota Dinas No. ND- /GLIK
K3: tanggal Maret 2021
A4: PROYEKSI PENERIMAAN DAN PENGELUARAN
A5: KOPERASI BPR ABANG PASAR (DL)
A7: No. | B7: Kegiatan | C7: Periode | M7: Jumlah
C8: 44228 | D8: 44256 | E8: 44287 | F8: 44317 | G8: 44348 | H8: 44378 | I8: 44409 | J8: 44440 | K8: 44470 | L8: 44501 | M8: (Rp)
A9: A. | B9: Saldo Kas dan Giro
B10: Kas Tunai per 11 Februri 2021 | C10: 2391800 | D10: 0 | E10: 0 | F10: 0 | G10: 0 | H10: 0 | I10: 0 | J10: 0 | K10: 0 | L10: 0 | M10: =SUM(C10:L10) -> 2391800
B11: Giro BRI per 11 Februari 2021 (yg diblokir) | C11: 0 | D11: 0 | E11: 110456216 | F11: 0 | G11: 0 | H11: 0 | I11: 0 | J11: 0 | K11: 0 | L11: 0 | M11: =SUM(C11:L11) -> 110456216
B12: Jumlah kas dan Tabungan | C12: =SUM(C10:C11) -> 2391800 | D12: =SUM(D10:D11) -> 0 | E12: =SUM(E10:E11) -> 110456216 | G12: =SUM(G10:G11) -> 0 | H12: =SUM(H10:H11) -> 0 | I12: =SUM(I10:I11) -> 0 | J12: =SUM(J10:J11) -> 0 | K12: =SUM(K10:K11) -> 0 | L12: =SUM(L10:L11) -> 0 | M12: =SUM(C12:L12) -> 112848016
M13: =SUM(C13:L13) -> 0
A14: B. | B14: Perkiraan Penerimaan | M14: =SUM(C14:L14) -> 0
B15: 1. Pencairan piutang hapus buku | C15: ='1.4 Rincian HB'!G128 -> 1000000 | D15: ='1.4 Rincian HB'!H128 -> 0 | E15: ='1.4 Rincian HB'!I128 -> 0 | F15: ='1.4 Rincian HB'!J128 -> 0 | G15: ='1.4 Rincian HB'!K128 -> 0 | H15: ='1.4 Rincian HB'!L128 -> 0 | I15: ='1.4 Rincian HB'!M128 -> 82441626 | J15: 0 | K15: 0 | L15: 0 | M15: =SUM(C15:L15) -> 83441626
B16: 2. Penjualan Inventaris | C16: ='1.3 Rincian ATI'!G79 -> 0 | D16: ='1.3 Rincian ATI'!H79 -> 0 | E16: ='1.3 Rincian ATI'!I79 -> 0 | F16: ='1.3 Rincian ATI'!J79 -> 0 | G16: ='1.3 Rincian ATI'!K79 -> 0 | H16: ='1.3 Rincian ATI'!L79 -> 0 | I16: ='1.3 Rincian ATI'!M79 -> 5902500 | J16: ='1.3 Rincian ATI'!N79 -> 0 | ... L16: ='1.3 Rincian ATI'!P79 -> 0 | M16: =SUM(C16:L16) -> 5902500
B17: Total Penerimaan | C17: =SUM(C15:C16) -> 1000000 | D17: =SUM(D15:D16) -> 0 | E17: =SUM(E15:E16) -> 0 | F17: =SUM(F15:F16) -> 0 | G17: =SUM(G15:G16) -> 0 | H17: =SUM(H15:H16) -> 0 | I17: =SUM(I15:I16) -> 88344126 | J17: =SUM(J15:J16) -> 0 | ... L17: =SUM(L15:L16) -> 0 | M17: =SUM(C17:L17) -> 89344126
M18: =SUM(C18:L18) -> 0
A19: C. | B19: Biaya Pendukung Likuidasi | M19: =SUM(C19:L19) -> 0
A20: 1. | B20: Pembayaran honor Tim Likuidasi. | C20: ='1.2 Usulan Anggaran Biaya'!E9 -> 0 | D20: ='1.2 Usulan Anggaran Biaya'!F9 -> 34508270 | E20: ='1.2 Usulan Anggaran Biaya'!G9 -> 17254135 | F20: ='1.2 Usulan Anggaran Biaya'!H9 -> 17254135 | G20: ='1.2 Usulan Anggaran Biaya'!I9 -> 17254135 | H20: ='1.2 Usulan Anggaran Biaya'!J9 -> 17254135 | I20: ='1.2 Usulan Anggaran Biaya'!K9 -> 17254135 | J20: ='1.2 Usulan Anggaran Biaya'!L9 -> 0 | ... L20: ='1.2 Usulan Anggaran Biaya'!N9 -> 0 | M20: =SUM(C20:L20) -> 1.2077894e+08
A21: 2. | B21: Pembayaran honor tenaga pendukung TL. | C21: ='1.2 Usulan Anggaran Biaya'!E10 -> 0 | D21: ='1.2 Usulan Anggaran Biaya'!F10 -> 6113595.4 | E21: ='1.2 Usulan Anggaran Biaya'!G10 -> 3056797.7 | F21: ='1.2 Usulan Anggaran Biaya'!H10 -> 3056797.7 | G21: ='1.2 Usulan Anggaran Biaya'!I10 -> 3056797.7 | H21: ='1.2 Usulan Anggaran Biaya'!J10 -> 3056797.7 | I21: ='1.2 Usulan Anggaran Biaya'!K10 -> 3056797.7 | J21: ='1.2 Usulan Anggaran Biaya'!L10 -> 0 | ... L21: ='1.2 Usulan Anggaran Biaya'!N10 -> 0 | M21: =SUM(C21:L21) -> 21397584
A22: 3. | B22: THR | C22: ='1.2 Usulan Anggaran Biaya'!E11 -> 0 | D22: ='1.2 Usulan Anggaran Biaya'!F11 -> 1612381 | E22: ='1.2 Usulan Anggaran Biaya'!G11 -> 806190.48 | F22: ='1.2 Usulan Anggaran Biaya'!H11 -> 806190.48 | G22: ='1.2 Usulan Anggaran Biaya'!I11 -> 806190.48 | H22: ='1.2 Usulan Anggaran Biaya'!J11 -> 806190.48 | I22: ='1.2 Usulan Anggaran Biaya'!K11 -> 806190.48 | J22: ='1.2 Usulan Anggaran Biaya'!L11 -> 0 | ... L22: ='1.2 Usulan Anggaran Biaya'!N11 -> 0 | M22: =SUM(C22:L22) -> 5643333.3
A23: 4. | B23: Biaya kantor dan operasional lainnya | C23: ='1.2 Usulan Anggaran Biaya'!E12 -> 0 | D23: ='1.2 Usulan Anggaran Biaya'!F12 -> 7408400 | E23: ='1.2 Usulan Anggaran Biaya'!G12 -> 3704200 | F23: ='1.2 Usulan Anggaran Biaya'!H12 -> 3704200 | G23: ='1.2 Usulan Anggaran Biaya'!I12 -> 3704200 | H23: ='1.2 Usulan Anggaran Biaya'!J12 -> 3704200 | I23: ='1.2 Usulan Anggaran Biaya'!K12 -> 3704200 | J23: ='1.2 Usulan Anggaran Biaya'!L12 -> 0 | ... L23: ='1.2 Usulan Anggaran Biaya'!N12 -> 0 | M23: =SUM(C23:L23) -> 25929400
A24: 5. | B24: Insentif pencairan aset dan penagihan piutang. | C24: ='1.2 Usulan Anggaran Biaya'!E13 -> 0 | D24: ='1.2 Usulan Anggaran Biaya'!F13 -> 3439486.9 | E24: ='1.2 Usulan Anggaran Biaya'!G13 -> 1719743.5 | F24: ='1.2 Usulan Anggaran Biaya'!H13 -> 1719743.5 | G24: ='1.2 Usulan Anggaran Biaya'!I13 -> 1719743.5 | H24: ='1.2 Usulan Anggaran Biaya'!J13 -> 1719743.5 | I24: ='1.2 Usulan Anggaran Biaya'!K13 -> 1719743.5 | J24: ='1.2 Usulan Anggaran Biaya'!L13 -> 0 | ... L24: ='1.2 Usulan Anggaran Biaya'!N13 -> 0 | M24: =SUM(C24:L24) -> 12038204
B25: Jumlah Biaya Pendukung Likuidasi | C25: =SUM(C20:C24) -> 0 | D25: =SUM(D20:D24) -> 53082133 | E25: =SUM(E20:E24) -> 26541067 | F25: =SUM(F20:F24) -> 26541067 | G25: =SUM(G20:G24) -> 26541067 | H25: =SUM(H20:H24) -> 26541067 | I25: =SUM(I20:I24) -> 26541067 | J25: =SUM(J20:J24) -> 0 | ... L25: =SUM(L20:L24) -> 0 | M25: =SUM(C25:L25) -> 1.8578747e+08
M26: =SUM(C26:L26) -> 0
A27: D. | B27: Biaya Kegiatan Likuidasi | M27: =SUM(C27:L27) -> 0
A28: 1. | B28: Menyampaikan RKAB | C28: ='1.2 Usulan Anggaran Biaya'!E15 -> 0 | D28: ='1.2 Usulan Anggaran Biaya'!F15 -> 1242000 | E28: ='1.2 Usulan Anggaran Biaya'!G15 -> 0 | F28: ='1.2 Usulan Anggaran Biaya'!H15 -> 0 | G28: ='1.2 Usulan Anggaran Biaya'!I15 -> 0 | H28: ='1.2 Usulan Anggaran Biaya'!J15 -> 0 | I28: ='1.2 Usulan Anggaran Biaya'!K15 -> 0 | J28: ='1.2 Usulan Anggaran Biaya'!L15 -> 0 | ... L28: ='1.2 Usulan Anggaran Biaya'!N15 -> 0 | M28: =SUM(C28:L28) -> 1242000
A29: 2. | B29: Menindaklanjuti aspek legal pembubaran badan hukum bank. | C29: ='1.2 Usulan Anggaran Biaya'!E16 -> 0 | D29: ='1.2 Usulan Anggaran Biaya'!F16 -> 6727000 | E29: ='1.2 Usulan Anggaran Biaya'!G16 -> 0 | F29: ='1.2 Usulan Anggaran Biaya'!H16 -> 0 | G29: ='1.2 Usulan Anggaran Biaya'!I16 -> 0 | H29: ='1.2 Usulan Anggaran Biaya'!J16 -> 0 | I29: ='1.2 Usulan Anggaran Biaya'!K16 -> 0 | J29: ='1.2 Usulan Anggaran Biaya'!L16 -> 0 | ... L29: ='1.2 Usulan Anggaran Biaya'!N16 -> 0 | M29: =SUM(C29:L29) -> 6727000
A30: 3. | B30: Menyelesaikan kewajiban kepada pegawai dan mengangkat tenaga pendukung TL | C30: ='1.2 Usulan Anggaran Biaya'!E17 -> 0 | D30: ='1.2 Usulan Anggaran Biaya'!F17 -> 38705206 | E30: ='1.2 Usulan Anggaran Biaya'!G17 -> 19352603 | F30: ='1.2 Usulan Anggaran Biaya'!H17 -> 86168909 | G30: ='1.2 Usulan Anggaran Biaya'!I17 -> 0 | H30: ='1.2 Usulan Anggaran Biaya'!J17 -> 0 | I30: ='1.2 Usulan Anggaran Biaya'!K17 -> 0 | J30: ='1.2 Usulan Anggaran Biaya'!L17 -> 0 | ... L30: ='1.2 Usulan Anggaran Biaya'!N17 -> 0 | M30: =SUM(C30:L30) -> 144226718
A31: 4. | B31: Menyampaikan Neraca Penutupan yang telah diaudit KAP kepada LPS | C31: ='1.2 Usulan Anggaran Biaya'!E18 -> 0 | D31: ='1.2 Usulan Anggaran Biaya'!F18 -> 48398000 | E31: ='1.2 Usulan Anggaran Biaya'!G18 -> 48398000 | F31: ='1.2 Usulan Anggaran Biaya'!H18 -> 0 | G31: ='1.2 Usulan Anggaran Biaya'!I18 -> 0 | H31: ='1.2 Usulan Anggaran Biaya'!J18 -> 0 | I31: ='1.2 Usulan Anggaran Biaya'!K18 -> 0 | J31: ='1.2 Usulan Anggaran Biaya'!L18 -> 0 | ... L31: ='1.2 Usulan Anggaran Biaya'!N18 -> 0 | M31: =SUM(C31:L31) -> 96796000
A32: 5. | B32: Melakukan inventarisasi aset dan kewajiban. | C32: ='1.2 Usulan Anggaran Biaya'!E19 -> 0 | D32: ='1.2 Usulan Anggaran Biaya'!F19 -> 200000 | E32: ='1.2 Usulan Anggaran Biaya'!G19 -> 100000 | F32: ='1.2 Usulan Anggaran Biaya'!H19 -> 100000 | G32: ='1.2 Usulan Anggaran Biaya'!I19 -> 100000 | H32: ='1.2 Usulan Anggaran Biaya'!J19 -> 100000 | I32: ='1.2 Usulan Anggaran Biaya'!K19 -> 100000 | J32: ='1.2 Usulan Anggaran Biaya'!L19 -> 0 | ... L32: ='1.2 Usulan Anggaran Biaya'!N19 -> 0 | M32: =SUM(C32:L32) -> 700000
A33: 6. | B33: Melakukan penyelesaian kewajiban pihak - pihak yang melakukan | C33: ='1.2 Usulan Anggaran Biaya'!E20 -> 0 | D33: ='1.2 Usulan Anggaran Biaya'!F20 -> 0 | E33: ='1.2 Usulan Anggaran Biaya'!G20 -> 0 | F33: ='1.2 Usulan Anggaran Biaya'!H20 -> 0 | G33: ='1.2 Usulan Anggaran Biaya'!I20 -> 0 | H33: ='1.2 Usulan Anggaran Biaya'!J20 -> 0 | I33: ='1.2 Usulan Anggaran Biaya'!K20 -> 0 | J33: ='1.2 Usulan Anggaran Biaya'!L20 -> 0 | ... L33: ='1.2 Usulan Anggaran Biaya'!N20 -> 0 | M33: =SUM(C33:L33) -> 0
A34: 7. | B34: Menyampaikan Neraca Sementara Likuidasi (NSL) untuk mendapat persetujuan LPS | C34: ='1.2 Usulan Anggaran Biaya'!E21 -> 0 | D34: ='1.2 Usulan Anggaran Biaya'!F21 -> 0 | E34: ='1.2 Usulan Anggaran Biaya'!G21 -> 0 | F34: ='1.2 Usulan Anggaran Biaya'!H21 -> 25665250 | G34: ='1.2 Usulan Anggaran Biaya'!I21 -> 25665250 | H34: ='1.2 Usulan Anggaran Biaya'!J21 -> 0 | I34: ='1.2 Usulan Anggaran Biaya'!K21 -> 0 | J34: ='1.2 Usulan Anggaran Biaya'!L21 -> 0 | ... L34: ='1.2 Usulan Anggaran Biaya'!N21 -> 0 | M34: =SUM(C34:L34) -> 51330500
A35: 8. | B35: ='1.2 Usulan Anggaran Biaya'!B22 -> Melakukan pencairan aset. | C35: ='1.2 Usulan Anggaran Biaya'!E22 -> 0 | D35: ='1.2 Usulan Anggaran Biaya'!F22 -> 0 | E35: ='1.2 Usulan Anggaran Biaya'!G22 -> 1000000 | F35: ='1.2 Usulan Anggaran Biaya'!H22 -> 1000000 | G35: ='1.2 Usulan Anggaran Biaya'!I22 -> 1000000 | H35: ='1.2 Usulan Anggaran Biaya'!J22 -> 0 | I35: ='1.2 Usulan Anggaran Biaya'!K22 -> 0 | J35: ='1.2 Usulan Anggaran Biaya'!L22 -> 0 | ... L35: ='1.2 Usulan Anggaran Biaya'!N22 -> 0 | M35: =SUM(C35:L35) -> 3000000
A36: 9. | B36: ='1.2 Usulan Anggaran Biaya'!B23 -> Melakukan penagihan piutang. | C36: ='1.2 Usulan Anggaran Biaya'!E23 -> 0 | D36: ='1.2 Usulan Anggaran Biaya'!F23 -> 17504857 | E36: ='1.2 Usulan Anggaran Biaya'!G23 -> 8752428.6 | F36: ='1.2 Usulan Anggaran Biaya'!H23 -> 8752428.6 | G36: ='1.2 Usulan Anggaran Biaya'!I23 -> 8752428.6 | H36: ='1.2 Usulan Anggaran Biaya'!J23 -> 8752428.6 | I36: ='1.2 Usulan Anggaran Biaya'!K23 -> 8752428.6 | J36: ='1.2 Usulan Anggaran Biaya'!L23 -> 0 | ... L36: ='1.2 Usulan Anggaran Biaya'!N23 -> 0 | M36: =SUM(C36:L36) -> 61267000
A37: 10. | B37: ='1.2 Usulan Anggaran Biaya'!B24 -> Menyampaikan Laporan Perubahan Aset Neto Selama Periode untuk mendapat persetujuan LPS. | C37: ='1.2 Usulan Anggaran Biaya'!E24 -> 0 | D37: ='1.2 Usulan Anggaran Biaya'!F24 -> 0 | E37: ='1.2 Usulan Anggaran Biaya'!G24 -> 0 | F37: ='1.2 Usulan Anggaran Biaya'!H24 -> 0 | G37: ='1.2 Usulan Anggaran Biaya'!I24 -> 0 | H37: ='1.2 Usulan Anggaran Biaya'!J24 -> 0 | I37: ='1.2 Usulan Anggaran Biaya'!K24 -> 0 | J37: ='1.2 Usulan Anggaran Biaya'!L24 -> 0 | ... L37: ='1.2 Usulan Anggaran Biaya'!N24 -> 0 | M37: =SUM(C37:L37) -> 0
A38: 11. | B38: Melakukan pembayaran kewajiban sesuai ketentuan. | C38: ='1.2 Usulan Anggaran Biaya'!E25 -> 0 | D38: ='1.2 Usulan Anggaran Biaya'!F25 -> 1742000 | E38: ='1.2 Usulan Anggaran Biaya'!G25 -> 871000 | F38: ='1.2 Usulan Anggaran Biaya'!H25 -> 871000 | G38: ='1.2 Usulan Anggaran Biaya'!I25 -> 871000 | H38: ='1.2 Usulan Anggaran Biaya'!J25 -> 871000 | I38: ='1.2 Usulan Anggaran Biaya'!K25 -> 871000 | J38: ='1.2 Usulan Anggaran Biaya'!L25 -> 0 | ... L38: ='1.2 Usulan Anggaran Biaya'!N25 -> 0 | M38: =SUM(C38:L38) -> 6097000
A39: 12. | B39: ='1.2 Usulan Anggaran Biaya'!B26 -> Mempertanggungjawabkan pelaksanaan likuidasi. | C39: ='1.2 Usulan Anggaran Biaya'!E26 -> 0 | D39: ='1.2 Usulan Anggaran Biaya'!F26 -> 0 | E39: ='1.2 Usulan Anggaran Biaya'!G26 -> 0 | F39: ='1.2 Usulan Anggaran Biaya'!H26 -> 0 | G39: ='1.2 Usulan Anggaran Biaya'!I26 -> 0 | H39: ='1.2 Usulan Anggaran Biaya'!J26 -> 0 | I39: ='1.2 Usulan Anggaran Biaya'!K26 -> 117000 | J39: ='1.2 Usulan Anggaran Biaya'!L26 -> 0 | ... L39: ='1.2 Usulan Anggaran Biaya'!N26 -> 0 | M39: =SUM(C39:L39) -> 117000
A40: 13 | B40: ='1.2 Usulan Anggaran Biaya'!B27 -> Menindaklanjuti pengakhiran proses likuidasi. | C40: ='1.2 Usulan Anggaran Biaya'!E27 -> 0 | D40: ='1.2 Usulan Anggaran Biaya'!F27 -> 0 | E40: ='1.2 Usulan Anggaran Biaya'!G27 -> 0 | F40: ='1.2 Usulan Anggaran Biaya'!H27 -> 0 | G40: ='1.2 Usulan Anggaran Biaya'!I27 -> 0 | H40: ='1.2 Usulan Anggaran Biaya'!J27 -> 0 | I40: ='1.2 Usulan Anggaran Biaya'!K27 -> 8630500 | J40: ='1.2 Usulan Anggaran Biaya'!L27 -> 23370346 | ... L40: ='1.2 Usulan Anggaran Biaya'!N27 -> 23370346 | M40: =SUM(C40:L40) -> 78741539
B41: Jumlah Biaya Kegiatan Likuidasi | C41: =SUM(C28:C40) -> 0 | D41: =SUM(D28:D40) -> 1.1451906e+08 | E41: =SUM(E28:E40) -> 78474032 | F41: =SUM(F28:F40) -> 1.2255759e+08 | G41: =SUM(G28:G40) -> 36388679 | H41: =SUM(H28:H40) -> 9723428.6 | I41: =SUM(I28:I40) -> 18470929 | J41: =SUM(J28:J40) -> 23370346 | ... L41: =SUM(L28:L40) -> 23370346 | M41: =SUM(C41:L41) -> 4.5024476e+08
...
