Workbook

Sheet Upaya Debitur
A1: FORM 1
A2: Upaya Tim Likuidasi Terhadap Debitur
A4: Bank | B4: PT BPRS Hareukat (DL) | D4: Wilayah Hukum (Kabupaten/Kota)
A5: Tanggal CIU | B5: 43749 | D5: BDL | E5: Aceh Besar | CB5: Ket: | CC5: Harus dilakukan
A6: Periode | B6: 44196 | D6: TP/TL | CC6: Tidak harus namun telah dilakukan
A7: Bulan Ke | B7: =INDEX(Periode[],MATCH(B6,Periode[Nama Bulan],0),1) -> 15 | CC7: Tidak perlu dilakukan
A8: Waktu Lik. | B8: 15
A9: *jangka waktu likuidasi sesuai PKE (termasuk perpanjangan)
A10: Set Off
A11: *kosongkan bila belum dilakukan (hapus dengan tombol "Delete")
A13: Target Upaya | B13: =SUM(Upaya_Debitur[Target Upaya]) -> 1695
A14: Realisasi | B14: =SUM(Upaya_Debitur[Realisasi]) -> 1695
A15: Pencapaian | B15: =IF(ISNUMBER(B14/B13),B14/B13,1) -> 1
P17: Haircut | R17: Set Off | U17: Pencairan Aset per Bulan (diisi sampai dengan periode berlangsung) | BS17: Target Upaya Berdasarkan Debitur | CB17: Upaya Berdasarkan Debitur | CK17: Kalkulasi Upaya
A18: No | B18: Rekening | C18: Nomor PK | D18: Nama Debitur | E18: Kewajiban Pokok | F18: Kewajiban Bunga | G18: Kewajiban Denda | H18: Kewajiban Total | I18: Angsuran Sesuai PK | J18: Angsuran Diperhitungkan | K18: Wilayah Hukum | L18: Kondisi Debitur | M18: Bukti | N18: Tanggal Kunjungan | O18: Keterangan | P18: Haircut | Q18: Periode Haircut | R18: Set Off | S18: Haircut Diperhitungkan | T18: Set Off Diperhitungkan | U18: 1 | V18: 2 | W18: 3 | X18: 4 | Y18: 5 | Z18: 6 | AA18: 7 | AB18: 8 | AC18: 9 | AD18: 10 | AE18: 11 | AF18: 12 | AG18: 13 | AH18: 14 | AI18: 15 | AJ18: 16 | AK18: 17 | AL18: 18 | AM18: 19 | AN18: 20 | AO18: 21 | AP18: 22 | AQ18: 23 | AR18: 24 | AS18: 25 | AT18: 26 | AU18: 27 | AV18: 28 | AW18: 29 | AX18: 30 | AY18: 31 | AZ18: 32 | BA18: 33 | BB18: 34 | BC18: 35 | BD18: 36 | BE18: 37 | BF18: 38 | BG18: 39 | BH18: 40 | BI18: 41 | BJ18: 42 | BK18: 43 | BL18: 44 | BM18: 45 | BN18: 46 | BO18: 47 | BP18: 48 | BQ18: Total Pencairan | BR18: Lunas? | BS18: Surat Pemberitahuan? | BT18: Update SLIK OJK? | BU18: SP 1? | BV18: SP2? | BW18: SP3? | BX18: Pemanggilan Koran? | BY18: Iklan Cessie 1? | BZ18: Iklan Cessie 2? | CA18: Gugatan Sederhana? | CB18: Surat Pemberitahuan | CC18: Update SLIK OJK | CD18: SP1 | CE18: SP2 | CF18: SP3 | CG18: Pemanggilan Koran | CH18: Iklan Cessie 1 | CI18: Iklan Cessie 2 | CJ18: Gugatan Sederhana | CK18: Target Upaya | CL18: Realisasi | CM18: Pencapaian | CQ18: Bulan Ke | CR18: Nama Bulan | CS18: Durasi | CU18: Kondisi Debitur
A19: 1 | C19: 225/BBA/1452/VI/1994 | D19: A F N A N | E19: 4850000 | F19: 0 | G19: 0 | H19: =SUM(Upaya_Debitur[[#This Row],[Kewajiban Pokok]:[Kewajiban Denda]]) -> 4850000 | J19: =IF(ISNUMBER(Upaya_Debitur[[#This Row],[Angsuran Sesuai PK]]),Upaya_Debitur[[#This Row],[Angsuran Sesuai PK]],1) -> 1 | L19: Tidak ditemukan | S19: =IF(Upaya_Debitur[[#This Row],[Periode Haircut]]="",0,IF(Upaya_Debitur[[#This Row],[Periode Haircut]]<=$B$6,Upaya_Debitur[[#This Row],[Haircut]],0)) -> 0 | T19: =IF($B$10="",0,IF($B$10<=$B$6,Upaya_Debitur[[#This Row],[Set Off]],0)) -> 0 | U19: 0 | V19: 0 | W19: 0 | X19: 0 | Y19: 0 | Z19: 0 | AA19: 0 | AB19: 0 | AC19: 0 | AD19: 0 | AE19: 0 | AF19: 0 | AG19: 0 | AH19: 0 | AI19: 0 | BQ19: =SUM(OFFSET(Upaya_Debitur[[#This Row],[Haircut Diperhitungkan]],0,0,1,$B$7+2)) -> 0 | BR19: =IF(Upaya_Debitur[[#This Row],[Total Pencairan]]>=Upaya_Debitur[[#This Row],[Kewajiban Total]],"Lunas","Belum Lunas") -> Belum Lunas | BS19: ="Ya" -> Ya | BT19: ="Ya" -> Ya | BU19: =IF(AND(DATEDIF($B$5,$B$6,"D")>=30,Upaya_Debitur[[#This Row],[Haircut Diperhitungkan]]+Upaya_Debitur[[#This Row],[Set Off Diperhitungkan]]+SUM(OFFSET(Upaya_Debitur[[#This Row],[1]],0,0,1,$B$7))<Upaya_Debitur[[#This Row],[Kewajiban Total]],OR($B$7-COUNTIF(OFFSET(Upaya_Debitur[[#This Row],[1]],0,0,1,$B$7),">="&Upaya_Debitur[[#This Row],[Angsuran Diperhitungkan]])>=1,DATEDIF($B$6,EDATE($B$5,$B$8)-1,"D")<180)),"Ya","Tidak") -> Ya | BV19: =IF(AND(Upaya_Debitur[[#This Row],[SP 1?]]="Ya",DATEDIF($B$5,$B$6,"D")>=60,Upaya_Debitur[[#This Row],[Haircut Diperhitungkan]]+Upaya_Debitur[[#This Row],[Set Off Diperhitungkan]]+SUM(OFFSET(Upaya_Debitur[[#This Row],[1]],0,0,1,$B$7))<Upaya_Debitur[[#This Row],[Kewajiban Total]],OR($B$7-COUNTIF(OFFSET(Upaya_Debitur[[#This Row],[1]],0,0,1,$B$7),">="&Upaya_Debitur[[#This Row],[Angsuran Diperhitungkan]])>=2,DATEDIF($B$6,EDATE($B$5,$B$8)-1,"D")<150)),"Ya","Tidak") -> Ya | BW19: =IF(AND(Upaya_Debitur[[#This Row],[SP2?]]="Ya",DATEDIF($B$5,$B$6,"D")>=90,Upaya_Debitur[[#This Row],[Haircut Diperhitungkan]]+Upaya_Debitur[[#This Row],[Set Off Diperhitungkan]]+SUM(OFFSET(Upaya_Debitur[[#This Row],[1]],0,0,1,$B$7))<Upaya_Debitur[[#This Row],[Kewajiban Total]],OR($B$7-COUNTIF(OFFSET(Upaya_Debitur[[#This Row],[1]],0,0,1,$B$7),">="&Upaya_Debitur[[#This Row],[Angsuran Diperhitungkan]])>=3,DATEDIF($B$6,EDATE($B$5,$B$8)-1,"D")<120)),"Ya","Tidak") -> Ya | BX19: =IF(Upaya_Debitur[[#This Row],[Kondisi Debitur]]="Tidak ditemukan","Ya","Tidak") -> Ya | BY19: =IF(AND(Upaya_Debitur[[#This Row],[SP3?]]="Ya",DATEDIF($B$5,$B$6,"D")>=90,Upaya_Debitur[[#This Row],[Haircut Diperhitungkan]]+Upaya_Debitur[[#This Row],[Set Off Diperhitungkan]]+SUM(OFFSET(Upaya_Debitur[[#This Row],[1]],0,0,1,$B$7))<Upaya_Debitur[[#This Row],[Kewajiban Total]]),"Ya","Tidak") -> Ya | BZ19: =IF(AND(Upaya_Debitur[[#This Row],[Iklan Cessie 1?]]="Ya",DATEDIF($B$5,$B$6,"D")>=120,Upaya_Debitur[[#This Row],[Haircut Diperhitungkan]]+Upaya_Debitur[[#This Row],[Set Off Diperhitungkan]]+SUM(OFFSET(Upaya_Debitur[[#This Row],[1]],0,0,1,$B$7))<Upaya_Debitur[[#This Row],[Kewajiban Total]]),"Ya","Tidak") -> Ya | CA19: =IF(AND(ISNUMBER(MATCH(Upaya_Debitur[[#This Row],[Wilayah Hukum]],$E$5:$E$12,0)),Upaya_Debitur[[#This Row],[SP3?]]="Ya",DATEDIF($B$5,$B$6,"D")>=120,Upaya_Debitur[[#This Row],[Haircut Diperhitungkan]]+Upaya_Debitur[[#This Row],[Set Off Diperhitungkan]]+SUM(OFFSET(Upaya_Debitur[[#This Row],[1]],0,0,1,$B$7))<Upaya_Debitur[[#This Row],[Kewajiban Total]],COUNTIFS(Upaya_Agunan[Nomor PK],Upaya_Debitur[[#This Row],[Nomor PK]],Upaya_Agunan[Agunan],"SHM")+COUNTIFS(Upaya_Agunan[Nomor PK],Upaya_Debitur[[#This Row],[Nomor PK]],Upaya_Agunan[Agunan],"SHGB")>0,AND(Upaya_Debitur[[#This Row],[Kewajiban Pokok]]<=500000000,Upaya_Debitur[[#This Row],[Kewajiban Pokok]]>50000000)),"Ya","Tidak") -> Tidak | CB19: 43781 | CC19: 43999 | CD19: 43826 | CE19: 43871 | CF19: 43887 | CG19: 44035 | CH19: 44057 | CI19: 44077 | CK19: =COUNTIF(Upaya_Debitur[[#This Row],[Surat Pemberitahuan?]:[Gugatan Sederhana?]],"Ya") -> 8 | CL19: =Upaya_Debitur[[#This Row],[Target Upaya]]-COUNTIFS(Upaya_Debitur[[#This Row],[Surat Pemberitahuan?]:[Gugatan Sederhana?]],"Ya",Upaya_Debitur[[#This Row],[Surat Pemberitahuan]:[Gugatan Sederhana]],"") -> 8 | CM19: =IF(ISNUMBER(Upaya_Debitur[[#This Row],[Realisasi]]/Upaya_Debitur[[#This Row],[Target Upaya]]),Upaya_Debitur[[#This Row],[Realisasi]]/Upaya_Debitur[[#This Row],[Target Upaya]],1) -> 1 | CQ19: 1 | CR19: =DATE(YEAR('Upaya Debitur'!B5),MONTH('Upaya Debitur'!B5)+1,1)-1 -> 43769 | CS19: =Periode[[#This Row],[Bulan Ke]] -> 1 | CU19: Koperatif
A20: 2 | C20: 52/MBA-02/1187/VI/2004 | D20: A Z W A R | E20: 1925196 | F20: 0 | G20: 0 | H20: =SUM(Upaya_Debitur[[#This Row],[Kewajiban Pokok]:[Kewajiban Denda]]) -> 1925196 | J20: =IF(ISNUMBER(Upaya_Debitur[[#This Row],[Angsuran Sesuai PK]]),Upaya_Debitur[[#This Row],[Angsuran Sesuai PK]],1) -> 1 | L20: Tidak ditemukan | S20: =IF(Upaya_Debitur[[#This Row],[Periode Haircut]]="",0,IF(Upaya_Debitur[[#This Row],[Periode Haircut]]<=$B$6,Upaya_Debitur[[#This Row],[Haircut]],0)) -> 0 | T20: =IF($B$10="",0,IF($B$10<=$B$6,Upaya_Debitur[[#This Row],[Set Off]],0)) -> 0 | U20: 0 | V20: 0 | W20: 0 | X20: 0 | Y20: 0 | Z20: 0 | AA20: 0 | AB20: 0 | AC20: 0 | AD20: 0 | AE20: 0 | AF20: 0 | AG20: 0 | AH20: 0 | AI20: 0 | BQ20: =SUM(OFFSET(Upaya_Debitur[[#This Row],[Haircut Diperhitungkan]],0,0,1,$B$7+2)) -> 0 | BR20: =IF(Upaya_Debitur[[#This Row],[Total Pencairan]]>=Upaya_Debitur[[#This Row],[Kewajiban Total]],"Lunas","Belum Lunas") -> Belum Lunas | BS20: ="Ya" -> Ya | BT20: ="Ya" -> Ya | BU20: =IF(AND(DATEDIF($B$5,$B$6,"D")>=30,Upaya_Debitur[[#This Row],[Haircut Diperhitungkan]]+Upaya_Debitur[[#This Row],[Set Off Diperhitungkan]]+SUM(OFFSET(Upaya_Debitur[[#This Row],[1]],0,0,1,$B$7))<Upaya_Debitur[[#This Row],[Kewajiban Total]],OR($B$7-COUNTIF(OFFSET(Upaya_Debitur[[#This Row],[1]],0,0,1,$B$7),">="&Upaya_Debitur[[#This Row],[Angsuran Diperhitungkan]])>=1,DATEDIF($B$6,EDATE($B$5,$B$8)-1,"D")<180)),"Ya","Tidak") -> Ya | BV20: =IF(AND(Upaya_Debitur[[#This Row],[SP 1?]]="Ya",DATEDIF($B$5,$B$6,"D")>=60,Upaya_Debitur[[#This Row],[Haircut Diperhitungkan]]+Upaya_Debitur[[#This Row],[Set Off Diperhitungkan]]+SUM(OFFSET(Upaya_Debitur[[#This Row],[1]],0,0,1,$B$7))<Upaya_Debitur[[#This Row],[Kewajiban Total]],OR($B$7-COUNTIF(OFFSET(Upaya_Debitur[[#This Row],[1]],0,0,1,$B$7),">="&Upaya_Debitur[[#This Row],[Angsuran Diperhitungkan]])>=2,DATEDIF($B$6,EDATE($B$5,$B$8)-1,"D")<150)),"Ya","Tidak") -> Ya | BW20: =IF(AND(Upaya_Debitur[[#This Row],[SP2?]]="Ya",DATEDIF($B$5,$B$6,"D")>=90,Upaya_Debitur[[#This Row],[Haircut Diperhitungkan]]+Upaya_Debitur[[#This Row],[Set Off Diperhitungkan]]+SUM(OFFSET(Upaya_Debitur[[#This Row],[1]],0,0,1,$B$7))<Upaya_Debitur[[#This Row],[Kewajiban Total]],OR($B$7-COUNTIF(OFFSET(Upaya_Debitur[[#This Row],[1]],0,0,1,$B$7),">="&Upaya_Debitur[[#This Row],[Angsuran Diperhitungkan]])>=3,DATEDIF($B$6,EDATE($B$5,$B$8)-1,"D")<120)),"Ya","Tidak") -> Ya | BX20: =IF(Upaya_Debitur[[#This Row],[Kondisi Debitur]]="Tidak ditemukan","Ya","Tidak") -> Ya | BY20: =IF(AND(Upaya_Debitur[[#This Row],[SP3?]]="Ya",DATEDIF($B$5,$B$6,"D")>=90,Upaya_Debitur[[#This Row],[Haircut Diperhitungkan]]+Upaya_Debitur[[#This Row],[Set Off Diperhitungkan]]+SUM(OFFSET(Upaya_Debitur[[#This Row],[1]],0,0,1,$B$7))<Upaya_Debitur[[#This Row],[Kewajiban Total]]),"Ya","Tidak") -> Ya | BZ20: =IF(AND(Upaya_Debitur[[#This Row],[Iklan Cessie 1?]]="Ya",DATEDIF($B$5,$B$6,"D")>=120,Upaya_Debitur[[#This Row],[Haircut Diperhitungkan]]+Upaya_Debitur[[#This Row],[Set Off Diperhitungkan]]+SUM(OFFSET(Upaya_Debitur[[#This Row],[1]],0,0,1,$B$7))<Upaya_Debitur[[#This Row],[Kewajiban Total]]),"Ya","Tidak") -> Ya | CA20: =IF(AND(ISNUMBER(MATCH(Upaya_Debitur[[#This Row],[Wilayah Hukum]],$E$5:$E$12,0)),Upaya_Debitur[[#This Row],[SP3?]]="Ya",DATEDIF($B$5,$B$6,"D")>=120,Upaya_Debitur[[#This Row],[Haircut Diperhitungkan]]+Upaya_Debitur[[#This Row],[Set Off Diperhitungkan]]+SUM(OFFSET(Upaya_Debitur[[#This Row],[1]],0,0,1,$B$7))<Upaya_Debitur[[#This Row],[Kewajiban Total]],COUNTIFS(Upaya_Agunan[Nomor PK],Upaya_Debitur[[#This Row],[Nomor PK]],Upaya_Agunan[Agunan],"SHM")+COUNTIFS(Upaya_Agunan[Nomor PK],Upaya_Debitur[[#This Row],[Nomor PK]],Upaya_Agunan[Agunan],"SHGB")>0,AND(Upaya_Debitur[[#This Row],[Kewajiban Pokok]]<=500000000,Upaya_Debitur[[#This Row],[Kewajiban Pokok]]>50000000)),"Ya","Tidak") -> Tidak | CB20: 43781 | CC20: 43999 | CD20: 43826 | CE20: 43871 | CF20: 43887 | CG20: 43888 | CH20: 44057 | CI20: 44077 | CK20: =COUNTIF(Upaya_Debitur[[#This Row],[Surat Pemberitahuan?]:[Gugatan Sederhana?]],"Ya") -> 8 | CL20: =Upaya_Debitur[[#This Row],[Target Upaya]]-COUNTIFS(Upaya_Debitur[[#This Row],[Surat Pemberitahuan?]:[Gugatan Sederhana?]],"Ya",Upaya_Debitur[[#This Row],[Surat Pemberitahuan]:[Gugatan Sederhana]],"") -> 8 | CM20: =IF(ISNUMBER(Upaya_Debitur[[#This Row],[Realisasi]]/Upaya_Debitur[[#This Row],[Target Upaya]]),Upaya_Debitur[[#This Row],[Realisasi]]/Upaya_Debitur[[#This Row],[Target Upaya]],1) -> 1 | CQ20: 2 | CR20: =DATE(YEAR(CR19),MONTH(CR19)+2,1)-1 -> 43799 | CS20: =Periode[[#This Row],[Bulan Ke]] -> 2 | CU20: Tidak koperatif
A21: 3 | C21: 054/BBA-03/0490/III/1996 | D21: A. RAFAR MUSA | E21: 1039806 | F21: 0 | G21: 0 | H21: =SUM(Upaya_Debitur[[#This Row],[Kewajiban Pokok]:[Kewajiban Denda]]) -> 1039806 | J21: =IF(ISNUMBER(Upaya_Debitur[[#This Row],[Angsuran Sesuai PK]]),Upaya_Debitur[[#This Row],[Angsuran Sesuai PK]],1) -> 1 | L21: Tidak ditemukan | S21: =IF(Upaya_Debitur[[#This Row],[Periode Haircut]]="",0,IF(Upaya_Debitur[[#This Row],[Periode Haircut]]<=$B$6,Upaya_Debitur[[#This Row],[Haircut]],0)) -> 0 | T21: =IF($B$10="",0,IF($B$10<=$B$6,Upaya_Debitur[[#This Row],[Set Off]],0)) -> 0 | U21: 0 | V21: 0 | W21: 0 | X21: 0 | Y21: 0 | Z21: 0 | AA21: 0 | AB21: 0 | AC21: 0 | AD21: 0 | AE21: 0 | AF21: 0 | AG21: 0 | AH21: 0 | AI21: 0 | BQ21: =SUM(OFFSET(Upaya_Debitur[[#This Row],[Haircut Diperhitungkan]],0,0,1,$B$7+2)) -> 0 | BR21: =IF(Upaya_Debitur[[#This Row],[Total Pencairan]]>=Upaya_Debitur[[#This Row],[Kewajiban Total]],"Lunas","Belum Lunas") -> Belum Lunas | BS21: ="Ya" -> Ya | BT21: ="Ya" -> Ya | BU21: =IF(AND(DATEDIF($B$5,$B$6,"D")>=30,Upaya_Debitur[[#This Row],[Haircut Diperhitungkan]]+Upaya_Debitur[[#This Row],[Set Off Diperhitungkan]]+SUM(OFFSET(Upaya_Debitur[[#This Row],[1]],0,0,1,$B$7))<Upaya_Debitur[[#This Row],[Kewajiban Total]],OR($B$7-COUNTIF(OFFSET(Upaya_Debitur[[#This Row],[1]],0,0,1,$B$7),">="&Upaya_Debitur[[#This Row],[Angsuran Diperhitungkan]])>=1,DATEDIF($B$6,EDATE($B$5,$B$8)-1,"D")<180)),"Ya","Tidak") -> Ya | BV21: =IF(AND(Upaya_Debitur[[#This Row],[SP 1?]]="Ya",DATEDIF($B$5,$B$6,"D")>=60,Upaya_Debitur[[#This Row],[Haircut Diperhitungkan]]+Upaya_Debitur[[#This Row],[Set Off Diperhitungkan]]+SUM(OFFSET(Upaya_Debitur[[#This Row],[1]],0,0,1,$B$7))<Upaya_Debitur[[#This Row],[Kewajiban Total]],OR($B$7-COUNTIF(OFFSET(Upaya_Debitur[[#This Row],[1]],0,0,1,$B$7),">="&Upaya_Debitur[[#This Row],[Angsuran Diperhitungkan]])>=2,DATEDIF($B$6,EDATE($B$5,$B$8)-1,"D")<150)),"Ya","Tidak") -> Ya | BW21: =IF(AND(Upaya_Debitur[[#This Row],[SP2?]]="Ya",DATEDIF($B$5,$B$6,"D")>=90,Upaya_Debitur[[#This Row],[Haircut Diperhitungkan]]+Upaya_Debitur[[#This Row],[Set Off Diperhitungkan]]+SUM(OFFSET(Upaya_Debitur[[#This Row],[1]],0,0,1,$B$7))<Upaya_Debitur[[#This Row],[Kewajiban Total]],OR($B$7-COUNTIF(OFFSET(Upaya_Debitur[[#This Row],[1]],0,0,1,$B$7),">="&Upaya_Debitur[[#This Row],[Angsuran Diperhitungkan]])>=3,DATEDIF($B$6,EDATE($B$5,$B$8)-1,"D")<120)),"Ya","Tidak") -> Ya | BX21: =IF(Upaya_Debitur[[#This Row],[Kondisi Debitur]]="Tidak ditemukan","Ya","Tidak") -> Ya | BY21: =IF(AND(Upaya_Debitur[[#This Row],[SP3?]]="Ya",DATEDIF($B$5,$B$6,"D")>=90,Upaya_Debitur[[#This Row],[Haircut Diperhitungkan]]+Upaya_Debitur[[#This Row],[Set Off Diperhitungkan]]+SUM(OFFSET(Upaya_Debitur[[#This Row],[1]],0,0,1,$B$7))<Upaya_Debitur[[#This Row],[Kewajiban Total]]),"Ya","Tidak") -> Ya | BZ21: =IF(AND(Upaya_Debitur[[#This Row],[Iklan Cessie 1?]]="Ya",DATEDIF($B$5,$B$6,"D")>=120,Upaya_Debitur[[#This Row],[Haircut Diperhitungkan]]+Upaya_Debitur[[#This Row],[Set Off Diperhitungkan]]+SUM(OFFSET(Upaya_Debitur[[#This Row],[1]],0,0,1,$B$7))<Upaya_Debitur[[#This Row],[Kewajiban Total]]),"Ya","Tidak") -> Ya | CA21: =IF(AND(ISNUMBER(MATCH(Upaya_Debitur[[#This Row],[Wilayah Hukum]],$E$5:$E$12,0)),Upaya_Debitur[[#This Row],[SP3?]]="Ya",DATEDIF($B$5,$B$6,"D")>=120,Upaya_Debitur[[#This Row],[Haircut Diperhitungkan]]+Upaya_Debitur[[#This Row],[Set Off Diperhitungkan]]+SUM(OFFSET(Upaya_Debitur[[#This Row],[1]],0,0,1,$B$7))<Upaya_Debitur[[#This Row],[Kewajiban Total]],COUNTIFS(Upaya_Agunan[Nomor PK],Upaya_Debitur[[#This Row],[Nomor PK]],Upaya_Agunan[Agunan],"SHM")+COUNTIFS(Upaya_Agunan[Nomor PK],Upaya_Debitur[[#This Row],[Nomor PK]],Upaya_Agunan[Agunan],"SHGB")>0,AND(Upaya_Debitur[[#This Row],[Kewajiban Pokok]]<=500000000,Upaya_Debitur[[#This Row],[Kewajiban Pokok]]>50000000)),"Ya","Tidak") -> Tidak | CB21: 43781 | CC21: 43999 | CD21: 43826 | CE21: 43871 | CF21: 43887 | CG21: 43888 | CH21: 44057 | CI21: 44077 | CK21: =COUNTIF(Upaya_Debitur[[#This Row],[Surat Pemberitahuan?]:[Gugatan Sederhana?]],"Ya") -> 8 | CL21: =Upaya_Debitur[[#This Row],[Target Upaya]]-COUNTIFS(Upaya_Debitur[[#This Row],[Surat Pemberitahuan?]:[Gugatan Sederhana?]],"Ya",Upaya_Debitur[[#This Row],[Surat Pemberitahuan]:[Gugatan Sederhana]],"") -> 8 | CM21: =IF(ISNUMBER(Upaya_Debitur[[#This Row],[Realisasi]]/Upaya_Debitur[[#This Row],[Target Upaya]]),Upaya_Debitur[[#This Row],[Realisasi]]/Upaya_Debitur[[#This Row],[Target Upaya]],1) -> 1 | CQ21: 3 | CR21: =DATE(YEAR(CR20),MONTH(CR20)+2,1)-1 -> 43830 | CS21: =Periode[[#This Row],[Bulan Ke]] -> 3 | CU21: Tidak ditemukan
A22: 4 | C22: 036/BBA-03/0752/III/1997 | D22: A. RAHMAN ABDULLAH | E22: 4510000 | F22: 0 | G22: 0 | H22: =SUM(Upaya_Debitur[[#This Row],[Kewajiban Pokok]:[Kewajiban Denda]]) -> 4510000 | J22: =IF(ISNUMBER(Upaya_Debitur[[#This Row],[Angsuran Sesuai PK]]),Upaya_Debitur[[#This Row],[Angsuran Sesuai PK]],1) -> 1 | L22: Meninggal | S22: =IF(Upaya_Debitur[[#This Row],[Periode Haircut]]="",0,IF(Upaya_Debitur[[#This Row],[Periode Haircut]]<=$B$6,Upaya_Debitur[[#This Row],[Haircut]],0)) -> 0 | T22: =IF($B$10="",0,IF($B$10<=$B$6,Upaya_Debitur[[#This Row],[Set Off]],0)) -> 0 | U22: 0 | V22: 0 | W22: 0 | X22: 0 | Y22: 70000 | Z22: 0 | AA22: 0 | AB22: 0 | AC22: 0 | AD22: 0 | AE22: 0 | AF22: 0 | AG22: 0 | AH22: 0 | AI22: 0 | BQ22: =SUM(OFFSET(Upaya_Debitur[[#This Row],[Haircut Diperhitungkan]],0,0,1,$B$7+2)) -> 70000 | BR22: =IF(Upaya_Debitur[[#This Row],[Total Pencairan]]>=Upaya_Debitur[[#This Row],[Kewajiban Total]],"Lunas","Belum Lunas") -> Belum Lunas | BS22: ="Ya" -> Ya | BT22: ="Ya" -> Ya | BU22: =IF(AND(DATEDIF($B$5,$B$6,"D")>=30,Upaya_Debitur[[#This Row],[Haircut Diperhitungkan]]+Upaya_Debitur[[#This Row],[Set Off Diperhitungkan]]+SUM(OFFSET(Upaya_Debitur[[#This Row],[1]],0,0,1,$B$7))<Upaya_Debitur[[#This Row],[Kewajiban Total]],OR($B$7-COUNTIF(OFFSET(Upaya_Debitur[[#This Row],[1]],0,0,1,$B$7),">="&Upaya_Debitur[[#This Row],[Angsuran Diperhitungkan]])>=1,DATEDIF($B$6,EDATE($B$5,$B$8)-1,"D")<180)),"Ya","Tidak") -> Ya | BV22: =IF(AND(Upaya_Debitur[[#This Row],[SP 1?]]="Ya",DATEDIF($B$5,$B$6,"D")>=60,Upaya_Debitur[[#This Row],[Haircut Diperhitungkan]]+Upaya_Debitur[[#This Row],[Set Off Diperhitungkan]]+SUM(OFFSET(Upaya_Debitur[[#This Row],[1]],0,0,1,$B$7))<Upaya_Debitur[[#This Row],[Kewajiban Total]],OR($B$7-COUNTIF(OFFSET(Upaya_Debitur[[#This Row],[1]],0,0,1,$B$7),">="&Upaya_Debitur[[#This Row],[Angsuran Diperhitungkan]])>=2,DATEDIF($B$6,EDATE($B$5,$B$8)-1,"D")<150)),"Ya","Tidak") -> Ya | BW22: =IF(AND(Upaya_Debitur[[#This Row],[SP2?]]="Ya",DATEDIF($B$5,$B$6,"D")>=90,Upaya_Debitur[[#This Row],[Haircut Diperhitungkan]]+Upaya_Debitur[[#This Row],[Set Off Diperhitungkan]]+SUM(OFFSET(Upaya_Debitur[[#This Row],[1]],0,0,1,$B$7))<Upaya_Debitur[[#This Row],[Kewajiban Total]],OR($B$7-COUNTIF(OFFSET(Upaya_Debitur[[#This Row],[1]],0,0,1,$B$7),">="&Upaya_Debitur[[#This Row],[Angsuran Diperhitungkan]])>=3,DATEDIF($B$6,EDATE($B$5,$B$8)-1,"D")<120)),"Ya","Tidak") -> Ya | BX22: =IF(Upaya_Debitur[[#This Row],[Kondisi Debitur]]="Tidak ditemukan","Ya","Tidak") -> Tidak | BY22: =IF(AND(Upaya_Debitur[[#This Row],[SP3?]]="Ya",DATEDIF($B$5,$B$6,"D")>=90,Upaya_Debitur[[#This Row],[Haircut Diperhitungkan]]+Upaya_Debitur[[#This Row],[Set Off Diperhitungkan]]+SUM(OFFSET(Upaya_Debitur[[#This Row],[1]],0,0,1,$B$7))<Upaya_Debitur[[#This Row],[Kewajiban Total]]),"Ya","Tidak") -> Ya | BZ22: =IF(AND(Upaya_Debitur[[#This Row],[Iklan Cessie 1?]]="Ya",DATEDIF($B$5,$B$6,"D")>=120,Upaya_Debitur[[#This Row],[Haircut Diperhitungkan]]+Upaya_Debitur[[#This Row],[Set Off Diperhitungkan]]+SUM(OFFSET(Upaya_Debitur[[#This Row],[1]],0,0,1,$B$7))<Upaya_Debitur[[#This Row],[Kewajiban Total]]),"Ya","Tidak") -> Ya | CA22: =IF(AND(ISNUMBER(MATCH(Upaya_Debitur[[#This Row],[Wilayah Hukum]],$E$5:$E$12,0)),Upaya_Debitur[[#This Row],[SP3?]]="Ya",DATEDIF($B$5,$B$6,"D")>=120,Upaya_Debitur[[#This Row],[Haircut Diperhitungkan]]+Upaya_Debitur[[#This Row],[Set Off Diperhitungkan]]+SUM(OFFSET(Upaya_Debitur[[#This Row],[1]],0,0,1,$B$7))<Upaya_Debitur[[#This Row],[Kewajiban Total]],COUNTIFS(Upaya_Agunan[Nomor PK],Upaya_Debitur[[#This Row],[Nomor PK]],Upaya_Agunan[Agunan],"SHM")+COUNTIFS(Upaya_Agunan[Nomor PK],Upaya_Debitur[[#This Row],[Nomor PK]],Upaya_Agunan[Agunan],"SHGB")>0,AND(Upaya_Debitur[[#This Row],[Kewajiban Pokok]]<=500000000,Upaya_Debitur[[#This Row],[Kewajiban Pokok]]>50000000)),"Ya","Tidak") -> Tidak | CB22: 43781 | CC22: 43999 | CD22: 43826 | CE22: 43871 | CF22: 43887 | CH22: 44057 | CI22: 44077 | CK22: =COUNTIF(Upaya_Debitur[[#This Row],[Surat Pemberitahuan?]:[Gugatan Sederhana?]],"Ya") -> 7 | CL22: =Upaya_Debitur[[#This Row],[Target Upaya]]-COUNTIFS(Upaya_Debitur[[#This Row],[Surat Pemberitahuan?]:[Gugatan Sederhana?]],"Ya",Upaya_Debitur[[#This Row],[Surat Pemberitahuan]:[Gugatan Sederhana]],"") -> 7 | CM22: =IF(ISNUMBER(Upaya_Debitur[[#This Row],[Realisasi]]/Upaya_Debitur[[#This Row],[Target Upaya]]),Upaya_Debitur[[#This Row],[Realisasi]]/Upaya_Debitur[[#This Row],[Target Upaya]],1) -> 1 | CQ22: 4 | CR22: =DATE(YEAR(CR21),MONTH(CR21)+2,1)-1 -> 43861 | CS22: =Periode[[#This Row],[Bulan Ke]] -> 4 | CU22: Meninggal
A23: 5 | C23: 075/BBA-03/0792/V/1997 | D23: ABD. JABAR | E23: 2205725 | F23: 0 | G23: 0 | H23: =SUM(Upaya_Debitur[[#This Row],[Kewajiban Pokok]:[Kewajiban Denda]]) -> 2205725 | J23: =IF(ISNUMBER(Upaya_Debitur[[#This Row],[Angsuran Sesuai PK]]),Upaya_Debitur[[#This Row],[Angsuran Sesuai PK]],1) -> 1 | L23: Tidak koperatif | S23: =IF(Upaya_Debitur[[#This Row],[Periode Haircut]]="",0,IF(Upaya_Debitur[[#This Row],[Periode Haircut]]<=$B$6,Upaya_Debitur[[#This Row],[Haircut]],0)) -> 0 | T23: =IF($B$10="",0,IF($B$10<=$B$6,Upaya_Debitur[[#This Row],[Set Off]],0)) -> 0 | U23: 0 | V23: 2205725 | W23: 0 | X23: 0 | Y23: 0 | Z23: 0 | AA23: 0 | AB23: 0 | AC23: 0 | AD23: 0 | AE23: 0 | AF23: 0 | AG23: 0 | AH23: 0 | AI23: 0 | BQ23: =SUM(OFFSET(Upaya_Debitur[[#This Row],[Haircut Diperhitungkan]],0,0,1,$B$7+2)) -> 2205725 | BR23: =IF(Upaya_Debitur[[#This Row],[Total Pencairan]]>=Upaya_Debitur[[#This Row],[Kewajiban Total]],"Lunas","Belum Lunas") -> Lunas | BS23: ="Ya" -> Ya | BT23: ="Ya" -> Ya | BU23: =IF(AND(DATEDIF($B$5,$B$6,"D")>=30,Upaya_Debitur[[#This Row],[Haircut Diperhitungkan]]+Upaya_Debitur[[#This Row],[Set Off Diperhitungkan]]+SUM(OFFSET(Upaya_Debitur[[#This Row],[1]],0,0,1,$B$7))<Upaya_Debitur[[#This Row],[Kewajiban Total]],OR($B$7-COUNTIF(OFFSET(Upaya_Debitur[[#This Row],[1]],0,0,1,$B$7),">="&Upaya_Debitur[[#This Row],[Angsuran Diperhitungkan]])>=1,DATEDIF($B$6,EDATE($B$5,$B$8)-1,"D")<180)),"Ya","Tidak") -> Tidak | BV23: =IF(AND(Upaya_Debitur[[#This Row],[SP 1?]]="Ya",DATEDIF($B$5,$B$6,"D")>=60,Upaya_Debitur[[#This Row],[Haircut Diperhitungkan]]+Upaya_Debitur[[#This Row],[Set Off Diperhitungkan]]+SUM(OFFSET(Upaya_Debitur[[#This Row],[1]],0,0,1,$B$7))<Upaya_Debitur[[#This Row],[Kewajiban Total]],OR($B$7-COUNTIF(OFFSET(Upaya_Debitur[[#This Row],[1]],0,0,1,$B$7),">="&Upaya_Debitur[[#This Row],[Angsuran Diperhitungkan]])>=2,DATEDIF($B$6,EDATE($B$5,$B$8)-1,"D")<150)),"Ya","Tidak") -> Tidak | BW23: =IF(AND(Upaya_Debitur[[#This Row],[SP2?]]="Ya",DATEDIF($B$5,$B$6,"D")>=90,Upaya_Debitur[[#This Row],[Haircut Diperhitungkan]]+Upaya_Debitur[[#This Row],[Set Off Diperhitungkan]]+SUM(OFFSET(Upaya_Debitur[[#This Row],[1]],0,0,1,$B$7))<Upaya_Debitur[[#This Row],[Kewajiban Total]],OR($B$7-COUNTIF(OFFSET(Upaya_Debitur[[#This Row],[1]],0,0,1,$B$7),">="&Upaya_Debitur[[#This Row],[Angsuran Diperhitungkan]])>=3,DATEDIF($B$6,EDATE($B$5,$B$8)-1,"D")<120)),"Ya","Tidak") -> Tidak | BX23: =IF(Upaya_Debitur[[#This Row],[Kondisi Debitur]]="Tidak ditemukan","Ya","Tidak") -> Tidak | BY23: =IF(AND(Upaya_Debitur[[#This Row],[SP3?]]="Ya",DATEDIF($B$5,$B$6,"D")>=90,Upaya_Debitur[[#This Row],[Haircut Diperhitungkan]]+Upaya_Debitur[[#This Row],[Set Off Diperhitungkan]]+SUM(OFFSET(Upaya_Debitur[[#This Row],[1]],0,0,1,$B$7))<Upaya_Debitur[[#This Row],[Kewajiban Total]]),"Ya","Tidak") -> Tidak | BZ23: =IF(AND(Upaya_Debitur[[#This Row],[Iklan Cessie 1?]]="Ya",DATEDIF($B$5,$B$6,"D")>=120,Upaya_Debitur[[#This Row],[Haircut Diperhitungkan]]+Upaya_Debitur[[#This Row],[Set Off Diperhitungkan]]+SUM(OFFSET(Upaya_Debitur[[#This Row],[1]],0,0,1,$B$7))<Upaya_Debitur[[#This Row],[Kewajiban Total]]),"Ya","Tidak") -> Tidak | CA23: =IF(AND(ISNUMBER(MATCH(Upaya_Debitur[[#This Row],[Wilayah Hukum]],$E$5:$E$12,0)),Upaya_Debitur[[#This Row],[SP3?]]="Ya",DATEDIF($B$5,$B$6,"D")>=120,Upaya_Debitur[[#This Row],[Haircut Diperhitungkan]]+Upaya_Debitur[[#This Row],[Set Off Diperhitungkan]]+SUM(OFFSET(Upaya_Debitur[[#This Row],[1]],0,0,1,$B$7))<Upaya_Debitur[[#This Row],[Kewajiban Total]],COUNTIFS(Upaya_Agunan[Nomor PK],Upaya_Debitur[[#This Row],[Nomor PK]],Upaya_Agunan[Agunan],"SHM")+COUNTIFS(Upaya_Agunan[Nomor PK],Upaya_Debitur[[#This Row],[Nomor PK]],Upaya_Agunan[Agunan],"SHGB")>0,AND(Upaya_Debitur[[#This Row],[Kewajiban Pokok]]<=500000000,Upaya_Debitur[[#This Row],[Kewajiban Pokok]]>50000000)),"Ya","Tidak") -> Tidak | CB23: 43781 | CC23: 43871 | CH23: 44057 | CI23: 44077 | CK23: =COUNTIF(Upaya_Debitur[[#This Row],[Surat Pemberitahuan?]:[Gugatan Sederhana?]],"Ya") -> 2 | CL23: =Upaya_Debitur[[#This Row],[Target Upaya]]-COUNTIFS(Upaya_Debitur[[#This Row],[Surat Pemberitahuan?]:[Gugatan Sederhana?]],"Ya",Upaya_Debitur[[#This Row],[Surat Pemberitahuan]:[Gugatan Sederhana]],"") -> 2 | CM23: =IF(ISNUMBER(Upaya_Debitur[[#This Row],[Realisasi]]/Upaya_Debitur[[#This Row],[Target Upaya]]),Upaya_Debitur[[#This Row],[Realisasi]]/Upaya_Debitur[[#This Row],[Target Upaya]],1) -> 1 | CQ23: 5 | CR23: =DATE(YEAR(CR22),MONTH(CR22)+2,1)-1 -> 43890 | CS23: =Periode[[#This Row],[Bulan Ke]] -> 5 | CU23: Tidak memiliki kemampuan bayar
A24: 6 | C24: 125/MBA-02/0333/XII/2000 | D24: ABD. MANAF DAUD | E24: 1356853 | F24: 0 | G24: 0 | H24: =SUM(Upaya_Debitur[[#This Row],[Kewajiban Pokok]:[Kewajiban Denda]]) -> 1356853 | J24: =IF(ISNUMBER(Upaya_Debitur[[#This Row],[Angsuran Sesuai PK]]),Upaya_Debitur[[#This Row],[Angsuran Sesuai PK]],1) -> 1 | L24: Tidak koperatif | S24: =IF(Upaya_Debitur[[#This Row],[Periode Haircut]]="",0,IF(Upaya_Debitur[[#This Row],[Periode Haircut]]<=$B$6,Upaya_Debitur[[#This Row],[Haircut]],0)) -> 0 | T24: =IF($B$10="",0,IF($B$10<=$B$6,Upaya_Debitur[[#This Row],[Set Off]],0)) -> 0 | U24: 0 | V24: 0 | W24: 0 | X24: 0 | Y24: 0 | Z24: 0 | AA24: 0 | AB24: 0 | AC24: 0 | AD24: 0 | AE24: 0 | AF24: 0 | AG24: 0 | AH24: 0 | AI24: 0 | BQ24: =SUM(OFFSET(Upaya_Debitur[[#This Row],[Haircut Diperhitungkan]],0,0,1,$B$7+2)) -> 0 | BR24: =IF(Upaya_Debitur[[#This Row],[Total Pencairan]]>=Upaya_Debitur[[#This Row],[Kewajiban Total]],"Lunas","Belum Lunas") -> Belum Lunas | BS24: ="Ya" -> Ya | BT24: ="Ya" -> Ya | BU24: =IF(AND(DATEDIF($B$5,$B$6,"D")>=30,Upaya_Debitur[[#This Row],[Haircut Diperhitungkan]]+Upaya_Debitur[[#This Row],[Set Off Diperhitungkan]]+SUM(OFFSET(Upaya_Debitur[[#This Row],[1]],0,0,1,$B$7))<Upaya_Debitur[[#This Row],[Kewajiban Total]],OR($B$7-COUNTIF(OFFSET(Upaya_Debitur[[#This Row],[1]],0,0,1,$B$7),">="&Upaya_Debitur[[#This Row],[Angsuran Diperhitungkan]])>=1,DATEDIF($B$6,EDATE($B$5,$B$8)-1,"D")<180)),"Ya","Tidak") -> Ya | BV24: =IF(AND(Upaya_Debitur[[#This Row],[SP 1?]]="Ya",DATEDIF($B$5,$B$6,"D")>=60,Upaya_Debitur[[#This Row],[Haircut Diperhitungkan]]+Upaya_Debitur[[#This Row],[Set Off Diperhitungkan]]+SUM(OFFSET(Upaya_Debitur[[#This Row],[1]],0,0,1,$B$7))<Upaya_Debitur[[#This Row],[Kewajiban Total]],OR($B$7-COUNTIF(OFFSET(Upaya_Debitur[[#This Row],[1]],0,0,1,$B$7),">="&Upaya_Debitur[[#This Row],[Angsuran Diperhitungkan]])>=2,DATEDIF($B$6,EDATE($B$5,$B$8)-1,"D")<150)),"Ya","Tidak") -> Ya | BW24: =IF(AND(Upaya_Debitur[[#This Row],[SP2?]]="Ya",DATEDIF($B$5,$B$6,"D")>=90,Upaya_Debitur[[#This Row],[Haircut Diperhitungkan]]+Upaya_Debitur[[#This Row],[Set Off Diperhitungkan]]+SUM(OFFSET(Upaya_Debitur[[#This Row],[1]],0,0,1,$B$7))<Upaya_Debitur[[#This Row],[Kewajiban Total]],OR($B$7-COUNTIF(OFFSET(Upaya_Debitur[[#This Row],[1]],0,0,1,$B$7),">="&Upaya_Debitur[[#This Row],[Angsuran Diperhitungkan]])>=3,DATEDIF($B$6,EDATE($B$5,$B$8)-1,"D")<120)),"Ya","Tidak") -> Ya | BX24: =IF(Upaya_Debitur[[#This Row],[Kondisi Debitur]]="Tidak ditemukan","Ya","Tidak") -> Tidak | BY24: =IF(AND(Upaya_Debitur[[#This Row],[SP3?]]="Ya",DATEDIF($B$5,$B$6,"D")>=90,Upaya_Debitur[[#This Row],[Haircut Diperhitungkan]]+Upaya_Debitur[[#This Row],[Set Off Diperhitungkan]]+SUM(OFFSET(Upaya_Debitur[[#This Row],[1]],0,0,1,$B$7))<Upaya_Debitur[[#This Row],[Kewajiban Total]]),"Ya","Tidak") -> Ya | BZ24: =IF(AND(Upaya_Debitur[[#This Row],[Iklan Cessie 1?]]="Ya",DATEDIF($B$5,$B$6,"D")>=120,Upaya_Debitur[[#This Row],[Haircut Diperhitungkan]]+Upaya_Debitur[[#This Row],[Set Off Diperhitungkan]]+SUM(OFFSET(Upaya_Debitur[[#This Row],[1]],0,0,1,$B$7))<Upaya_Debitur[[#This Row],[Kewajiban Total]]),"Ya","Tidak") -> Ya | CA24: =IF(AND(ISNUMBER(MATCH(Upaya_Debitur[[#This Row],[Wilayah Hukum]],$E$5:$E$12,0)),Upaya_Debitur[[#This Row],[SP3?]]="Ya",DATEDIF($B$5,$B$6,"D")>=120,Upaya_Debitur[[#This Row],[Haircut Diperhitungkan]]+Upaya_Debitur[[#This Row],[Set Off Diperhitungkan]]+SUM(OFFSET(Upaya_Debitur[[#This Row],[1]],0,0,1,$B$7))<Upaya_Debitur[[#This Row],[Kewajiban Total]],COUNTIFS(Upaya_Agunan[Nomor PK],Upaya_Debitur[[#This Row],[Nomor PK]],Upaya_Agunan[Agunan],"SHM")+COUNTIFS(Upaya_Agunan[Nomor PK],Upaya_Debitur[[#This Row],[Nomor PK]],Upaya_Agunan[Agunan],"SHGB")>0,AND(Upaya_Debitur[[#This Row],[Kewajiban Pokok]]<=500000000,Upaya_Debitur[[#This Row],[Kewajiban Pokok]]>50000000)),"Ya","Tidak") -> Tidak | CB24: 43781 | CC24: 43999 | CD24: 43826 | CE24: 43871 | CF24: 43887 | CG24: 43888 | CH24: 44057 | CI24: 44077 | CK24: =COUNTIF(Upaya_Debitur[[#This Row],[Surat Pemberitahuan?]:[Gugatan Sederhana?]],"Ya") -> 7 | CL24: =Upaya_Debitur[[#This Row],[Target Upaya]]-COUNTIFS(Upaya_Debitur[[#This Row],[Surat Pemberitahuan?]:[Gugatan Sederhana?]],"Ya",Upaya_Debitur[[#This Row],[Surat Pemberitahuan]:[Gugatan Sederhana]],"") -> 7 | CM24: =IF(ISNUMBER(Upaya_Debitur[[#This Row],[Realisasi]]/Upaya_Debitur[[#This Row],[Target Upaya]]),Upaya_Debitur[[#This Row],[Realisasi]]/Upaya_Debitur[[#This Row],[Target Upaya]],1) -> 1 | CQ24: 6 | CR24: =DATE(YEAR(CR23),MONTH(CR23)+2,1)-1 -> 43921 | CS24: =Periode[[#This Row],[Bulan Ke]] -> 6
A25: 7 | C25: 250/BBA-03/0686/XI/1996 | D25: ABD. MUKTY ALI MUHAMMAD | E25: 4824450 | F25: 0 | G25: 0 | H25: =SUM(Upaya_Debitur[[#This Row],[Kewajiban Pokok]:[Kewajiban Denda]]) -> 4824450 | J25: =IF(ISNUMBER(Upaya_Debitur[[#This Row],[Angsuran Sesuai PK]]),Upaya_Debitur[[#This Row],[Angsuran Sesuai PK]],1) -> 1 | L25: Tidak koperatif | S25: =IF(Upaya_Debitur[[#This Row],[Periode Haircut]]="",0,IF(Upaya_Debitur[[#This Row],[Periode Haircut]]<=$B$6,Upaya_Debitur[[#This Row],[Haircut]],0)) -> 0 | T25: =IF($B$10="",0,IF($B$10<=$B$6,Upaya_Debitur[[#This Row],[Set Off]],0)) -> 0 | U25: 0 | V25: 0 | W25: 0 | X25: 0 | Y25: 0 | Z25: 0 | AA25: 0 | AB25: 0 | AC25: 0 | AD25: 0 | AE25: 0 | AF25: 0 | AG25: 0 | AH25: 0 | AI25: 0 | BQ25: =SUM(OFFSET(Upaya_Debitur[[#This Row],[Haircut Diperhitungkan]],0,0,1,$B$7+2)) -> 0 | BR25: =IF(Upaya_Debitur[[#This Row],[Total Pencairan]]>=Upaya_Debitur[[#This Row],[Kewajiban Total]],"Lunas","Belum Lunas") -> Belum Lunas | BS25: ="Ya" -> Ya | BT25: ="Ya" -> Ya | BU25: =IF(AND(DATEDIF($B$5,$B$6,"D")>=30,Upaya_Debitur[[#This Row],[Haircut Diperhitungkan]]+Upaya_Debitur[[#This Row],[Set Off Diperhitungkan]]+SUM(OFFSET(Upaya_Debitur[[#This Row],[1]],0,0,1,$B$7))<Upaya_Debitur[[#This Row],[Kewajiban Total]],OR($B$7-COUNTIF(OFFSET(Upaya_Debitur[[#This Row],[1]],0,0,1,$B$7),">="&Upaya_Debitur[[#This Row],[Angsuran Diperhitungkan]])>=1,DATEDIF($B$6,EDATE($B$5,$B$8)-1,"D")<180)),"Ya","Tidak") -> Ya | BV25: =IF(AND(Upaya_Debitur[[#This Row],[SP 1?]]="Ya",DATEDIF($B$5,$B$6,"D")>=60,Upaya_Debitur[[#This Row],[Haircut Diperhitungkan]]+Upaya_Debitur[[#This Row],[Set Off Diperhitungkan]]+SUM(OFFSET(Upaya_Debitur[[#This Row],[1]],0,0,1,$B$7))<Upaya_Debitur[[#This Row],[Kewajiban Total]],OR($B$7-COUNTIF(OFFSET(Upaya_Debitur[[#This Row],[1]],0,0,1,$B$7),">="&Upaya_Debitur[[#This Row],[Angsuran Diperhitungkan]])>=2,DATEDIF($B$6,EDATE($B$5,$B$8)-1,"D")<150)),"Ya","Tidak") -> Ya | BW25: =IF(AND(Upaya_Debitur[[#This Row],[SP2?]]="Ya",DATEDIF($B$5,$B$6,"D")>=90,Upaya_Debitur[[#This Row],[Haircut Diperhitungkan]]+Upaya_Debitur[[#This Row],[Set Off Diperhitungkan]]+SUM(OFFSET(Upaya_Debitur[[#This Row],[1]],0,0,1,$B$7))<Upaya_Debitur[[#This Row],[Kewajiban Total]],OR($B$7-COUNTIF(OFFSET(Upaya_Debitur[[#This Row],[1]],0,0,1,$B$7),">="&Upaya_Debitur[[#This Row],[Angsuran Diperhitungkan]])>=3,DATEDIF($B$6,EDATE($B$5,$B$8)-1,"D")<120)),"Ya","Tidak") -> Ya | BX25: =IF(Upaya_Debitur[[#This Row],[Kondisi Debitur]]="Tidak ditemukan","Ya","Tidak") -> Tidak | BY25: =IF(AND(Upaya_Debitur[[#This Row],[SP3?]]="Ya",DATEDIF($B$5,$B$6,"D")>=90,Upaya_Debitur[[#This Row],[Haircut Diperhitungkan]]+Upaya_Debitur[[#This Row],[Set Off Diperhitungkan]]+SUM(OFFSET(Upaya_Debitur[[#This Row],[1]],0,0,1,$B$7))<Upaya_Debitur[[#This Row],[Kewajiban Total]]),"Ya","Tidak") -> Ya | BZ25: =IF(AND(Upaya_Debitur[[#This Row],[Iklan Cessie 1?]]="Ya",DATEDIF($B$5,$B$6,"D")>=120,Upaya_Debitur[[#This Row],[Haircut Diperhitungkan]]+Upaya_Debitur[[#This Row],[Set Off Diperhitungkan]]+SUM(OFFSET(Upaya_Debitur[[#This Row],[1]],0,0,1,$B$7))<Upaya_Debitur[[#This Row],[Kewajiban Total]]),"Ya","Tidak") -> Ya | CA25: =IF(AND(ISNUMBER(MATCH(Upaya_Debitur[[#This Row],[Wilayah Hukum]],$E$5:$E$12,0)),Upaya_Debitur[[#This Row],[SP3?]]="Ya",DATEDIF($B$5,$B$6,"D")>=120,Upaya_Debitur[[#This Row],[Haircut Diperhitungkan]]+Upaya_Debitur[[#This Row],[Set Off Diperhitungkan]]+SUM(OFFSET(Upaya_Debitur[[#This Row],[1]],0,0,1,$B$7))<Upaya_Debitur[[#This Row],[Kewajiban Total]],COUNTIFS(Upaya_Agunan[Nomor PK],Upaya_Debitur[[#This Row],[Nomor PK]],Upaya_Agunan[Agunan],"SHM")+COUNTIFS(Upaya_Agunan[Nomor PK],Upaya_Debitur[[#This Row],[Nomor PK]],Upaya_Agunan[Agunan],"SHGB")>0,AND(Upaya_Debitur[[#This Row],[Kewajiban Pokok]]<=500000000,Upaya_Debitur[[#This Row],[Kewajiban Pokok]]>50000000)),"Ya","Tidak") -> Tidak | CB25: 43781 | CC25: 43999 | CD25: 43826 | CE25: 43871 | CF25: 43887 | CH25: 44057 | CI25: 44077 | CK25: =COUNTIF(Upaya_Debitur[[#This Row],[Surat Pemberitahuan?]:[Gugatan Sederhana?]],"Ya") -> 7 | CL25: =Upaya_Debitur[[#This Row],[Target Upaya]]-COUNTIFS(Upaya_Debitur[[#This Row],[Surat Pemberitahuan?]:[Gugatan Sederhana?]],"Ya",Upaya_Debitur[[#This Row],[Surat Pemberitahuan]:[Gugatan Sederhana]],"") -> 7 | CM25: =IF(ISNUMBER(Upaya_Debitur[[#This Row],[Realisasi]]/Upaya_Debitur[[#This Row],[Target Upaya]]),Upaya_Debitur[[#This Row],[Realisasi]]/Upaya_Debitur[[#This Row],[Target Upaya]],1) -> 1 | CQ25: 7 | CR25: =DATE(YEAR(CR24),MONTH(CR24)+2,1)-1 -> 43951 | CS25: =Periode[[#This Row],[Bulan Ke]] -> 7
A26: 8 | C26: 211/BBA-03/0647/IX/1996 | D26: ABDUL JALIL | E26: 1500000 | F26: 0 | G26: 0 | H26: =SUM(Upaya_Debitur[[#This Row],[Kewajiban Pokok]:[Kewajiban Denda]]) -> 1500000 | J26: =IF(ISNUMBER(Upaya_Debitur[[#This Row],[Angsuran Sesuai PK]]),Upaya_Debitur[[#This Row],[Angsuran Sesuai PK]],1) -> 1 | L26: Tidak koperatif | S26: =IF(Upaya_Debitur[[#This Row],[Periode Haircut]]="",0,IF(Upaya_Debitur[[#This Row],[Periode Haircut]]<=$B$6,Upaya_Debitur[[#This Row],[Haircut]],0)) -> 0 | T26: =IF($B$10="",0,IF($B$10<=$B$6,Upaya_Debitur[[#This Row],[Set Off]],0)) -> 0 | U26: 0 | V26: 0 | W26: 1500000 | X26: 0 | Y26: 0 | Z26: 0 | AA26: 0 | AB26: 0 | AC26: 0 | AD26: 0 | AE26: 0 | AF26: 0 | AG26: 0 | AH26: 0 | AI26: 0 | BQ26: =SUM(OFFSET(Upaya_Debitur[[#This Row],[Haircut Diperhitungkan]],0,0,1,$B$7+2)) -> 1500000 | BR26: =IF(Upaya_Debitur[[#This Row],[Total Pencairan]]>=Upaya_Debitur[[#This Row],[Kewajiban Total]],"Lunas","Belum Lunas") -> Lunas | BS26: ="Ya" -> Ya | BT26: ="Ya" -> Ya | BU26: =IF(AND(DATEDIF($B$5,$B$6,"D")>=30,Upaya_Debitur[[#This Row],[Haircut Diperhitungkan]]+Upaya_Debitur[[#This Row],[Set Off Diperhitungkan]]+SUM(OFFSET(Upaya_Debitur[[#This Row],[1]],0,0,1,$B$7))<Upaya_Debitur[[#This Row],[Kewajiban Total]],OR($B$7-COUNTIF(OFFSET(Upaya_Debitur[[#This Row],[1]],0,0,1,$B$7),">="&Upaya_Debitur[[#This Row],[Angsuran Diperhitungkan]])>=1,DATEDIF($B$6,EDATE($B$5,$B$8)-1,"D")<180)),"Ya","Tidak") -> Tidak | BV26: =IF(AND(Upaya_Debitur[[#This Row],[SP 1?]]="Ya",DATEDIF($B$5,$B$6,"D")>=60,Upaya_Debitur[[#This Row],[Haircut Diperhitungkan]]+Upaya_Debitur[[#This Row],[Set Off Diperhitungkan]]+SUM(OFFSET(Upaya_Debitur[[#This Row],[1]],0,0,1,$B$7))<Upaya_Debitur[[#This Row],[Kewajiban Total]],OR($B$7-COUNTIF(OFFSET(Upaya_Debitur[[#This Row],[1]],0,0,1,$B$7),">="&Upaya_Debitur[[#This Row],[Angsuran Diperhitungkan]])>=2,DATEDIF($B$6,EDATE($B$5,$B$8)-1,"D")<150)),"Ya","Tidak") -> Tidak | BW26: =IF(AND(Upaya_Debitur[[#This Row],[SP2?]]="Ya",DATEDIF($B$5,$B$6,"D")>=90,Upaya_Debitur[[#This Row],[Haircut Diperhitungkan]]+Upaya_Debitur[[#This Row],[Set Off Diperhitungkan]]+SUM(OFFSET(Upaya_Debitur[[#This Row],[1]],0,0,1,$B$7))<Upaya_Debitur[[#This Row],[Kewajiban Total]],OR($B$7-COUNTIF(OFFSET(Upaya_Debitur[[#This Row],[1]],0,0,1,$B$7),">="&Upaya_Debitur[[#This Row],[Angsuran Diperhitungkan]])>=3,DATEDIF($B$6,EDATE($B$5,$B$8)-1,"D")<120)),"Ya","Tidak") -> Tidak | BX26: =IF(Upaya_Debitur[[#This Row],[Kondisi Debitur]]="Tidak ditemukan","Ya","Tidak") -> Tidak | BY26: =IF(AND(Upaya_Debitur[[#This Row],[SP3?]]="Ya",DATEDIF($B$5,$B$6,"D")>=90,Upaya_Debitur[[#This Row],[Haircut Diperhitungkan]]+Upaya_Debitur[[#This Row],[Set Off Diperhitungkan]]+SUM(OFFSET(Upaya_Debitur[[#This Row],[1]],0,0,1,$B$7))<Upaya_Debitur[[#This Row],[Kewajiban Total]]),"Ya","Tidak") -> Tidak | BZ26: =IF(AND(Upaya_Debitur[[#This Row],[Iklan Cessie 1?]]="Ya",DATEDIF($B$5,$B$6,"D")>=120,Upaya_Debitur[[#This Row],[Haircut Diperhitungkan]]+Upaya_Debitur[[#This Row],[Set Off Diperhitungkan]]+SUM(OFFSET(Upaya_Debitur[[#This Row],[1]],0,0,1,$B$7))<Upaya_Debitur[[#This Row],[Kewajiban Total]]),"Ya","Tidak") -> Tidak | CA26: =IF(AND(ISNUMBER(MATCH(Upaya_Debitur[[#This Row],[Wilayah Hukum]],$E$5:$E$12,0)),Upaya_Debitur[[#This Row],[SP3?]]="Ya",DATEDIF($B$5,$B$6,"D")>=120,Upaya_Debitur[[#This Row],[Haircut Diperhitungkan]]+Upaya_Debitur[[#This Row],[Set Off Diperhitungkan]]+SUM(OFFSET(Upaya_Debitur[[#This Row],[1]],0,0,1,$B$7))<Upaya_Debitur[[#This Row],[Kewajiban Total]],COUNTIFS(Upaya_Agunan[Nomor PK],Upaya_Debitur[[#This Row],[Nomor PK]],Upaya_Agunan[Agunan],"SHM")+COUNTIFS(Upaya_Agunan[Nomor PK],Upaya_Debitur[[#This Row],[Nomor PK]],Upaya_Agunan[Agunan],"SHGB")>0,AND(Upaya_Debitur[[#This Row],[Kewajiban Pokok]]<=500000000,Upaya_Debitur[[#This Row],[Kewajiban Pokok]]>50000000)),"Ya","Tidak") -> Tidak | CB26: 43781 | CC26: 43871 | CG26: 43888 | CH26: 44057 | CI26: 44077 | CK26: =COUNTIF(Upaya_Debitur[[#This Row],[Surat Pemberitahuan?]:[Gugatan Sederhana?]],"Ya") -> 2 | CL26: =Upaya_Debitur[[#This Row],[Target Upaya]]-COUNTIFS(Upaya_Debitur[[#This Row],[Surat Pemberitahuan?]:[Gugatan Sederhana?]],"Ya",Upaya_Debitur[[#This Row],[Surat Pemberitahuan]:[Gugatan Sederhana]],"") -> 2 | CM26: =IF(ISNUMBER(Upaya_Debitur[[#This Row],[Realisasi]]/Upaya_Debitur[[#This Row],[Target Upaya]]),Upaya_Debitur[[#This Row],[Realisasi]]/Upaya_Debitur[[#This Row],[Target Upaya]],1) -> 1 | CQ26: 8 | CR26: =DATE(YEAR(CR25),MONTH(CR25)+2,1)-1 -> 43982 | CS26: =Periode[[#This Row],[Bulan Ke]] -> 8
A27: 9 | C27: 24/MBA-NAD.K/0030/III/2004 | D27: ABDUL MAJID, MD | E27: 440000 | F27: 0 | G27: 0 | H27: =SUM(Upaya_Debitur[[#This Row],[Kewajiban Pokok]:[Kewajiban Denda]]) -> 440000 | J27: =IF(ISNUMBER(Upaya_Debitur[[#This Row],[Angsuran Sesuai PK]]),Upaya_Debitur[[#This Row],[Angsuran Sesuai PK]],1) -> 1 | L27: Tidak ditemukan | S27: =IF(Upaya_Debitur[[#This Row],[Periode Haircut]]="",0,IF(Upaya_Debitur[[#This Row],[Periode Haircut]]<=$B$6,Upaya_Debitur[[#This Row],[Haircut]],0)) -> 0 | T27: =IF($B$10="",0,IF($B$10<=$B$6,Upaya_Debitur[[#This Row],[Set Off]],0)) -> 0 | U27: 0 | V27: 0 | W27: 0 | X27: 0 | Y27: 0 | Z27: 0 | AA27: 0 | AB27: 0 | AC27: 0 | AD27: 0 | AE27: 0 | AF27: 0 | AG27: 0 | AH27: 0 | AI27: 0 | BQ27: =SUM(OFFSET(Upaya_Debitur[[#This Row],[Haircut Diperhitungkan]],0,0,1,$B$7+2)) -> 0 | BR27: =IF(Upaya_Debitur[[#This Row],[Total Pencairan]]>=Upaya_Debitur[[#This Row],[Kewajiban Total]],"Lunas","Belum Lunas") -> Belum Lunas | BS27: ="Ya" -> Ya | BT27: ="Ya" -> Ya | BU27: =IF(AND(DATEDIF($B$5,$B$6,"D")>=30,Upaya_Debitur[[#This Row],[Haircut Diperhitungkan]]+Upaya_Debitur[[#This Row],[Set Off Diperhitungkan]]+SUM(OFFSET(Upaya_Debitur[[#This Row],[1]],0,0,1,$B$7))<Upaya_Debitur[[#This Row],[Kewajiban Total]],OR($B$7-COUNTIF(OFFSET(Upaya_Debitur[[#This Row],[1]],0,0,1,$B$7),">="&Upaya_Debitur[[#This Row],[Angsuran Diperhitungkan]])>=1,DATEDIF($B$6,EDATE($B$5,$B$8)-1,"D")<180)),"Ya","Tidak") -> Ya | BV27: =IF(AND(Upaya_Debitur[[#This Row],[SP 1?]]="Ya",DATEDIF($B$5,$B$6,"D")>=60,Upaya_Debitur[[#This Row],[Haircut Diperhitungkan]]+Upaya_Debitur[[#This Row],[Set Off Diperhitungkan]]+SUM(OFFSET(Upaya_Debitur[[#This Row],[1]],0,0,1,$B$7))<Upaya_Debitur[[#This Row],[Kewajiban Total]],OR($B$7-COUNTIF(OFFSET(Upaya_Debitur[[#This Row],[1]],0,0,1,$B$7),">="&Upaya_Debitur[[#This Row],[Angsuran Diperhitungkan]])>=2,DATEDIF($B$6,EDATE($B$5,$B$8)-1,"D")<150)),"Ya","Tidak") -> Ya | BW27: =IF(AND(Upaya_Debitur[[#This Row],[SP2?]]="Ya",DATEDIF($B$5,$B$6,"D")>=90,Upaya_Debitur[[#This Row],[Haircut Diperhitungkan]]+Upaya_Debitur[[#This Row],[Set Off Diperhitungkan]]+SUM(OFFSET(Upaya_Debitur[[#This Row],[1]],0,0,1,$B$7))<Upaya_Debitur[[#This Row],[Kewajiban Total]],OR($B$7-COUNTIF(OFFSET(Upaya_Debitur[[#This Row],[1]],0,0,1,$B$7),">="&Upaya_Debitur[[#This Row],[Angsuran Diperhitungkan]])>=3,DATEDIF($B$6,EDATE($B$5,$B$8)-1,"D")<120)),"Ya","Tidak") -> Ya | BX27: =IF(Upaya_Debitur[[#This Row],[Kondisi Debitur]]="Tidak ditemukan","Ya","Tidak") -> Ya | BY27: =IF(AND(Upaya_Debitur[[#This Row],[SP3?]]="Ya",DATEDIF($B$5,$B$6,"D")>=90,Upaya_Debitur[[#This Row],[Haircut Diperhitungkan]]+Upaya_Debitur[[#This Row],[Set Off Diperhitungkan]]+SUM(OFFSET(Upaya_Debitur[[#This Row],[1]],0,0,1,$B$7))<Upaya_Debitur[[#This Row],[Kewajiban Total]]),"Ya","Tidak") -> Ya | BZ27: =IF(AND(Upaya_Debitur[[#This Row],[Iklan Cessie 1?]]="Ya",DATEDIF($B$5,$B$6,"D")>=120,Upaya_Debitur[[#This Row],[Haircut Diperhitungkan]]+Upaya_Debitur[[#This Row],[Set Off Diperhitungkan]]+SUM(OFFSET(Upaya_Debitur[[#This Row],[1]],0,0,1,$B$7))<Upaya_Debitur[[#This Row],[Kewajiban Total]]),"Ya","Tidak") -> Ya | CA27: =IF(AND(ISNUMBER(MATCH(Upaya_Debitur[[#This Row],[Wilayah Hukum]],$E$5:$E$12,0)),Upaya_Debitur[[#This Row],[SP3?]]="Ya",DATEDIF($B$5,$B$6,"D")>=120,Upaya_Debitur[[#This Row],[Haircut Diperhitungkan]]+Upaya_Debitur[[#This Row],[Set Off Diperhitungkan]]+SUM(OFFSET(Upaya_Debitur[[#This Row],[1]],0,0,1,$B$7))<Upaya_Debitur[[#This Row],[Kewajiban Total]],COUNTIFS(Upaya_Agunan[Nomor PK],Upaya_Debitur[[#This Row],[Nomor PK]],Upaya_Agunan[Agunan],"SHM")+COUNTIFS(Upaya_Agunan[Nomor PK],Upaya_Debitur[[#This Row],[Nomor PK]],Upaya_Agunan[Agunan],"SHGB")>0,AND(Upaya_Debitur[[#This Row],[Kewajiban Pokok]]<=500000000,Upaya_Debitur[[#This Row],[Kewajiban Pokok]]>50000000)),"Ya","Tidak") -> Tidak | CB27: 43781 | CC27: 43999 | CD27: 43826 | CE27: 43871 | CF27: 43887 | CG27: 44035 | CH27: 44057 | CI27: 44077 | CK27: =COUNTIF(Upaya_Debitur[[#This Row],[Surat Pemberitahuan?]:[Gugatan Sederhana?]],"Ya") -> 8 | CL27: =Upaya_Debitur[[#This Row],[Target Upaya]]-COUNTIFS(Upaya_Debitur[[#This Row],[Surat Pemberitahuan?]:[Gugatan Sederhana?]],"Ya",Upaya_Debitur[[#This Row],[Surat Pemberitahuan]:[Gugatan Sederhana]],"") -> 8 | CM27: =IF(ISNUMBER(Upaya_Debitur[[#This Row],[Realisasi]]/Upaya_Debitur[[#This Row],[Target Upaya]]),Upaya_Debitur[[#This Row],[Realisasi]]/Upaya_Debitur[[#This Row],[Target Upaya]],1) -> 1 | CQ27: 9 | CR27: =DATE(YEAR(CR26),MONTH(CR26)+2,1)-1 -> 44012 | CS27: =Periode[[#This Row],[Bulan Ke]] -> 9
A28: 10 | C28: 36/MBA-NAD.K/0042/IV/2004 | D28: ABDUL WAHAB | E28: 4000000 | F28: 0 | G28: 0 | H28: =SUM(Upaya_Debitur[[#This Row],[Kewajiban Pokok]:[Kewajiban Denda]]) -> 4000000 | J28: =IF(ISNUMBER(Upaya_Debitur[[#This Row],[Angsuran Sesuai PK]]),Upaya_Debitur[[#This Row],[Angsuran Sesuai PK]],1) -> 1 | L28: Tidak koperatif | S28: =IF(Upaya_Debitur[[#This Row],[Periode Haircut]]="",0,IF(Upaya_Debitur[[#This Row],[Periode Haircut]]<=$B$6,Upaya_Debitur[[#This Row],[Haircut]],0)) -> 0 | T28: =IF($B$10="",0,IF($B$10<=$B$6,Upaya_Debitur[[#This Row],[Set Off]],0)) -> 0 | U28: 0 | V28: 0 | W28: 0 | X28: 0 | Y28: 0 | Z28: 0 | AA28: 0 | AB28: 0 | AC28: 0 | AD28: 0 | AE28: 0 | AF28: 0 | AG28: 0 | AH28: 0 | AI28: 0 | BQ28: =SUM(OFFSET(Upaya_Debitur[[#This Row],[Haircut Diperhitungkan]],0,0,1,$B$7+2)) -> 0 | BR28: =IF(Upaya_Debitur[[#This Row],[Total Pencairan]]>=Upaya_Debitur[[#This Row],[Kewajiban Total]],"Lunas","Belum Lunas") -> Belum Lunas | BS28: ="Ya" -> Ya | BT28: ="Ya" -> Ya | BU28: =IF(AND(DATEDIF($B$5,$B$6,"D")>=30,Upaya_Debitur[[#This Row],[Haircut Diperhitungkan]]+Upaya_Debitur[[#This Row],[Set Off Diperhitungkan]]+SUM(OFFSET(Upaya_Debitur[[#This Row],[1]],0,0,1,$B$7))<Upaya_Debitur[[#This Row],[Kewajiban Total]],OR($B$7-COUNTIF(OFFSET(Upaya_Debitur[[#This Row],[1]],0,0,1,$B$7),">="&Upaya_Debitur[[#This Row],[Angsuran Diperhitungkan]])>=1,DATEDIF($B$6,EDATE($B$5,$B$8)-1,"D")<180)),"Ya","Tidak") -> Ya | BV28: =IF(AND(Upaya_Debitur[[#This Row],[SP 1?]]="Ya",DATEDIF($B$5,$B$6,"D")>=60,Upaya_Debitur[[#This Row],[Haircut Diperhitungkan]]+Upaya_Debitur[[#This Row],[Set Off Diperhitungkan]]+SUM(OFFSET(Upaya_Debitur[[#This Row],[1]],0,0,1,$B$7))<Upaya_Debitur[[#This Row],[Kewajiban Total]],OR($B$7-COUNTIF(OFFSET(Upaya_Debitur[[#This Row],[1]],0,0,1,$B$7),">="&Upaya_Debitur[[#This Row],[Angsuran Diperhitungkan]])>=2,DATEDIF($B$6,EDATE($B$5,$B$8)-1,"D")<150)),"Ya","Tidak") -> Ya | BW28: =IF(AND(Upaya_Debitur[[#This Row],[SP2?]]="Ya",DATEDIF($B$5,$B$6,"D")>=90,Upaya_Debitur[[#This Row],[Haircut Diperhitungkan]]+Upaya_Debitur[[#This Row],[Set Off Diperhitungkan]]+SUM(OFFSET(Upaya_Debitur[[#This Row],[1]],0,0,1,$B$7))<Upaya_Debitur[[#This Row],[Kewajiban Total]],OR($B$7-COUNTIF(OFFSET(Upaya_Debitur[[#This Row],[1]],0,0,1,$B$7),">="&Upaya_Debitur[[#This Row],[Angsuran Diperhitungkan]])>=3,DATEDIF($B$6,EDATE($B$5,$B$8)-1,"D")<120)),"Ya","Tidak") -> Ya | BX28: =IF(Upaya_Debitur[[#This Row],[Kondisi Debitur]]="Tidak ditemukan","Ya","Tidak") -> Tidak | BY28: =IF(AND(Upaya_Debitur[[#This Row],[SP3?]]="Ya",DATEDIF($B$5,$B$6,"D")>=90,Upaya_Debitur[[#This Row],[Haircut Diperhitungkan]]+Upaya_Debitur[[#This Row],[Set Off Diperhitungkan]]+SUM(OFFSET(Upaya_Debitur[[#This Row],[1]],0,0,1,$B$7))<Upaya_Debitur[[#This Row],[Kewajiban Total]]),"Ya","Tidak") -> Ya | BZ28: =IF(AND(Upaya_Debitur[[#This Row],[Iklan Cessie 1?]]="Ya",DATEDIF($B$5,$B$6,"D")>=120,Upaya_Debitur[[#This Row],[Haircut Diperhitungkan]]+Upaya_Debitur[[#This Row],[Set Off Diperhitungkan]]+SUM(OFFSET(Upaya_Debitur[[#This Row],[1]],0,0,1,$B$7))<Upaya_Debitur[[#This Row],[Kewajiban Total]]),"Ya","Tidak") -> Ya | CA28: =IF(AND(ISNUMBER(MATCH(Upaya_Debitur[[#This Row],[Wilayah Hukum]],$E$5:$E$12,0)),Upaya_Debitur[[#This Row],[SP3?]]="Ya",DATEDIF($B$5,$B$6,"D")>=120,Upaya_Debitur[[#This Row],[Haircut Diperhitungkan]]+Upaya_Debitur[[#This Row],[Set Off Diperhitungkan]]+SUM(OFFSET(Upaya_Debitur[[#This Row],[1]],0,0,1,$B$7))<Upaya_Debitur[[#This Row],[Kewajiban Total]],COUNTIFS(Upaya_Agunan[Nomor PK],Upaya_Debitur[[#This Row],[Nomor PK]],Upaya_Agunan[Agunan],"SHM")+COUNTIFS(Upaya_Agunan[Nomor PK],Upaya_Debitur[[#This Row],[Nomor PK]],Upaya_Agunan[Agunan],"SHGB")>0,AND(Upaya_Debitur[[#This Row],[Kewajiban Pokok]]<=500000000,Upaya_Debitur[[#This Row],[Kewajiban Pokok]]>50000000)),"Ya","Tidak") -> Tidak | CB28: 43781 | CC28: 43999 | CD28: 43826 | CE28: 43871 | CF28: 43887 | CG28: 43888 | CH28: 44057 | CI28: 44077 | CK28: =COUNTIF(Upaya_Debitur[[#This Row],[Surat Pemberitahuan?]:[Gugatan Sederhana?]],"Ya") -> 7 | CL28: =Upaya_Debitur[[#This Row],[Target Upaya]]-COUNTIFS(Upaya_Debitur[[#This Row],[Surat Pemberitahuan?]:[Gugatan Sederhana?]],"Ya",Upaya_Debitur[[#This Row],[Surat Pemberitahuan]:[Gugatan Sederhana]],"") -> 7 | CM28: =IF(ISNUMBER(Upaya_Debitur[[#This Row],[Realisasi]]/Upaya_Debitur[[#This Row],[Target Upaya]]),Upaya_Debitur[[#This Row],[Realisasi]]/Upaya_Debitur[[#This Row],[Target Upaya]],1) -> 1 | CQ28: 10 | CR28: =DATE(YEAR(CR27),MONTH(CR27)+2,1)-1 -> 44043 | CS28: =Periode[[#This Row],[Bulan Ke]] -> 10
A29: 11 | C29: 132/BBA-03/0849/VII/1997 | D29: ABDULLAH | E29: 271500 | F29: 0 | G29: 0 | H29: =SUM(Upaya_Debitur[[#This Row],[Kewajiban Pokok]:[Kewajiban Denda]]) -> 271500 | J29: =IF(ISNUMBER(Upaya_Debitur[[#This Row],[Angsuran Sesuai PK]]),Upaya_Debitur[[#This Row],[Angsuran Sesuai PK]],1) -> 1 | L29: Tidak ditemukan | S29: =IF(Upaya_Debitur[[#This Row],[Periode Haircut]]="",0,IF(Upaya_Debitur[[#This Row],[Periode Haircut]]<=$B$6,Upaya_Debitur[[#This Row],[Haircut]],0)) -> 0 | T29: =IF($B$10="",0,IF($B$10<=$B$6,Upaya_Debitur[[#This Row],[Set Off]],0)) -> 0 | U29: 0 | V29: 0 | W29: 0 | X29: 0 | Y29: 0 | Z29: 0 | AA29: 0 | AB29: 0 | AC29: 0 | AD29: 0 | AE29: 0 | AF29: 0 | AG29: 0 | AH29: 0 | AI29: 0 | BQ29: =SUM(OFFSET(Upaya_Debitur[[#This Row],[Haircut Diperhitungkan]],0,0,1,$B$7+2)) -> 0 | BR29: =IF(Upaya_Debitur[[#This Row],[Total Pencairan]]>=Upaya_Debitur[[#This Row],[Kewajiban Total]],"Lunas","Belum Lunas") -> Belum Lunas | BS29: ="Ya" -> Ya | BT29: ="Ya" -> Ya | BU29: =IF(AND(DATEDIF($B$5,$B$6,"D")>=30,Upaya_Debitur[[#This Row],[Haircut Diperhitungkan]]+Upaya_Debitur[[#This Row],[Set Off Diperhitungkan]]+SUM(OFFSET(Upaya_Debitur[[#This Row],[1]],0,0,1,$B$7))<Upaya_Debitur[[#This Row],[Kewajiban Total]],OR($B$7-COUNTIF(OFFSET(Upaya_Debitur[[#This Row],[1]],0,0,1,$B$7),">="&Upaya_Debitur[[#This Row],[Angsuran Diperhitungkan]])>=1,DATEDIF($B$6,EDATE($B$5,$B$8)-1,"D")<180)),"Ya","Tidak") -> Ya | BV29: =IF(AND(Upaya_Debitur[[#This Row],[SP 1?]]="Ya",DATEDIF($B$5,$B$6,"D")>=60,Upaya_Debitur[[#This Row],[Haircut Diperhitungkan]]+Upaya_Debitur[[#This Row],[Set Off Diperhitungkan]]+SUM(OFFSET(Upaya_Debitur[[#This Row],[1]],0,0,1,$B$7))<Upaya_Debitur[[#This Row],[Kewajiban Total]],OR($B$7-COUNTIF(OFFSET(Upaya_Debitur[[#This Row],[1]],0,0,1,$B$7),">="&Upaya_Debitur[[#This Row],[Angsuran Diperhitungkan]])>=2,DATEDIF($B$6,EDATE($B$5,$B$8)-1,"D")<150)),"Ya","Tidak") -> Ya | BW29: =IF(AND(Upaya_Debitur[[#This Row],[SP2?]]="Ya",DATEDIF($B$5,$B$6,"D")>=90,Upaya_Debitur[[#This Row],[Haircut Diperhitungkan]]+Upaya_Debitur[[#This Row],[Set Off Diperhitungkan]]+SUM(OFFSET(Upaya_Debitur[[#This Row],[1]],0,0,1,$B$7))<Upaya_Debitur[[#This Row],[Kewajiban Total]],OR($B$7-COUNTIF(OFFSET(Upaya_Debitur[[#This Row],[1]],0,0,1,$B$7),">="&Upaya_Debitur[[#This Row],[Angsuran Diperhitungkan]])>=3,DATEDIF($B$6,EDATE($B$5,$B$8)-1,"D")<120)),"Ya","Tidak") -> Ya | BX29: =IF(Upaya_Debitur[[#This Row],[Kondisi Debitur]]="Tidak ditemukan","Ya","Tidak") -> Ya | BY29: =IF(AND(Upaya_Debitur[[#This Row],[SP3?]]="Ya",DATEDIF($B$5,$B$6,"D")>=90,Upaya_Debitur[[#This Row],[Haircut Diperhitungkan]]+Upaya_Debitur[[#This Row],[Set Off Diperhitungkan]]+SUM(OFFSET(Upaya_Debitur[[#This Row],[1]],0,0,1,$B$7))<Upaya_Debitur[[#This Row],[Kewajiban Total]]),"Ya","Tidak") -> Ya | BZ29: =IF(AND(Upaya_Debitur[[#This Row],[Iklan Cessie 1?]]="Ya",DATEDIF($B$5,$B$6,"D")>=120,Upaya_Debitur[[#This Row],[Haircut Diperhitungkan]]+Upaya_Debitur[[#This Row],[Set Off Diperhitungkan]]+SUM(OFFSET(Upaya_Debitur[[#This Row],[1]],0,0,1,$B$7))<Upaya_Debitur[[#This Row],[Kewajiban Total]]),"Ya","Tidak") -> Ya | CA29: =IF(AND(ISNUMBER(MATCH(Upaya_Debitur[[#This Row],[Wilayah Hukum]],$E$5:$E$12,0)),Upaya_Debitur[[#This Row],[SP3?]]="Ya",DATEDIF($B$5,$B$6,"D")>=120,Upaya_Debitur[[#This Row],[Haircut Diperhitungkan]]+Upaya_Debitur[[#This Row],[Set Off Diperhitungkan]]+SUM(OFFSET(Upaya_Debitur[[#This Row],[1]],0,0,1,$B$7))<Upaya_Debitur[[#This Row],[Kewajiban Total]],COUNTIFS(Upaya_Agunan[Nomor PK],Upaya_Debitur[[#This Row],[Nomor PK]],Upaya_Agunan[Agunan],"SHM")+COUNTIFS(Upaya_Agunan[Nomor PK],Upaya_Debitur[[#This Row],[Nomor PK]],Upaya_Agunan[Agunan],"SHGB")>0,AND(Upaya_Debitur[[#This Row],[Kewajiban Pokok]]<=500000000,Upaya_Debitur[[#This Row],[Kewajiban Pokok]]>50000000)),"Ya","Tidak") -> Tidak | CB29: 43781 | CC29: 43999 | CD29: 43826 | CE29: 43871 | CF29: 43887 | CG29: 44035 | CH29: 44057 | CI29: 44077 | CK29: =COUNTIF(Upaya_Debitur[[#This Row],[Surat Pemberitahuan?]:[Gugatan Sederhana?]],"Ya") -> 8 | CL29: =Upaya_Debitur[[#This Row],[Target Upaya]]-COUNTIFS(Upaya_Debitur[[#This Row],[Surat Pemberitahuan?]:[Gugatan Sederhana?]],"Ya",Upaya_Debitur[[#This Row],[Surat Pemberitahuan]:[Gugatan Sederhana]],"") -> 8 | CM29: =IF(ISNUMBER(Upaya_Debitur[[#This Row],[Realisasi]]/Upaya_Debitur[[#This Row],[Target Upaya]]),Upaya_Debitur[[#This Row],[Realisasi]]/Upaya_Debitur[[#This Row],[Target Upaya]],1) -> 1 | CQ29: 11 | CR29: =DATE(YEAR(CR28),MONTH(CR28)+2,1)-1 -> 44074 | CS29: =Periode[[#This Row],[Bulan Ke]] -> 11
A30: 12 | C30: 077/MBA-02/0719/III/2002 | D30: ABDULLAH | E30: 5000000 | F30: 0 | G30: 0 | H30: =SUM(Upaya_Debitur[[#This Row],[Kewajiban Pokok]:[Kewajiban Denda]]) -> 5000000 | J30: =IF(ISNUMBER(Upaya_Debitur[[#This Row],[Angsuran Sesuai PK]]),Upaya_Debitur[[#This Row],[Angsuran Sesuai PK]],1) -> 1 | L30: Tidak koperatif | S30: =IF(Upaya_Debitur[[#This Row],[Periode Haircut]]="",0,IF(Upaya_Debitur[[#This Row],[Periode Haircut]]<=$B$6,Upaya_Debitur[[#This Row],[Haircut]],0)) -> 0 | T30: =IF($B$10="",0,IF($B$10<=$B$6,Upaya_Debitur[[#This Row],[Set Off]],0)) -> 0 | U30: 0 | V30: 0 | W30: 0 | X30: 0 | Y30: 0 | Z30: 0 | AA30: 0 | AB30: 0 | AC30: 0 | AD30: 0 | AE30: 0 | AF30: 0 | AG30: 0 | AH30: 0 | AI30: 0 | BQ30: =SUM(OFFSET(Upaya_Debitur[[#This Row],[Haircut Diperhitungkan]],0,0,1,$B$7+2)) -> 0 | BR30: =IF(Upaya_Debitur[[#This Row],[Total Pencairan]]>=Upaya_Debitur[[#This Row],[Kewajiban Total]],"Lunas","Belum Lunas") -> Belum Lunas | BS30: ="Ya" -> Ya | BT30: ="Ya" -> Ya | BU30: =IF(AND(DATEDIF($B$5,$B$6,"D")>=30,Upaya_Debitur[[#This Row],[Haircut Diperhitungkan]]+Upaya_Debitur[[#This Row],[Set Off Diperhitungkan]]+SUM(OFFSET(Upaya_Debitur[[#This Row],[1]],0,0,1,$B$7))<Upaya_Debitur[[#This Row],[Kewajiban Total]],OR($B$7-COUNTIF(OFFSET(Upaya_Debitur[[#This Row],[1]],0,0,1,$B$7),">="&Upaya_Debitur[[#This Row],[Angsuran Diperhitungkan]])>=1,DATEDIF($B$6,EDATE($B$5,$B$8)-1,"D")<180)),"Ya","Tidak") -> Ya | BV30: =IF(AND(Upaya_Debitur[[#This Row],[SP 1?]]="Ya",DATEDIF($B$5,$B$6,"D")>=60,Upaya_Debitur[[#This Row],[Haircut Diperhitungkan]]+Upaya_Debitur[[#This Row],[Set Off Diperhitungkan]]+SUM(OFFSET(Upaya_Debitur[[#This Row],[1]],0,0,1,$B$7))<Upaya_Debitur[[#This Row],[Kewajiban Total]],OR($B$7-COUNTIF(OFFSET(Upaya_Debitur[[#This Row],[1]],0,0,1,$B$7),">="&Upaya_Debitur[[#This Row],[Angsuran Diperhitungkan]])>=2,DATEDIF($B$6,EDATE($B$5,$B$8)-1,"D")<150)),"Ya","Tidak") -> Ya | BW30: =IF(AND(Upaya_Debitur[[#This Row],[SP2?]]="Ya",DATEDIF($B$5,$B$6,"D")>=90,Upaya_Debitur[[#This Row],[Haircut Diperhitungkan]]+Upaya_Debitur[[#This Row],[Set Off Diperhitungkan]]+SUM(OFFSET(Upaya_Debitur[[#This Row],[1]],0,0,1,$B$7))<Upaya_Debitur[[#This Row],[Kewajiban Total]],OR($B$7-COUNTIF(OFFSET(Upaya_Debitur[[#This Row],[1]],0,0,1,$B$7),">="&Upaya_Debitur[[#This Row],[Angsuran Diperhitungkan]])>=3,DATEDIF($B$6,EDATE($B$5,$B$8)-1,"D")<120)),"Ya","Tidak") -> Ya | BX30: =IF(Upaya_Debitur[[#This Row],[Kondisi Debitur]]="Tidak ditemukan","Ya","Tidak") -> Tidak | BY30: =IF(AND(Upaya_Debitur[[#This Row],[SP3?]]="Ya",DATEDIF($B$5,$B$6,"D")>=90,Upaya_Debitur[[#This Row],[Haircut Diperhitungkan]]+Upaya_Debitur[[#This Row],[Set Off Diperhitungkan]]+SUM(OFFSET(Upaya_Debitur[[#This Row],[1]],0,0,1,$B$7))<Upaya_Debitur[[#This Row],[Kewajiban Total]]),"Ya","Tidak") -> Ya | BZ30: =IF(AND(Upaya_Debitur[[#This Row],[Iklan Cessie 1?]]="Ya",DATEDIF($B$5,$B$6,"D")>=120,Upaya_Debitur[[#This Row],[Haircut Diperhitungkan]]+Upaya_Debitur[[#This Row],[Set Off Diperhitungkan]]+SUM(OFFSET(Upaya_Debitur[[#This Row],[1]],0,0,1,$B$7))<Upaya_Debitur[[#This Row],[Kewajiban Total]]),"Ya","Tidak") -> Ya | CA30: =IF(AND(ISNUMBER(MATCH(Upaya_Debitur[[#This Row],[Wilayah Hukum]],$E$5:$E$12,0)),Upaya_Debitur[[#This Row],[SP3?]]="Ya",DATEDIF($B$5,$B$6,"D")>=120,Upaya_Debitur[[#This Row],[Haircut Diperhitungkan]]+Upaya_Debitur[[#This Row],[Set Off Diperhitungkan]]+SUM(OFFSET(Upaya_Debitur[[#This Row],[1]],0,0,1,$B$7))<Upaya_Debitur[[#This Row],[Kewajiban Total]],COUNTIFS(Upaya_Agunan[Nomor PK],Upaya_Debitur[[#This Row],[Nomor PK]],Upaya_Agunan[Agunan],"SHM")+COUNTIFS(Upaya_Agunan[Nomor PK],Upaya_Debitur[[#This Row],[Nomor PK]],Upaya_Agunan[Agunan],"SHGB")>0,AND(Upaya_Debitur[[#This Row],[Kewajiban Pokok]]<=500000000,Upaya_Debitur[[#This Row],[Kewajiban Pokok]]>50000000)),"Ya","Tidak") -> Tidak | CB30: 43781 | CC30: 43999 | CD30: 43826 | CE30: 43871 | CF30: 43887 | CG30: 43888 | CH30: 44057 | CI30: 44077 | CK30: =COUNTIF(Upaya_Debitur[[#This Row],[Surat Pemberitahuan?]:[Gugatan Sederhana?]],"Ya") -> 7 | CL30: =Upaya_Debitur[[#This Row],[Target Upaya]]-COUNTIFS(Upaya_Debitur[[#This Row],[Surat Pemberitahuan?]:[Gugatan Sederhana?]],"Ya",Upaya_Debitur[[#This Row],[Surat Pemberitahuan]:[Gugatan Sederhana]],"") -> 7 | CM30: =IF(ISNUMBER(Upaya_Debitur[[#This Row],[Realisasi]]/Upaya_Debitur[[#This Row],[Target Upaya]]),Upaya_Debitur[[#This Row],[Realisasi]]/Upaya_Debitur[[#This Row],[Target Upaya]],1) -> 1 | CQ30: 12 | CR30: =DATE(YEAR(CR29),MONTH(CR29)+2,1)-1 -> 44104 | CS30: =Periode[[#This Row],[Bulan Ke]] -> 12
